Workbook

Sheet Guidelines
A1: CO–PO MAPPING: 20 ADDITIONAL METHODS — Auto-Calculation Workbook
A2: Based on: NBA OBE Guidelines | Additional Methods beyond Contact Hours, Assessment Tools, Assessment Type, Keywords & Rubrics
A4: UNIVERSAL MAPPING LEVELS (apply to all 20 methods)
A5: Level | B5: Symbol | C5: General Threshold | D5: Meaning | E5: Example From Methods
A6: No Mapping | B6: — | C6: Score=0 / No link | D6: CO does not contribute to PO | E6: No industry relevance; no tool usage; individual task only
A7: Low | B7: 1 | C7: Low score / partial link | D7: Small contribution to PO | E7: Simple theoretical problem; observation-only lab; reading only
A8: Medium | B8: 2 | C8: Moderate score / major link | D8: Moderate contribution to PO | E8: Guided experiment; mini project; moderate industry relevance
A9: High | B9: 3 | C9: High score / exact match | D9: Strong contribution to PO | E9: Design+implement+analyze lab; capstone project; strong real-world application
A11: 20 ADDITIONAL METHODS — QUICK REFERENCE
A12: # | B12: ID | C12: Method Name | D12: Input Type | E12: Mapping Formula / Logic | F12: Primary POs
A13: 1 | B13: M01 | C13: Bloom's Taxonomy Level | D13: Bloom Level (1–6) | E13: '=IF(input>=5,3,IF(input>=3,2,IF(input>=1,1,0))) | F13: PO1 | PO2 | PO3
A14: 2 | B14: M02 | C14: Syllabus Content Coverage | D14: Percentage (0–100) | E14: '=IF(input>40,3,IF(input>15,2,IF(input>5,1,0))) | F14: PO1 | PO2
A15: 3 | B15: M03 | C15: Problem Complexity | D15: Level (0–3) | E15: '=IF(input>=3,3,IF(input>=2,2,IF(input>=1,1,0))) | F15: PO2 | PO3
A16: 4 | B16: M04 | C16: Laboratory Experiment Depth | D16: Level (0–3) | E16: '=IF(input>=3,3,IF(input>=2,2,IF(input>=1,1,0))) | F16: PO4 | PO5
A17: 5 | B17: M05 | C17: Industry/Relevance Based | D17: Level (0–3) | E17: '=IF(input>=3,3,IF(input>=2,2,IF(input>=1,1,0))) | F17: PO3 | PO5 | PO11
A18: 6 | B18: M06 | C18: Project-Based Mapping | D18: Level (0–3) | E18: '=IF(input>=3,3,IF(input>=2,2,IF(input>=1,1,0))) | F18: PO3 | PO9 | PO10 | PO11
A19: 7 | B19: M07 | C19: Practical Skill Demonstration | D19: Level (0–3) | E19: '=IF(input>=3,3,IF(input>=2,2,IF(input>=1,1,0))) | F19: PO5 | PO4
A20: 8 | B20: M08 | C20: Real-World Application | D20: Level (0–3) | E20: '=IF(input>=3,3,IF(input>=2,2,IF(input>=1,1,0))) | F20: PO6 | PO7
A21: 9 | B21: M09 | C21: Interdisciplinary Integration | D21: Level (0–3) | E21: '=IF(input>=3,3,IF(input>=2,2,IF(input>=1,1,0))) | F21: PO3 | PO5 | PO12
A22: 10 | B22: M10 | C22: Innovation and Creativity | D22: Level (0–3) | E22: '=IF(input>=3,3,IF(input>=2,2,IF(input>=1,1,0))) | F22: PO3 | PO12
A23: 11 | B23: M11 | C23: Research Orientation | D23: Level (0–3) | E23: '=IF(input>=3,3,IF(input>=2,2,IF(input>=1,1,0))) | F23: PO4 | PO12
A24: 12 | B24: M12 | C24: Teamwork Contribution | D24: Level (0–3) | E24: '=IF(input>=3,3,IF(input>=2,2,IF(input>=1,1,0))) | F24: PO9
... A32: 20 | B32: M20 | C32: Weighted Rubric Score | D32: Percentage (0–100) | E32: '=IF(input>70,3,IF(input>40,2,IF(input>0,1,0))) | F32: PO5 | PO9 | PO10 | PO11
A34: NBA RECOMMENDED: COMBINED APPROACH (Multiple Methods Together)
A35: Criterion | B35: Weight | C35: Sheet Reference
A36: Keywords/Action Verbs | B36: 20% | C36: Keywords_CO_PO_Mapping.xlsx
A37: Contact Hours (L-T-P-S) | B37: 20% | C37: LTPS_CO_PO_Mapping_AutoCalc.xlsx
A38: Assessment Type | B38: 20% | C38: AssessmentType_CO_PO_Mapping.xlsx
A39: Rubric-Based Records | B39: 20% | C39: CriticalAssessment_PO5_PO12_Mapping.xlsx
A40: Bloom's Taxonomy Level | B40: 20% | C40: This workbook — Method M01
A42: HOW TO USE THIS WORKBOOK
A43: 1. Open any course sheet (CS301–CS305) → Enter input score in YELLOW cells per method per CO
A44: 2. Input types: Bloom Level (1–6) for M01 | Percentage (0–100) for M02,M16,M17,M20 | Level 0–3 for all others
A45: 3. Mapping Level auto-calculates using the formula for each method → Symbol (—/1/2/3) also auto-shown
A46: 4. Weighted Combined Score auto-calculates: weighted average of all 20 method levels
A47: 5. Final Mapping Level auto-derived from combined score
A48: 6. 'Combined CO-PO Matrix' sheet — full matrix showing final combined levels for all courses
A49: 7. 'Method Comparison' sheet — see how each method scores per CO for detailed NBA justification
A50: 8. 'PO Summary Dashboard' — programme-level attainment across all 20 methods

Sheet CS301
A1: ADDITIONAL CO–PO MAPPING (20 Methods) — Data Structures & Algorithms (CS301)
A2: Enter input scores in YELLOW cells per method per CO | Level auto-calculates per method | Combined weighted score gives Final Mapping Level | All 20 methods from NBA OBE Additional Guidelines
A4: Input Types → | C4: Bloom 1–6 | D4: Percent 0–100 | E4: Level 0–3 | F4: Weighted % 0–100
A5: CO | B5: CO Topic | C5: INPUT SCORES (Edit Yellow Cells) | W5: MAPPING LEVELS (Auto-Calculated per Method) | AQ5: Combined Weighted Score | AR5: Final Mapping Level | AS5: Final Symbol | AT5: PROGRAMME OUTCOMES (PO1–PO12) | BF5: PSOs
B6: Method → | C6: M01 | D6: M02 | E6: M03 | F6: M04 | G6: M05 | H6: M06 | I6: M07 | J6: M08 | K6: M09 | L6: M10 | M6: M11 | N6: M12 | O6: M13 | P6: M14 | Q6: M15 | R6: M16 | S6: M17 | T6: M18 | U6: M19 | V6: M20 | W6: M01 | X6: M02 | Y6: M03 | Z6: M04 | AA6: M05 | AB6: M06 | AC6: M07 | AD6: M08 | AE6: M09 | AF6: M10 | AG6: M11 | AH6: M12 | AI6: M13 | AJ6: M14 | AK6: M15 | AL6: M16 | AM6: M17 | AN6: M18 | AO6: M19 | AP6: M20 | AQ6: Wtd Avg | AR6: 0–3 | AS6: —/1/2/3 | AT6: PO1 | AU6: PO2 | AV6: PO3 | AW6: PO4 | AX6: PO5 | AY6: PO6 | AZ6: PO7 | BA6: PO8 | BB6: PO9 | BC6: PO10 | BD6: PO11 | BE6: PO12 | BF6: PSO1 | BG6: PSO2 | BH6: PSO3
A7: Method Weights (Equal = 5%) | C7: 0.05 | D7: 0.05 | E7: 0.05 | F7: 0.05 | G7: 0.05 | H7: 0.05 | I7: 0.05 | J7: 0.05 | K7: 0.05 | L7: 0.05 | M7: 0.05 | N7: 0.05 | O7: 0.05 | P7: 0.05 | Q7: 0.05 | R7: 0.05 | S7: 0.05 | T7: 0.05 | U7: 0.05 | V7: 0.05 | AQ7: =SUM(C7:V7) -> 1
A8: ↓ Enter scores in YELLOW cells (columns C–V) → All calculations auto-update ↓
A9: CO1 | B9: Arrays, Linked Lists, Stacks, Queues | C9: 3 | D9: 35 | E9: 2 | F9: 2 | G9: 2 | H9: 1 | I9: 2 | J9: 1 | K9: 1 | L9: 1 | M9: 1 | N9: 1 | O9: 1 | P9: 2 | Q9: 1 | R9: 40 | S9: 72 | T9: 2 | U9: 1 | V9: 55 | W9: =IF(C9>=5,3,IF(C9>=3,2,IF(C9>=1,1,0))) -> 2 | X9: =IF(D9>40,3,IF(D9>15,2,IF(D9>5,1,0))) -> 2 | Y9: =IF(E9>=3,3,IF(E9>=2,2,IF(E9>=1,1,0))) -> 2 | Z9: =IF(F9>=3,3,IF(F9>=2,2,IF(F9>=1,1,0))) -> 2 | AA9: =IF(G9>=3,3,IF(G9>=2,2,IF(G9>=1,1,0))) -> 2 | AB9: =IF(H9>=3,3,IF(H9>=2,2,IF(H9>=1,1,0))) -> 1 | AC9: =IF(I9>=3,3,IF(I9>=2,2,IF(I9>=1,1,0))) -> 2 | AD9: =IF(J9>=3,3,IF(J9>=2,2,IF(J9>=1,1,0))) -> 1 | AE9: =IF(K9>=3,3,IF(K9>=2,2,IF(K9>=1,1,0))) -> 1 | AF9: =IF(L9>=3,3,IF(L9>=2,2,IF(L9>=1,1,0))) -> 1 | ... AK9: =IF(Q9>=3,3,IF(Q9>=2,2,IF(Q9>=1,1,0))) -> 1 | AL9: =IF(R9>60,3,IF(R9>40,2,IF(R9>25,1,0))) -> 1 | AM9: =IF(S9>70,3,IF(S9>50,2,IF(S9>40,1,0))) -> 3 | AN9: =IF(T9>=3,3,IF(T9>=2,2,IF(T9>=1,1,0))) -> 2 | AO9: =IF(U9>=3,3,IF(U9>=2,2,IF(U9>=1,1,0))) -> 1 | AP9: =IF(V9>70,3,IF(V9>40,2,IF(V9>0,1,0))) -> 2 | AQ9: =IFERROR(SUMPRODUCT(C7:V7,W9:AP9)/SUM(C7:V7),0) -> 1.55 | AR9: =IF(AQ9>=2.5,3,IF(AQ9>=1.5,2,IF(AQ9>=0.5,1,0))) -> 2 | AS9: =IF(AR9=0,"—",TEXT(AR9,"0")) -> 2 | AT9: =IF(AR9=0,"—",TEXT(AR9,"0")) -> 2 | AU9: =IF(AR9=0,"—",TEXT(AR9,"0")) -> 2 | AV9: =IF(AR9=0,"—",TEXT(AR9,"0")) -> 2 | AW9: — | AX9: — | AY9: — | AZ9: — | BA9: — | BB9: — | BC9: — | BD9: — | BE9: =IF(AR9=0,"—",TEXT(AR9,"0")) -> 2 | BF9: — | BG9: — | BH9: —
A10: CO2 | B10: Trees and Binary Search Trees | C10: 4 | D10: 40 | E10: 3 | F10: 2 | G10: 2 | H10: 2 | I10: 2 | J10: 2 | K10: 1 | L10: 2 | M10: 2 | N10: 2 | O10: 1 | P10: 2 | Q10: 1 | R10: 45 | S10: 75 | T10: 2 | U10: 1 | V10: 60 | W10: =IF(C10>=5,3,IF(C10>=3,2,IF(C10>=1,1,0))) -> 2 | X10: =IF(D10>40,3,IF(D10>15,2,IF(D10>5,1,0))) -> 2 | Y10: =IF(E10>=3,3,IF(E10>=2,2,IF(E10>=1,1,0))) -> 3 | Z10: =IF(F10>=3,3,IF(F10>=2,2,IF(F10>=1,1,0))) -> 2 | AA10: =IF(G10>=3,3,IF(G10>=2,2,IF(G10>=1,1,0))) -> 2 | AB10: =IF(H10>=3,3,IF(H10>=2,2,IF(H10>=1,1,0))) -> 2 | AC10: =IF(I10>=3,3,IF(I10>=2,2,IF(I10>=1,1,0))) -> 2 | AD10: =IF(J10>=3,3,IF(J10>=2,2,IF(J10>=1,1,0))) -> 2 | AE10: =IF(K10>=3,3,IF(K10>=2,2,IF(K10>=1,1,0))) -> 1 | AF10: =IF(L10>=3,3,IF(L10>=2,2,IF(L10>=1,1,0))) -> 2 | ... AK10: =IF(Q10>=3,3,IF(Q10>=2,2,IF(Q10>=1,1,0))) -> 1 | AL10: =IF(R10>60,3,IF(R10>40,2,IF(R10>25,1,0))) -> 2 | AM10: =IF(S10>70,3,IF(S10>50,2,IF(S10>40,1,0))) -> 3 | AN10: =IF(T10>=3,3,IF(T10>=2,2,IF(T10>=1,1,0))) -> 2 | AO10: =IF(U10>=3,3,IF(U10>=2,2,IF(U10>=1,1,0))) -> 1 | AP10: =IF(V10>70,3,IF(V10>40,2,IF(V10>0,1,0))) -> 2 | AQ10: =IFERROR(SUMPRODUCT(C7:V7,W10:AP10)/SUM(C7:V7),0) -> 1.9 | AR10: =IF(AQ10>=2.5,3,IF(AQ10>=1.5,2,IF(AQ10>=0.5,1,0))) -> 2 | AS10: =IF(AR10=0,"—",TEXT(AR10,"0")) -> 2 | AT10: =IF(AR10=0,"—",TEXT(AR10,"0")) -> 2 | AU10: =IF(AR10=0,"—",TEXT(AR10,"0")) -> 2 | AV10: =IF(AR10=0,"—",TEXT(AR10,"0")) -> 2 | AW10: =IF(AR10=0,"—",TEXT(AR10,"0")) -> 2 | AX10: — | AY10: — | AZ10: — | BA10: — | BB10: — | BC10: — | BD10: — | BE10: =IF(AR10=0,"—",TEXT(AR10,"0")) -> 2 | BF10: — | BG10: — | BH10: —
A11: CO3 | B11: Graphs: BFS, DFS, Shortest Paths | C11: 5 | D11: 45 | E11: 3 | F11: 3 | G11: 3 | H11: 2 | I11: 3 | J11: 2 | K11: 2 | L11: 2 | M11: 2 | N11: 2 | O11: 2 | P11: 3 | Q11: 2 | R11: 55 | S11: 78 | T11: 3 | U11: 2 | V11: 72 | W11: =IF(C11>=5,3,IF(C11>=3,2,IF(C11>=1,1,0))) -> 3 | X11: =IF(D11>40,3,IF(D11>15,2,IF(D11>5,1,0))) -> 3 | Y11: =IF(E11>=3,3,IF(E11>=2,2,IF(E11>=1,1,0))) -> 3 | Z11: =IF(F11>=3,3,IF(F11>=2,2,IF(F11>=1,1,0))) -> 3 | AA11: =IF(G11>=3,3,IF(G11>=2,2,IF(G11>=1,1,0))) -> 3 | AB11: =IF(H11>=3,3,IF(H11>=2,2,IF(H11>=1,1,0))) -> 2 | AC11: =IF(I11>=3,3,IF(I11>=2,2,IF(I11>=1,1,0))) -> 3 | AD11: =IF(J11>=3,3,IF(J11>=2,2,IF(J11>=1,1,0))) -> 2 | AE11: =IF(K11>=3,3,IF(K11>=2,2,IF(K11>=1,1,0))) -> 2 | AF11: =IF(L11>=3,3,IF(L11>=2,2,IF(L11>=1,1,0))) -> 2 | ... AK11: =IF(Q11>=3,3,IF(Q11>=2,2,IF(Q11>=1,1,0))) -> 2 | AL11: =IF(R11>60,3,IF(R11>40,2,IF(R11>25,1,0))) -> 2 | AM11: =IF(S11>70,3,IF(S11>50,2,IF(S11>40,1,0))) -> 3 | AN11: =IF(T11>=3,3,IF(T11>=2,2,IF(T11>=1,1,0))) -> 3 | AO11: =IF(U11>=3,3,IF(U11>=2,2,IF(U11>=1,1,0))) -> 2 | AP11: =IF(V11>70,3,IF(V11>40,2,IF(V11>0,1,0))) -> 3 | AQ11: =IFERROR(SUMPRODUCT(C7:V7,W11:AP11)/SUM(C7:V7),0) -> 2.5 | AR11: =IF(AQ11>=2.5,3,IF(AQ11>=1.5,2,IF(AQ11>=0.5,1,0))) -> 3 | AS11: =IF(AR11=0,"—",TEXT(AR11,"0")) -> 3 | AT11: =IF(AR11=0,"—",TEXT(AR11,"0")) -> 3 | AU11: =IF(AR11=0,"—",TEXT(AR11,"0")) -> 3 | AV11: =IF(AR11=0,"—",TEXT(AR11,"0")) -> 3 | AW11: =IF(AR11=0,"—",TEXT(AR11,"0")) -> 3 | AX11: =IF(AR11=0,"—",TEXT(AR11,"0")) -> 3 | AY11: — | AZ11: — | BA11: — | BB11: — | BC11: — | BD11: — | BE11: =IF(AR11=0,"—",TEXT(AR11,"0")) -> 3 | BF11: — | BG11: — | BH11: —
A12: CO4 | B12: Sorting and Searching Algorithms | C12: 4 | D12: 38 | E12: 3 | F12: 2 | G12: 2 | H12: 2 | I12: 2 | J12: 1 | K12: 1 | L12: 2 | M12: 2 | N12: 1 | O12: 1 | P12: 2 | Q12: 1 | R12: 42 | S12: 73 | T12: 2 | U12: 1 | V12: 58 | W12: =IF(C12>=5,3,IF(C12>=3,2,IF(C12>=1,1,0))) -> 2 | X12: =IF(D12>40,3,IF(D12>15,2,IF(D12>5,1,0))) -> 2 | Y12: =IF(E12>=3,3,IF(E12>=2,2,IF(E12>=1,1,0))) -> 3 | Z12: =IF(F12>=3,3,IF(F12>=2,2,IF(F12>=1,1,0))) -> 2 | AA12: =IF(G12>=3,3,IF(G12>=2,2,IF(G12>=1,1,0))) -> 2 | AB12: =IF(H12>=3,3,IF(H12>=2,2,IF(H12>=1,1,0))) -> 2 | AC12: =IF(I12>=3,3,IF(I12>=2,2,IF(I12>=1,1,0))) -> 2 | AD12: =IF(J12>=3,3,IF(J12>=2,2,IF(J12>=1,1,0))) -> 1 | AE12: =IF(K12>=3,3,IF(K12>=2,2,IF(K12>=1,1,0))) -> 1 | AF12: =IF(L12>=3,3,IF(L12>=2,2,IF(L12>=1,1,0))) -> 2 | ... AK12: =IF(Q12>=3,3,IF(Q12>=2,2,IF(Q12>=1,1,0))) -> 1 | AL12: =IF(R12>60,3,IF(R12>40,2,IF(R12>25,1,0))) -> 2 | AM12: =IF(S12>70,3,IF(S12>50,2,IF(S12>40,1,0))) -> 3 | AN12: =IF(T12>=3,3,IF(T12>=2,2,IF(T12>=1,1,0))) -> 2 | AO12: =IF(U12>=3,3,IF(U12>=2,2,IF(U12>=1,1,0))) -> 1 | AP12: =IF(V12>70,3,IF(V12>40,2,IF(V12>0,1,0))) -> 2 | AQ12: =IFERROR(SUMPRODUCT(C7:V7,W12:AP12)/SUM(C7:V7),0) -> 1.8 | AR12: =IF(AQ12>=2.5,3,IF(AQ12>=1.5,2,IF(AQ12>=0.5,1,0))) -> 2 | AS12: =IF(AR12=0,"—",TEXT(AR12,"0")) -> 2 | AT12: =IF(AR12=0,"—",TEXT(AR12,"0")) -> 2 | AU12: =IF(AR12=0,"—",TEXT(AR12,"0")) -> 2 | AV12: =IF(AR12=0,"—",TEXT(AR12,"0")) -> 2 | AW12: — | AX12: — | AY12: — | AZ12: — | BA12: — | BB12: — | BC12: — | BD12: — | BE12: =IF(AR12=0,"—",TEXT(AR12,"0")) -> 2 | BF12: — | BG12: — | BH12: —
A13: CO5 | B13: Hashing and Complexity Analysis | C13: 4 | D13: 38 | E13: 3 | F13: 2 | G13: 2 | H13: 1 | I13: 2 | J13: 2 | K13: 1 | L13: 2 | M13: 2 | N13: 1 | O13: 2 | P13: 2 | Q13: 2 | R13: 48 | S13: 74 | T13: 2 | U13: 2 | V13: 65 | W13: =IF(C13>=5,3,IF(C13>=3,2,IF(C13>=1,1,0))) -> 2 | X13: =IF(D13>40,3,IF(D13>15,2,IF(D13>5,1,0))) -> 2 | Y13: =IF(E13>=3,3,IF(E13>=2,2,IF(E13>=1,1,0))) -> 3 | Z13: =IF(F13>=3,3,IF(F13>=2,2,IF(F13>=1,1,0))) -> 2 | AA13: =IF(G13>=3,3,IF(G13>=2,2,IF(G13>=1,1,0))) -> 2 | AB13: =IF(H13>=3,3,IF(H13>=2,2,IF(H13>=1,1,0))) -> 1 | AC13: =IF(I13>=3,3,IF(I13>=2,2,IF(I13>=1,1,0))) -> 2 | AD13: =IF(J13>=3,3,IF(J13>=2,2,IF(J13>=1,1,0))) -> 2 | AE13: =IF(K13>=3,3,IF(K13>=2,2,IF(K13>=1,1,0))) -> 1 | AF13: =IF(L13>=3,3,IF(L13>=2,2,IF(L13>=1,1,0))) -> 2 | ... AK13: =IF(Q13>=3,3,IF(Q13>=2,2,IF(Q13>=1,1,0))) -> 2 | AL13: =IF(R13>60,3,IF(R13>40,2,IF(R13>25,1,0))) -> 2 | AM13: =IF(S13>70,3,IF(S13>50,2,IF(S13>40,1,0))) -> 3 | AN13: =IF(T13>=3,3,IF(T13>=2,2,IF(T13>=1,1,0))) -> 2 | AO13: =IF(U13>=3,3,IF(U13>=2,2,IF(U13>=1,1,0))) -> 2 | AP13: =IF(V13>70,3,IF(V13>40,2,IF(V13>0,1,0))) -> 2 | AQ13: =IFERROR(SUMPRODUCT(C7:V7,W13:AP13)/SUM(C7:V7),0) -> 1.95 | AR13: =IF(AQ13>=2.5,3,IF(AQ13>=1.5,2,IF(AQ13>=0.5,1,0))) -> 2 | AS13: =IF(AR13=0,"—",TEXT(AR13,"0")) -> 2 | AT13: =IF(AR13=0,"—",TEXT(AR13,"0")) -> 2 | AU13: =IF(AR13=0,"—",TEXT(AR13,"0")) -> 2 | AV13: — | AW13: — | AX13: — | AY13: — | AZ13: — | BA13: — | BB13: — | BC13: — | BD13: — | BE13: =IF(AR13=0,"—",TEXT(AR13,"0")) -> 2 | BF13: — | BG13: — | BH13: —
A15: COURSE AVG | C15: =AVERAGE(C9:C13) -> 4 | D15: =AVERAGE(D9:D13) -> 39.2 | E15: =AVERAGE(E9:E13) -> 2.8 | F15: =AVERAGE(F9:F13) -> 2.2 | G15: =AVERAGE(G9:G13) -> 2.2 | H15: =AVERAGE(H9:H13) -> 1.6 | I15: =AVERAGE(I9:I13) -> 2.2 | J15: =AVERAGE(J9:J13) -> 1.6 | ... AR15: =AVERAGE(AR9:AR13) -> 2.2 | AT15: =IFERROR(AVERAGEIF(AT9:AT13,"<>—"),"") | AU15: =IFERROR(AVERAGEIF(AU9:AU13,"<>—"),"") | AV15: =IFERROR(AVERAGEIF(AV9:AV13,"<>—"),"") | AW15: =IFERROR(AVERAGEIF(AW9:AW13,"<>—"),"") | AX15: =IFERROR(AVERAGEIF(AX9:AX13,"<>—"),"") | AY15: =IFERROR(AVERAGEIF(AY9:AY13,"<>—"),"") | AZ15: =IFERROR(AVERAGEIF(AZ9:AZ13,"<>—"),"") | BA15: =IFERROR(AVERAGEIF(BA9:BA13,"<>—"),"") | ... BH15: =IFERROR(AVERAGEIF(BH9:BH13,"<>—"),"")

Sheet CS302
A1: ADDITIONAL CO–PO MAPPING (20 Methods) — Database Management Systems (CS302)
A2: Enter input scores in YELLOW cells per method per CO | Level auto-calculates per method | Combined weighted score gives Final Mapping Level | All 20 methods from NBA OBE Additional Guidelines
A4: Input Types → | C4: Bloom 1–6 | D4: Percent 0–100 | E4: Level 0–3 | F4: Weighted % 0–100
A5: CO | B5: CO Topic | C5: INPUT SCORES (Edit Yellow Cells) | W5: MAPPING LEVELS (Auto-Calculated per Method) | AQ5: Combined Weighted Score | AR5: Final Mapping Level | AS5: Final Symbol | AT5: PROGRAMME OUTCOMES (PO1–PO12) | BF5: PSOs
B6: Method → | C6: M01 | D6: M02 | E6: M03 | F6: M04 | G6: M05 | H6: M06 | I6: M07 | J6: M08 | K6: M09 | L6: M10 | M6: M11 | N6: M12 | O6: M13 | P6: M14 | Q6: M15 | R6: M16 | S6: M17 | T6: M18 | U6: M19 | V6: M20 | W6: M01 | X6: M02 | Y6: M03 | Z6: M04 | AA6: M05 | AB6: M06 | AC6: M07 | AD6: M08 | AE6: M09 | AF6: M10 | AG6: M11 | AH6: M12 | AI6: M13 | AJ6: M14 | AK6: M15 | AL6: M16 | AM6: M17 | AN6: M18 | AO6: M19 | AP6: M20 | AQ6: Wtd Avg | AR6: 0–3 | AS6: —/1/2/3 | AT6: PO1 | AU6: PO2 | AV6: PO3 | AW6: PO4 | AX6: PO5 | AY6: PO6 | AZ6: PO7 | BA6: PO8 | BB6: PO9 | BC6: PO10 | BD6: PO11 | BE6: PO12 | BF6: PSO1 | BG6: PSO2 | BH6: PSO3
A7: Method Weights (Equal = 5%) | C7: 0.05 | D7: 0.05 | E7: 0.05 | F7: 0.05 | G7: 0.05 | H7: 0.05 | I7: 0.05 | J7: 0.05 | K7: 0.05 | L7: 0.05 | M7: 0.05 | N7: 0.05 | O7: 0.05 | P7: 0.05 | Q7: 0.05 | R7: 0.05 | S7: 0.05 | T7: 0.05 | U7: 0.05 | V7: 0.05 | AQ7: =SUM(C7:V7) -> 1
A8: ↓ Enter scores in YELLOW cells (columns C–V) → All calculations auto-update ↓
A9: CO1 | B9: ER Model and Relational Algebra | C9: 2 | D9: 28 | E9: 2 | F9: 1 | G9: 2 | H9: 1 | I9: 1 | J9: 1 | K9: 1 | L9: 1 | M9: 1 | N9: 1 | O9: 1 | P9: 1 | Q9: 1 | R9: 32 | S9: 65 | T9: 1 | U9: 1 | V9: 42 | W9: =IF(C9>=5,3,IF(C9>=3,2,IF(C9>=1,1,0))) -> 1 | X9: =IF(D9>40,3,IF(D9>15,2,IF(D9>5,1,0))) -> 2 | Y9: =IF(E9>=3,3,IF(E9>=2,2,IF(E9>=1,1,0))) -> 2 | Z9: =IF(F9>=3,3,IF(F9>=2,2,IF(F9>=1,1,0))) -> 1 | AA9: =IF(G9>=3,3,IF(G9>=2,2,IF(G9>=1,1,0))) -> 2 | AB9: =IF(H9>=3,3,IF(H9>=2,2,IF(H9>=1,1,0))) -> 1 | AC9: =IF(I9>=3,3,IF(I9>=2,2,IF(I9>=1,1,0))) -> 1 | AD9: =IF(J9>=3,3,IF(J9>=2,2,IF(J9>=1,1,0))) -> 1 | AE9: =IF(K9>=3,3,IF(K9>=2,2,IF(K9>=1,1,0))) -> 1 | AF9: =IF(L9>=3,3,IF(L9>=2,2,IF(L9>=1,1,0))) -> 1 | ... AK9: =IF(Q9>=3,3,IF(Q9>=2,2,IF(Q9>=1,1,0))) -> 1 | AL9: =IF(R9>60,3,IF(R9>40,2,IF(R9>25,1,0))) -> 1 | AM9: =IF(S9>70,3,IF(S9>50,2,IF(S9>40,1,0))) -> 2 | AN9: =IF(T9>=3,3,IF(T9>=2,2,IF(T9>=1,1,0))) -> 1 | AO9: =IF(U9>=3,3,IF(U9>=2,2,IF(U9>=1,1,0))) -> 1 | AP9: =IF(V9>70,3,IF(V9>40,2,IF(V9>0,1,0))) -> 2 | AQ9: =IFERROR(SUMPRODUCT(C7:V7,W9:AP9)/SUM(C7:V7),0) -> 1.25 | AR9: =IF(AQ9>=2.5,3,IF(AQ9>=1.5,2,IF(AQ9>=0.5,1,0))) -> 1 | AS9: =IF(AR9=0,"—",TEXT(AR9,"0")) -> 1 | AT9: =IF(AR9=0,"—",TEXT(AR9,"0")) -> 1 | AU9: =IF(AR9=0,"—",TEXT(AR9,"0")) -> 1 | AV9: =IF(AR9=0,"—",TEXT(AR9,"0")) -> 1 | AW9: — | AX9: — | AY9: — | AZ9: — | BA9: — | BB9: — | BC9: — | BD9: — | BE9: =IF(AR9=0,"—",TEXT(AR9,"0")) -> 1 | BF9: — | BG9: — | BH9: —
A10: CO2 | B10: SQL: DDL, DML, Complex Queries | C10: 5 | D10: 50 | E10: 3 | F10: 3 | G10: 3 | H10: 2 | I10: 3 | J10: 2 | K10: 2 | L10: 2 | M10: 2 | N10: 2 | O10: 2 | P10: 3 | Q10: 2 | R10: 58 | S10: 80 | T10: 3 | U10: 2 | V10: 75 | W10: =IF(C10>=5,3,IF(C10>=3,2,IF(C10>=1,1,0))) -> 3 | X10: =IF(D10>40,3,IF(D10>15,2,IF(D10>5,1,0))) -> 3 | Y10: =IF(E10>=3,3,IF(E10>=2,2,IF(E10>=1,1,0))) -> 3 | Z10: =IF(F10>=3,3,IF(F10>=2,2,IF(F10>=1,1,0))) -> 3 | AA10: =IF(G10>=3,3,IF(G10>=2,2,IF(G10>=1,1,0))) -> 3 | AB10: =IF(H10>=3,3,IF(H10>=2,2,IF(H10>=1,1,0))) -> 2 | AC10: =IF(I10>=3,3,IF(I10>=2,2,IF(I10>=1,1,0))) -> 3 | AD10: =IF(J10>=3,3,IF(J10>=2,2,IF(J10>=1,1,0))) -> 2 | AE10: =IF(K10>=3,3,IF(K10>=2,2,IF(K10>=1,1,0))) -> 2 | AF10: =IF(L10>=3,3,IF(L10>=2,2,IF(L10>=1,1,0))) -> 2 | ... AK10: =IF(Q10>=3,3,IF(Q10>=2,2,IF(Q10>=1,1,0))) -> 2 | AL10: =IF(R10>60,3,IF(R10>40,2,IF(R10>25,1,0))) -> 2 | AM10: =IF(S10>70,3,IF(S10>50,2,IF(S10>40,1,0))) -> 3 | AN10: =IF(T10>=3,3,IF(T10>=2,2,IF(T10>=1,1,0))) -> 3 | AO10: =IF(U10>=3,3,IF(U10>=2,2,IF(U10>=1,1,0))) -> 2 | AP10: =IF(V10>70,3,IF(V10>40,2,IF(V10>0,1,0))) -> 3 | AQ10: =IFERROR(SUMPRODUCT(C7:V7,W10:AP10)/SUM(C7:V7),0) -> 2.5 | AR10: =IF(AQ10>=2.5,3,IF(AQ10>=1.5,2,IF(AQ10>=0.5,1,0))) -> 3 | AS10: =IF(AR10=0,"—",TEXT(AR10,"0")) -> 3 | AT10: =IF(AR10=0,"—",TEXT(AR10,"0")) -> 3 | AU10: =IF(AR10=0,"—",TEXT(AR10,"0")) -> 3 | AV10: =IF(AR10=0,"—",TEXT(AR10,"0")) -> 3 | AW10: — | AX10: =IF(AR10=0,"—",TEXT(AR10,"0")) -> 3 | AY10: — | AZ10: — | BA10: — | BB10: — | BC10: — | BD10: — | BE10: =IF(AR10=0,"—",TEXT(AR10,"0")) -> 3 | BF10: — | BG10: — | BH10: —
A11: CO3 | B11: Normalization: 1NF to BCNF | C11: 4 | D11: 38 | E11: 3 | F11: 1 | G11: 2 | H11: 1 | I11: 1 | J11: 1 | K11: 1 | L11: 2 | M11: 2 | N11: 1 | O11: 1 | P11: 1 | Q11: 2 | R11: 42 | S11: 70 | T11: 2 | U11: 1 | V11: 52 | W11: =IF(C11>=5,3,IF(C11>=3,2,IF(C11>=1,1,0))) -> 2 | X11: =IF(D11>40,3,IF(D11>15,2,IF(D11>5,1,0))) -> 2 | Y11: =IF(E11>=3,3,IF(E11>=2,2,IF(E11>=1,1,0))) -> 3 | Z11: =IF(F11>=3,3,IF(F11>=2,2,IF(F11>=1,1,0))) -> 1 | AA11: =IF(G11>=3,3,IF(G11>=2,2,IF(G11>=1,1,0))) -> 2 | AB11: =IF(H11>=3,3,IF(H11>=2,2,IF(H11>=1,1,0))) -> 1 | AC11: =IF(I11>=3,3,IF(I11>=2,2,IF(I11>=1,1,0))) -> 1 | AD11: =IF(J11>=3,3,IF(J11>=2,2,IF(J11>=1,1,0))) -> 1 | AE11: =IF(K11>=3,3,IF(K11>=2,2,IF(K11>=1,1,0))) -> 1 | AF11: =IF(L11>=3,3,IF(L11>=2,2,IF(L11>=1,1,0))) -> 2 | ... AK11: =IF(Q11>=3,3,IF(Q11>=2,2,IF(Q11>=1,1,0))) -> 2 | AL11: =IF(R11>60,3,IF(R11>40,2,IF(R11>25,1,0))) -> 2 | AM11: =IF(S11>70,3,IF(S11>50,2,IF(S11>40,1,0))) -> 2 | AN11: =IF(T11>=3,3,IF(T11>=2,2,IF(T11>=1,1,0))) -> 2 | AO11: =IF(U11>=3,3,IF(U11>=2,2,IF(U11>=1,1,0))) -> 1 | AP11: =IF(V11>70,3,IF(V11>40,2,IF(V11>0,1,0))) -> 2 | AQ11: =IFERROR(SUMPRODUCT(C7:V7,W11:AP11)/SUM(C7:V7),0) -> 1.6 | AR11: =IF(AQ11>=2.5,3,IF(AQ11>=1.5,2,IF(AQ11>=0.5,1,0))) -> 2 | AS11: =IF(AR11=0,"—",TEXT(AR11,"0")) -> 2 | AT11: =IF(AR11=0,"—",TEXT(AR11,"0")) -> 2 | AU11: =IF(AR11=0,"—",TEXT(AR11,"0")) -> 2 | AV11: =IF(AR11=0,"—",TEXT(AR11,"0")) -> 2 | AW11: — | AX11: — | AY11: — | AZ11: — | BA11: — | BB11: — | BC11: — | BD11: — | BE11: =IF(AR11=0,"—",TEXT(AR11,"0")) -> 2 | BF11: — | BG11: — | BH11: —
A12: CO4 | B12: Transaction Management & Concurrency | C12: 5 | D12: 42 | E12: 3 | F12: 2 | G12: 2 | H12: 2 | I12: 2 | J12: 2 | K12: 2 | L12: 2 | M12: 2 | N12: 2 | O12: 2 | P12: 2 | Q12: 2 | R12: 50 | S12: 75 | T12: 2 | U12: 2 | V12: 68 | W12: =IF(C12>=5,3,IF(C12>=3,2,IF(C12>=1,1,0))) -> 3 | X12: =IF(D12>40,3,IF(D12>15,2,IF(D12>5,1,0))) -> 3 | Y12: =IF(E12>=3,3,IF(E12>=2,2,IF(E12>=1,1,0))) -> 3 | Z12: =IF(F12>=3,3,IF(F12>=2,2,IF(F12>=1,1,0))) -> 2 | AA12: =IF(G12>=3,3,IF(G12>=2,2,IF(G12>=1,1,0))) -> 2 | AB12: =IF(H12>=3,3,IF(H12>=2,2,IF(H12>=1,1,0))) -> 2 | AC12: =IF(I12>=3,3,IF(I12>=2,2,IF(I12>=1,1,0))) -> 2 | AD12: =IF(J12>=3,3,IF(J12>=2,2,IF(J12>=1,1,0))) -> 2 | AE12: =IF(K12>=3,3,IF(K12>=2,2,IF(K12>=1,1,0))) -> 2 | AF12: =IF(L12>=3,3,IF(L12>=2,2,IF(L12>=1,1,0))) -> 2 | ... AK12: =IF(Q12>=3,3,IF(Q12>=2,2,IF(Q12>=1,1,0))) -> 2 | AL12: =IF(R12>60,3,IF(R12>40,2,IF(R12>25,1,0))) -> 2 | AM12: =IF(S12>70,3,IF(S12>50,2,IF(S12>40,1,0))) -> 3 | AN12: =IF(T12>=3,3,IF(T12>=2,2,IF(T12>=1,1,0))) -> 2 | AO12: =IF(U12>=3,3,IF(U12>=2,2,IF(U12>=1,1,0))) -> 2 | AP12: =IF(V12>70,3,IF(V12>40,2,IF(V12>0,1,0))) -> 2 | AQ12: =IFERROR(SUMPRODUCT(C7:V7,W12:AP12)/SUM(C7:V7),0) -> 2.2 | AR12: =IF(AQ12>=2.5,3,IF(AQ12>=1.5,2,IF(AQ12>=0.5,1,0))) -> 2 | AS12: =IF(AR12=0,"—",TEXT(AR12,"0")) -> 2 | AT12: =IF(AR12=0,"—",TEXT(AR12,"0")) -> 2 | AU12: =IF(AR12=0,"—",TEXT(AR12,"0")) -> 2 | AV12: =IF(AR12=0,"—",TEXT(AR12,"0")) -> 2 | AW12: =IF(AR12=0,"—",TEXT(AR12,"0")) -> 2 | AX12: — | AY12: — | AZ12: — | BA12: — | BB12: — | BC12: — | BD12: — | BE12: =IF(AR12=0,"—",TEXT(AR12,"0")) -> 2 | BF12: — | BG12: — | BH12: —
A13: CO5 | B13: Indexing & Query Optimization | C13: 5 | D13: 45 | E13: 3 | F13: 2 | G13: 3 | H13: 2 | I13: 2 | J13: 1 | K13: 1 | L13: 2 | M13: 2 | N13: 1 | O13: 2 | P13: 3 | Q13: 1 | R13: 52 | S13: 76 | T13: 2 | U13: 1 | V13: 70 | W13: =IF(C13>=5,3,IF(C13>=3,2,IF(C13>=1,1,0))) -> 3 | X13: =IF(D13>40,3,IF(D13>15,2,IF(D13>5,1,0))) -> 3 | Y13: =IF(E13>=3,3,IF(E13>=2,2,IF(E13>=1,1,0))) -> 3 | Z13: =IF(F13>=3,3,IF(F13>=2,2,IF(F13>=1,1,0))) -> 2 | AA13: =IF(G13>=3,3,IF(G13>=2,2,IF(G13>=1,1,0))) -> 3 | AB13: =IF(H13>=3,3,IF(H13>=2,2,IF(H13>=1,1,0))) -> 2 | AC13: =IF(I13>=3,3,IF(I13>=2,2,IF(I13>=1,1,0))) -> 2 | AD13: =IF(J13>=3,3,IF(J13>=2,2,IF(J13>=1,1,0))) -> 1 | AE13: =IF(K13>=3,3,IF(K13>=2,2,IF(K13>=1,1,0))) -> 1 | AF13: =IF(L13>=3,3,IF(L13>=2,2,IF(L13>=1,1,0))) -> 2 | ... AK13: =IF(Q13>=3,3,IF(Q13>=2,2,IF(Q13>=1,1,0))) -> 1 | AL13: =IF(R13>60,3,IF(R13>40,2,IF(R13>25,1,0))) -> 2 | AM13: =IF(S13>70,3,IF(S13>50,2,IF(S13>40,1,0))) -> 3 | AN13: =IF(T13>=3,3,IF(T13>=2,2,IF(T13>=1,1,0))) -> 2 | AO13: =IF(U13>=3,3,IF(U13>=2,2,IF(U13>=1,1,0))) -> 1 | AP13: =IF(V13>70,3,IF(V13>40,2,IF(V13>0,1,0))) -> 2 | AQ13: =IFERROR(SUMPRODUCT(C7:V7,W13:AP13)/SUM(C7:V7),0) -> 2.05 | AR13: =IF(AQ13>=2.5,3,IF(AQ13>=1.5,2,IF(AQ13>=0.5,1,0))) -> 2 | AS13: =IF(AR13=0,"—",TEXT(AR13,"0")) -> 2 | AT13: =IF(AR13=0,"—",TEXT(AR13,"0")) -> 2 | AU13: =IF(AR13=0,"—",TEXT(AR13,"0")) -> 2 | AV13: — | AW13: =IF(AR13=0,"—",TEXT(AR13,"0")) -> 2 | AX13: =IF(AR13=0,"—",TEXT(AR13,"0")) -> 2 | AY13: — | AZ13: — | BA13: — | BB13: — | BC13: — | BD13: — | BE13: =IF(AR13=0,"—",TEXT(AR13,"0")) -> 2 | BF13: — | BG13: — | BH13: —
A15: COURSE AVG | C15: =AVERAGE(C9:C13) -> 4.2 | D15: =AVERAGE(D9:D13) -> 40.6 | E15: =AVERAGE(E9:E13) -> 2.8 | F15: =AVERAGE(F9:F13) -> 1.8 | G15: =AVERAGE(G9:G13) -> 2.4 | H15: =AVERAGE(H9:H13) -> 1.6 | I15: =AVERAGE(I9:I13) -> 1.8 | J15: =AVERAGE(J9:J13) -> 1.4 | ... AR15: =AVERAGE(AR9:AR13) -> 2 | AT15: =IFERROR(AVERAGEIF(AT9:AT13,"<>—"),"") | AU15: =IFERROR(AVERAGEIF(AU9:AU13,"<>—"),"") | AV15: =IFERROR(AVERAGEIF(AV9:AV13,"<>—"),"") | AW15: =IFERROR(AVERAGEIF(AW9:AW13,"<>—"),"") | AX15: =IFERROR(AVERAGEIF(AX9:AX13,"<>—"),"") | AY15: =IFERROR(AVERAGEIF(AY9:AY13,"<>—"),"") | AZ15: =IFERROR(AVERAGEIF(AZ9:AZ13,"<>—"),"") | BA15: =IFERROR(AVERAGEIF(BA9:BA13,"<>—"),"") | ... BH15: =IFERROR(AVERAGEIF(BH9:BH13,"<>—"),"")

Sheet Combined CO-PO Matrix
A1: COMBINED CO–PO MAPPING MATRIX (All 20 Additional Methods) — Auto-linked
A2: Final Level = Combined Weighted Score of all 20 additional methods | — = CO not relevant to that PO | 1=Low 2=Medium 3=High
A4: LEGEND → | F4: — Not Relevant | G4: 1 Low | H4: 2 Medium | I4: 3 High
A5: # | B5: Course | C5: Code | D5: CO | E5: Comb Level | F5: PROGRAMME OUTCOMES | R5: PSOs
F6: PO1 | G6: PO2 | H6: PO3 | I6: PO4 | J6: PO5 | K6: PO6 | L6: PO7 | M6: PO8 | N6: PO9 | O6: PO10 | P6: PO11 | Q6: PO12 | R6: PSO1 | S6: PSO2 | T6: PSO3
A7: 1 | B7: Data Structures & Algorithms | C7: CS301 | D7: CO1 | E7: =CS301!AR9 -> 2 | F7: =IF(CS301!AR9=0,"—",TEXT(CS301!AR9,"0")) -> 2 | G7: =IF(CS301!AR9=0,"—",TEXT(CS301!AR9,"0")) -> 2 | H7: =IF(CS301!AR9=0,"—",TEXT(CS301!AR9,"0")) -> 2 | I7: — | J7: — | K7: — | L7: — | M7: — | N7: — | O7: — | P7: — | Q7: =IF(CS301!AR9=0,"—",TEXT(CS301!AR9,"0")) -> 2 | R7: — | S7: — | T7: —
D8: CO2 | E8: =CS301!AR10 -> 2 | F8: =IF(CS301!AR10=0,"—",TEXT(CS301!AR10,"0")) -> 2 | G8: =IF(CS301!AR10=0,"—",TEXT(CS301!AR10,"0")) -> 2 | H8: =IF(CS301!AR10=0,"—",TEXT(CS301!AR10,"0")) -> 2 | I8: =IF(CS301!AR10=0,"—",TEXT(CS301!AR10,"0")) -> 2 | J8: — | K8: — | L8: — | M8: — | N8: — | O8: — | P8: — | Q8: =IF(CS301!AR10=0,"—",TEXT(CS301!AR10,"0")) -> 2 | R8: — | S8: — | T8: —
D9: CO3 | E9: =CS301!AR11 -> 3 | F9: =IF(CS301!AR11=0,"—",TEXT(CS301!AR11,"0")) -> 3 | G9: =IF(CS301!AR11=0,"—",TEXT(CS301!AR11,"0")) -> 3 | H9: =IF(CS301!AR11=0,"—",TEXT(CS301!AR11,"0")) -> 3 | I9: =IF(CS301!AR11=0,"—",TEXT(CS301!AR11,"0")) -> 3 | J9: =IF(CS301!AR11=0,"—",TEXT(CS301!AR11,"0")) -> 3 | K9: — | L9: — | M9: — | N9: — | O9: — | P9: — | Q9: =IF(CS301!AR11=0,"—",TEXT(CS301!AR11,"0")) -> 3 | R9: — | S9: — | T9: —
D10: CO4 | E10: =CS301!AR12 -> 2 | F10: =IF(CS301!AR12=0,"—",TEXT(CS301!AR12,"0")) -> 2 | G10: =IF(CS301!AR12=0,"—",TEXT(CS301!AR12,"0")) -> 2 | H10: =IF(CS301!AR12=0,"—",TEXT(CS301!AR12,"0")) -> 2 | I10: — | J10: — | K10: — | L10: — | M10: — | N10: — | O10: — | P10: — | Q10: =IF(CS301!AR12=0,"—",TEXT(CS301!AR12,"0")) -> 2 | R10: — | S10: — | T10: —
D11: CO5 | E11: =CS301!AR13 -> 2 | F11: =IF(CS301!AR13=0,"—",TEXT(CS301!AR13,"0")) -> 2 | G11: =IF(CS301!AR13=0,"—",TEXT(CS301!AR13,"0")) -> 2 | H11: — | I11: — | J11: — | K11: — | L11: — | M11: — | N11: — | O11: — | P11: — | Q11: =IF(CS301!AR13=0,"—",TEXT(CS301!AR13,"0")) -> 2 | R11: — | S11: — | T11: —
A12: 2 | B12: Database Management Systems | C12: CS302 | D12: CO1 | E12: =CS302!AR9 -> 1 | F12: =IF(CS302!AR9=0,"—",TEXT(CS302!AR9,"0")) -> 1 | G12: =IF(CS302!AR9=0,"—",TEXT(CS302!AR9,"0")) -> 1 | H12: =IF(CS302!AR9=0,"—",TEXT(CS302!AR9,"0")) -> 1 | I12: — | J12: — | K12: — | L12: — | M12: — | N12: — | O12: — | P12: — | Q12: =IF(CS302!AR9=0,"—",TEXT(CS302!AR9,"0")) -> 1 | R12: — | S12: — | T12: —
D13: CO2 | E13: =CS302!AR10 -> 3 | F13: =IF(CS302!AR10=0,"—",TEXT(CS302!AR10,"0")) -> 3 | G13: =IF(CS302!AR10=0,"—",TEXT(CS302!AR10,"0")) -> 3 | H13: =IF(CS302!AR10=0,"—",TEXT(CS302!AR10,"0")) -> 3 | I13: — | J13: =IF(CS302!AR10=0,"—",TEXT(CS302!AR10,"0")) -> 3 | K13: — | L13: — | M13: — | N13: — | O13: — | P13: — | Q13: =IF(CS302!AR10=0,"—",TEXT(CS302!AR10,"0")) -> 3 | R13: — | S13: — | T13: —
D14: CO3 | E14: =CS302!AR11 -> 2 | F14: =IF(CS302!AR11=0,"—",TEXT(CS302!AR11,"0")) -> 2 | G14: =IF(CS302!AR11=0,"—",TEXT(CS302!AR11,"0")) -> 2 | H14: =IF(CS302!AR11=0,"—",TEXT(CS302!AR11,"0")) -> 2 | I14: — | J14: — | K14: — | L14: — | M14: — | N14: — | O14: — | P14: — | Q14: =IF(CS302!AR11=0,"—",TEXT(CS302!AR11,"0")) -> 2 | R14: — | S14: — | T14: —
D15: CO4 | E15: =CS302!AR12 -> 2 | F15: =IF(CS302!AR12=0,"—",TEXT(CS302!AR12,"0")) -> 2 | G15: =IF(CS302!AR12=0,"—",TEXT(CS302!AR12,"0")) -> 2 | H15: =IF(CS302!AR12=0,"—",TEXT(CS302!AR12,"0")) -> 2 | I15: =IF(CS302!AR12=0,"—",TEXT(CS302!AR12,"0")) -> 2 | J15: — | K15: — | L15: — | M15: — | N15: — | O15: — | P15: — | Q15: =IF(CS302!AR12=0,"—",TEXT(CS302!AR12,"0")) -> 2 | R15: — | S15: — | T15: —
D16: CO5 | E16: =CS302!AR13 -> 2 | F16: =IF(CS302!AR13=0,"—",TEXT(CS302!AR13,"0")) -> 2 | G16: =IF(CS302!AR13=0,"—",TEXT(CS302!AR13,"0")) -> 2 | H16: — | I16: =IF(CS302!AR13=0,"—",TEXT(CS302!AR13,"0")) -> 2 | J16: =IF(CS302!AR13=0,"—",TEXT(CS302!AR13,"0")) -> 2 | K16: — | L16: — | M16: — | N16: — | O16: — | P16: — | Q16: =IF(CS302!AR13=0,"—",TEXT(CS302!AR13,"0")) -> 2 | R16: — | S16: — | T16: —
A17: 3 | B17: Computer Networks | C17: CS303 | D17: CO1 | E17: =CS303!AR9 -> 1 | F17: =IF(CS303!AR9=0,"—",TEXT(CS303!AR9,"0")) -> 1 | G17: =IF(CS303!AR9=0,"—",TEXT(CS303!AR9,"0")) -> 1 | H17: — | I17: — | J17: =IF(CS303!AR9=0,"—",TEXT(CS303!AR9,"0")) -> 1 | K17: — | L17: — | M17: — | N17: — | O17: — | P17: — | Q17: =IF(CS303!AR9=0,"—",TEXT(CS303!AR9,"0")) -> 1 | R17: — | S17: — | T17: —
D18: CO2 | E18: =CS303!AR10 -> 2 | F18: =IF(CS303!AR10=0,"—",TEXT(CS303!AR10,"0")) -> 2 | G18: =IF(CS303!AR10=0,"—",TEXT(CS303!AR10,"0")) -> 2 | H18: =IF(CS303!AR10=0,"—",TEXT(CS303!AR10,"0")) -> 2 | I18: — | J18: =IF(CS303!AR10=0,"—",TEXT(CS303!AR10,"0")) -> 2 | K18: — | L18: — | M18: — | N18: — | O18: — | P18: — | Q18: =IF(CS303!AR10=0,"—",TEXT(CS303!AR10,"0")) -> 2 | R18: — | S18: — | T18: —
D19: CO3 | E19: =CS303!AR11 -> 3 | F19: =IF(CS303!AR11=0,"—",TEXT(CS303!AR11,"0")) -> 3 | G19: =IF(CS303!AR11=0,"—",TEXT(CS303!AR11,"0")) -> 3 | H19: =IF(CS303!AR11=0,"—",TEXT(CS303!AR11,"0")) -> 3 | I19: =IF(CS303!AR11=0,"—",TEXT(CS303!AR11,"0")) -> 3 | J19: =IF(CS303!AR11=0,"—",TEXT(CS303!AR11,"0")) -> 3 | K19: — | L19: — | M19: — | N19: — | O19: — | P19: — | Q19: =IF(CS303!AR11=0,"—",TEXT(CS303!AR11,"0")) -> 3 | R19: — | S19: — | T19: —
D20: CO4 | E20: =CS303!AR12 -> 2 | F20: =IF(CS303!AR12=0,"—",TEXT(CS303!AR12,"0")) -> 2 | G20: =IF(CS303!AR12=0,"—",TEXT(CS303!AR12,"0")) -> 2 | H20: =IF(CS303!AR12=0,"—",TEXT(CS303!AR12,"0")) -> 2 | I20: — | J20: — | K20: — | L20: — | M20: — | N20: — | O20: — | P20: — | Q20: =IF(CS303!AR12=0,"—",TEXT(CS303!AR12,"0")) -> 2 | R20: — | S20: — | T20: —
D21: CO5 | E21: =CS303!AR13 -> 2 | F21: =IF(CS303!AR13=0,"—",TEXT(CS303!AR13,"0")) -> 2 | G21: =IF(CS303!AR13=0,"—",TEXT(CS303!AR13,"0")) -> 2 | H21: — | I21: — | J21: =IF(CS303!AR13=0,"—",TEXT(CS303!AR13,"0")) -> 2 | K21: — | L21: — | M21: — | N21: — | O21: — | P21: — | Q21: =IF(CS303!AR13=0,"—",TEXT(CS303!AR13,"0")) -> 2 | R21: — | S21: — | T21: —
A22: 4 | B22: Operating Systems | C22: CS304 | D22: CO1 | E22: =CS304!AR9 -> 2 | F22: =IF(CS304!AR9=0,"—",TEXT(CS304!AR9,"0")) -> 2 | G22: =IF(CS304!AR9=0,"—",TEXT(CS304!AR9,"0")) -> 2 | H22: — | I22: — | J22: — | K22: — | L22: — | M22: — | N22: — | O22: — | P22: — | Q22: =IF(CS304!AR9=0,"—",TEXT(CS304!AR9,"0")) -> 2 | R22: — | S22: — | T22: —
D23: CO2 | E23: =CS304!AR10 -> 2 | F23: =IF(CS304!AR10=0,"—",TEXT(CS304!AR10,"0")) -> 2 | G23: =IF(CS304!AR10=0,"—",TEXT(CS304!AR10,"0")) -> 2 | H23: =IF(CS304!AR10=0,"—",TEXT(CS304!AR10,"0")) -> 2 | I23: =IF(CS304!AR10=0,"—",TEXT(CS304!AR10,"0")) -> 2 | J23: — | K23: — | L23: — | M23: — | N23: — | O23: — | P23: — | Q23: =IF(CS304!AR10=0,"—",TEXT(CS304!AR10,"0")) -> 2 | R23: — | S23: — | T23: —
D24: CO3 | E24: =CS304!AR11 -> 2 | F24: =IF(CS304!AR11=0,"—",TEXT(CS304!AR11,"0")) -> 2 | G24: =IF(CS304!AR11=0,"—",TEXT(CS304!AR11,"0")) -> 2 | H24: =IF(CS304!AR11=0,"—",TEXT(CS304!AR11,"0")) -> 2 | I24: =IF(CS304!AR11=0,"—",TEXT(CS304!AR11,"0")) -> 2 | J24: — | K24: — | L24: — | M24: — | N24: — | O24: — | P24: — | Q24: =IF(CS304!AR11=0,"—",TEXT(CS304!AR11,"0")) -> 2 | R24: — | S24: — | T24: —
D25: CO4 | E25: =CS304!AR12 -> 2 | F25: =IF(CS304!AR12=0,"—",TEXT(CS304!AR12,"0")) -> 2 | G25: =IF(CS304!AR12=0,"—",TEXT(CS304!AR12,"0")) -> 2 | H25: — | I25: — | J25: — | K25: — | L25: — | M25: — | N25: — | O25: — | P25: — | Q25: =IF(CS304!AR12=0,"—",TEXT(CS304!AR12,"0")) -> 2 | R25: — | S25: — | T25: —
D26: CO5 | E26: =CS304!AR13 -> 2 | F26: =IF(CS304!AR13=0,"—",TEXT(CS304!AR13,"0")) -> 2 | G26: =IF(CS304!AR13=0,"—",TEXT(CS304!AR13,"0")) -> 2 | H26: — | I26: =IF(CS304!AR13=0,"—",TEXT(CS304!AR13,"0")) -> 2 | J26: =IF(CS304!AR13=0,"—",TEXT(CS304!AR13,"0")) -> 2 | K26: — | L26: — | M26: — | N26: — | O26: — | P26: — | Q26: =IF(CS304!AR13=0,"—",TEXT(CS304!AR13,"0")) -> 2 | R26: — | S26: — | T26: —
A27: 5 | B27: Machine Learning | C27: CS305 | D27: CO1 | E27: =CS305!AR9 -> 2 | F27: =IF(CS305!AR9=0,"—",TEXT(CS305!AR9,"0")) -> 2 | G27: =IF(CS305!AR9=0,"—",TEXT(CS305!AR9,"0")) -> 2 | H27: — | I27: — | J27: =IF(CS305!AR9=0,"—",TEXT(CS305!AR9,"0")) -> 2 | K27: — | L27: — | M27: — | N27: — | O27: — | P27: — | Q27: =IF(CS305!AR9=0,"—",TEXT(CS305!AR9,"0")) -> 2 | R27: — | S27: — | T27: —
D28: CO2 | E28: =CS305!AR10 -> 2 | F28: =IF(CS305!AR10=0,"—",TEXT(CS305!AR10,"0")) -> 2 | G28: =IF(CS305!AR10=0,"—",TEXT(CS305!AR10,"0")) -> 2 | H28: =IF(CS305!AR10=0,"—",TEXT(CS305!AR10,"0")) -> 2 | I28: — | J28: =IF(CS305!AR10=0,"—",TEXT(CS305!AR10,"0")) -> 2 | K28: — | L28: — | M28: — | N28: — | O28: — | P28: — | Q28: =IF(CS305!AR10=0,"—",TEXT(CS305!AR10,"0")) -> 2 | R28: — | S28: — | T28: —
D29: CO3 | E29: =CS305!AR11 -> 3 | F29: =IF(CS305!AR11=0,"—",TEXT(CS305!AR11,"0")) -> 3 | G29: =IF(CS305!AR11=0,"—",TEXT(CS305!AR11,"0")) -> 3 | H29: =IF(CS305!AR11=0,"—",TEXT(CS305!AR11,"0")) -> 3 | I29: — | J29: =IF(CS305!AR11=0,"—",TEXT(CS305!AR11,"0")) -> 3 | K29: — | L29: — | M29: — | N29: — | O29: — | P29: — | Q29: =IF(CS305!AR11=0,"—",TEXT(CS305!AR11,"0")) -> 3 | R29: — | S29: — | T29: —
D30: CO4 | E30: =CS305!AR12 -> 2 | F30: =IF(CS305!AR12=0,"—",TEXT(CS305!AR12,"0")) -> 2 | G30: =IF(CS305!AR12=0,"—",TEXT(CS305!AR12,"0")) -> 2 | H30: — | I30: =IF(CS305!AR12=0,"—",TEXT(CS305!AR12,"0")) -> 2 | J30: =IF(CS305!AR12=0,"—",TEXT(CS305!AR12,"0")) -> 2 | K30: — | L30: — | M30: — | N30: — | O30: — | P30: — | Q30: =IF(CS305!AR12=0,"—",TEXT(CS305!AR12,"0")) -> 2 | R30: — | S30: — | T30: —
D31: CO5 | E31: =CS305!AR13 -> 3 | F31: =IF(CS305!AR13=0,"—",TEXT(CS305!AR13,"0")) -> 3 | G31: =IF(CS305!AR13=0,"—",TEXT(CS305!AR13,"0")) -> 3 | H31: =IF(CS305!AR13=0,"—",TEXT(CS305!AR13,"0")) -> 3 | I31: =IF(CS305!AR13=0,"—",TEXT(CS305!AR13,"0")) -> 3 | J31: =IF(CS305!AR13=0,"—",TEXT(CS305!AR13,"0")) -> 3 | K31: — | L31: — | M31: — | N31: — | O31: — | P31: — | Q31: =IF(CS305!AR13=0,"—",TEXT(CS305!AR13,"0")) -> 3 | R31: — | S31: — | T31: —
D32: CO6 | E32: =CS305!AR14 -> 3 | F32: =IF(CS305!AR14=0,"—",TEXT(CS305!AR14,"0")) -> 3 | G32: =IF(CS305!AR14=0,"—",TEXT(CS305!AR14,"0")) -> 3 | H32: =IF(CS305!AR14=0,"—",TEXT(CS305!AR14,"0")) -> 3 | I32: =IF(CS305!AR14=0,"—",TEXT(CS305!AR14,"0")) -> 3 | J32: =IF(CS305!AR14=0,"—",TEXT(CS305!AR14,"0")) -> 3 | K32: — | L32: — | M32: =IF(CS305!AR14=0,"—",TEXT(CS305!AR14,"0")) -> 3 | N32: =IF(CS305!AR14=0,"—",TEXT(CS305!AR14,"0")) -> 3 | O32: =IF(CS305!AR14=0,"—",TEXT(CS305!AR14,"0")) -> 3 | P32: =IF(CS305!AR14=0,"—",TEXT(CS305!AR14,"0")) -> 3 | Q32: =IF(CS305!AR14=0,"—",TEXT(CS305!AR14,"0")) -> 3 | R32: — | S32: — | T32: —
A34: DEPT AVERAGE | E34: =IFERROR(AVERAGE(E7:E32),0) -> 2.1538462 | F34: =IFERROR(AVERAGEIF(F7:F32,"<>—"),"") | G34: =IFERROR(AVERAGEIF(G7:G32,"<>—"),"") | H34: =IFERROR(AVERAGEIF(H7:H32,"<>—"),"") | I34: =IFERROR(AVERAGEIF(I7:I32,"<>—"),"") | J34: =IFERROR(AVERAGEIF(J7:J32,"<>—"),"") | K34: =IFERROR(AVERAGEIF(K7:K32,"<>—"),"") | L34: =IFERROR(AVERAGEIF(L7:L32,"<>—"),"") | M34: =IFERROR(AVERAGEIF(M7:M32,"<>—"),"") | ... T34: =IFERROR(AVERAGEIF(T7:T32,"<>—"),"")

Sheet CS303
A1: ADDITIONAL CO–PO MAPPING (20 Methods) — Computer Networks (CS303)
A2: Enter input scores in YELLOW cells per method per CO | Level auto-calculates per method | Combined weighted score gives Final Mapping Level | All 20 methods from NBA OBE Additional Guidelines
A4: Input Types → | C4: Bloom 1–6 | D4: Percent 0–100 | E4: Level 0–3 | F4: Weighted % 0–100
A5: CO | B5: CO Topic | C5: INPUT SCORES (Edit Yellow Cells) | W5: MAPPING LEVELS (Auto-Calculated per Method) | AQ5: Combined Weighted Score | AR5: Final Mapping Level | AS5: Final Symbol | AT5: PROGRAMME OUTCOMES (PO1–PO12) | BF5: PSOs
B6: Method → | C6: M01 | D6: M02 | E6: M03 | F6: M04 | G6: M05 | H6: M06 | I6: M07 | J6: M08 | K6: M09 | L6: M10 | M6: M11 | N6: M12 | O6: M13 | P6: M14 | Q6: M15 | R6: M16 | S6: M17 | T6: M18 | U6: M19 | V6: M20 | W6: M01 | X6: M02 | Y6: M03 | Z6: M04 | AA6: M05 | AB6: M06 | AC6: M07 | AD6: M08 | AE6: M09 | AF6: M10 | AG6: M11 | AH6: M12 | AI6: M13 | AJ6: M14 | AK6: M15 | AL6: M16 | AM6: M17 | AN6: M18 | AO6: M19 | AP6: M20 | AQ6: Wtd Avg | AR6: 0–3 | AS6: —/1/2/3 | AT6: PO1 | AU6: PO2 | AV6: PO3 | AW6: PO4 | AX6: PO5 | AY6: PO6 | AZ6: PO7 | BA6: PO8 | BB6: PO9 | BC6: PO10 | BD6: PO11 | BE6: PO12 | BF6: PSO1 | BG6: PSO2 | BH6: PSO3
A7: Method Weights (Equal = 5%) | C7: 0.05 | D7: 0.05 | E7: 0.05 | F7: 0.05 | G7: 0.05 | H7: 0.05 | I7: 0.05 | J7: 0.05 | K7: 0.05 | L7: 0.05 | M7: 0.05 | N7: 0.05 | O7: 0.05 | P7: 0.05 | Q7: 0.05 | R7: 0.05 | S7: 0.05 | T7: 0.05 | U7: 0.05 | V7: 0.05 | AQ7: =SUM(C7:V7) -> 1
A8: ↓ Enter scores in YELLOW cells (columns C–V) → All calculations auto-update ↓
A9: CO1 | B9: OSI and TCP/IP Model | C9: 2 | D9: 25 | E9: 1 | F9: 1 | G9: 2 | H9: 1 | I9: 1 | J9: 1 | K9: 1 | L9: 1 | M9: 1 | N9: 1 | O9: 1 | P9: 1 | Q9: 1 | R9: 30 | S9: 62 | T9: 1 | U9: 1 | V9: 40 | W9: =IF(C9>=5,3,IF(C9>=3,2,IF(C9>=1,1,0))) -> 1 | X9: =IF(D9>40,3,IF(D9>15,2,IF(D9>5,1,0))) -> 2 | Y9: =IF(E9>=3,3,IF(E9>=2,2,IF(E9>=1,1,0))) -> 1 | Z9: =IF(F9>=3,3,IF(F9>=2,2,IF(F9>=1,1,0))) -> 1 | AA9: =IF(G9>=3,3,IF(G9>=2,2,IF(G9>=1,1,0))) -> 2 | AB9: =IF(H9>=3,3,IF(H9>=2,2,IF(H9>=1,1,0))) -> 1 | AC9: =IF(I9>=3,3,IF(I9>=2,2,IF(I9>=1,1,0))) -> 1 | AD9: =IF(J9>=3,3,IF(J9>=2,2,IF(J9>=1,1,0))) -> 1 | AE9: =IF(K9>=3,3,IF(K9>=2,2,IF(K9>=1,1,0))) -> 1 | AF9: =IF(L9>=3,3,IF(L9>=2,2,IF(L9>=1,1,0))) -> 1 | ... AK9: =IF(Q9>=3,3,IF(Q9>=2,2,IF(Q9>=1,1,0))) -> 1 | AL9: =IF(R9>60,3,IF(R9>40,2,IF(R9>25,1,0))) -> 1 | AM9: =IF(S9>70,3,IF(S9>50,2,IF(S9>40,1,0))) -> 2 | AN9: =IF(T9>=3,3,IF(T9>=2,2,IF(T9>=1,1,0))) -> 1 | AO9: =IF(U9>=3,3,IF(U9>=2,2,IF(U9>=1,1,0))) -> 1 | AP9: =IF(V9>70,3,IF(V9>40,2,IF(V9>0,1,0))) -> 1 | AQ9: =IFERROR(SUMPRODUCT(C7:V7,W9:AP9)/SUM(C7:V7),0) -> 1.15 | AR9: =IF(AQ9>=2.5,3,IF(AQ9>=1.5,2,IF(AQ9>=0.5,1,0))) -> 1 | AS9: =IF(AR9=0,"—",TEXT(AR9,"0")) -> 1 | AT9: =IF(AR9=0,"—",TEXT(AR9,"0")) -> 1 | AU9: =IF(AR9=0,"—",TEXT(AR9,"0")) -> 1 | AV9: — | AW9: — | AX9: =IF(AR9=0,"—",TEXT(AR9,"0")) -> 1 | AY9: — | AZ9: — | BA9: — | BB9: — | BC9: — | BD9: — | BE9: =IF(AR9=0,"—",TEXT(AR9,"0")) -> 1 | BF9: — | BG9: — | BH9: —
A10: CO2 | B10: Data Link Layer Protocols | C10: 4 | D10: 38 | E10: 3 | F10: 3 | G10: 3 | H10: 2 | I10: 3 | J10: 2 | K10: 2 | L10: 2 | M10: 2 | N10: 2 | O10: 2 | P10: 3 | Q10: 2 | R10: 48 | S10: 74 | T10: 2 | U10: 2 | V10: 65 | W10: =IF(C10>=5,3,IF(C10>=3,2,IF(C10>=1,1,0))) -> 2 | X10: =IF(D10>40,3,IF(D10>15,2,IF(D10>5,1,0))) -> 2 | Y10: =IF(E10>=3,3,IF(E10>=2,2,IF(E10>=1,1,0))) -> 3 | Z10: =IF(F10>=3,3,IF(F10>=2,2,IF(F10>=1,1,0))) -> 3 | AA10: =IF(G10>=3,3,IF(G10>=2,2,IF(G10>=1,1,0))) -> 3 | AB10: =IF(H10>=3,3,IF(H10>=2,2,IF(H10>=1,1,0))) -> 2 | AC10: =IF(I10>=3,3,IF(I10>=2,2,IF(I10>=1,1,0))) -> 3 | AD10: =IF(J10>=3,3,IF(J10>=2,2,IF(J10>=1,1,0))) -> 2 | AE10: =IF(K10>=3,3,IF(K10>=2,2,IF(K10>=1,1,0))) -> 2 | AF10: =IF(L10>=3,3,IF(L10>=2,2,IF(L10>=1,1,0))) -> 2 | ... AK10: =IF(Q10>=3,3,IF(Q10>=2,2,IF(Q10>=1,1,0))) -> 2 | AL10: =IF(R10>60,3,IF(R10>40,2,IF(R10>25,1,0))) -> 2 | AM10: =IF(S10>70,3,IF(S10>50,2,IF(S10>40,1,0))) -> 3 | AN10: =IF(T10>=3,3,IF(T10>=2,2,IF(T10>=1,1,0))) -> 2 | AO10: =IF(U10>=3,3,IF(U10>=2,2,IF(U10>=1,1,0))) -> 2 | AP10: =IF(V10>70,3,IF(V10>40,2,IF(V10>0,1,0))) -> 2 | AQ10: =IFERROR(SUMPRODUCT(C7:V7,W10:AP10)/SUM(C7:V7),0) -> 2.3 | AR10: =IF(AQ10>=2.5,3,IF(AQ10>=1.5,2,IF(AQ10>=0.5,1,0))) -> 2 | AS10: =IF(AR10=0,"—",TEXT(AR10,"0")) -> 2 | AT10: =IF(AR10=0,"—",TEXT(AR10,"0")) -> 2 | AU10: =IF(AR10=0,"—",TEXT(AR10,"0")) -> 2 | AV10: =IF(AR10=0,"—",TEXT(AR10,"0")) -> 2 | AW10: — | AX10: =IF(AR10=0,"—",TEXT(AR10,"0")) -> 2 | AY10: — | AZ10: — | BA10: — | BB10: — | BC10: — | BD10: — | BE10: =IF(AR10=0,"—",TEXT(AR10,"0")) -> 2 | BF10: — | BG10: — | BH10: —
A11: CO3 | B11: Network Layer: IP & Routing | C11: 5 | D11: 45 | E11: 3 | F11: 3 | G11: 3 | H11: 2 | I11: 3 | J11: 2 | K11: 2 | L11: 3 | M11: 3 | N11: 2 | O11: 2 | P11: 3 | Q11: 2 | R11: 55 | S11: 78 | T11: 3 | U11: 2 | V11: 72 | W11: =IF(C11>=5,3,IF(C11>=3,2,IF(C11>=1,1,0))) -> 3 | X11: =IF(D11>40,3,IF(D11>15,2,IF(D11>5,1,0))) -> 3 | Y11: =IF(E11>=3,3,IF(E11>=2,2,IF(E11>=1,1,0))) -> 3 | Z11: =IF(F11>=3,3,IF(F11>=2,2,IF(F11>=1,1,0))) -> 3 | AA11: =IF(G11>=3,3,IF(G11>=2,2,IF(G11>=1,1,0))) -> 3 | AB11: =IF(H11>=3,3,IF(H11>=2,2,IF(H11>=1,1,0))) -> 2 | AC11: =IF(I11>=3,3,IF(I11>=2,2,IF(I11>=1,1,0))) -> 3 | AD11: =IF(J11>=3,3,IF(J11>=2,2,IF(J11>=1,1,0))) -> 2 | AE11: =IF(K11>=3,3,IF(K11>=2,2,IF(K11>=1,1,0))) -> 2 | AF11: =IF(L11>=3,3,IF(L11>=2,2,IF(L11>=1,1,0))) -> 3 | ... AK11: =IF(Q11>=3,3,IF(Q11>=2,2,IF(Q11>=1,1,0))) -> 2 | AL11: =IF(R11>60,3,IF(R11>40,2,IF(R11>25,1,0))) -> 2 | AM11: =IF(S11>70,3,IF(S11>50,2,IF(S11>40,1,0))) -> 3 | AN11: =IF(T11>=3,3,IF(T11>=2,2,IF(T11>=1,1,0))) -> 3 | AO11: =IF(U11>=3,3,IF(U11>=2,2,IF(U11>=1,1,0))) -> 2 | AP11: =IF(V11>70,3,IF(V11>40,2,IF(V11>0,1,0))) -> 3 | AQ11: =IFERROR(SUMPRODUCT(C7:V7,W11:AP11)/SUM(C7:V7),0) -> 2.6 | AR11: =IF(AQ11>=2.5,3,IF(AQ11>=1.5,2,IF(AQ11>=0.5,1,0))) -> 3 | AS11: =IF(AR11=0,"—",TEXT(AR11,"0")) -> 3 | AT11: =IF(AR11=0,"—",TEXT(AR11,"0")) -> 3 | AU11: =IF(AR11=0,"—",TEXT(AR11,"0")) -> 3 | AV11: =IF(AR11=0,"—",TEXT(AR11,"0")) -> 3 | AW11: =IF(AR11=0,"—",TEXT(AR11,"0")) -> 3 | AX11: =IF(AR11=0,"—",TEXT(AR11,"0")) -> 3 | AY11: — | AZ11: — | BA11: — | BB11: — | BC11: — | BD11: — | BE11: =IF(AR11=0,"—",TEXT(AR11,"0")) -> 3 | BF11: — | BG11: — | BH11: —
A12: CO4 | B12: Transport Layer: TCP & UDP | C12: 4 | D12: 38 | E12: 2 | F12: 2 | G12: 2 | H12: 1 | I12: 2 | J12: 1 | K12: 1 | L12: 1 | M12: 1 | N12: 1 | O12: 1 | P12: 2 | Q12: 1 | R12: 42 | S12: 70 | T12: 2 | U12: 1 | V12: 55 | W12: =IF(C12>=5,3,IF(C12>=3,2,IF(C12>=1,1,0))) -> 2 | X12: =IF(D12>40,3,IF(D12>15,2,IF(D12>5,1,0))) -> 2 | Y12: =IF(E12>=3,3,IF(E12>=2,2,IF(E12>=1,1,0))) -> 2 | Z12: =IF(F12>=3,3,IF(F12>=2,2,IF(F12>=1,1,0))) -> 2 | AA12: =IF(G12>=3,3,IF(G12>=2,2,IF(G12>=1,1,0))) -> 2 | AB12: =IF(H12>=3,3,IF(H12>=2,2,IF(H12>=1,1,0))) -> 1 | AC12: =IF(I12>=3,3,IF(I12>=2,2,IF(I12>=1,1,0))) -> 2 | AD12: =IF(J12>=3,3,IF(J12>=2,2,IF(J12>=1,1,0))) -> 1 | AE12: =IF(K12>=3,3,IF(K12>=2,2,IF(K12>=1,1,0))) -> 1 | AF12: =IF(L12>=3,3,IF(L12>=2,2,IF(L12>=1,1,0))) -> 1 | ... AK12: =IF(Q12>=3,3,IF(Q12>=2,2,IF(Q12>=1,1,0))) -> 1 | AL12: =IF(R12>60,3,IF(R12>40,2,IF(R12>25,1,0))) -> 2 | AM12: =IF(S12>70,3,IF(S12>50,2,IF(S12>40,1,0))) -> 2 | AN12: =IF(T12>=3,3,IF(T12>=2,2,IF(T12>=1,1,0))) -> 2 | AO12: =IF(U12>=3,3,IF(U12>=2,2,IF(U12>=1,1,0))) -> 1 | AP12: =IF(V12>70,3,IF(V12>40,2,IF(V12>0,1,0))) -> 2 | AQ12: =IFERROR(SUMPRODUCT(C7:V7,W12:AP12)/SUM(C7:V7),0) -> 1.55 | AR12: =IF(AQ12>=2.5,3,IF(AQ12>=1.5,2,IF(AQ12>=0.5,1,0))) -> 2 | AS12: =IF(AR12=0,"—",TEXT(AR12,"0")) -> 2 | AT12: =IF(AR12=0,"—",TEXT(AR12,"0")) -> 2 | AU12: =IF(AR12=0,"—",TEXT(AR12,"0")) -> 2 | AV12: =IF(AR12=0,"—",TEXT(AR12,"0")) -> 2 | AW12: — | AX12: — | AY12: — | AZ12: — | BA12: — | BB12: — | BC12: — | BD12: — | BE12: =IF(AR12=0,"—",TEXT(AR12,"0")) -> 2 | BF12: — | BG12: — | BH12: —
A13: CO5 | B13: Application Layer Protocols | C13: 4 | D13: 40 | E13: 2 | F13: 2 | G13: 3 | H13: 2 | I13: 2 | J13: 1 | K13: 2 | L13: 2 | M13: 2 | N13: 2 | O13: 2 | P13: 3 | Q13: 2 | R13: 48 | S13: 73 | T13: 2 | U13: 2 | V13: 65 | W13: =IF(C13>=5,3,IF(C13>=3,2,IF(C13>=1,1,0))) -> 2 | X13: =IF(D13>40,3,IF(D13>15,2,IF(D13>5,1,0))) -> 2 | Y13: =IF(E13>=3,3,IF(E13>=2,2,IF(E13>=1,1,0))) -> 2 | Z13: =IF(F13>=3,3,IF(F13>=2,2,IF(F13>=1,1,0))) -> 2 | AA13: =IF(G13>=3,3,IF(G13>=2,2,IF(G13>=1,1,0))) -> 3 | AB13: =IF(H13>=3,3,IF(H13>=2,2,IF(H13>=1,1,0))) -> 2 | AC13: =IF(I13>=3,3,IF(I13>=2,2,IF(I13>=1,1,0))) -> 2 | AD13: =IF(J13>=3,3,IF(J13>=2,2,IF(J13>=1,1,0))) -> 1 | AE13: =IF(K13>=3,3,IF(K13>=2,2,IF(K13>=1,1,0))) -> 2 | AF13: =IF(L13>=3,3,IF(L13>=2,2,IF(L13>=1,1,0))) -> 2 | ... AK13: =IF(Q13>=3,3,IF(Q13>=2,2,IF(Q13>=1,1,0))) -> 2 | AL13: =IF(R13>60,3,IF(R13>40,2,IF(R13>25,1,0))) -> 2 | AM13: =IF(S13>70,3,IF(S13>50,2,IF(S13>40,1,0))) -> 3 | AN13: =IF(T13>=3,3,IF(T13>=2,2,IF(T13>=1,1,0))) -> 2 | AO13: =IF(U13>=3,3,IF(U13>=2,2,IF(U13>=1,1,0))) -> 2 | AP13: =IF(V13>70,3,IF(V13>40,2,IF(V13>0,1,0))) -> 2 | AQ13: =IFERROR(SUMPRODUCT(C7:V7,W13:AP13)/SUM(C7:V7),0) -> 2.1 | AR13: =IF(AQ13>=2.5,3,IF(AQ13>=1.5,2,IF(AQ13>=0.5,1,0))) -> 2 | AS13: =IF(AR13=0,"—",TEXT(AR13,"0")) -> 2 | AT13: =IF(AR13=0,"—",TEXT(AR13,"0")) -> 2 | AU13: =IF(AR13=0,"—",TEXT(AR13,"0")) -> 2 | AV13: — | AW13: — | AX13: =IF(AR13=0,"—",TEXT(AR13,"0")) -> 2 | AY13: — | AZ13: — | BA13: — | BB13: — | BC13: — | BD13: — | BE13: =IF(AR13=0,"—",TEXT(AR13,"0")) -> 2 | BF13: — | BG13: — | BH13: —
A15: COURSE AVG | C15: =AVERAGE(C9:C13) -> 3.8 | D15: =AVERAGE(D9:D13) -> 37.2 | E15: =AVERAGE(E9:E13) -> 2.2 | F15: =AVERAGE(F9:F13) -> 2.2 | G15: =AVERAGE(G9:G13) -> 2.6 | H15: =AVERAGE(H9:H13) -> 1.6 | I15: =AVERAGE(I9:I13) -> 2.2 | J15: =AVERAGE(J9:J13) -> 1.4 | ... AR15: =AVERAGE(AR9:AR13) -> 2 | AT15: =IFERROR(AVERAGEIF(AT9:AT13,"<>—"),"") | AU15: =IFERROR(AVERAGEIF(AU9:AU13,"<>—"),"") | AV15: =IFERROR(AVERAGEIF(AV9:AV13,"<>—"),"") | AW15: =IFERROR(AVERAGEIF(AW9:AW13,"<>—"),"") | AX15: =IFERROR(AVERAGEIF(AX9:AX13,"<>—"),"") | AY15: =IFERROR(AVERAGEIF(AY9:AY13,"<>—"),"") | AZ15: =IFERROR(AVERAGEIF(AZ9:AZ13,"<>—"),"") | BA15: =IFERROR(AVERAGEIF(BA9:BA13,"<>—"),"") | ... BH15: =IFERROR(AVERAGEIF(BH9:BH13,"<>—"),"")

Sheet Method Comparison
A1: METHOD COMPARISON — ALL 20 ADDITIONAL METHODS × ALL COURSES
A2: All values auto-linked from course sheets. Shows mapping level per method per CO.
A4: # | B4: Course | C4: Code | D4: CO | E4: MAPPING LEVELS PER METHOD (Auto-linked) | Y4: Combined Final Level
E5: M01 | F5: M02 | G5: M03 | H5: M04 | I5: M05 | J5: M06 | K5: M07 | L5: M08 | M5: M09 | N5: M10 | O5: M11 | P5: M12 | Q5: M13 | R5: M14 | S5: M15 | T5: M16 | U5: M17 | V5: M18 | W5: M19 | X5: M20 | Y5: Comb Score | Z5: Final Level
A6: 1 | B6: Data Structures & Algorithms | C6: CS301 | D6: CO1 | E6: =CS301!W9 -> 2 | F6: =CS301!X9 -> 2 | G6: =CS301!Y9 -> 2 | H6: =CS301!Z9 -> 2 | I6: =CS301!AA9 -> 2 | J6: =CS301!AB9 -> 1 | K6: =CS301!AC9 -> 2 | L6: =CS301!AD9 -> 1 | ... X6: =CS301!AP9 -> 2 | Y6: =IFERROR(AVERAGE(CS301!W9,CS301!X9,CS301!Y9,CS301!Z9,CS301!AA9,CS301!AB9,CS301!AC9,CS301!AD9,CS301!AE9,CS301!AF9,CS301!AG9,CS301!AH9,CS301!AI9,CS301!AJ9,CS301!AK9,CS301!AL9,CS301!AM9,CS301!AN9,CS301!AO9,CS301!AP9),0) -> 1.55 | Z6: =CS301!AR9 -> 2
D7: CO2 | E7: =CS301!W10 -> 2 | F7: =CS301!X10 -> 2 | G7: =CS301!Y10 -> 3 | H7: =CS301!Z10 -> 2 | I7: =CS301!AA10 -> 2 | J7: =CS301!AB10 -> 2 | K7: =CS301!AC10 -> 2 | L7: =CS301!AD10 -> 2 | ... X7: =CS301!AP10 -> 2 | Y7: =IFERROR(AVERAGE(CS301!W10,CS301!X10,CS301!Y10,CS301!Z10,CS301!AA10,CS301!AB10,CS301!AC10,CS301!AD10,CS301!AE10,CS301!AF10,CS301!AG10,CS301!AH10,CS301!AI10,CS301!AJ10,CS301!AK10,CS301!AL10,CS301!AM10,CS301!AN10,CS301!AO10,CS301!AP10),0) -> 1.9 | Z7: =CS301!AR10 -> 2
D8: CO3 | E8: =CS301!W11 -> 3 | F8: =CS301!X11 -> 3 | G8: =CS301!Y11 -> 3 | H8: =CS301!Z11 -> 3 | I8: =CS301!AA11 -> 3 | J8: =CS301!AB11 -> 2 | K8: =CS301!AC11 -> 3 | L8: =CS301!AD11 -> 2 | ... X8: =CS301!AP11 -> 3 | Y8: =IFERROR(AVERAGE(CS301!W11,CS301!X11,CS301!Y11,CS301!Z11,CS301!AA11,CS301!AB11,CS301!AC11,CS301!AD11,CS301!AE11,CS301!AF11,CS301!AG11,CS301!AH11,CS301!AI11,CS301!AJ11,CS301!AK11,CS301!AL11,CS301!AM11,CS301!AN11,CS301!AO11,CS301!AP11),0) -> 2.5 | Z8: =CS301!AR11 -> 3
D9: CO4 | E9: =CS301!W12 -> 2 | F9: =CS301!X12 -> 2 | G9: =CS301!Y12 -> 3 | H9: =CS301!Z12 -> 2 | I9: =CS301!AA12 -> 2 | J9: =CS301!AB12 -> 2 | K9: =CS301!AC12 -> 2 | L9: =CS301!AD12 -> 1 | ... X9: =CS301!AP12 -> 2 | Y9: =IFERROR(AVERAGE(CS301!W12,CS301!X12,CS301!Y12,CS301!Z12,CS301!AA12,CS301!AB12,CS301!AC12,CS301!AD12,CS301!AE12,CS301!AF12,CS301!AG12,CS301!AH12,CS301!AI12,CS301!AJ12,CS301!AK12,CS301!AL12,CS301!AM12,CS301!AN12,CS301!AO12,CS301!AP12),0) -> 1.8 | Z9: =CS301!AR12 -> 2
D10: CO5 | E10: =CS301!W13 -> 2 | F10: =CS301!X13 -> 2 | G10: =CS301!Y13 -> 3 | H10: =CS301!Z13 -> 2 | I10: =CS301!AA13 -> 2 | J10: =CS301!AB13 -> 1 | K10: =CS301!AC13 -> 2 | L10: =CS301!AD13 -> 2 | ... X10: =CS301!AP13 -> 2 | Y10: =IFERROR(AVERAGE(CS301!W13,CS301!X13,CS301!Y13,CS301!Z13,CS301!AA13,CS301!AB13,CS301!AC13,CS301!AD13,CS301!AE13,CS301!AF13,CS301!AG13,CS301!AH13,CS301!AI13,CS301!AJ13,CS301!AK13,CS301!AL13,CS301!AM13,CS301!AN13,CS301!AO13,CS301!AP13),0) -> 1.95 | Z10: =CS301!AR13 -> 2
A11: 2 | B11: Database Management Systems | C11: CS302 | D11: CO1 | E11: =CS302!W9 -> 1 | F11: =CS302!X9 -> 2 | G11: =CS302!Y9 -> 2 | H11: =CS302!Z9 -> 1 | I11: =CS302!AA9 -> 2 | J11: =CS302!AB9 -> 1 | K11: =CS302!AC9 -> 1 | L11: =CS302!AD9 -> 1 | ... X11: =CS302!AP9 -> 2 | Y11: =IFERROR(AVERAGE(CS302!W9,CS302!X9,CS302!Y9,CS302!Z9,CS302!AA9,CS302!AB9,CS302!AC9,CS302!AD9,CS302!AE9,CS302!AF9,CS302!AG9,CS302!AH9,CS302!AI9,CS302!AJ9,CS302!AK9,CS302!AL9,CS302!AM9,CS302!AN9,CS302!AO9,CS302!AP9),0) -> 1.25 | Z11: =CS302!AR9 -> 1
D12: CO2 | E12: =CS302!W10 -> 3 | F12: =CS302!X10 -> 3 | G12: =CS302!Y10 -> 3 | H12: =CS302!Z10 -> 3 | I12: =CS302!AA10 -> 3 | J12: =CS302!AB10 -> 2 | K12: =CS302!AC10 -> 3 | L12: =CS302!AD10 -> 2 | ... X12: =CS302!AP10 -> 3 | Y12: =IFERROR(AVERAGE(CS302!W10,CS302!X10,CS302!Y10,CS302!Z10,CS302!AA10,CS302!AB10,CS302!AC10,CS302!AD10,CS302!AE10,CS302!AF10,CS302!AG10,CS302!AH10,CS302!AI10,CS302!AJ10,CS302!AK10,CS302!AL10,CS302!AM10,CS302!AN10,CS302!AO10,CS302!AP10),0) -> 2.5 | Z12: =CS302!AR10 -> 3
D13: CO3 | E13: =CS302!W11 -> 2 | F13: =CS302!X11 -> 2 | G13: =CS302!Y11 -> 3 | H13: =CS302!Z11 -> 1 | I13: =CS302!AA11 -> 2 | J13: =CS302!AB11 -> 1 | K13: =CS302!AC11 -> 1 | L13: =CS302!AD11 -> 1 | ... X13: =CS302!AP11 -> 2 | Y13: =IFERROR(AVERAGE(CS302!W11,CS302!X11,CS302!Y11,CS302!Z11,CS302!AA11,CS302!AB11,CS302!AC11,CS302!AD11,CS302!AE11,CS302!AF11,CS302!AG11,CS302!AH11,CS302!AI11,CS302!AJ11,CS302!AK11,CS302!AL11,CS302!AM11,CS302!AN11,CS302!AO11,CS302!AP11),0) -> 1.6 | Z13: =CS302!AR11 -> 2
D14: CO4 | E14: =CS302!W12 -> 3 | F14: =CS302!X12 -> 3 | G14: =CS302!Y12 -> 3 | H14: =CS302!Z12 -> 2 | I14: =CS302!AA12 -> 2 | J14: =CS302!AB12 -> 2 | K14: =CS302!AC12 -> 2 | L14: =CS302!AD12 -> 2 | ... X14: =CS302!AP12 -> 2 | Y14: =IFERROR(AVERAGE(CS302!W12,CS302!X12,CS302!Y12,CS302!Z12,CS302!AA12,CS302!AB12,CS302!AC12,CS302!AD12,CS302!AE12,CS302!AF12,CS302!AG12,CS302!AH12,CS302!AI12,CS302!AJ12,CS302!AK12,CS302!AL12,CS302!AM12,CS302!AN12,CS302!AO12,CS302!AP12),0) -> 2.2 | Z14: =CS302!AR12 -> 2
D15: CO5 | E15: =CS302!W13 -> 3 | F15: =CS302!X13 -> 3 | G15: =CS302!Y13 -> 3 | H15: =CS302!Z13 -> 2 | I15: =CS302!AA13 -> 3 | J15: =CS302!AB13 -> 2 | K15: =CS302!AC13 -> 2 | L15: =CS302!AD13 -> 1 | ... X15: =CS302!AP13 -> 2 | Y15: =IFERROR(AVERAGE(CS302!W13,CS302!X13,CS302!Y13,CS302!Z13,CS302!AA13,CS302!AB13,CS302!AC13,CS302!AD13,CS302!AE13,CS302!AF13,CS302!AG13,CS302!AH13,CS302!AI13,CS302!AJ13,CS302!AK13,CS302!AL13,CS302!AM13,CS302!AN13,CS302!AO13,CS302!AP13),0) -> 2.05 | Z15: =CS302!AR13 -> 2
A16: 3 | B16: Computer Networks | C16: CS303 | D16: CO1 | E16: =CS303!W9 -> 1 | F16: =CS303!X9 -> 2 | G16: =CS303!Y9 -> 1 | H16: =CS303!Z9 -> 1 | I16: =CS303!AA9 -> 2 | J16: =CS303!AB9 -> 1 | K16: =CS303!AC9 -> 1 | L16: =CS303!AD9 -> 1 | ... X16: =CS303!AP9 -> 1 | Y16: =IFERROR(AVERAGE(CS303!W9,CS303!X9,CS303!Y9,CS303!Z9,CS303!AA9,CS303!AB9,CS303!AC9,CS303!AD9,CS303!AE9,CS303!AF9,CS303!AG9,CS303!AH9,CS303!AI9,CS303!AJ9,CS303!AK9,CS303!AL9,CS303!AM9,CS303!AN9,CS303!AO9,CS303!AP9),0) -> 1.15 | Z16: =CS303!AR9 -> 1
D17: CO2 | E17: =CS303!W10 -> 2 | F17: =CS303!X10 -> 2 | G17: =CS303!Y10 -> 3 | H17: =CS303!Z10 -> 3 | I17: =CS303!AA10 -> 3 | J17: =CS303!AB10 -> 2 | K17: =CS303!AC10 -> 3 | L17: =CS303!AD10 -> 2 | ... X17: =CS303!AP10 -> 2 | Y17: =IFERROR(AVERAGE(CS303!W10,CS303!X10,CS303!Y10,CS303!Z10,CS303!AA10,CS303!AB10,CS303!AC10,CS303!AD10,CS303!AE10,CS303!AF10,CS303!AG10,CS303!AH10,CS303!AI10,CS303!AJ10,CS303!AK10,CS303!AL10,CS303!AM10,CS303!AN10,CS303!AO10,CS303!AP10),0) -> 2.3 | Z17: =CS303!AR10 -> 2
D18: CO3 | E18: =CS303!W11 -> 3 | F18: =CS303!X11 -> 3 | G18: =CS303!Y11 -> 3 | H18: =CS303!Z11 -> 3 | I18: =CS303!AA11 -> 3 | J18: =CS303!AB11 -> 2 | K18: =CS303!AC11 -> 3 | L18: =CS303!AD11 -> 2 | ... X18: =CS303!AP11 -> 3 | Y18: =IFERROR(AVERAGE(CS303!W11,CS303!X11,CS303!Y11,CS303!Z11,CS303!AA11,CS303!AB11,CS303!AC11,CS303!AD11,CS303!AE11,CS303!AF11,CS303!AG11,CS303!AH11,CS303!AI11,CS303!AJ11,CS303!AK11,CS303!AL11,CS303!AM11,CS303!AN11,CS303!AO11,CS303!AP11),0) -> 2.6 | Z18: =CS303!AR11 -> 3
D19: CO4 | E19: =CS303!W12 -> 2 | F19: =CS303!X12 -> 2 | G19: =CS303!Y12 -> 2 | H19: =CS303!Z12 -> 2 | I19: =CS303!AA12 -> 2 | J19: =CS303!AB12 -> 1 | K19: =CS303!AC12 -> 2 | L19: =CS303!AD12 -> 1 | ... X19: =CS303!AP12 -> 2 | Y19: =IFERROR(AVERAGE(CS303!W12,CS303!X12,CS303!Y12,CS303!Z12,CS303!AA12,CS303!AB12,CS303!AC12,CS303!AD12,CS303!AE12,CS303!AF12,CS303!AG12,CS303!AH12,CS303!AI12,CS303!AJ12,CS303!AK12,CS303!AL12,CS303!AM12,CS303!AN12,CS303!AO12,CS303!AP12),0) -> 1.55 | Z19: =CS303!AR12 -> 2
D20: CO5 | E20: =CS303!W13 -> 2 | F20: =CS303!X13 -> 2 | G20: =CS303!Y13 -> 2 | H20: =CS303!Z13 -> 2 | I20: =CS303!AA13 -> 3 | J20: =CS303!AB13 -> 2 | K20: =CS303!AC13 -> 2 | L20: =CS303!AD13 -> 1 | ... X20: =CS303!AP13 -> 2 | Y20: =IFERROR(AVERAGE(CS303!W13,CS303!X13,CS303!Y13,CS303!Z13,CS303!AA13,CS303!AB13,CS303!AC13,CS303!AD13,CS303!AE13,CS303!AF13,CS303!AG13,CS303!AH13,CS303!AI13,CS303!AJ13,CS303!AK13,CS303!AL13,CS303!AM13,CS303!AN13,CS303!AO13,CS303!AP13),0) -> 2.1 | Z20: =CS303!AR13 -> 2
A21: 4 | B21: Operating Systems | C21: CS304 | D21: CO1 | E21: =CS304!W9 -> 2 | F21: =CS304!X9 -> 2 | G21: =CS304!Y9 -> 3 | H21: =CS304!Z9 -> 2 | I21: =CS304!AA9 -> 2 | J21: =CS304!AB9 -> 1 | K21: =CS304!AC9 -> 2 | L21: =CS304!AD9 -> 1 | ... X21: =CS304!AP9 -> 2 | Y21: =IFERROR(AVERAGE(CS304!W9,CS304!X9,CS304!Y9,CS304!Z9,CS304!AA9,CS304!AB9,CS304!AC9,CS304!AD9,CS304!AE9,CS304!AF9,CS304!AG9,CS304!AH9,CS304!AI9,CS304!AJ9,CS304!AK9,CS304!AL9,CS304!AM9,CS304!AN9,CS304!AO9,CS304!AP9),0) -> 1.7 | Z21: =CS304!AR9 -> 2
D22: CO2 | E22: =CS304!W10 -> 3 | F22: =CS304!X10 -> 3 | G22: =CS304!Y10 -> 3 | H22: =CS304!Z10 -> 3 | I22: =CS304!AA10 -> 2 | J22: =CS304!AB10 -> 2 | K22: =CS304!AC10 -> 2 | L22: =CS304!AD10 -> 2 | ... X22: =CS304!AP10 -> 2 | Y22: =IFERROR(AVERAGE(CS304!W10,CS304!X10,CS304!Y10,CS304!Z10,CS304!AA10,CS304!AB10,CS304!AC10,CS304!AD10,CS304!AE10,CS304!AF10,CS304!AG10,CS304!AH10,CS304!AI10,CS304!AJ10,CS304!AK10,CS304!AL10,CS304!AM10,CS304!AN10,CS304!AO10,CS304!AP10),0) -> 2.35 | Z22: =CS304!AR10 -> 2
D23: CO3 | E23: =CS304!W11 -> 2 | F23: =CS304!X11 -> 2 | G23: =CS304!Y11 -> 3 | H23: =CS304!Z11 -> 2 | I23: =CS304!AA11 -> 2 | J23: =CS304!AB11 -> 1 | K23: =CS304!AC11 -> 2 | L23: =CS304!AD11 -> 1 | ... X23: =CS304!AP11 -> 2 | Y23: =IFERROR(AVERAGE(CS304!W11,CS304!X11,CS304!Y11,CS304!Z11,CS304!AA11,CS304!AB11,CS304!AC11,CS304!AD11,CS304!AE11,CS304!AF11,CS304!AG11,CS304!AH11,CS304!AI11,CS304!AJ11,CS304!AK11,CS304!AL11,CS304!AM11,CS304!AN11,CS304!AO11,CS304!AP11),0) -> 1.6 | Z23: =CS304!AR11 -> 2
D24: CO4 | E24: =CS304!W12 -> 2 | F24: =CS304!X12 -> 2 | G24: =CS304!Y12 -> 2 | H24: =CS304!Z12 -> 2 | I24: =CS304!AA12 -> 2 | J24: =CS304!AB12 -> 1 | K24: =CS304!AC12 -> 2 | L24: =CS304!AD12 -> 1 | ... X24: =CS304!AP12 -> 2 | Y24: =IFERROR(AVERAGE(CS304!W12,CS304!X12,CS304!Y12,CS304!Z12,CS304!AA12,CS304!AB12,CS304!AC12,CS304!AD12,CS304!AE12,CS304!AF12,CS304!AG12,CS304!AH12,CS304!AI12,CS304!AJ12,CS304!AK12,CS304!AL12,CS304!AM12,CS304!AN12,CS304!AO12,CS304!AP12),0) -> 1.5 | Z24: =CS304!AR12 -> 2
D25: CO5 | E25: =CS304!W13 -> 2 | F25: =CS304!X13 -> 2 | G25: =CS304!Y13 -> 2 | H25: =CS304!Z13 -> 2 | I25: =CS304!AA13 -> 2 | J25: =CS304!AB13 -> 1 | K25: =CS304!AC13 -> 2 | L25: =CS304!AD13 -> 1 | ... X25: =CS304!AP13 -> 2 | Y25: =IFERROR(AVERAGE(CS304!W13,CS304!X13,CS304!Y13,CS304!Z13,CS304!AA13,CS304!AB13,CS304!AC13,CS304!AD13,CS304!AE13,CS304!AF13,CS304!AG13,CS304!AH13,CS304!AI13,CS304!AJ13,CS304!AK13,CS304!AL13,CS304!AM13,CS304!AN13,CS304!AO13,CS304!AP13),0) -> 1.55 | Z25: =CS304!AR13 -> 2
A26: 5 | B26: Machine Learning | C26: CS305 | D26: CO1 | E26: =CS305!W9 -> 2 | F26: =CS305!X9 -> 2 | G26: =CS305!Y9 -> 2 | H26: =CS305!Z9 -> 3 | I26: =CS305!AA9 -> 3 | J26: =CS305!AB9 -> 2 | K26: =CS305!AC9 -> 3 | L26: =CS305!AD9 -> 2 | ... X26: =CS305!AP9 -> 2 | Y26: =IFERROR(AVERAGE(CS305!W9,CS305!X9,CS305!Y9,CS305!Z9,CS305!AA9,CS305!AB9,CS305!AC9,CS305!AD9,CS305!AE9,CS305!AF9,CS305!AG9,CS305!AH9,CS305!AI9,CS305!AJ9,CS305!AK9,CS305!AL9,CS305!AM9,CS305!AN9,CS305!AO9,CS305!AP9),0) -> 2.25 | Z26: =CS305!AR9 -> 2
D27: CO2 | E27: =CS305!W10 -> 2 | F27: =CS305!X10 -> 3 | G27: =CS305!Y10 -> 3 | H27: =CS305!Z10 -> 3 | I27: =CS305!AA10 -> 3 | J27: =CS305!AB10 -> 2 | K27: =CS305!AC10 -> 3 | L27: =CS305!AD10 -> 2 | ... X27: =CS305!AP10 -> 2 | Y27: =IFERROR(AVERAGE(CS305!W10,CS305!X10,CS305!Y10,CS305!Z10,CS305!AA10,CS305!AB10,CS305!AC10,CS305!AD10,CS305!AE10,CS305!AF10,CS305!AG10,CS305!AH10,CS305!AI10,CS305!AJ10,CS305!AK10,CS305!AL10,CS305!AM10,CS305!AN10,CS305!AO10,CS305!AP10),0) -> 2.45 | Z27: =CS305!AR10 -> 2
D28: CO3 | E28: =CS305!W11 -> 3 | F28: =CS305!X11 -> 3 | G28: =CS305!Y11 -> 3 | H28: =CS305!Z11 -> 3 | I28: =CS305!AA11 -> 3 | J28: =CS305!AB11 -> 3 | K28: =CS305!AC11 -> 3 | L28: =CS305!AD11 -> 2 | ... X28: =CS305!AP11 -> 3 | Y28: =IFERROR(AVERAGE(CS305!W11,CS305!X11,CS305!Y11,CS305!Z11,CS305!AA11,CS305!AB11,CS305!AC11,CS305!AD11,CS305!AE11,CS305!AF11,CS305!AG11,CS305!AH11,CS305!AI11,CS305!AJ11,CS305!AK11,CS305!AL11,CS305!AM11,CS305!AN11,CS305!AO11,CS305!AP11),0) -> 2.95 | Z28: =CS305!AR11 -> 3
D29: CO4 | E29: =CS305!W12 -> 2 | F29: =CS305!X12 -> 2 | G29: =CS305!Y12 -> 3 | H29: =CS305!Z12 -> 3 | I29: =CS305!AA12 -> 3 | J29: =CS305!AB12 -> 2 | K29: =CS305!AC12 -> 3 | L29: =CS305!AD12 -> 2 | ... X29: =CS305!AP12 -> 2 | Y29: =IFERROR(AVERAGE(CS305!W12,CS305!X12,CS305!Y12,CS305!Z12,CS305!AA12,CS305!AB12,CS305!AC12,CS305!AD12,CS305!AE12,CS305!AF12,CS305!AG12,CS305!AH12,CS305!AI12,CS305!AJ12,CS305!AK12,CS305!AL12,CS305!AM12,CS305!AN12,CS305!AO12,CS305!AP12),0) -> 2.35 | Z29: =CS305!AR12 -> 2
D30: CO5 | E30: =CS305!W13 -> 3 | F30: =CS305!X13 -> 3 | G30: =CS305!Y13 -> 3 | H30: =CS305!Z13 -> 3 | I30: =CS305!AA13 -> 3 | J30: =CS305!AB13 -> 2 | K30: =CS305!AC13 -> 3 | L30: =CS305!AD13 -> 2 | ... X30: =CS305!AP13 -> 3 | Y30: =IFERROR(AVERAGE(CS305!W13,CS305!X13,CS305!Y13,CS305!Z13,CS305!AA13,CS305!AB13,CS305!AC13,CS305!AD13,CS305!AE13,CS305!AF13,CS305!AG13,CS305!AH13,CS305!AI13,CS305!AJ13,CS305!AK13,CS305!AL13,CS305!AM13,CS305!AN13,CS305!AO13,CS305!AP13),0) -> 2.55 | Z30: =CS305!AR13 -> 3
D31: CO6 | E31: =CS305!W14 -> 3 | F31: =CS305!X14 -> 3 | G31: =CS305!Y14 -> 3 | H31: =CS305!Z14 -> 3 | I31: =CS305!AA14 -> 3 | J31: =CS305!AB14 -> 3 | K31: =CS305!AC14 -> 3 | L31: =CS305!AD14 -> 3 | ... X31: =CS305!AP14 -> 3 | Y31: =IFERROR(AVERAGE(CS305!W14,CS305!X14,CS305!Y14,CS305!Z14,CS305!AA14,CS305!AB14,CS305!AC14,CS305!AD14,CS305!AE14,CS305!AF14,CS305!AG14,CS305!AH14,CS305!AI14,CS305!AJ14,CS305!AK14,CS305!AL14,CS305!AM14,CS305!AN14,CS305!AO14,CS305!AP14),0) -> 3 | Z31: =CS305!AR14 -> 3
