Workbook

Sheet Course_Config
A1: Parameter | B1: Value | C1: Notes
A2: Weeks | B2: 12 | C2: Edit as needed
A3: L_per_week (hrs) | B3: 3 | C3: Lecture hours per week
A4: T_per_week (hrs) | B4: 1 | C4: Tutorial hours per week
A5: P_per_week (hrs) | B5: 2 | C5: Practical/Lab hours per week
A6: S_per_week (hrs) | B6: 0 | C6: Skilling/Project hrs per week (if any)
A7: Total_Course_Hours | C7: =(L+T+P+S) × Weeks (auto)
A8: Total_Course_Hours | B8: =B2*(B3+B4+B5+B6) | C8: Auto-calculated
A10: Named References | C10: (Do not edit)
A11: TotalHours | B11: =B8
A12: Weeks_ref | B12: =B2

Sheet Thresholds
A1: Level | B1: Contact Hours Percentage | C1: Mapping Value
A2: No Mapping (–) | B2: < 5% | C2: –
A3: Low (1) | B3: 5% – 15% | C3: 1
A4: Medium (2) | B4: 15% – 25% | C4: 2
A5: High (3) | B5: > 25% | C5: 3

Sheet CO_Definition
A1: CO | B1: L hours | C1: T hours | D1: P hours | E1: S hours | F1: CO Total Hours | G1: CO % of Total Course Hours | H1: Notes
A2: CO1 | B2: 0 | C2: 0 | D2: 0 | E2: 0 | F2: =SUM(B2:E2) | G2: =IF('Course_Config'!B8>0, F2/'Course_Config'!B8, 0) | H2: Enter hours that directly support this CO (from L/T/P/S)
A3: CO2 | B3: 0 | C3: 0 | D3: 0 | E3: 0 | F3: =SUM(B3:E3) | G3: =IF('Course_Config'!B8>0, F3/'Course_Config'!B8, 0) | H3: Enter hours that directly support this CO (from L/T/P/S)
A4: CO3 | B4: 0 | C4: 0 | D4: 0 | E4: 0 | F4: =SUM(B4:E4) | G4: =IF('Course_Config'!B8>0, F4/'Course_Config'!B8, 0) | H4: Enter hours that directly support this CO (from L/T/P/S)
A5: CO4 | B5: 0 | C5: 0 | D5: 0 | E5: 0 | F5: =SUM(B5:E5) | G5: =IF('Course_Config'!B8>0, F5/'Course_Config'!B8, 0) | H5: Enter hours that directly support this CO (from L/T/P/S)
A6: CO5 | B6: 0 | C6: 0 | D6: 0 | E6: 0 | F6: =SUM(B6:E6) | G6: =IF('Course_Config'!B8>0, F6/'Course_Config'!B8, 0) | H6: Enter hours that directly support this CO (from L/T/P/S)
A7: CO6 | B7: 0 | C7: 0 | D7: 0 | E7: 0 | F7: =SUM(B7:E7) | G7: =IF('Course_Config'!B8>0, F7/'Course_Config'!B8, 0) | H7: Enter hours that directly support this CO (from L/T/P/S)

Sheet CO_PO_Input
A1: CO | B1: PO1 | C1: PO2 | D1: PO3 | E1: PO4 | F1: PO5 | G1: PO6 | H1: PO7 | I1: PO8 | J1: PO9 | K1: PO10 | L1: PO11 | M1: PO12
A2: CO1 | B2: 0 | C2: 0 | D2: 0 | E2: 0 | F2: 0 | G2: 0 | H2: 0 | I2: 0 | J2: 0 | K2: 0 | L2: 0 | M2: 0
A3: CO2 | B3: 0 | C3: 0 | D3: 0 | E3: 0 | F3: 0 | G3: 0 | H3: 0 | I3: 0 | J3: 0 | K3: 0 | L3: 0 | M3: 0
A4: CO3 | B4: 0 | C4: 0 | D4: 0 | E4: 0 | F4: 0 | G4: 0 | H4: 0 | I4: 0 | J4: 0 | K4: 0 | L4: 0 | M4: 0
A5: CO4 | B5: 0 | C5: 0 | D5: 0 | E5: 0 | F5: 0 | G5: 0 | H5: 0 | I5: 0 | J5: 0 | K5: 0 | L5: 0 | M5: 0
A6: CO5 | B6: 0 | C6: 0 | D6: 0 | E6: 0 | F6: 0 | G6: 0 | H6: 0 | I6: 0 | J6: 0 | K6: 0 | L6: 0 | M6: 0
A7: CO6 | B7: 0 | C7: 0 | D7: 0 | E7: 0 | F7: 0 | G7: 0 | H7: 0 | I7: 0 | J7: 0 | K7: 0 | L7: 0 | M7: 0
A10: Guidance:
A11: Enter the *hours* (from L/T/P/S) that specifically contribute to each PO, per CO.
A12: These should be a subset of total course hours (see Course_Config!B8).

Sheet CO_PO_Mapping
A1: CO | B1: PO | C1: Hours for this CO–PO (ref) | D1: % of Total Course Hours | E1: Mapping Value (–/1/2/3)
A2: CO1 | B2: PO1 | C2: ='CO_PO_Input'!B2 | D2: =IF('Course_Config'!B8>0, C2/'Course_Config'!B8, 0) | E2: =IF(D2<0.05,"–", IF(D2<=0.15,1, IF(D2<=0.25,2,3)))
A3: CO1 | B3: PO2 | C3: ='CO_PO_Input'!C2 | D3: =IF('Course_Config'!B8>0, C3/'Course_Config'!B8, 0) | E3: =IF(D3<0.05,"–", IF(D3<=0.15,1, IF(D3<=0.25,2,3)))
A4: CO1 | B4: PO3 | C4: ='CO_PO_Input'!D2 | D4: =IF('Course_Config'!B8>0, C4/'Course_Config'!B8, 0) | E4: =IF(D4<0.05,"–", IF(D4<=0.15,1, IF(D4<=0.25,2,3)))
A5: CO1 | B5: PO4 | C5: ='CO_PO_Input'!E2 | D5: =IF('Course_Config'!B8>0, C5/'Course_Config'!B8, 0) | E5: =IF(D5<0.05,"–", IF(D5<=0.15,1, IF(D5<=0.25,2,3)))
A6: CO1 | B6: PO5 | C6: ='CO_PO_Input'!F2 | D6: =IF('Course_Config'!B8>0, C6/'Course_Config'!B8, 0) | E6: =IF(D6<0.05,"–", IF(D6<=0.15,1, IF(D6<=0.25,2,3)))
A7: CO1 | B7: PO6 | C7: ='CO_PO_Input'!G2 | D7: =IF('Course_Config'!B8>0, C7/'Course_Config'!B8, 0) | E7: =IF(D7<0.05,"–", IF(D7<=0.15,1, IF(D7<=0.25,2,3)))
A8: CO1 | B8: PO7 | C8: ='CO_PO_Input'!H2 | D8: =IF('Course_Config'!B8>0, C8/'Course_Config'!B8, 0) | E8: =IF(D8<0.05,"–", IF(D8<=0.15,1, IF(D8<=0.25,2,3)))
A9: CO1 | B9: PO8 | C9: ='CO_PO_Input'!I2 | D9: =IF('Course_Config'!B8>0, C9/'Course_Config'!B8, 0) | E9: =IF(D9<0.05,"–", IF(D9<=0.15,1, IF(D9<=0.25,2,3)))
A10: CO1 | B10: PO9 | C10: ='CO_PO_Input'!J2 | D10: =IF('Course_Config'!B8>0, C10/'Course_Config'!B8, 0) | E10: =IF(D10<0.05,"–", IF(D10<=0.15,1, IF(D10<=0.25,2,3)))
A11: CO1 | B11: PO10 | C11: ='CO_PO_Input'!K2 | D11: =IF('Course_Config'!B8>0, C11/'Course_Config'!B8, 0) | E11: =IF(D11<0.05,"–", IF(D11<=0.15,1, IF(D11<=0.25,2,3)))
A12: CO1 | B12: PO11 | C12: ='CO_PO_Input'!L2 | D12: =IF('Course_Config'!B8>0, C12/'Course_Config'!B8, 0) | E12: =IF(D12<0.05,"–", IF(D12<=0.15,1, IF(D12<=0.25,2,3)))
A13: CO1 | B13: PO12 | C13: ='CO_PO_Input'!M2 | D13: =IF('Course_Config'!B8>0, C13/'Course_Config'!B8, 0) | E13: =IF(D13<0.05,"–", IF(D13<=0.15,1, IF(D13<=0.25,2,3)))
A14: CO2 | B14: PO1 | C14: ='CO_PO_Input'!B3 | D14: =IF('Course_Config'!B8>0, C14/'Course_Config'!B8, 0) | E14: =IF(D14<0.05,"–", IF(D14<=0.15,1, IF(D14<=0.25,2,3)))
A15: CO2 | B15: PO2 | C15: ='CO_PO_Input'!C3 | D15: =IF('Course_Config'!B8>0, C15/'Course_Config'!B8, 0) | E15: =IF(D15<0.05,"–", IF(D15<=0.15,1, IF(D15<=0.25,2,3)))
A16: CO2 | B16: PO3 | C16: ='CO_PO_Input'!D3 | D16: =IF('Course_Config'!B8>0, C16/'Course_Config'!B8, 0) | E16: =IF(D16<0.05,"–", IF(D16<=0.15,1, IF(D16<=0.25,2,3)))
A17: CO2 | B17: PO4 | C17: ='CO_PO_Input'!E3 | D17: =IF('Course_Config'!B8>0, C17/'Course_Config'!B8, 0) | E17: =IF(D17<0.05,"–", IF(D17<=0.15,1, IF(D17<=0.25,2,3)))
A18: CO2 | B18: PO5 | C18: ='CO_PO_Input'!F3 | D18: =IF('Course_Config'!B8>0, C18/'Course_Config'!B8, 0) | E18: =IF(D18<0.05,"–", IF(D18<=0.15,1, IF(D18<=0.25,2,3)))
A19: CO2 | B19: PO6 | C19: ='CO_PO_Input'!G3 | D19: =IF('Course_Config'!B8>0, C19/'Course_Config'!B8, 0) | E19: =IF(D19<0.05,"–", IF(D19<=0.15,1, IF(D19<=0.25,2,3)))
A20: CO2 | B20: PO7 | C20: ='CO_PO_Input'!H3 | D20: =IF('Course_Config'!B8>0, C20/'Course_Config'!B8, 0) | E20: =IF(D20<0.05,"–", IF(D20<=0.15,1, IF(D20<=0.25,2,3)))
A21: CO2 | B21: PO8 | C21: ='CO_PO_Input'!I3 | D21: =IF('Course_Config'!B8>0, C21/'Course_Config'!B8, 0) | E21: =IF(D21<0.05,"–", IF(D21<=0.15,1, IF(D21<=0.25,2,3)))
A22: CO2 | B22: PO9 | C22: ='CO_PO_Input'!J3 | D22: =IF('Course_Config'!B8>0, C22/'Course_Config'!B8, 0) | E22: =IF(D22<0.05,"–", IF(D22<=0.15,1, IF(D22<=0.25,2,3)))
A23: CO2 | B23: PO10 | C23: ='CO_PO_Input'!K3 | D23: =IF('Course_Config'!B8>0, C23/'Course_Config'!B8, 0) | E23: =IF(D23<0.05,"–", IF(D23<=0.15,1, IF(D23<=0.25,2,3)))
A24: CO2 | B24: PO11 | C24: ='CO_PO_Input'!L3 | D24: =IF('Course_Config'!B8>0, C24/'Course_Config'!B8, 0) | E24: =IF(D24<0.05,"–", IF(D24<=0.15,1, IF(D24<=0.25,2,3)))
A25: CO2 | B25: PO12 | C25: ='CO_PO_Input'!M3 | D25: =IF('Course_Config'!B8>0, C25/'Course_Config'!B8, 0) | E25: =IF(D25<0.05,"–", IF(D25<=0.15,1, IF(D25<=0.25,2,3)))
A26: CO3 | B26: PO1 | C26: ='CO_PO_Input'!B4 | D26: =IF('Course_Config'!B8>0, C26/'Course_Config'!B8, 0) | E26: =IF(D26<0.05,"–", IF(D26<=0.15,1, IF(D26<=0.25,2,3)))
A27: CO3 | B27: PO2 | C27: ='CO_PO_Input'!C4 | D27: =IF('Course_Config'!B8>0, C27/'Course_Config'!B8, 0) | E27: =IF(D27<0.05,"–", IF(D27<=0.15,1, IF(D27<=0.25,2,3)))
A28: CO3 | B28: PO3 | C28: ='CO_PO_Input'!D4 | D28: =IF('Course_Config'!B8>0, C28/'Course_Config'!B8, 0) | E28: =IF(D28<0.05,"–", IF(D28<=0.15,1, IF(D28<=0.25,2,3)))
A29: CO3 | B29: PO4 | C29: ='CO_PO_Input'!E4 | D29: =IF('Course_Config'!B8>0, C29/'Course_Config'!B8, 0) | E29: =IF(D29<0.05,"–", IF(D29<=0.15,1, IF(D29<=0.25,2,3)))
A30: CO3 | B30: PO5 | C30: ='CO_PO_Input'!F4 | D30: =IF('Course_Config'!B8>0, C30/'Course_Config'!B8, 0) | E30: =IF(D30<0.05,"–", IF(D30<=0.15,1, IF(D30<=0.25,2,3)))
A31: CO3 | B31: PO6 | C31: ='CO_PO_Input'!G4 | D31: =IF('Course_Config'!B8>0, C31/'Course_Config'!B8, 0) | E31: =IF(D31<0.05,"–", IF(D31<=0.15,1, IF(D31<=0.25,2,3)))
A32: CO3 | B32: PO7 | C32: ='CO_PO_Input'!H4 | D32: =IF('Course_Config'!B8>0, C32/'Course_Config'!B8, 0) | E32: =IF(D32<0.05,"–", IF(D32<=0.15,1, IF(D32<=0.25,2,3)))
A33: CO3 | B33: PO8 | C33: ='CO_PO_Input'!I4 | D33: =IF('Course_Config'!B8>0, C33/'Course_Config'!B8, 0) | E33: =IF(D33<0.05,"–", IF(D33<=0.15,1, IF(D33<=0.25,2,3)))
A34: CO3 | B34: PO9 | C34: ='CO_PO_Input'!J4 | D34: =IF('Course_Config'!B8>0, C34/'Course_Config'!B8, 0) | E34: =IF(D34<0.05,"–", IF(D34<=0.15,1, IF(D34<=0.25,2,3)))
A35: CO3 | B35: PO10 | C35: ='CO_PO_Input'!K4 | D35: =IF('Course_Config'!B8>0, C35/'Course_Config'!B8, 0) | E35: =IF(D35<0.05,"–", IF(D35<=0.15,1, IF(D35<=0.25,2,3)))
A36: CO3 | B36: PO11 | C36: ='CO_PO_Input'!L4 | D36: =IF('Course_Config'!B8>0, C36/'Course_Config'!B8, 0) | E36: =IF(D36<0.05,"–", IF(D36<=0.15,1, IF(D36<=0.25,2,3)))
A37: CO3 | B37: PO12 | C37: ='CO_PO_Input'!M4 | D37: =IF('Course_Config'!B8>0, C37/'Course_Config'!B8, 0) | E37: =IF(D37<0.05,"–", IF(D37<=0.15,1, IF(D37<=0.25,2,3)))
A38: CO4 | B38: PO1 | C38: ='CO_PO_Input'!B5 | D38: =IF('Course_Config'!B8>0, C38/'Course_Config'!B8, 0) | E38: =IF(D38<0.05,"–", IF(D38<=0.15,1, IF(D38<=0.25,2,3)))
A39: CO4 | B39: PO2 | C39: ='CO_PO_Input'!C5 | D39: =IF('Course_Config'!B8>0, C39/'Course_Config'!B8, 0) | E39: =IF(D39<0.05,"–", IF(D39<=0.15,1, IF(D39<=0.25,2,3)))
A40: CO4 | B40: PO3 | C40: ='CO_PO_Input'!D5 | D40: =IF('Course_Config'!B8>0, C40/'Course_Config'!B8, 0) | E40: =IF(D40<0.05,"–", IF(D40<=0.15,1, IF(D40<=0.25,2,3)))
...

Sheet Summary_Matrix
B1: PO1 | C1: PO2 | D1: PO3 | E1: PO4 | F1: PO5 | G1: PO6 | H1: PO7 | I1: PO8 | J1: PO9 | K1: PO10 | L1: PO11 | M1: PO12
A2: CO1 | B2: =INDEX('CO_PO_Mapping'!E:E,2) | C2: =INDEX('CO_PO_Mapping'!E:E,3) | D2: =INDEX('CO_PO_Mapping'!E:E,4) | E2: =INDEX('CO_PO_Mapping'!E:E,5) | F2: =INDEX('CO_PO_Mapping'!E:E,6) | G2: =INDEX('CO_PO_Mapping'!E:E,7) | H2: =INDEX('CO_PO_Mapping'!E:E,8) | I2: =INDEX('CO_PO_Mapping'!E:E,9) | J2: =INDEX('CO_PO_Mapping'!E:E,10) | K2: =INDEX('CO_PO_Mapping'!E:E,11) | L2: =INDEX('CO_PO_Mapping'!E:E,12) | M2: =INDEX('CO_PO_Mapping'!E:E,13)
A3: CO2 | B3: =INDEX('CO_PO_Mapping'!E:E,14) | C3: =INDEX('CO_PO_Mapping'!E:E,15) | D3: =INDEX('CO_PO_Mapping'!E:E,16) | E3: =INDEX('CO_PO_Mapping'!E:E,17) | F3: =INDEX('CO_PO_Mapping'!E:E,18) | G3: =INDEX('CO_PO_Mapping'!E:E,19) | H3: =INDEX('CO_PO_Mapping'!E:E,20) | I3: =INDEX('CO_PO_Mapping'!E:E,21) | J3: =INDEX('CO_PO_Mapping'!E:E,22) | K3: =INDEX('CO_PO_Mapping'!E:E,23) | L3: =INDEX('CO_PO_Mapping'!E:E,24) | M3: =INDEX('CO_PO_Mapping'!E:E,25)
A4: CO3 | B4: =INDEX('CO_PO_Mapping'!E:E,26) | C4: =INDEX('CO_PO_Mapping'!E:E,27) | D4: =INDEX('CO_PO_Mapping'!E:E,28) | E4: =INDEX('CO_PO_Mapping'!E:E,29) | F4: =INDEX('CO_PO_Mapping'!E:E,30) | G4: =INDEX('CO_PO_Mapping'!E:E,31) | H4: =INDEX('CO_PO_Mapping'!E:E,32) | I4: =INDEX('CO_PO_Mapping'!E:E,33) | J4: =INDEX('CO_PO_Mapping'!E:E,34) | K4: =INDEX('CO_PO_Mapping'!E:E,35) | L4: =INDEX('CO_PO_Mapping'!E:E,36) | M4: =INDEX('CO_PO_Mapping'!E:E,37)
A5: CO4 | B5: =INDEX('CO_PO_Mapping'!E:E,38) | C5: =INDEX('CO_PO_Mapping'!E:E,39) | D5: =INDEX('CO_PO_Mapping'!E:E,40) | E5: =INDEX('CO_PO_Mapping'!E:E,41) | F5: =INDEX('CO_PO_Mapping'!E:E,42) | G5: =INDEX('CO_PO_Mapping'!E:E,43) | H5: =INDEX('CO_PO_Mapping'!E:E,44) | I5: =INDEX('CO_PO_Mapping'!E:E,45) | J5: =INDEX('CO_PO_Mapping'!E:E,46) | K5: =INDEX('CO_PO_Mapping'!E:E,47) | L5: =INDEX('CO_PO_Mapping'!E:E,48) | M5: =INDEX('CO_PO_Mapping'!E:E,49)
A6: CO5 | B6: =INDEX('CO_PO_Mapping'!E:E,50) | C6: =INDEX('CO_PO_Mapping'!E:E,51) | D6: =INDEX('CO_PO_Mapping'!E:E,52) | E6: =INDEX('CO_PO_Mapping'!E:E,53) | F6: =INDEX('CO_PO_Mapping'!E:E,54) | G6: =INDEX('CO_PO_Mapping'!E:E,55) | H6: =INDEX('CO_PO_Mapping'!E:E,56) | I6: =INDEX('CO_PO_Mapping'!E:E,57) | J6: =INDEX('CO_PO_Mapping'!E:E,58) | K6: =INDEX('CO_PO_Mapping'!E:E,59) | L6: =INDEX('CO_PO_Mapping'!E:E,60) | M6: =INDEX('CO_PO_Mapping'!E:E,61)
A7: CO6 | B7: =INDEX('CO_PO_Mapping'!E:E,62) | C7: =INDEX('CO_PO_Mapping'!E:E,63) | D7: =INDEX('CO_PO_Mapping'!E:E,64) | E7: =INDEX('CO_PO_Mapping'!E:E,65) | F7: =INDEX('CO_PO_Mapping'!E:E,66) | G7: =INDEX('CO_PO_Mapping'!E:E,67) | H7: =INDEX('CO_PO_Mapping'!E:E,68) | I7: =INDEX('CO_PO_Mapping'!E:E,69) | J7: =INDEX('CO_PO_Mapping'!E:E,70) | K7: =INDEX('CO_PO_Mapping'!E:E,71) | L7: =INDEX('CO_PO_Mapping'!E:E,72) | M7: =INDEX('CO_PO_Mapping'!E:E,73)

Sheet ReadMe
A1: How to use
A2: 1) Go to Course_Config and set Weeks and L/T/P/S hours per week.
A3: 2) (Optional) In CO_Definition, apportion L/T/P/S hours that directly support each CO. This is for your internal tracking.
A4: 3) In CO_PO_Input, for each CO–PO pair, enter the number of hours that contribute to that PO (subset of total course hours).
A5: 4) CO_PO_Mapping will auto-calc the percentage of total and map it to –/1/2/3 using thresholds.
A6: 5) Summary_Matrix shows the articulation matrix (CO rows × PO columns) using the calculated mapping values.
A8: Thresholds used
A9: – : < 5% | 1 : 5%–15% | 2 : 15%–25% | 3 : > 25%
A11: Notes
A12: • If your institution counts S (Skilling) hours separately, set S_per_week accordingly in Course_Config.
A13: • You can expand COs by inserting rows in CO_Definition and CO_PO_Input and dragging formulas down in dependent sheets.
