Workbook

Sheet Master Dashboard
A1: CO & PO ATTAINMENT — COMPLETE AUTO-CALCULATION MASTER DASHBOARD | B.Tech CSE | AY 2024-25
A2: Enter marks in Course sheets (CS301–CS305) → CO Att% auto-calculates → CO-PO Mapping links CO att% → PO Direct Att% auto-calculates → Add survey scores in Indirect sheet → PO Total Att% auto-updates
A4: 📥 STEP 1: Enter Marks → 📊 STEP 2: CO Att% Auto → 🔗 STEP 3: CO-PO Mapping → 📈 STEP 4: PO Direct Auto → 📝 STEP 5: Survey Scores → 🏁 STEP 6: PO Total Auto
A6: SECTION A — CO ATTAINMENT SUMMARY | J6: SECTION B — PO TOTAL ATTAINMENT SUMMARY
A7: # | B7: Course | C7: Code | D7: Cr | E7: CO1 | F7: CO2 | G7: CO3 | H7: CO4 | I7: CO5 | J7: PO/PSO | K7: Description | L7: Direct% | M7: Indirect% | N7: Total% | O7: Level | P7: Target | Q7: Gap | R7: Status
A8: 1 | B8: Data Structures & Algorithms | C8: CS301 | D8: 4 | E8: =CS301!D31 -> 0.76586333 | F8: =CS301!E31 -> 0.73686667 | G8: =CS301!F31 -> 0.74786167 | H8: =CS301!G31 -> 0.757025 | I8: =CS301!H31 -> 0.74627667 | J8: PO1 | K8: Engineering Knowledge | L8: ='PO Total Attainment'!D8 -> 0.75241888 | M8: ='PO Total Attainment'!F8 -> 0.7402 | N8: ='PO Total Attainment'!H8 -> 0.74997511 | O8: =IF(N8>=0.6,3,IF(N8>=0.4,2,1)) -> 3 | P8: ='PO Total Attainment'!$G$5 -> 0.6 | Q8: =N8-P8 -> 0.14997511 | R8: =IF(N8>=P8,"✔ Met","✘ Not Met") -> ✔ Met
A9: 2 | B9: Database Management Systems | C9: CS302 | D9: 4 | E9: =CS302!D31 -> 0.78649 | F9: =CS302!E31 -> 0.75331333 | G9: =CS302!F31 -> 0.76343333 | H9: =CS302!G31 -> 0.7418 | I9: =CS302!H31 -> 0.76381333 | J9: PO2 | K9: Problem Analysis | L9: ='PO Total Attainment'!D9 -> 0.75227716 | M9: ='PO Total Attainment'!F9 -> 0.7659 | N9: ='PO Total Attainment'!H9 -> 0.75500173 | O9: =IF(N9>=0.6,3,IF(N9>=0.4,2,1)) -> 3 | P9: ='PO Total Attainment'!$G$5 -> 0.6 | Q9: =N9-P9 -> 0.15500173 | R9: =IF(N9>=P9,"✔ Met","✘ Not Met") -> ✔ Met
A10: 3 | B10: Computer Networks | C10: CS303 | D10: 4 | E10: =CS303!D31 -> 0.74761667 | F10: =CS303!E31 -> 0.73379667 | G10: =CS303!F31 -> 0.77289 | H10: =CS303!G31 -> 0.73717 | I10: =CS303!H31 -> 0.73067667 | J10: PO3 | K10: Design/Development of Solutions | L10: ='PO Total Attainment'!D10 -> 0.75210743 | M10: ='PO Total Attainment'!F10 -> 0.8082 | N10: ='PO Total Attainment'!H10 -> 0.76332594 | O10: =IF(N10>=0.6,3,IF(N10>=0.4,2,1)) -> 3 | P10: ='PO Total Attainment'!$G$5 -> 0.6 | Q10: =N10-P10 -> 0.16332594 | R10: =IF(N10>=P10,"✔ Met","✘ Not Met") -> ✔ Met
A11: 4 | B11: Operating Systems | C11: CS304 | D11: 4 | E11: =CS304!D31 -> 0.75902833 | F11: =CS304!E31 -> 0.77700333 | G11: =CS304!F31 -> 0.73537667 | H11: =CS304!G31 -> 0.74555667 | I11: =CS304!H31 -> 0.75619667 | J11: PO4 | K11: Conduct Investigations | L11: ='PO Total Attainment'!D11 -> 0.75060921 | M11: ='PO Total Attainment'!F11 -> 0.7578 | N11: ='PO Total Attainment'!H11 -> 0.75204737 | O11: =IF(N11>=0.6,3,IF(N11>=0.4,2,1)) -> 3 | P11: ='PO Total Attainment'!$G$5 -> 0.6 | Q11: =N11-P11 -> 0.15204737 | R11: =IF(N11>=P11,"✔ Met","✘ Not Met") -> ✔ Met
A12: 5 | B12: Machine Learning | C12: CS305 | D12: 4 | E12: =CS305!D31 -> 0.72408173 | F12: =CS305!E31 -> 0.76603884 | G12: =CS305!F31 -> 0.75570953 | H12: =CS305!G31 -> 0.76194972 | I12: =CS305!H31 -> 0.7470058 | J12: PO5 | K12: Modern Tool Usage | L12: ='PO Total Attainment'!D12 -> 0.75154653 | M12: ='PO Total Attainment'!F12 -> 0.7708 | N12: ='PO Total Attainment'!H12 -> 0.75539722 | O12: =IF(N12>=0.6,3,IF(N12>=0.4,2,1)) -> 3 | P12: ='PO Total Attainment'!$G$5 -> 0.6 | Q12: =N12-P12 -> 0.15539722 | R12: =IF(N12>=P12,"✔ Met","✘ Not Met") -> ✔ Met
J13: PO6 | K13: The Engineer and Society | L13: ='PO Total Attainment'!D13 -> 0.29783477 | M13: ='PO Total Attainment'!F13 -> 0.8618 | N13: ='PO Total Attainment'!H13 -> 0.41062781 | O13: =IF(N13>=0.6,3,IF(N13>=0.4,2,1)) -> 2 | P13: ='PO Total Attainment'!$G$5 -> 0.6 | Q13: =N13-P13 -> -0.18937219 | R13: =IF(N13>=P13,"✔ Met","✘ Not Met") -> ✘ Not Met
J14: PO7 | K14: Environment and Sustainability | L14: ='PO Total Attainment'!D14 -> 0.154578 | M14: ='PO Total Attainment'!F14 -> 0.8157 | N14: ='PO Total Attainment'!H14 -> 0.2868024 | O14: =IF(N14>=0.6,3,IF(N14>=0.4,2,1)) -> 1 | P14: ='PO Total Attainment'!$G$5 -> 0.6 | Q14: =N14-P14 -> -0.3131976 | R14: =IF(N14>=P14,"✔ Met","✘ Not Met") -> ✘ Not Met
J15: PO8 | K15: Ethics | L15: ='PO Total Attainment'!D15 -> 0 | M15: ='PO Total Attainment'!F15 -> 0.7358 | N15: ='PO Total Attainment'!H15 -> 0.14716 | O15: =IF(N15>=0.6,3,IF(N15>=0.4,2,1)) -> 1 | P15: ='PO Total Attainment'!$G$5 -> 0.6 | Q15: =N15-P15 -> -0.45284 | R15: =IF(N15>=P15,"✔ Met","✘ Not Met") -> ✘ Not Met
J16: PO9 | K16: Individual and Team Work | L16: ='PO Total Attainment'!D16 -> 0.74984631 | M16: ='PO Total Attainment'!F16 -> 0.7106 | N16: ='PO Total Attainment'!H16 -> 0.74199705 | O16: =IF(N16>=0.6,3,IF(N16>=0.4,2,1)) -> 3 | P16: ='PO Total Attainment'!$G$5 -> 0.6 | Q16: =N16-P16 -> 0.14199705 | R16: =IF(N16>=P16,"✔ Met","✘ Not Met") -> ✔ Met
J17: PO10 | K17: Communication | L17: ='PO Total Attainment'!D17 -> 0.74882764 | M17: ='PO Total Attainment'!F17 -> 0.736 | N17: ='PO Total Attainment'!H17 -> 0.74626211 | O17: =IF(N17>=0.6,3,IF(N17>=0.4,2,1)) -> 3 | P17: ='PO Total Attainment'!$G$5 -> 0.6 | Q17: =N17-P17 -> 0.14626211 | R17: =IF(N17>=P17,"✔ Met","✘ Not Met") -> ✔ Met
J18: PO11 | K18: Project Management and Finance | L18: ='PO Total Attainment'!D18 -> 0.14836 | M18: ='PO Total Attainment'!F18 -> 0.7146 | N18: ='PO Total Attainment'!H18 -> 0.261608 | O18: =IF(N18>=0.6,3,IF(N18>=0.4,2,1)) -> 1 | P18: ='PO Total Attainment'!$G$5 -> 0.6 | Q18: =N18-P18 -> -0.338392 | R18: =IF(N18>=P18,"✔ Met","✘ Not Met") -> ✘ Not Met
J19: PO12 | K19: Life-long Learning | L19: ='PO Total Attainment'!D19 -> 0.75165822 | M19: ='PO Total Attainment'!F19 -> 0.8104 | N19: ='PO Total Attainment'!H19 -> 0.76340657 | O19: =IF(N19>=0.6,3,IF(N19>=0.4,2,1)) -> 3 | P19: ='PO Total Attainment'!$G$5 -> 0.6 | Q19: =N19-P19 -> 0.16340657 | R19: =IF(N19>=P19,"✔ Met","✘ Not Met") -> ✔ Met
J20: PSO1 | K20: Apply core CS concepts to design software systems | L20: ='PO Total Attainment'!D20 -> 0.75195843 | M20: ='PO Total Attainment'!F20 -> 0.786 | N20: ='PO Total Attainment'!H20 -> 0.75876674 | O20: =IF(N20>=0.6,3,IF(N20>=0.4,2,1)) -> 3 | P20: ='PO Total Attainment'!$G$5 -> 0.6 | Q20: =N20-P20 -> 0.15876674 | R20: =IF(N20>=P20,"✔ Met","✘ Not Met") -> ✔ Met
J21: PSO2 | K21: Use modern tools to solve real-world engineering problems | L21: ='PO Total Attainment'!D21 -> 0.75208393 | M21: ='PO Total Attainment'!F21 -> 0.6811 | N21: ='PO Total Attainment'!H21 -> 0.73788714 | O21: =IF(N21>=0.6,3,IF(N21>=0.4,2,1)) -> 3 | P21: ='PO Total Attainment'!$G$5 -> 0.6 | Q21: =N21-P21 -> 0.13788714 | R21: =IF(N21>=P21,"✔ Met","✘ Not Met") -> ✔ Met
J22: PSO3 | K22: Demonstrate professional skills for industry/research | L22: ='PO Total Attainment'!D22 -> 0.75215849 | M22: ='PO Total Attainment'!F22 -> 0.7702 | N22: ='PO Total Attainment'!H22 -> 0.75576679 | O22: =IF(N22>=0.6,3,IF(N22>=0.4,2,1)) -> 3 | P22: ='PO Total Attainment'!$G$5 -> 0.6 | Q22: =N22-P22 -> 0.15576679 | R22: =IF(N22>=P22,"✔ Met","✘ Not Met") -> ✔ Met
A25: 📌 HOW TO USE THIS WORKBOOK — FULLY AUTO-CALCULATION: 1️⃣ CS301–CS305 sheets: Enter Mid-1, Mid-2, Assignment, Quiz, SEE marks per student per CO → CIE, SEE Scaled, Total, Class Avg, CO Att% all auto-calculate 2️⃣ CO-PO Mapping sheet: Edit correlation values (0–3) in yellow cells only → CO Att% auto-links from course sheets 3️⃣ PO Direct Attainment sheet: Everything auto-calculates — no manual entry needed 4️⃣ PO Indirect Attainment sheet: Enter avg survey score (1–5) in yellow cells per PO per tool → Indirect Att% auto-calculates 5️⃣ PO Total Attainment sheet: Total = Direct×80% + Indirect×20% — change weights in D5/E5 → All PO levels, gaps, status auto-update 6️⃣ This Dashboard auto-updates as you enter data — all values linked via formulas.

Sheet CS301
A1: CO ATTAINMENT — Data Structures & Algorithms (CS301)
A2: CIE = (Mid-1+Mid-2)/2 + Assignment + Quiz → 50M | SEE = 100M → 50M | Total = 100M
A4: Student Info | D4: MID-1 (Max=30M) | I4: MID-2 (Max=30M) | N4: ASSIGNMENT (Max=10M) | S4: QUIZ (Max=10M) | X4: SEE (Max=100M) | AC4: CIE (50M) | AD4: SEE (50M) | AE4: TOTAL (100M)
A5: S.No | B5: Reg No | C5: Name | D5: CO1 | E5: CO2 | F5: CO3 | G5: CO4 | H5: CO5 | I5: CO1 | J5: CO2 | K5: CO3 | L5: CO4 | M5: CO5 | N5: CO1 | O5: CO2 | P5: CO3 | Q5: CO4 | R5: CO5 | S5: CO1 | T5: CO2 | U5: CO3 | V5: CO4 | W5: CO5 | X5: CO1 | Y5: CO2 | Z5: CO3 | AA5: CO4 | AB5: CO5 | AC5: Formula | AD5: Formula | AE5: Formula
A6: MAX MARKS ← Edit here | D6: 6 | E6: 6 | F6: 6 | G6: 6 | H6: 6 | I6: 6 | J6: 6 | K6: 6 | L6: 6 | M6: 6 | N6: 2 | O6: 2 | P6: 2 | Q6: 2 | R6: 2 | S6: 2 | T6: 2 | U6: 2 | V6: 2 | W6: 2 | X6: 20 | Y6: 20 | Z6: 20 | AA6: 20 | AB6: 20 | AC6: 50 | AD6: 50 | AE6: 100
A7: ↓ Enter student marks in white/grey cells below — CIE, SEE Scaled, Total calculate automatically ↓
A8: 1 | B8: S001 | C8: Aarav Sharma | D8: 4.92 | E8: 3.08 | F8: 3.83 | G8: 3.67 | H8: 5.21 | I8: 5.03 | J8: 5.68 | K8: 3.26 | L8: 4.27 | M8: 3.09 | N8: 1.22 | O8: 1.51 | P8: 1.03 | Q8: 1.2 | R8: 1.65 | S8: 1.54 | T8: 1.22 | U8: 1.59 | V8: 1.81 | W8: 1.01 | X8: 18.06 | Y8: 16.98 | Z8: 13.4 | AA8: 11.55 | AB8: 19.57 | AC8: =(SUM(D8:H8)+SUM(I8:M8))/2+SUM(N8:R8)+SUM(S8:W8) -> 34.8 | AD8: =SUM(X8:AB8)/100*50 -> 39.78 | AE8: =AC8+AD8 -> 74.58
A9: 2 | B9: S002 | C9: Priya Patel | D9: 4.01 | E9: 3.28 | F9: 3.29 | G9: 5.54 | H9: 4.81 | I9: 5.42 | J9: 5.19 | K9: 4.61 | L9: 5.92 | M9: 4.14 | N9: 1.55 | O9: 1.83 | P9: 1.62 | Q9: 1.86 | R9: 1.58 | S9: 1.7 | T9: 1.05 | U9: 1.23 | V9: 1.29 | W9: 1.08 | X9: 12.33 | Y9: 11.01 | Z9: 12.78 | AA9: 16.36 | AB9: 13.65 | AC9: =(SUM(D9:H9)+SUM(I9:M9))/2+SUM(N9:R9)+SUM(S9:W9) -> 37.895 | AD9: =SUM(X9:AB9)/100*50 -> 33.065 | AE9: =AC9+AD9 -> 70.96
A10: 3 | B10: S003 | C10: Rohan Mehta | D10: 4.11 | E10: 3.63 | F10: 3.8 | G10: 5.81 | H10: 4.94 | I10: 4.83 | J10: 3.51 | K10: 5.19 | L10: 3.49 | M10: 4.14 | N10: 1.99 | O10: 1.64 | P10: 1.56 | Q10: 1.68 | R10: 1.84 | S10: 1.78 | T10: 1.23 | U10: 1.03 | V10: 1.32 | W10: 1.27 | X10: 12.11 | Y10: 19.43 | Z10: 18.76 | AA10: 13.15 | AB10: 16.55 | AC10: =(SUM(D10:H10)+SUM(I10:M10))/2+SUM(N10:R10)+SUM(S10:W10) -> 37.065 | AD10: =SUM(X10:AB10)/100*50 -> 40 | AE10: =AC10+AD10 -> 77.065
A11: 4 | B11: S004 | C11: Sneha Reddy | D11: 4.19 | E11: 5.74 | F11: 4.38 | G11: 3.79 | H11: 3.74 | I11: 4.68 | J11: 3.79 | K11: 4.75 | L11: 5.69 | M11: 4.2 | N11: 1.22 | O11: 2 | P11: 1.51 | Q11: 1.09 | R11: 1.05 | S11: 1.11 | T11: 1.63 | U11: 1.79 | V11: 1.42 | W11: 1.06 | X11: 13.82 | Y11: 19.96 | Z11: 15.29 | AA11: 19.71 | AB11: 18.61 | AC11: =(SUM(D11:H11)+SUM(I11:M11))/2+SUM(N11:R11)+SUM(S11:W11) -> 36.355 | AD11: =SUM(X11:AB11)/100*50 -> 43.695 | AE11: =AC11+AD11 -> 80.05
A12: 5 | B12: S005 | C12: Vikram Singh | D12: 3.03 | E12: 5.16 | F12: 5.05 | G12: 4.61 | H12: 3.8 | I12: 4.92 | J12: 3.33 | K12: 4.3 | L12: 4.36 | M12: 5.86 | N12: 1.88 | O12: 1.26 | P12: 1.5 | Q12: 1.18 | R12: 1.91 | S12: 1.87 | T12: 1.3 | U12: 1.64 | V12: 1.61 | W12: 1.15 | X12: 17.63 | Y12: 15.39 | Z12: 17.79 | AA12: 15.3 | AB12: 10.01 | AC12: =(SUM(D12:H12)+SUM(I12:M12))/2+SUM(N12:R12)+SUM(S12:W12) -> 37.51 | AD12: =SUM(X12:AB12)/100*50 -> 38.06 | AE12: =AC12+AD12 -> 75.57
A13: 6 | B13: S006 | C13: Anjali Nair | D13: 3.97 | E13: 3.06 | F13: 5.79 | G13: 5.64 | H13: 5.49 | I13: 3.92 | J13: 3.17 | K13: 5.63 | L13: 5.84 | M13: 3.26 | N13: 1.49 | O13: 1.07 | P13: 1.76 | Q13: 1.77 | R13: 1.13 | S13: 1.48 | T13: 1.55 | U13: 1.27 | V13: 1.87 | W13: 1.42 | X13: 12.12 | Y13: 15.39 | Z13: 17.3 | AA13: 12.01 | AB13: 13.12 | AC13: =(SUM(D13:H13)+SUM(I13:M13))/2+SUM(N13:R13)+SUM(S13:W13) -> 37.695 | AD13: =SUM(X13:AB13)/100*50 -> 34.97 | AE13: =AC13+AD13 -> 72.665
A14: 7 | B14: S007 | C14: Kiran Kumar | D14: 5.99 | E14: 4.95 | F14: 4.31 | G14: 4.55 | H14: 3.36 | I14: 3.67 | J14: 4.01 | K14: 4.76 | L14: 3.69 | M14: 3.66 | N14: 1.07 | O14: 1.63 | P14: 1.23 | Q14: 1.91 | R14: 1.86 | S14: 1.07 | T14: 1.24 | U14: 1.67 | V14: 1.21 | W14: 1.13 | X14: 19.36 | Y14: 15.71 | Z14: 14.73 | AA14: 17.85 | AB14: 18.07 | AC14: =(SUM(D14:H14)+SUM(I14:M14))/2+SUM(N14:R14)+SUM(S14:W14) -> 35.495 | AD14: =SUM(X14:AB14)/100*50 -> 42.86 | AE14: =AC14+AD14 -> 78.355
A15: 8 | B15: S008 | C15: Divya Rao | D15: 3.57 | E15: 3.29 | F15: 4.29 | G15: 4.27 | H15: 4.4 | I15: 5.19 | J15: 5.02 | K15: 5.95 | L15: 3.3 | M15: 4.21 | N15: 1.34 | O15: 1.86 | P15: 1.25 | Q15: 1.19 | R15: 1.45 | S15: 1.42 | T15: 1.28 | U15: 1.25 | V15: 1.92 | W15: 1.44 | X15: 18.61 | Y15: 15.5 | Z15: 10.51 | AA15: 19.99 | AB15: 18.36 | AC15: =(SUM(D15:H15)+SUM(I15:M15))/2+SUM(N15:R15)+SUM(S15:W15) -> 36.145 | AD15: =SUM(X15:AB15)/100*50 -> 41.485 | AE15: =AC15+AD15 -> 77.63
A16: 9 | B16: S009 | C16: Arjun Gupta | D16: 5.91 | E16: 5.78 | F16: 5.55 | G16: 3.5 | H16: 4.46 | I16: 3.64 | J16: 4.2 | K16: 3.18 | L16: 4.14 | M16: 5.96 | N16: 1.27 | O16: 1.78 | P16: 1.46 | Q16: 1.42 | R16: 1.96 | S16: 2 | T16: 1.56 | U16: 1.72 | V16: 1.15 | W16: 1.3 | X16: 19.69 | Y16: 15.79 | Z16: 15.42 | AA16: 17.48 | AB16: 10.57 | AC16: =(SUM(D16:H16)+SUM(I16:M16))/2+SUM(N16:R16)+SUM(S16:W16) -> 38.78 | AD16: =SUM(X16:AB16)/100*50 -> 39.475 | AE16: =AC16+AD16 -> 78.255
A17: 10 | B17: S010 | C17: Pooja Iyer | D17: 4.75 | E17: 4.51 | F17: 5.56 | G17: 3.47 | H17: 5.88 | I17: 3.24 | J17: 3.56 | K17: 4.79 | L17: 5.03 | M17: 3.71 | N17: 1.12 | O17: 1.89 | P17: 1.25 | Q17: 1.59 | R17: 1.62 | S17: 1.42 | T17: 1.58 | U17: 1.52 | V17: 1.93 | W17: 1.2 | X17: 17.16 | Y17: 12.39 | Z17: 13.96 | AA17: 16.72 | AB17: 13 | AC17: =(SUM(D17:H17)+SUM(I17:M17))/2+SUM(N17:R17)+SUM(S17:W17) -> 37.37 | AD17: =SUM(X17:AB17)/100*50 -> 36.615 | AE17: =AC17+AD17 -> 73.985
A18: 11 | B18: S011 | C18: Rahul Verma | D18: 3.95 | E18: 5.26 | F18: 3.22 | G18: 4.37 | H18: 6 | I18: 5.99 | J18: 3.22 | K18: 3.64 | L18: 3.8 | M18: 5.8 | N18: 1.88 | O18: 1.88 | P18: 1.37 | Q18: 1.16 | R18: 1.83 | S18: 1.7 | T18: 1.61 | U18: 1.99 | V18: 1.65 | W18: 1.01 | X18: 18.17 | Y18: 12.99 | Z18: 16.63 | AA18: 19.39 | AB18: 11.34 | AC18: =(SUM(D18:H18)+SUM(I18:M18))/2+SUM(N18:R18)+SUM(S18:W18) -> 38.705 | AD18: =SUM(X18:AB18)/100*50 -> 39.26 | AE18: =AC18+AD18 -> 77.965
A19: 12 | B19: S012 | C19: Meera Joshi | D19: 3.35 | E19: 3.32 | F19: 4.66 | G19: 3.82 | H19: 4.81 | I19: 5.15 | J19: 3.61 | K19: 4.9 | L19: 3.79 | M19: 4.47 | N19: 1.91 | O19: 1.85 | P19: 1.09 | Q19: 1.42 | R19: 1.28 | S19: 1 | T19: 1.77 | U19: 1.64 | V19: 1.26 | W19: 1.74 | X19: 15.52 | Y19: 14.28 | Z19: 10.1 | AA19: 10.75 | AB19: 18.83 | AC19: =(SUM(D19:H19)+SUM(I19:M19))/2+SUM(N19:R19)+SUM(S19:W19) -> 35.9 | AD19: =SUM(X19:AB19)/100*50 -> 34.74 | AE19: =AC19+AD19 -> 70.64
... A27: 20 | B27: S020 | C27: Deepa Nambiar | D27: 5.71 | E27: 4.75 | F27: 5.09 | G27: 5.57 | H27: 5.3 | I27: 4.14 | J27: 3.02 | K27: 4.06 | L27: 5.26 | M27: 5.56 | N27: 1.95 | O27: 1.42 | P27: 1.75 | Q27: 1.55 | R27: 1.6 | S27: 1.22 | T27: 1.22 | U27: 1.44 | V27: 1.03 | W27: 1.34 | X27: 16.79 | Y27: 14.04 | Z27: 11.65 | AA27: 14.67 | AB27: 11.28 | AC27: =(SUM(D27:H27)+SUM(I27:M27))/2+SUM(N27:R27)+SUM(S27:W27) -> 38.75 | AD27: =SUM(X27:AB27)/100*50 -> 34.215 | AE27: =AC27+AD27 -> 72.965
A29: CLASS AVERAGE | D29: =AVERAGE(D8:D27) -> 4.564 | E29: =AVERAGE(E8:E27) -> 4.3945 | F29: =AVERAGE(F8:F27) -> 4.589 | G29: =AVERAGE(G8:G27) -> 4.5395 | H29: =AVERAGE(H8:H27) -> 4.856 | I29: =AVERAGE(I8:I27) -> 4.4535 | J29: =AVERAGE(J8:J27) -> 4.0825 | K29: =AVERAGE(K8:K27) -> 4.5225 | ... AE29: =AVERAGE(AE8:AE27) -> 75.933
A31: CO ATTAINMENT % (Auto-calculated) | D31: =(IFERROR(D29/D6,0)+IFERROR(I29/I6,0)+IFERROR(N29/N6,0)+IFERROR(S29/S6,0)+IFERROR(X29/X6,0))/5 -> 0.76586333 | E31: =(IFERROR(E29/E6,0)+IFERROR(J29/J6,0)+IFERROR(O29/O6,0)+IFERROR(T29/T6,0)+IFERROR(Y29/Y6,0))/5 -> 0.73686667 | F31: =(IFERROR(F29/F6,0)+IFERROR(K29/K6,0)+IFERROR(P29/P6,0)+IFERROR(U29/U6,0)+IFERROR(Z29/Z6,0))/5 -> 0.74786167 | G31: =(IFERROR(G29/G6,0)+IFERROR(L29/L6,0)+IFERROR(Q29/Q6,0)+IFERROR(V29/V6,0)+IFERROR(AA29/AA6,0))/5 -> 0.757025 | H31: =(IFERROR(H29/H6,0)+IFERROR(M29/M6,0)+IFERROR(R29/R6,0)+IFERROR(W29/W6,0)+IFERROR(AB29/AB6,0))/5 -> 0.74627667
A32: CIE CO ATT% | D32: =(IFERROR(D29/D6,0)+IFERROR(I29/I6,0)+IFERROR(N29/N6,0)+IFERROR(S29/S6,0))/4 -> 0.75654167 | E32: =(IFERROR(E29/E6,0)+IFERROR(J29/J6,0)+IFERROR(O29/O6,0)+IFERROR(T29/T6,0))/4 -> 0.72189583 | F32: =(IFERROR(F29/F6,0)+IFERROR(K29/K6,0)+IFERROR(P29/P6,0)+IFERROR(U29/U6,0))/4 -> 0.75133333 | G32: =(IFERROR(G29/G6,0)+IFERROR(L29/L6,0)+IFERROR(Q29/Q6,0)+IFERROR(V29/V6,0))/4 -> 0.7458125 | H32: =(IFERROR(H29/H6,0)+IFERROR(M29/M6,0)+IFERROR(R29/R6,0)+IFERROR(W29/W6,0))/4 -> 0.75152083
A33: SEE CO ATT% | D33: =IFERROR(X29/X6,0) -> 0.80315 | E33: =IFERROR(Y29/Y6,0) -> 0.79675 | F33: =IFERROR(Z29/Z6,0) -> 0.733975 | G33: =IFERROR(AA29/AA6,0) -> 0.801875 | H33: =IFERROR(AB29/AB6,0) -> 0.7253
A34: LEVEL (3=High≥60% / 2=Med≥40% / 1=Low) | D34: =IF(D31>=0.6,3,IF(D31>=0.4,2,1)) -> 3 | E34: =IF(E31>=0.6,3,IF(E31>=0.4,2,1)) -> 3 | F34: =IF(F31>=0.6,3,IF(F31>=0.4,2,1)) -> 3 | G34: =IF(G31>=0.6,3,IF(G31>=0.4,2,1)) -> 3 | H34: =IF(H31>=0.6,3,IF(H31>=0.4,2,1)) -> 3

Sheet CS302
A1: CO ATTAINMENT — Database Management Systems (CS302)
A2: CIE = (Mid-1+Mid-2)/2 + Assignment + Quiz → 50M | SEE = 100M → 50M | Total = 100M
A4: Student Info | D4: MID-1 (Max=30M) | I4: MID-2 (Max=30M) | N4: ASSIGNMENT (Max=10M) | S4: QUIZ (Max=10M) | X4: SEE (Max=100M) | AC4: CIE (50M) | AD4: SEE (50M) | AE4: TOTAL (100M)
A5: S.No | B5: Reg No | C5: Name | D5: CO1 | E5: CO2 | F5: CO3 | G5: CO4 | H5: CO5 | I5: CO1 | J5: CO2 | K5: CO3 | L5: CO4 | M5: CO5 | N5: CO1 | O5: CO2 | P5: CO3 | Q5: CO4 | R5: CO5 | S5: CO1 | T5: CO2 | U5: CO3 | V5: CO4 | W5: CO5 | X5: CO1 | Y5: CO2 | Z5: CO3 | AA5: CO4 | AB5: CO5 | AC5: Formula | AD5: Formula | AE5: Formula
A6: MAX MARKS ← Edit here | D6: 6 | E6: 6 | F6: 6 | G6: 6 | H6: 6 | I6: 6 | J6: 6 | K6: 6 | L6: 6 | M6: 6 | N6: 2 | O6: 2 | P6: 2 | Q6: 2 | R6: 2 | S6: 2 | T6: 2 | U6: 2 | V6: 2 | W6: 2 | X6: 20 | Y6: 20 | Z6: 20 | AA6: 20 | AB6: 20 | AC6: 50 | AD6: 50 | AE6: 100
A7: ↓ Enter student marks in white/grey cells below — CIE, SEE Scaled, Total calculate automatically ↓
A8: 1 | B8: S001 | C8: Aarav Sharma | D8: 4.87 | E8: 3.08 | F8: 4.18 | G8: 4.69 | H8: 3.08 | I8: 4.93 | J8: 3.41 | K8: 4.39 | L8: 3.15 | M8: 4.14 | N8: 1.21 | O8: 1.33 | P8: 1.76 | Q8: 1.38 | R8: 1.75 | S8: 1.83 | T8: 1.25 | U8: 1.08 | V8: 1.02 | W8: 1.54 | X8: 20 | Y8: 13.5 | Z8: 16.5 | AA8: 17.81 | AB8: 16.52 | AC8: =(SUM(D8:H8)+SUM(I8:M8))/2+SUM(N8:R8)+SUM(S8:W8) -> 34.11 | AD8: =SUM(X8:AB8)/100*50 -> 42.165 | AE8: =AC8+AD8 -> 76.275
A9: 2 | B9: S002 | C9: Priya Patel | D9: 5.26 | E9: 5.85 | F9: 3.6 | G9: 3.06 | H9: 3.46 | I9: 3.38 | J9: 5.01 | K9: 4.69 | L9: 3.65 | M9: 5.1 | N9: 1.77 | O9: 1.17 | P9: 1.61 | Q9: 1.75 | R9: 1.11 | S9: 1.82 | T9: 1.96 | U9: 1.11 | V9: 1.03 | W9: 1.31 | X9: 16.77 | Y9: 19.58 | Z9: 13.97 | AA9: 17.15 | AB9: 10.76 | AC9: =(SUM(D9:H9)+SUM(I9:M9))/2+SUM(N9:R9)+SUM(S9:W9) -> 36.17 | AD9: =SUM(X9:AB9)/100*50 -> 39.115 | AE9: =AC9+AD9 -> 75.285
A10: 3 | B10: S003 | C10: Rohan Mehta | D10: 5.07 | E10: 4.88 | F10: 3.31 | G10: 5.32 | H10: 5.55 | I10: 4.8 | J10: 3.36 | K10: 5.95 | L10: 5.35 | M10: 4.04 | N10: 1.43 | O10: 1.37 | P10: 1.51 | Q10: 1.34 | R10: 1.85 | S10: 1.82 | T10: 1.11 | U10: 1.96 | V10: 1.64 | W10: 1.83 | X10: 17.07 | Y10: 14.35 | Z10: 17.34 | AA10: 19.65 | AB10: 12.7 | AC10: =(SUM(D10:H10)+SUM(I10:M10))/2+SUM(N10:R10)+SUM(S10:W10) -> 39.675 | AD10: =SUM(X10:AB10)/100*50 -> 40.555 | AE10: =AC10+AD10 -> 80.23
A11: 4 | B11: S004 | C11: Sneha Reddy | D11: 5.42 | E11: 4.61 | F11: 4.45 | G11: 4.31 | H11: 5.19 | I11: 3.81 | J11: 5.56 | K11: 5.49 | L11: 3.26 | M11: 5.64 | N11: 1.24 | O11: 1.46 | P11: 1.61 | Q11: 1.38 | R11: 1.03 | S11: 1.85 | T11: 1.18 | U11: 1.21 | V11: 1.8 | W11: 1.34 | X11: 18.8 | Y11: 17.01 | Z11: 12.76 | AA11: 10.1 | AB11: 19.48 | AC11: =(SUM(D11:H11)+SUM(I11:M11))/2+SUM(N11:R11)+SUM(S11:W11) -> 37.97 | AD11: =SUM(X11:AB11)/100*50 -> 39.075 | AE11: =AC11+AD11 -> 77.045
A12: 5 | B12: S005 | C12: Vikram Singh | D12: 3.26 | E12: 5.16 | F12: 4.47 | G12: 5.27 | H12: 5.07 | I12: 4.94 | J12: 4.47 | K12: 5.38 | L12: 3.28 | M12: 3.66 | N12: 1.69 | O12: 1.31 | P12: 1.58 | Q12: 1.47 | R12: 1.53 | S12: 1.43 | T12: 1.75 | U12: 1.33 | V12: 1.7 | W12: 1.27 | X12: 12.51 | Y12: 11.21 | Z12: 11.93 | AA12: 11.2 | AB12: 15.36 | AC12: =(SUM(D12:H12)+SUM(I12:M12))/2+SUM(N12:R12)+SUM(S12:W12) -> 37.54 | AD12: =SUM(X12:AB12)/100*50 -> 31.105 | AE12: =AC12+AD12 -> 68.645
A13: 6 | B13: S006 | C13: Anjali Nair | D13: 5.29 | E13: 3.56 | F13: 3.65 | G13: 4.45 | H13: 5.17 | I13: 5.93 | J13: 4.57 | K13: 3.85 | L13: 3.3 | M13: 3.58 | N13: 1.23 | O13: 1.18 | P13: 1.01 | Q13: 1.53 | R13: 1.27 | S13: 1.97 | T13: 1.55 | U13: 1.7 | V13: 1.13 | W13: 1.87 | X13: 14.91 | Y13: 18.73 | Z13: 15.74 | AA13: 14.69 | AB13: 14.4 | AC13: =(SUM(D13:H13)+SUM(I13:M13))/2+SUM(N13:R13)+SUM(S13:W13) -> 36.115 | AD13: =SUM(X13:AB13)/100*50 -> 39.235 | AE13: =AC13+AD13 -> 75.35
A14: 7 | B14: S007 | C14: Kiran Kumar | D14: 3.55 | E14: 3.15 | F14: 5.82 | G14: 4.43 | H14: 5.47 | I14: 4.2 | J14: 3.22 | K14: 4.89 | L14: 3.16 | M14: 3.45 | N14: 1.56 | O14: 1.3 | P14: 1.99 | Q14: 1.12 | R14: 1.76 | S14: 1.61 | T14: 1.79 | U14: 1.23 | V14: 1.52 | W14: 1.45 | X14: 14.43 | Y14: 18.6 | Z14: 19.9 | AA14: 13.05 | AB14: 16.21 | AC14: =(SUM(D14:H14)+SUM(I14:M14))/2+SUM(N14:R14)+SUM(S14:W14) -> 36 | AD14: =SUM(X14:AB14)/100*50 -> 41.095 | AE14: =AC14+AD14 -> 77.095
A15: 8 | B15: S008 | C15: Divya Rao | D15: 4.83 | E15: 5.22 | F15: 5.84 | G15: 3.62 | H15: 3.63 | I15: 4.98 | J15: 3.47 | K15: 3.52 | L15: 3.23 | M15: 3.01 | N15: 1.45 | O15: 1.59 | P15: 1.29 | Q15: 1.23 | R15: 1.71 | S15: 1.7 | T15: 1.45 | U15: 1.69 | V15: 1.92 | W15: 1.79 | X15: 16.25 | Y15: 16.61 | Z15: 19.34 | AA15: 14.25 | AB15: 15.45 | AC15: =(SUM(D15:H15)+SUM(I15:M15))/2+SUM(N15:R15)+SUM(S15:W15) -> 36.495 | AD15: =SUM(X15:AB15)/100*50 -> 40.95 | AE15: =AC15+AD15 -> 77.445
A16: 9 | B16: S009 | C16: Arjun Gupta | D16: 4.94 | E16: 5.73 | F16: 5.48 | G16: 3.21 | H16: 3.5 | I16: 3.92 | J16: 5.25 | K16: 4.71 | L16: 3.87 | M16: 3.37 | N16: 1.69 | O16: 1.7 | P16: 1.94 | Q16: 1.5 | R16: 1.49 | S16: 1.08 | T16: 1.04 | U16: 1.43 | V16: 1.32 | W16: 1.25 | X16: 10.91 | Y16: 19.62 | Z16: 18.36 | AA16: 15.75 | AB16: 19.51 | AC16: =(SUM(D16:H16)+SUM(I16:M16))/2+SUM(N16:R16)+SUM(S16:W16) -> 36.43 | AD16: =SUM(X16:AB16)/100*50 -> 42.075 | AE16: =AC16+AD16 -> 78.505
A17: 10 | B17: S010 | C17: Pooja Iyer | D17: 6 | E17: 5.02 | F17: 3.81 | G17: 3.12 | H17: 5.27 | I17: 4.41 | J17: 4.95 | K17: 5.75 | L17: 3.54 | M17: 4.76 | N17: 1.63 | O17: 1.49 | P17: 1.09 | Q17: 1.35 | R17: 1.33 | S17: 1.67 | T17: 1.86 | U17: 1.33 | V17: 1.69 | W17: 1.29 | X17: 19.45 | Y17: 18.14 | Z17: 15.5 | AA17: 14.55 | AB17: 13.15 | AC17: =(SUM(D17:H17)+SUM(I17:M17))/2+SUM(N17:R17)+SUM(S17:W17) -> 38.045 | AD17: =SUM(X17:AB17)/100*50 -> 40.395 | AE17: =AC17+AD17 -> 78.44
A18: 11 | B18: S011 | C18: Rahul Verma | D18: 3.97 | E18: 5.91 | F18: 4.21 | G18: 4.54 | H18: 5.96 | I18: 4.97 | J18: 4.63 | K18: 4.24 | L18: 3.56 | M18: 4.09 | N18: 1.76 | O18: 1.63 | P18: 1.76 | Q18: 1.2 | R18: 1.55 | S18: 1.93 | T18: 1.44 | U18: 1.7 | V18: 1.12 | W18: 1.97 | X18: 16.09 | Y18: 12.39 | Z18: 11.58 | AA18: 15.51 | AB18: 15.52 | AC18: =(SUM(D18:H18)+SUM(I18:M18))/2+SUM(N18:R18)+SUM(S18:W18) -> 39.1 | AD18: =SUM(X18:AB18)/100*50 -> 35.545 | AE18: =AC18+AD18 -> 74.645
A19: 12 | B19: S012 | C19: Meera Joshi | D19: 3.28 | E19: 5.98 | F19: 5.74 | G19: 4.38 | H19: 3.35 | I19: 5.5 | J19: 4.5 | K19: 5.15 | L19: 4.53 | M19: 3.82 | N19: 1.83 | O19: 1.98 | P19: 1.24 | Q19: 1.55 | R19: 1.38 | S19: 1.92 | T19: 1.51 | U19: 1.88 | V19: 1.86 | W19: 1.28 | X19: 17.9 | Y19: 14.15 | Z19: 19.34 | AA19: 15.08 | AB19: 18.21 | AC19: =(SUM(D19:H19)+SUM(I19:M19))/2+SUM(N19:R19)+SUM(S19:W19) -> 39.545 | AD19: =SUM(X19:AB19)/100*50 -> 42.34 | AE19: =AC19+AD19 -> 81.885
... A27: 20 | B27: S020 | C27: Deepa Nambiar | D27: 4.22 | E27: 3.42 | F27: 5.84 | G27: 3.91 | H27: 4.48 | I27: 3.29 | J27: 5.66 | K27: 3.41 | L27: 4.36 | M27: 5.01 | N27: 1.74 | O27: 1.95 | P27: 1.42 | Q27: 1.74 | R27: 1.15 | S27: 1.41 | T27: 1.1 | U27: 1.49 | V27: 1.41 | W27: 1.95 | X27: 10.33 | Y27: 13.71 | Z27: 14.43 | AA27: 19.51 | AB27: 18.55 | AC27: =(SUM(D27:H27)+SUM(I27:M27))/2+SUM(N27:R27)+SUM(S27:W27) -> 37.16 | AD27: =SUM(X27:AB27)/100*50 -> 38.265 | AE27: =AC27+AD27 -> 75.425
A29: CLASS AVERAGE | D29: =AVERAGE(D8:D27) -> 4.693 | E29: =AVERAGE(E8:E27) -> 4.478 | F29: =AVERAGE(F8:F27) -> 4.7595 | G29: =AVERAGE(G8:G27) -> 4.449 | H29: =AVERAGE(H8:H27) -> 4.5295 | I29: =AVERAGE(I8:I27) -> 4.592 | J29: =AVERAGE(J8:J27) -> 4.4675 | K29: =AVERAGE(K8:K27) -> 4.537 | ... AE29: =AVERAGE(AE8:AE27) -> 77.12125
A31: CO ATTAINMENT % (Auto-calculated) | D31: =(IFERROR(D29/D6,0)+IFERROR(I29/I6,0)+IFERROR(N29/N6,0)+IFERROR(S29/S6,0)+IFERROR(X29/X6,0))/5 -> 0.78649 | E31: =(IFERROR(E29/E6,0)+IFERROR(J29/J6,0)+IFERROR(O29/O6,0)+IFERROR(T29/T6,0)+IFERROR(Y29/Y6,0))/5 -> 0.75331333 | F31: =(IFERROR(F29/F6,0)+IFERROR(K29/K6,0)+IFERROR(P29/P6,0)+IFERROR(U29/U6,0)+IFERROR(Z29/Z6,0))/5 -> 0.76343333 | G31: =(IFERROR(G29/G6,0)+IFERROR(L29/L6,0)+IFERROR(Q29/Q6,0)+IFERROR(V29/V6,0)+IFERROR(AA29/AA6,0))/5 -> 0.7418 | H31: =(IFERROR(H29/H6,0)+IFERROR(M29/M6,0)+IFERROR(R29/R6,0)+IFERROR(W29/W6,0)+IFERROR(AB29/AB6,0))/5 -> 0.76381333
A32: CIE CO ATT% | D32: =(IFERROR(D29/D6,0)+IFERROR(I29/I6,0)+IFERROR(N29/N6,0)+IFERROR(S29/S6,0))/4 -> 0.788375 | E32: =(IFERROR(E29/E6,0)+IFERROR(J29/J6,0)+IFERROR(O29/O6,0)+IFERROR(T29/T6,0))/4 -> 0.74372917 | F32: =(IFERROR(F29/F6,0)+IFERROR(K29/K6,0)+IFERROR(P29/P6,0)+IFERROR(U29/U6,0))/4 -> 0.76272917 | G32: =(IFERROR(G29/G6,0)+IFERROR(L29/L6,0)+IFERROR(Q29/Q6,0)+IFERROR(V29/V6,0))/4 -> 0.7285 | H32: =(IFERROR(H29/H6,0)+IFERROR(M29/M6,0)+IFERROR(R29/R6,0)+IFERROR(W29/W6,0))/4 -> 0.75116667
A33: SEE CO ATT% | D33: =IFERROR(X29/X6,0) -> 0.77895 | E33: =IFERROR(Y29/Y6,0) -> 0.79165 | F33: =IFERROR(Z29/Z6,0) -> 0.76625 | G33: =IFERROR(AA29/AA6,0) -> 0.795 | H33: =IFERROR(AB29/AB6,0) -> 0.8144
A34: LEVEL (3=High≥60% / 2=Med≥40% / 1=Low) | D34: =IF(D31>=0.6,3,IF(D31>=0.4,2,1)) -> 3 | E34: =IF(E31>=0.6,3,IF(E31>=0.4,2,1)) -> 3 | F34: =IF(F31>=0.6,3,IF(F31>=0.4,2,1)) -> 3 | G34: =IF(G31>=0.6,3,IF(G31>=0.4,2,1)) -> 3 | H34: =IF(H31>=0.6,3,IF(H31>=0.4,2,1)) -> 3

Sheet CS303
A1: CO ATTAINMENT — Computer Networks (CS303)
A2: CIE = (Mid-1+Mid-2)/2 + Assignment + Quiz → 50M | SEE = 100M → 50M | Total = 100M
A4: Student Info | D4: MID-1 (Max=30M) | I4: MID-2 (Max=30M) | N4: ASSIGNMENT (Max=10M) | S4: QUIZ (Max=10M) | X4: SEE (Max=100M) | AC4: CIE (50M) | AD4: SEE (50M) | AE4: TOTAL (100M)
A5: S.No | B5: Reg No | C5: Name | D5: CO1 | E5: CO2 | F5: CO3 | G5: CO4 | H5: CO5 | I5: CO1 | J5: CO2 | K5: CO3 | L5: CO4 | M5: CO5 | N5: CO1 | O5: CO2 | P5: CO3 | Q5: CO4 | R5: CO5 | S5: CO1 | T5: CO2 | U5: CO3 | V5: CO4 | W5: CO5 | X5: CO1 | Y5: CO2 | Z5: CO3 | AA5: CO4 | AB5: CO5 | AC5: Formula | AD5: Formula | AE5: Formula
A6: MAX MARKS ← Edit here | D6: 6 | E6: 6 | F6: 6 | G6: 6 | H6: 6 | I6: 6 | J6: 6 | K6: 6 | L6: 6 | M6: 6 | N6: 2 | O6: 2 | P6: 2 | Q6: 2 | R6: 2 | S6: 2 | T6: 2 | U6: 2 | V6: 2 | W6: 2 | X6: 20 | Y6: 20 | Z6: 20 | AA6: 20 | AB6: 20 | AC6: 50 | AD6: 50 | AE6: 100
A7: ↓ Enter student marks in white/grey cells below — CIE, SEE Scaled, Total calculate automatically ↓
A8: 1 | B8: S001 | C8: Aarav Sharma | D8: 3.3 | E8: 5.06 | F8: 4.63 | G8: 5.93 | H8: 4.08 | I8: 4.19 | J8: 3.57 | K8: 3.37 | L8: 5.54 | M8: 4.36 | N8: 1.66 | O8: 1.64 | P8: 1.6 | Q8: 1.02 | R8: 1.79 | S8: 1.24 | T8: 1.13 | U8: 1.56 | V8: 1.07 | W8: 1.77 | X8: 12.07 | Y8: 12.16 | Z8: 18.7 | AA8: 13.29 | AB8: 11.48 | AC8: =(SUM(D8:H8)+SUM(I8:M8))/2+SUM(N8:R8)+SUM(S8:W8) -> 36.495 | AD8: =SUM(X8:AB8)/100*50 -> 33.85 | AE8: =AC8+AD8 -> 70.345
A9: 2 | B9: S002 | C9: Priya Patel | D9: 5.7 | E9: 3.01 | F9: 5.58 | G9: 3.43 | H9: 3.39 | I9: 3.75 | J9: 3.52 | K9: 4.98 | L9: 3.08 | M9: 3.04 | N9: 1.79 | O9: 1.24 | P9: 1.32 | Q9: 1.17 | R9: 1.05 | S9: 1.74 | T9: 1.53 | U9: 1.75 | V9: 1.48 | W9: 1.78 | X9: 15.13 | Y9: 11.09 | Z9: 15.04 | AA9: 19.45 | AB9: 10.43 | AC9: =(SUM(D9:H9)+SUM(I9:M9))/2+SUM(N9:R9)+SUM(S9:W9) -> 34.59 | AD9: =SUM(X9:AB9)/100*50 -> 35.57 | AE9: =AC9+AD9 -> 70.16
A10: 3 | B10: S003 | C10: Rohan Mehta | D10: 5.35 | E10: 5.6 | F10: 4.56 | G10: 4.37 | H10: 5.89 | I10: 3.18 | J10: 4.44 | K10: 4.2 | L10: 5.06 | M10: 4.47 | N10: 1.91 | O10: 1.07 | P10: 1.08 | Q10: 1.61 | R10: 1.07 | S10: 1.28 | T10: 1.63 | U10: 1.55 | V10: 1.33 | W10: 1.99 | X10: 15.31 | Y10: 14.54 | Z10: 16.05 | AA10: 10.99 | AB10: 17.02 | AC10: =(SUM(D10:H10)+SUM(I10:M10))/2+SUM(N10:R10)+SUM(S10:W10) -> 38.08 | AD10: =SUM(X10:AB10)/100*50 -> 36.955 | AE10: =AC10+AD10 -> 75.035
A11: 4 | B11: S004 | C11: Sneha Reddy | D11: 5.56 | E11: 4.95 | F11: 5.31 | G11: 5.16 | H11: 3.65 | I11: 4.35 | J11: 3.69 | K11: 4.02 | L11: 4.36 | M11: 4.25 | N11: 1.1 | O11: 1.43 | P11: 1.67 | Q11: 1.37 | R11: 1.15 | S11: 1.92 | T11: 1.07 | U11: 1.83 | V11: 1.09 | W11: 1.1 | X11: 17.39 | Y11: 18.12 | Z11: 15.56 | AA11: 15.86 | AB11: 15.62 | AC11: =(SUM(D11:H11)+SUM(I11:M11))/2+SUM(N11:R11)+SUM(S11:W11) -> 36.38 | AD11: =SUM(X11:AB11)/100*50 -> 41.275 | AE11: =AC11+AD11 -> 77.655
A12: 5 | B12: S005 | C12: Vikram Singh | D12: 3.99 | E12: 3.37 | F12: 4.06 | G12: 5 | H12: 5.25 | I12: 5.6 | J12: 5.16 | K12: 5.91 | L12: 4.8 | M12: 4.05 | N12: 1.58 | O12: 1.21 | P12: 1.66 | Q12: 1.22 | R12: 1.11 | S12: 1.85 | T12: 1.37 | U12: 1.76 | V12: 1.57 | W12: 1.81 | X12: 18.45 | Y12: 19.75 | Z12: 18.18 | AA12: 16.14 | AB12: 16.43 | AC12: =(SUM(D12:H12)+SUM(I12:M12))/2+SUM(N12:R12)+SUM(S12:W12) -> 38.735 | AD12: =SUM(X12:AB12)/100*50 -> 44.475 | AE12: =AC12+AD12 -> 83.21
A13: 6 | B13: S006 | C13: Anjali Nair | D13: 3.08 | E13: 5.79 | F13: 5.49 | G13: 3.8 | H13: 3.54 | I13: 5.11 | J13: 3.93 | K13: 4.02 | L13: 3.02 | M13: 5.61 | N13: 1.57 | O13: 1.4 | P13: 1.14 | Q13: 1.63 | R13: 1.03 | S13: 1.75 | T13: 1.22 | U13: 1.42 | V13: 1.34 | W13: 1.37 | X13: 17.22 | Y13: 17.77 | Z13: 15.68 | AA13: 10.85 | AB13: 10.53 | AC13: =(SUM(D13:H13)+SUM(I13:M13))/2+SUM(N13:R13)+SUM(S13:W13) -> 35.565 | AD13: =SUM(X13:AB13)/100*50 -> 36.025 | AE13: =AC13+AD13 -> 71.59
A14: 7 | B14: S007 | C14: Kiran Kumar | D14: 3.47 | E14: 4.85 | F14: 5.02 | G14: 3.82 | H14: 4.99 | I14: 4.46 | J14: 4.33 | K14: 3.82 | L14: 5.26 | M14: 3.34 | N14: 1.43 | O14: 1.28 | P14: 1.68 | Q14: 1.49 | R14: 1.67 | S14: 1.05 | T14: 1.4 | U14: 1.6 | V14: 1.01 | W14: 1.3 | X14: 12.11 | Y14: 11.37 | Z14: 12.56 | AA14: 13.28 | AB14: 10.08 | AC14: =(SUM(D14:H14)+SUM(I14:M14))/2+SUM(N14:R14)+SUM(S14:W14) -> 35.59 | AD14: =SUM(X14:AB14)/100*50 -> 29.7 | AE14: =AC14+AD14 -> 65.29
A15: 8 | B15: S008 | C15: Divya Rao | D15: 5.24 | E15: 3.53 | F15: 4.14 | G15: 5.11 | H15: 4.5 | I15: 5.5 | J15: 5.42 | K15: 3.22 | L15: 5.59 | M15: 3.13 | N15: 1.02 | O15: 1.92 | P15: 1.86 | Q15: 1.58 | R15: 1.57 | S15: 1.71 | T15: 1.42 | U15: 1.12 | V15: 1.02 | W15: 1.32 | X15: 18.01 | Y15: 16.18 | Z15: 18.32 | AA15: 19.2 | AB15: 10.88 | AC15: =(SUM(D15:H15)+SUM(I15:M15))/2+SUM(N15:R15)+SUM(S15:W15) -> 37.23 | AD15: =SUM(X15:AB15)/100*50 -> 41.295 | AE15: =AC15+AD15 -> 78.525
A16: 9 | B16: S009 | C16: Arjun Gupta | D16: 5.53 | E16: 3.73 | F16: 4.77 | G16: 4.57 | H16: 4.19 | I16: 3.93 | J16: 4.02 | K16: 4 | L16: 3.5 | M16: 4.53 | N16: 1.11 | O16: 1.51 | P16: 1.91 | Q16: 1.35 | R16: 1.73 | S16: 1.82 | T16: 1.82 | U16: 1.24 | V16: 1.15 | W16: 1.2 | X16: 16.02 | Y16: 17.6 | Z16: 16.56 | AA16: 11.77 | AB16: 17.73 | AC16: =(SUM(D16:H16)+SUM(I16:M16))/2+SUM(N16:R16)+SUM(S16:W16) -> 36.225 | AD16: =SUM(X16:AB16)/100*50 -> 39.84 | AE16: =AC16+AD16 -> 76.065
A17: 10 | B17: S010 | C17: Pooja Iyer | D17: 4.48 | E17: 5.26 | F17: 5.28 | G17: 4.35 | H17: 5.77 | I17: 4.69 | J17: 4.91 | K17: 4.87 | L17: 5.59 | M17: 4.88 | N17: 1.15 | O17: 1.07 | P17: 1.44 | Q17: 1.3 | R17: 1.27 | S17: 1.06 | T17: 1.51 | U17: 1.31 | V17: 1.45 | W17: 1.06 | X17: 18.32 | Y17: 10.77 | Z17: 18.64 | AA17: 18.55 | AB17: 16.15 | AC17: =(SUM(D17:H17)+SUM(I17:M17))/2+SUM(N17:R17)+SUM(S17:W17) -> 37.66 | AD17: =SUM(X17:AB17)/100*50 -> 41.215 | AE17: =AC17+AD17 -> 78.875
A18: 11 | B18: S011 | C18: Rahul Verma | D18: 4.52 | E18: 4.39 | F18: 4.66 | G18: 5.38 | H18: 5.69 | I18: 4.35 | J18: 5.43 | K18: 4.96 | L18: 3.96 | M18: 4.43 | N18: 1.15 | O18: 1.06 | P18: 1.1 | Q18: 1.9 | R18: 1.34 | S18: 1.71 | T18: 1.5 | U18: 1.17 | V18: 1.25 | W18: 1.44 | X18: 14.39 | Y18: 15.23 | Z18: 11.59 | AA18: 13.73 | AB18: 12.83 | AC18: =(SUM(D18:H18)+SUM(I18:M18))/2+SUM(N18:R18)+SUM(S18:W18) -> 37.505 | AD18: =SUM(X18:AB18)/100*50 -> 33.885 | AE18: =AC18+AD18 -> 71.39
A19: 12 | B19: S012 | C19: Meera Joshi | D19: 4.23 | E19: 4.02 | F19: 4.79 | G19: 5.37 | H19: 4.94 | I19: 3.2 | J19: 3.28 | K19: 5.04 | L19: 3.85 | M19: 5.17 | N19: 1.66 | O19: 1.91 | P19: 1.87 | Q19: 1.33 | R19: 1.58 | S19: 1.14 | T19: 1.35 | U19: 1.97 | V19: 1.7 | W19: 1.39 | X19: 15.95 | Y19: 19.38 | Z19: 13.1 | AA19: 13.77 | AB19: 17.92 | AC19: =(SUM(D19:H19)+SUM(I19:M19))/2+SUM(N19:R19)+SUM(S19:W19) -> 37.845 | AD19: =SUM(X19:AB19)/100*50 -> 40.06 | AE19: =AC19+AD19 -> 77.905
... A27: 20 | B27: S020 | C27: Deepa Nambiar | D27: 5.4 | E27: 5.18 | F27: 3.24 | G27: 4.81 | H27: 5.47 | I27: 4.64 | J27: 3.96 | K27: 3.24 | L27: 4.98 | M27: 3.92 | N27: 1.6 | O27: 1.43 | P27: 1.69 | Q27: 1.35 | R27: 1.04 | S27: 1.87 | T27: 1.35 | U27: 2 | V27: 1.27 | W27: 1.98 | X27: 19.48 | Y27: 10.75 | Z27: 16.38 | AA27: 13.63 | AB27: 18.01 | AC27: =(SUM(D27:H27)+SUM(I27:M27))/2+SUM(N27:R27)+SUM(S27:W27) -> 38 | AD27: =SUM(X27:AB27)/100*50 -> 39.125 | AE27: =AC27+AD27 -> 77.125
A29: CLASS AVERAGE | D29: =AVERAGE(D8:D27) -> 4.439 | E29: =AVERAGE(E8:E27) -> 4.391 | F29: =AVERAGE(F8:F27) -> 4.786 | G29: =AVERAGE(G8:G27) -> 4.816 | H29: =AVERAGE(H8:H27) -> 4.6085 | I29: =AVERAGE(I8:I27) -> 4.542 | J29: =AVERAGE(J8:J27) -> 4.3875 | K29: =AVERAGE(K8:K27) -> 4.3925 | ... AE29: =AVERAGE(AE8:AE27) -> 75.084
A31: CO ATTAINMENT % (Auto-calculated) | D31: =(IFERROR(D29/D6,0)+IFERROR(I29/I6,0)+IFERROR(N29/N6,0)+IFERROR(S29/S6,0)+IFERROR(X29/X6,0))/5 -> 0.74761667 | E31: =(IFERROR(E29/E6,0)+IFERROR(J29/J6,0)+IFERROR(O29/O6,0)+IFERROR(T29/T6,0)+IFERROR(Y29/Y6,0))/5 -> 0.73379667 | F31: =(IFERROR(F29/F6,0)+IFERROR(K29/K6,0)+IFERROR(P29/P6,0)+IFERROR(U29/U6,0)+IFERROR(Z29/Z6,0))/5 -> 0.77289 | G31: =(IFERROR(G29/G6,0)+IFERROR(L29/L6,0)+IFERROR(Q29/Q6,0)+IFERROR(V29/V6,0)+IFERROR(AA29/AA6,0))/5 -> 0.73717 | H31: =(IFERROR(H29/H6,0)+IFERROR(M29/M6,0)+IFERROR(R29/R6,0)+IFERROR(W29/W6,0)+IFERROR(AB29/AB6,0))/5 -> 0.73067667
A32: CIE CO ATT% | D32: =(IFERROR(D29/D6,0)+IFERROR(I29/I6,0)+IFERROR(N29/N6,0)+IFERROR(S29/S6,0))/4 -> 0.73283333 | E32: =(IFERROR(E29/E6,0)+IFERROR(J29/J6,0)+IFERROR(O29/O6,0)+IFERROR(T29/T6,0))/4 -> 0.72633333 | F32: =(IFERROR(F29/F6,0)+IFERROR(K29/K6,0)+IFERROR(P29/P6,0)+IFERROR(U29/U6,0))/4 -> 0.767375 | G32: =(IFERROR(G29/G6,0)+IFERROR(L29/L6,0)+IFERROR(Q29/Q6,0)+IFERROR(V29/V6,0))/4 -> 0.7406875 | H32: =(IFERROR(H29/H6,0)+IFERROR(M29/M6,0)+IFERROR(R29/R6,0)+IFERROR(W29/W6,0))/4 -> 0.73770833
A33: SEE CO ATT% | D33: =IFERROR(X29/X6,0) -> 0.80675 | E33: =IFERROR(Y29/Y6,0) -> 0.76365 | F33: =IFERROR(Z29/Z6,0) -> 0.79495 | G33: =IFERROR(AA29/AA6,0) -> 0.7231 | H33: =IFERROR(AB29/AB6,0) -> 0.70255
A34: LEVEL (3=High≥60% / 2=Med≥40% / 1=Low) | D34: =IF(D31>=0.6,3,IF(D31>=0.4,2,1)) -> 3 | E34: =IF(E31>=0.6,3,IF(E31>=0.4,2,1)) -> 3 | F34: =IF(F31>=0.6,3,IF(F31>=0.4,2,1)) -> 3 | G34: =IF(G31>=0.6,3,IF(G31>=0.4,2,1)) -> 3 | H34: =IF(H31>=0.6,3,IF(H31>=0.4,2,1)) -> 3

Sheet CS304
A1: CO ATTAINMENT — Operating Systems (CS304)
A2: CIE = (Mid-1+Mid-2)/2 + Assignment + Quiz → 50M | SEE = 100M → 50M | Total = 100M
A4: Student Info | D4: MID-1 (Max=30M) | I4: MID-2 (Max=30M) | N4: ASSIGNMENT (Max=10M) | S4: QUIZ (Max=10M) | X4: SEE (Max=100M) | AC4: CIE (50M) | AD4: SEE (50M) | AE4: TOTAL (100M)
A5: S.No | B5: Reg No | C5: Name | D5: CO1 | E5: CO2 | F5: CO3 | G5: CO4 | H5: CO5 | I5: CO1 | J5: CO2 | K5: CO3 | L5: CO4 | M5: CO5 | N5: CO1 | O5: CO2 | P5: CO3 | Q5: CO4 | R5: CO5 | S5: CO1 | T5: CO2 | U5: CO3 | V5: CO4 | W5: CO5 | X5: CO1 | Y5: CO2 | Z5: CO3 | AA5: CO4 | AB5: CO5 | AC5: Formula | AD5: Formula | AE5: Formula
A6: MAX MARKS ← Edit here | D6: 6 | E6: 6 | F6: 6 | G6: 6 | H6: 6 | I6: 6 | J6: 6 | K6: 6 | L6: 6 | M6: 6 | N6: 2 | O6: 2 | P6: 2 | Q6: 2 | R6: 2 | S6: 2 | T6: 2 | U6: 2 | V6: 2 | W6: 2 | X6: 20 | Y6: 20 | Z6: 20 | AA6: 20 | AB6: 20 | AC6: 50 | AD6: 50 | AE6: 100
A7: ↓ Enter student marks in white/grey cells below — CIE, SEE Scaled, Total calculate automatically ↓
A8: 1 | B8: S001 | C8: Aarav Sharma | D8: 5.04 | E8: 5.86 | F8: 3.43 | G8: 4.82 | H8: 5.34 | I8: 3.1 | J8: 3.2 | K8: 5.34 | L8: 4.1 | M8: 4.15 | N8: 1.57 | O8: 1.61 | P8: 1.68 | Q8: 1.95 | R8: 1.37 | S8: 1.76 | T8: 1.57 | U8: 1.53 | V8: 1.4 | W8: 1.65 | X8: 12.5 | Y8: 11.13 | Z8: 17.36 | AA8: 14.99 | AB8: 13.87 | AC8: =(SUM(D8:H8)+SUM(I8:M8))/2+SUM(N8:R8)+SUM(S8:W8) -> 38.28 | AD8: =SUM(X8:AB8)/100*50 -> 34.925 | AE8: =AC8+AD8 -> 73.205
A9: 2 | B9: S002 | C9: Priya Patel | D9: 4.69 | E9: 3.79 | F9: 3.78 | G9: 4.34 | H9: 5.99 | I9: 3.86 | J9: 5.75 | K9: 4.47 | L9: 3.37 | M9: 5.56 | N9: 1.45 | O9: 1.9 | P9: 1.45 | Q9: 1.09 | R9: 1.68 | S9: 1.85 | T9: 1.32 | U9: 1.35 | V9: 1.06 | W9: 1.54 | X9: 18.91 | Y9: 18.51 | Z9: 17.12 | AA9: 19.27 | AB9: 16.38 | AC9: =(SUM(D9:H9)+SUM(I9:M9))/2+SUM(N9:R9)+SUM(S9:W9) -> 37.49 | AD9: =SUM(X9:AB9)/100*50 -> 45.095 | AE9: =AC9+AD9 -> 82.585
A10: 3 | B10: S003 | C10: Rohan Mehta | D10: 5.38 | E10: 4.53 | F10: 3.36 | G10: 3.6 | H10: 3.42 | I10: 5.37 | J10: 3.08 | K10: 4.66 | L10: 4.11 | M10: 5.41 | N10: 1.55 | O10: 1.61 | P10: 1.09 | Q10: 1.31 | R10: 2 | S10: 1.72 | T10: 1.53 | U10: 1.77 | V10: 1.82 | W10: 1.07 | X10: 19.72 | Y10: 16.42 | Z10: 14.5 | AA10: 16.8 | AB10: 13.45 | AC10: =(SUM(D10:H10)+SUM(I10:M10))/2+SUM(N10:R10)+SUM(S10:W10) -> 36.93 | AD10: =SUM(X10:AB10)/100*50 -> 40.445 | AE10: =AC10+AD10 -> 77.375
A11: 4 | B11: S004 | C11: Sneha Reddy | D11: 5.63 | E11: 5.34 | F11: 4.92 | G11: 3.55 | H11: 5.9 | I11: 4.3 | J11: 5.73 | K11: 3.17 | L11: 3.37 | M11: 3.46 | N11: 1.16 | O11: 1.32 | P11: 1.71 | Q11: 1.35 | R11: 1.94 | S11: 1.89 | T11: 1.85 | U11: 1.25 | V11: 1.64 | W11: 1.55 | X11: 11.25 | Y11: 13.03 | Z11: 15.33 | AA11: 15.03 | AB11: 11.69 | AC11: =(SUM(D11:H11)+SUM(I11:M11))/2+SUM(N11:R11)+SUM(S11:W11) -> 38.345 | AD11: =SUM(X11:AB11)/100*50 -> 33.165 | AE11: =AC11+AD11 -> 71.51
A12: 5 | B12: S005 | C12: Vikram Singh | D12: 5.82 | E12: 3.46 | F12: 4.98 | G12: 5.16 | H12: 4.82 | I12: 5.53 | J12: 4.69 | K12: 5.48 | L12: 3.09 | M12: 3.14 | N12: 1.64 | O12: 1.58 | P12: 1.65 | Q12: 1.77 | R12: 1.42 | S12: 1.64 | T12: 1.5 | U12: 1.63 | V12: 1.29 | W12: 1.96 | X12: 14.83 | Y12: 18.05 | Z12: 16.85 | AA12: 12.97 | AB12: 10.73 | AC12: =(SUM(D12:H12)+SUM(I12:M12))/2+SUM(N12:R12)+SUM(S12:W12) -> 39.165 | AD12: =SUM(X12:AB12)/100*50 -> 36.715 | AE12: =AC12+AD12 -> 75.88
A13: 6 | B13: S006 | C13: Anjali Nair | D13: 3.18 | E13: 4.32 | F13: 4.45 | G13: 3.61 | H13: 4.82 | I13: 3.94 | J13: 5.16 | K13: 5.2 | L13: 5.58 | M13: 5.93 | N13: 1.13 | O13: 1.37 | P13: 1.56 | Q13: 1.32 | R13: 1.47 | S13: 1.27 | T13: 1.25 | U13: 1.1 | V13: 1.29 | W13: 1.38 | X13: 16.15 | Y13: 12.48 | Z13: 18.65 | AA13: 11.6 | AB13: 13.27 | AC13: =(SUM(D13:H13)+SUM(I13:M13))/2+SUM(N13:R13)+SUM(S13:W13) -> 36.235 | AD13: =SUM(X13:AB13)/100*50 -> 36.075 | AE13: =AC13+AD13 -> 72.31
A14: 7 | B14: S007 | C14: Kiran Kumar | D14: 4.73 | E14: 3.94 | F14: 5.29 | G14: 4.49 | H14: 4.54 | I14: 4.5 | J14: 3.93 | K14: 3.07 | L14: 5.84 | M14: 4.52 | N14: 1.97 | O14: 1.22 | P14: 1.35 | Q14: 1.05 | R14: 1.49 | S14: 1.88 | T14: 1.65 | U14: 1.47 | V14: 1.54 | W14: 1.85 | X14: 14.31 | Y14: 18.82 | Z14: 17.28 | AA14: 17.64 | AB14: 13.66 | AC14: =(SUM(D14:H14)+SUM(I14:M14))/2+SUM(N14:R14)+SUM(S14:W14) -> 37.895 | AD14: =SUM(X14:AB14)/100*50 -> 40.855 | AE14: =AC14+AD14 -> 78.75
A15: 8 | B15: S008 | C15: Divya Rao | D15: 4.2 | E15: 4.71 | F15: 3.58 | G15: 4.66 | H15: 3.22 | I15: 4.51 | J15: 5.29 | K15: 3.84 | L15: 5.97 | M15: 5.04 | N15: 1.12 | O15: 1.98 | P15: 1.39 | Q15: 1.79 | R15: 1.34 | S15: 1.94 | T15: 1.75 | U15: 1.2 | V15: 1.51 | W15: 1.5 | X15: 10.45 | Y15: 11.37 | Z15: 13.33 | AA15: 14.74 | AB15: 14.57 | AC15: =(SUM(D15:H15)+SUM(I15:M15))/2+SUM(N15:R15)+SUM(S15:W15) -> 38.03 | AD15: =SUM(X15:AB15)/100*50 -> 32.23 | AE15: =AC15+AD15 -> 70.26
A16: 9 | B16: S009 | C16: Arjun Gupta | D16: 4.82 | E16: 4.55 | F16: 3.98 | G16: 4.84 | H16: 3.49 | I16: 5.97 | J16: 5.22 | K16: 3.9 | L16: 4.01 | M16: 5.48 | N16: 1.53 | O16: 1.71 | P16: 1.3 | Q16: 1.82 | R16: 1.37 | S16: 1.67 | T16: 1.98 | U16: 1.58 | V16: 1.8 | W16: 1.73 | X16: 16.88 | Y16: 10.27 | Z16: 14.75 | AA16: 19.67 | AB16: 17.83 | AC16: =(SUM(D16:H16)+SUM(I16:M16))/2+SUM(N16:R16)+SUM(S16:W16) -> 39.62 | AD16: =SUM(X16:AB16)/100*50 -> 39.7 | AE16: =AC16+AD16 -> 79.32
A17: 10 | B17: S010 | C17: Pooja Iyer | D17: 5.33 | E17: 4.73 | F17: 5.16 | G17: 4.75 | H17: 3.51 | I17: 4.89 | J17: 4.86 | K17: 5.52 | L17: 3.44 | M17: 5.04 | N17: 1.03 | O17: 1.95 | P17: 1.11 | Q17: 1.02 | R17: 1.31 | S17: 1.15 | T17: 1.69 | U17: 1.41 | V17: 1.77 | W17: 1.92 | X17: 18.73 | Y17: 17.36 | Z17: 10.62 | AA17: 11.38 | AB17: 12.07 | AC17: =(SUM(D17:H17)+SUM(I17:M17))/2+SUM(N17:R17)+SUM(S17:W17) -> 37.975 | AD17: =SUM(X17:AB17)/100*50 -> 35.08 | AE17: =AC17+AD17 -> 73.055
A18: 11 | B18: S011 | C18: Rahul Verma | D18: 3.98 | E18: 4.99 | F18: 4.58 | G18: 3.94 | H18: 3.52 | I18: 5.74 | J18: 4.03 | K18: 4.06 | L18: 5.32 | M18: 5.16 | N18: 1.64 | O18: 1.69 | P18: 1.61 | Q18: 1.19 | R18: 1.25 | S18: 1.56 | T18: 1.22 | U18: 1.97 | V18: 1.3 | W18: 1.29 | X18: 12.07 | Y18: 17.05 | Z18: 13.17 | AA18: 13.49 | AB18: 19.34 | AC18: =(SUM(D18:H18)+SUM(I18:M18))/2+SUM(N18:R18)+SUM(S18:W18) -> 37.38 | AD18: =SUM(X18:AB18)/100*50 -> 37.56 | AE18: =AC18+AD18 -> 74.94
A19: 12 | B19: S012 | C19: Meera Joshi | D19: 5.39 | E19: 3.82 | F19: 3.37 | G19: 5.03 | H19: 4.14 | I19: 5.94 | J19: 5.46 | K19: 5.86 | L19: 5.41 | M19: 3.87 | N19: 1.29 | O19: 1.71 | P19: 1.35 | Q19: 1.44 | R19: 1.26 | S19: 1.48 | T19: 1.2 | U19: 1.54 | V19: 1.93 | W19: 1.7 | X19: 11.37 | Y19: 16.16 | Z19: 15.87 | AA19: 12.42 | AB19: 16.7 | AC19: =(SUM(D19:H19)+SUM(I19:M19))/2+SUM(N19:R19)+SUM(S19:W19) -> 39.045 | AD19: =SUM(X19:AB19)/100*50 -> 36.26 | AE19: =AC19+AD19 -> 75.305
... A27: 20 | B27: S020 | C27: Deepa Nambiar | D27: 4.26 | E27: 5.3 | F27: 5.65 | G27: 3.05 | H27: 3.62 | I27: 3.3 | J27: 3.1 | K27: 4.79 | L27: 5.11 | M27: 3.15 | N27: 1.74 | O27: 1.4 | P27: 1.23 | Q27: 1.22 | R27: 1.86 | S27: 1.06 | T27: 1.5 | U27: 1.29 | V27: 1.82 | W27: 1.73 | X27: 13.19 | Y27: 15.98 | Z27: 16.73 | AA27: 13.21 | AB27: 13.02 | AC27: =(SUM(D27:H27)+SUM(I27:M27))/2+SUM(N27:R27)+SUM(S27:W27) -> 35.515 | AD27: =SUM(X27:AB27)/100*50 -> 36.065 | AE27: =AC27+AD27 -> 71.58
A29: CLASS AVERAGE | D29: =AVERAGE(D8:D27) -> 4.6085 | E29: =AVERAGE(E8:E27) -> 4.724 | F29: =AVERAGE(F8:F27) -> 4.2875 | G29: =AVERAGE(G8:G27) -> 4.323 | H29: =AVERAGE(H8:H27) -> 4.5755 | I29: =AVERAGE(I8:I27) -> 4.5875 | J29: =AVERAGE(J8:J27) -> 4.529 | K29: =AVERAGE(K8:K27) -> 4.4925 | ... AE29: =AVERAGE(AE8:AE27) -> 75.5435
A31: CO ATTAINMENT % (Auto-calculated) | D31: =(IFERROR(D29/D6,0)+IFERROR(I29/I6,0)+IFERROR(N29/N6,0)+IFERROR(S29/S6,0)+IFERROR(X29/X6,0))/5 -> 0.75902833 | E31: =(IFERROR(E29/E6,0)+IFERROR(J29/J6,0)+IFERROR(O29/O6,0)+IFERROR(T29/T6,0)+IFERROR(Y29/Y6,0))/5 -> 0.77700333 | F31: =(IFERROR(F29/F6,0)+IFERROR(K29/K6,0)+IFERROR(P29/P6,0)+IFERROR(U29/U6,0)+IFERROR(Z29/Z6,0))/5 -> 0.73537667 | G31: =(IFERROR(G29/G6,0)+IFERROR(L29/L6,0)+IFERROR(Q29/Q6,0)+IFERROR(V29/V6,0)+IFERROR(AA29/AA6,0))/5 -> 0.74555667 | H31: =(IFERROR(H29/H6,0)+IFERROR(M29/M6,0)+IFERROR(R29/R6,0)+IFERROR(W29/W6,0)+IFERROR(AB29/AB6,0))/5 -> 0.75619667
A32: CIE CO ATT% | D32: =(IFERROR(D29/D6,0)+IFERROR(I29/I6,0)+IFERROR(N29/N6,0)+IFERROR(S29/S6,0))/4 -> 0.75960417 | E32: =(IFERROR(E29/E6,0)+IFERROR(J29/J6,0)+IFERROR(O29/O6,0)+IFERROR(T29/T6,0))/4 -> 0.77454167 | F32: =(IFERROR(F29/F6,0)+IFERROR(K29/K6,0)+IFERROR(P29/P6,0)+IFERROR(U29/U6,0))/4 -> 0.72839583 | G32: =(IFERROR(G29/G6,0)+IFERROR(L29/L6,0)+IFERROR(Q29/Q6,0)+IFERROR(V29/V6,0))/4 -> 0.74320833 | H32: =(IFERROR(H29/H6,0)+IFERROR(M29/M6,0)+IFERROR(R29/R6,0)+IFERROR(W29/W6,0))/4 -> 0.76564583
A33: SEE CO ATT% | D33: =IFERROR(X29/X6,0) -> 0.756725 | E33: =IFERROR(Y29/Y6,0) -> 0.78685 | F33: =IFERROR(Z29/Z6,0) -> 0.7633 | G33: =IFERROR(AA29/AA6,0) -> 0.75495 | H33: =IFERROR(AB29/AB6,0) -> 0.7184
A34: LEVEL (3=High≥60% / 2=Med≥40% / 1=Low) | D34: =IF(D31>=0.6,3,IF(D31>=0.4,2,1)) -> 3 | E34: =IF(E31>=0.6,3,IF(E31>=0.4,2,1)) -> 3 | F34: =IF(F31>=0.6,3,IF(F31>=0.4,2,1)) -> 3 | G34: =IF(G31>=0.6,3,IF(G31>=0.4,2,1)) -> 3 | H34: =IF(H31>=0.6,3,IF(H31>=0.4,2,1)) -> 3

Sheet CS305
A1: CO ATTAINMENT — Machine Learning (CS305)
A2: CIE = (Mid-1+Mid-2)/2 + Assignment + Quiz → 50M | SEE = 100M → 50M | Total = 100M
A4: Student Info | D4: MID-1 (Max=30M) | J4: MID-2 (Max=30M) | P4: ASSIGNMENT (Max=10M) | V4: QUIZ (Max=10M) | AB4: SEE (Max=100M) | AH4: CIE (50M) | AI4: SEE (50M) | AJ4: TOTAL (100M)
A5: S.No | B5: Reg No | C5: Name | D5: CO1 | E5: CO2 | F5: CO3 | G5: CO4 | H5: CO5 | I5: CO6 | J5: CO1 | K5: CO2 | L5: CO3 | M5: CO4 | N5: CO5 | O5: CO6 | P5: CO1 | Q5: CO2 | R5: CO3 | S5: CO4 | T5: CO5 | U5: CO6 | V5: CO1 | W5: CO2 | X5: CO3 | Y5: CO4 | Z5: CO5 | AA5: CO6 | AB5: CO1 | AC5: CO2 | AD5: CO3 | AE5: CO4 | AF5: CO5 | AG5: CO6 | AH5: Formula | AI5: Formula | AJ5: Formula
A6: MAX MARKS ← Edit here | D6: 5 | E6: 5 | F6: 5 | G6: 5 | H6: 5 | I6: 5 | J6: 5 | K6: 5 | L6: 5 | M6: 5 | N6: 5 | O6: 5 | P6: 1.67 | Q6: 1.67 | R6: 1.67 | S6: 1.67 | T6: 1.67 | U6: 1.67 | V6: 1.67 | W6: 1.67 | X6: 1.67 | Y6: 1.67 | Z6: 1.67 | AA6: 1.67 | AB6: 16.67 | AC6: 16.67 | AD6: 16.67 | AE6: 16.67 | AF6: 16.67 | AG6: 16.67 | AH6: 50 | AI6: 50 | AJ6: 100
A7: ↓ Enter student marks in white/grey cells below — CIE, SEE Scaled, Total calculate automatically ↓
A8: 1 | B8: S001 | C8: Aarav Sharma | D8: 2.86 | E8: 4.15 | F8: 3.05 | G8: 3.25 | H8: 2.65 | I8: 4.87 | J8: 4.7 | K8: 4.78 | L8: 4.06 | M8: 3.57 | N8: 3.74 | O8: 4.93 | P8: 1.62 | Q8: 1.39 | R8: 1.49 | S8: 1.1 | T8: 1.18 | U8: 0.96 | V8: 1.15 | W8: 1.46 | X8: 1.23 | Y8: 1.54 | Z8: 1.08 | AA8: 1.42 | AB8: 15.05 | AC8: 15.96 | AD8: 13.02 | AE8: 16.4 | AF8: 12.98 | AG8: 9.45 | AH8: =(SUM(D8:I8)+SUM(J8:O8))/2+SUM(P8:U8)+SUM(V8:AA8) -> 38.925 | AI8: =SUM(AB8:AG8)/100*50 -> 41.43 | AJ8: =AH8+AI8 -> 80.355
A9: 2 | B9: S002 | C9: Priya Patel | D9: 3.11 | E9: 3.01 | F9: 4.12 | G9: 4.81 | H9: 4.62 | I9: 2.73 | J9: 4.31 | K9: 2.98 | L9: 3.17 | M9: 4.18 | N9: 4.01 | O9: 4.68 | P9: 0.99 | Q9: 1.47 | R9: 1.44 | S9: 1.3 | T9: 1.23 | U9: 1.56 | V9: 1.11 | W9: 1.63 | X9: 0.85 | Y9: 1.61 | Z9: 1.64 | AA9: 0.93 | AB9: 16.66 | AC9: 12.32 | AD9: 10.35 | AE9: 13.37 | AF9: 10.04 | AG9: 15.96 | AH9: =(SUM(D9:I9)+SUM(J9:O9))/2+SUM(P9:U9)+SUM(V9:AA9) -> 38.625 | AI9: =SUM(AB9:AG9)/100*50 -> 39.35 | AJ9: =AH9+AI9 -> 77.975
A10: 3 | B10: S003 | C10: Rohan Mehta | D10: 3.88 | E10: 4.44 | F10: 3.45 | G10: 3.83 | H10: 3.4 | I10: 3.15 | J10: 3.78 | K10: 3.74 | L10: 2.75 | M10: 4.95 | N10: 3.67 | O10: 4.6 | P10: 1.6 | Q10: 1.14 | R10: 1.18 | S10: 1.3 | T10: 1.02 | U10: 0.95 | V10: 1.05 | W10: 1.61 | X10: 1.32 | Y10: 1.18 | Z10: 0.96 | AA10: 1.11 | AB10: 11.5 | AC10: 15.28 | AD10: 12.49 | AE10: 13.79 | AF10: 14.04 | AG10: 10.48 | AH10: =(SUM(D10:I10)+SUM(J10:O10))/2+SUM(P10:U10)+SUM(V10:AA10) -> 37.24 | AI10: =SUM(AB10:AG10)/100*50 -> 38.79 | AJ10: =AH10+AI10 -> 76.03
A11: 4 | B11: S004 | C11: Sneha Reddy | D11: 4.55 | E11: 4.92 | F11: 4.1 | G11: 3.73 | H11: 2.92 | I11: 4.49 | J11: 2.92 | K11: 4.3 | L11: 3.72 | M11: 4.79 | N11: 3.86 | O11: 4.1 | P11: 0.88 | Q11: 0.86 | R11: 1.54 | S11: 1.62 | T11: 1.39 | U11: 1.47 | V11: 1.18 | W11: 1.54 | X11: 1.03 | Y11: 1.42 | Z11: 0.84 | AA11: 1.25 | AB11: 11.44 | AC11: 13.48 | AD11: 13.89 | AE11: 13.47 | AF11: 12.36 | AG11: 12.4 | AH11: =(SUM(D11:I11)+SUM(J11:O11))/2+SUM(P11:U11)+SUM(V11:AA11) -> 39.22 | AI11: =SUM(AB11:AG11)/100*50 -> 38.52 | AJ11: =AH11+AI11 -> 77.74
A12: 5 | B12: S005 | C12: Vikram Singh | D12: 2.52 | E12: 3.88 | F12: 2.53 | G12: 3.82 | H12: 3.19 | I12: 4.94 | J12: 2.54 | K12: 4.53 | L12: 4.19 | M12: 4.52 | N12: 4.77 | O12: 2.77 | P12: 0.91 | Q12: 0.96 | R12: 0.99 | S12: 1.27 | T12: 1.51 | U12: 1.06 | V12: 1.16 | W12: 1.14 | X12: 1.17 | Y12: 1.3 | Z12: 1.66 | AA12: 1.02 | AB12: 14.03 | AC12: 15.4 | AD12: 13.78 | AE12: 15.49 | AF12: 14.66 | AG12: 9.11 | AH12: =(SUM(D12:I12)+SUM(J12:O12))/2+SUM(P12:U12)+SUM(V12:AA12) -> 36.25 | AI12: =SUM(AB12:AG12)/100*50 -> 41.235 | AJ12: =AH12+AI12 -> 77.485
A13: 6 | B13: S006 | C13: Anjali Nair | D13: 3.45 | E13: 3.88 | F13: 2.64 | G13: 2.52 | H13: 2.93 | I13: 3.75 | J13: 3.58 | K13: 4.46 | L13: 3.91 | M13: 4.64 | N13: 2.74 | O13: 3.82 | P13: 0.87 | Q13: 1.01 | R13: 1.56 | S13: 1.57 | T13: 1.23 | U13: 0.87 | V13: 0.9 | W13: 1.6 | X13: 1.58 | Y13: 1.3 | Z13: 0.86 | AA13: 1.61 | AB13: 10.95 | AC13: 16.35 | AD13: 13.23 | AE13: 14.6 | AF13: 14.27 | AG13: 11.65 | AH13: =(SUM(D13:I13)+SUM(J13:O13))/2+SUM(P13:U13)+SUM(V13:AA13) -> 36.12 | AI13: =SUM(AB13:AG13)/100*50 -> 40.525 | AJ13: =AH13+AI13 -> 76.645
A14: 7 | B14: S007 | C14: Kiran Kumar | D14: 2.69 | E14: 2.91 | F14: 3.1 | G14: 4.59 | H14: 3.47 | I14: 4.74 | J14: 3.33 | K14: 4.39 | L14: 2.85 | M14: 4.97 | N14: 4.31 | O14: 3.75 | P14: 1.65 | Q14: 0.88 | R14: 1.2 | S14: 1.53 | T14: 1.12 | U14: 1.47 | V14: 1.63 | W14: 1.16 | X14: 1.48 | Y14: 0.86 | Z14: 1.06 | AA14: 1.66 | AB14: 12.42 | AC14: 11.3 | AD14: 16.18 | AE14: 11.93 | AF14: 14 | AG14: 13.84 | AH14: =(SUM(D14:I14)+SUM(J14:O14))/2+SUM(P14:U14)+SUM(V14:AA14) -> 38.25 | AI14: =SUM(AB14:AG14)/100*50 -> 39.835 | AJ14: =AH14+AI14 -> 78.085
A15: 8 | B15: S008 | C15: Divya Rao | D15: 2.71 | E15: 4.05 | F15: 4.5 | G15: 4.28 | H15: 2.71 | I15: 2.89 | J15: 4.28 | K15: 4.08 | L15: 4.35 | M15: 3.29 | N15: 2.77 | O15: 2.51 | P15: 1.09 | Q15: 1.13 | R15: 1.06 | S15: 0.94 | T15: 0.99 | U15: 1.21 | V15: 1.3 | W15: 1.17 | X15: 0.86 | Y15: 1.13 | Z15: 0.91 | AA15: 1.33 | AB15: 11.04 | AC15: 11.54 | AD15: 10.77 | AE15: 11.56 | AF15: 9.04 | AG15: 15.84 | AH15: =(SUM(D15:I15)+SUM(J15:O15))/2+SUM(P15:U15)+SUM(V15:AA15) -> 34.33 | AI15: =SUM(AB15:AG15)/100*50 -> 34.895 | AJ15: =AH15+AI15 -> 69.225
A16: 9 | B16: S009 | C16: Arjun Gupta | D16: 4.76 | E16: 4.95 | F16: 3.93 | G16: 2.92 | H16: 3.45 | I16: 2.85 | J16: 3.25 | K16: 3.73 | L16: 2.66 | M16: 3.59 | N16: 3.55 | O16: 3.71 | P16: 0.9 | Q16: 1.04 | R16: 1.04 | S16: 1.35 | T16: 1.33 | U16: 1 | V16: 0.92 | W16: 1.09 | X16: 1.62 | Y16: 1.11 | Z16: 1.35 | AA16: 1.5 | AB16: 11.08 | AC16: 11.12 | AD16: 15.13 | AE16: 15.5 | AF16: 16.45 | AG16: 9.47 | AH16: =(SUM(D16:I16)+SUM(J16:O16))/2+SUM(P16:U16)+SUM(V16:AA16) -> 35.925 | AI16: =SUM(AB16:AG16)/100*50 -> 39.375 | AJ16: =AH16+AI16 -> 75.3
A17: 10 | B17: S010 | C17: Pooja Iyer | D17: 3.3 | E17: 4.87 | F17: 3 | G17: 3.29 | H17: 4.91 | I17: 4.92 | J17: 3.23 | K17: 4.24 | L17: 3.73 | M17: 3.94 | N17: 3.11 | O17: 3.44 | P17: 1.51 | Q17: 1.16 | R17: 0.93 | S17: 1.3 | T17: 1.33 | U17: 1.29 | V17: 1.4 | W17: 1.29 | X17: 1.63 | Y17: 1.22 | Z17: 1.42 | AA17: 1.2 | AB17: 10.76 | AC17: 14.11 | AD17: 15.16 | AE17: 14.96 | AF17: 11.74 | AG17: 12.49 | AH17: =(SUM(D17:I17)+SUM(J17:O17))/2+SUM(P17:U17)+SUM(V17:AA17) -> 38.67 | AI17: =SUM(AB17:AG17)/100*50 -> 39.61 | AJ17: =AH17+AI17 -> 78.28
A18: 11 | B18: S011 | C18: Rahul Verma | D18: 4.08 | E18: 3.11 | F18: 4.15 | G18: 4.29 | H18: 4.47 | I18: 2.68 | J18: 4.98 | K18: 3.7 | L18: 3.5 | M18: 3.77 | N18: 4.8 | O18: 4.23 | P18: 1.29 | Q18: 1.49 | R18: 1.13 | S18: 1.58 | T18: 1.28 | U18: 1.37 | V18: 0.9 | W18: 1.47 | X18: 1.38 | Y18: 1.13 | Z18: 1.37 | AA18: 0.87 | AB18: 16.53 | AC18: 13.98 | AD18: 11.66 | AE18: 14.61 | AF18: 16.38 | AG18: 11.92 | AH18: =(SUM(D18:I18)+SUM(J18:O18))/2+SUM(P18:U18)+SUM(V18:AA18) -> 39.14 | AI18: =SUM(AB18:AG18)/100*50 -> 42.54 | AJ18: =AH18+AI18 -> 81.68
A19: 12 | B19: S012 | C19: Meera Joshi | D19: 2.53 | E19: 3.15 | F19: 3.78 | G19: 3.8 | H19: 3.95 | I19: 3.94 | J19: 3.61 | K19: 3.48 | L19: 4.43 | M19: 3.97 | N19: 3.75 | O19: 3.36 | P19: 0.85 | Q19: 0.92 | R19: 1.18 | S19: 1.63 | T19: 0.93 | U19: 1.62 | V19: 0.95 | W19: 1.09 | X19: 1.21 | Y19: 1.01 | Z19: 1.24 | AA19: 1.23 | AB19: 11.98 | AC19: 14.14 | AD19: 10.99 | AE19: 10.84 | AF19: 15.08 | AG19: 9.29 | AH19: =(SUM(D19:I19)+SUM(J19:O19))/2+SUM(P19:U19)+SUM(V19:AA19) -> 35.735 | AI19: =SUM(AB19:AG19)/100*50 -> 36.16 | AJ19: =AH19+AI19 -> 71.895
... A27: 20 | B27: S020 | C27: Deepa Nambiar | D27: 4.54 | E27: 4.97 | F27: 3.56 | G27: 2.83 | H27: 2.68 | I27: 3.46 | J27: 4.33 | K27: 2.76 | L27: 3.28 | M27: 4.7 | N27: 2.84 | O27: 4.43 | P27: 1.46 | Q27: 0.94 | R27: 1.66 | S27: 0.95 | T27: 1.28 | U27: 0.84 | V27: 1.38 | W27: 1.2 | X27: 1.44 | Y27: 1.36 | Z27: 0.96 | AA27: 1.18 | AB27: 14.05 | AC27: 15.5 | AD27: 9.06 | AE27: 9.17 | AF27: 14.6 | AG27: 13.25 | AH27: =(SUM(D27:I27)+SUM(J27:O27))/2+SUM(P27:U27)+SUM(V27:AA27) -> 36.84 | AI27: =SUM(AB27:AG27)/100*50 -> 37.815 | AJ27: =AH27+AI27 -> 74.655
A29: CLASS AVERAGE | D29: =AVERAGE(D8:D27) -> 3.542 | E29: =AVERAGE(E8:E27) -> 3.9515 | F29: =AVERAGE(F8:F27) -> 3.676 | G29: =AVERAGE(G8:G27) -> 3.569 | H29: =AVERAGE(H8:H27) -> 3.7115 | I29: =AVERAGE(I8:I27) -> 3.666 | J29: =AVERAGE(J8:J27) -> 3.731 | K29: =AVERAGE(K8:K27) -> 3.7635 | ... AJ29: =AVERAGE(AJ8:AJ27) -> 75.3105
A31: CO ATTAINMENT % (Auto-calculated) | D31: =(IFERROR(D29/D6,0)+IFERROR(J29/J6,0)+IFERROR(P29/P6,0)+IFERROR(V29/V6,0)+IFERROR(AB29/AB6,0))/5 -> 0.72408173 | E31: =(IFERROR(E29/E6,0)+IFERROR(K29/K6,0)+IFERROR(Q29/Q6,0)+IFERROR(W29/W6,0)+IFERROR(AC29/AC6,0))/5 -> 0.76603884 | F31: =(IFERROR(F29/F6,0)+IFERROR(L29/L6,0)+IFERROR(R29/R6,0)+IFERROR(X29/X6,0)+IFERROR(AD29/AD6,0))/5 -> 0.75570953 | G31: =(IFERROR(G29/G6,0)+IFERROR(M29/M6,0)+IFERROR(S29/S6,0)+IFERROR(Y29/Y6,0)+IFERROR(AE29/AE6,0))/5 -> 0.76194972 | H31: =(IFERROR(H29/H6,0)+IFERROR(N29/N6,0)+IFERROR(T29/T6,0)+IFERROR(Z29/Z6,0)+IFERROR(AF29/AF6,0))/5 -> 0.7470058 | I31: =(IFERROR(I29/I6,0)+IFERROR(O29/O6,0)+IFERROR(U29/U6,0)+IFERROR(AA29/AA6,0)+IFERROR(AG29/AG6,0))/5 -> 0.7377394
A32: CIE CO ATT% | D32: =(IFERROR(D29/D6,0)+IFERROR(J29/J6,0)+IFERROR(P29/P6,0)+IFERROR(V29/V6,0))/4 -> 0.72173383 | E32: =(IFERROR(E29/E6,0)+IFERROR(K29/K6,0)+IFERROR(Q29/Q6,0)+IFERROR(W29/W6,0))/4 -> 0.76052545 | F32: =(IFERROR(F29/F6,0)+IFERROR(L29/L6,0)+IFERROR(R29/R6,0)+IFERROR(X29/X6,0))/4 -> 0.75758683 | G32: =(IFERROR(G29/G6,0)+IFERROR(M29/M6,0)+IFERROR(S29/S6,0)+IFERROR(Y29/Y6,0))/4 -> 0.76092545 | H32: =(IFERROR(H29/H6,0)+IFERROR(N29/N6,0)+IFERROR(T29/T6,0)+IFERROR(Z29/Z6,0))/4 -> 0.7384738 | I32: =(IFERROR(I29/I6,0)+IFERROR(O29/O6,0)+IFERROR(U29/U6,0)+IFERROR(AA29/AA6,0))/4 -> 0.74092799
A33: SEE CO ATT% | D33: =IFERROR(AB29/AB6,0) -> 0.73347331 | E33: =IFERROR(AC29/AC6,0) -> 0.78809238 | F33: =IFERROR(AD29/AD6,0) -> 0.74820036 | G33: =IFERROR(AE29/AE6,0) -> 0.76604679 | H33: =IFERROR(AF29/AF6,0) -> 0.78113377 | I33: =IFERROR(AG29/AG6,0) -> 0.724985
A34: LEVEL (3=High≥60% / 2=Med≥40% / 1=Low) | D34: =IF(D31>=0.6,3,IF(D31>=0.4,2,1)) -> 3 | E34: =IF(E31>=0.6,3,IF(E31>=0.4,2,1)) -> 3 | F34: =IF(F31>=0.6,3,IF(F31>=0.4,2,1)) -> 3 | G34: =IF(G31>=0.6,3,IF(G31>=0.4,2,1)) -> 3 | H34: =IF(H31>=0.6,3,IF(H31>=0.4,2,1)) -> 3 | I34: =IF(I31>=0.6,3,IF(I31>=0.4,2,1)) -> 3

Sheet CO-PO Mapping
A1: CO–PO / CO–PSO MAPPING (3=High 2=Medium 1=Low 0=No Relation) — Edit yellow cells only
A2: CO Attainment % is auto-linked from course sheets. Correlation values (0–3) are editable. PO Direct Attainment sheet reads both.
A4: Course | B4: Code | C4: CO | D4: CO Att% | E4: PROGRAMME OUTCOMES (PO1–PO12) | Q4: PROGRAMME SPECIFIC OUTCOMES
E5: PO1 | F5: PO2 | G5: PO3 | H5: PO4 | I5: PO5 | J5: PO6 | K5: PO7 | L5: PO8 | M5: PO9 | N5: PO10 | O5: PO11 | P5: PO12 | Q5: PSO1 | R5: PSO2 | S5: PSO3
A6: Data Structures & Algorithms | B6: CS301 | C6: CO1 | D6: =CS301!D31 -> 0.76586333 | E6: 3 | F6: 3 | G6: 2 | H6: 1 | I6: 0 | J6: 0 | K6: 0 | L6: 0 | M6: 1 | N6: 0 | O6: 0 | P6: 2 | Q6: 3 | R6: 2 | S6: 1
C7: CO2 | D7: =CS301!E31 -> 0.73686667 | E7: 3 | F7: 3 | G7: 3 | H7: 2 | I7: 1 | J7: 0 | K7: 0 | L7: 0 | M7: 1 | N7: 0 | O7: 0 | P7: 2 | Q7: 3 | R7: 2 | S7: 1
C8: CO3 | D8: =CS301!F31 -> 0.74786167 | E8: 2 | F8: 3 | G8: 3 | H8: 2 | I8: 2 | J8: 0 | K8: 0 | L8: 0 | M8: 0 | N8: 1 | O8: 0 | P8: 1 | Q8: 3 | R8: 3 | S8: 2
C9: CO4 | D9: =CS301!G31 -> 0.757025 | E9: 3 | F9: 3 | G9: 2 | H9: 3 | I9: 1 | J9: 0 | K9: 0 | L9: 0 | M9: 0 | N9: 0 | O9: 0 | P9: 2 | Q9: 3 | R9: 2 | S9: 1
C10: CO5 | D10: =CS301!H31 -> 0.74627667 | E10: 2 | F10: 2 | G10: 3 | H10: 2 | I10: 3 | J10: 0 | K10: 0 | L10: 0 | M10: 1 | N10: 0 | O10: 0 | P10: 2 | Q10: 2 | R10: 3 | S10: 2
A11: Database Management Systems | B11: CS302 | C11: CO1 | D11: =CS302!D31 -> 0.78649 | E11: 3 | F11: 2 | G11: 2 | H11: 1 | I11: 2 | J11: 0 | K11: 0 | L11: 0 | M11: 0 | N11: 1 | O11: 0 | P11: 1 | Q11: 3 | R11: 2 | S11: 2
C12: CO2 | D12: =CS302!E31 -> 0.75331333 | E12: 3 | F12: 3 | G12: 2 | H12: 2 | I12: 2 | J12: 0 | K12: 0 | L12: 0 | M12: 1 | N12: 0 | O12: 0 | P12: 1 | Q12: 3 | R12: 2 | S12: 1
C13: CO3 | D13: =CS302!F31 -> 0.76343333 | E13: 2 | F13: 3 | G13: 3 | H13: 2 | I13: 2 | J13: 0 | K13: 0 | L13: 0 | M13: 0 | N13: 1 | O13: 0 | P13: 2 | Q13: 2 | R13: 3 | S13: 2
C14: CO4 | D14: =CS302!G31 -> 0.7418 | E14: 2 | F14: 2 | G14: 2 | H14: 3 | I14: 1 | J14: 0 | K14: 0 | L14: 0 | M14: 1 | N14: 0 | O14: 1 | P14: 1 | Q14: 3 | R14: 2 | S14: 1
C15: CO5 | D15: =CS302!H31 -> 0.76381333 | E15: 3 | F15: 3 | G15: 2 | H15: 2 | I15: 3 | J15: 0 | K15: 0 | L15: 0 | M15: 0 | N15: 0 | O15: 0 | P15: 2 | Q15: 2 | R15: 3 | S15: 2
A16: Computer Networks | B16: CS303 | C16: CO1 | D16: =CS303!D31 -> 0.74761667 | E16: 3 | F16: 2 | G16: 1 | H16: 1 | I16: 3 | J16: 1 | K16: 0 | L16: 0 | M16: 0 | N16: 1 | O16: 0 | P16: 2 | Q16: 2 | R16: 3 | S16: 2
C17: CO2 | D17: =CS303!E31 -> 0.73379667 | E17: 3 | F17: 3 | G17: 2 | H17: 2 | I17: 3 | J17: 1 | K17: 0 | L17: 0 | M17: 1 | N17: 0 | O17: 0 | P17: 2 | Q17: 3 | R17: 3 | S17: 2
C18: CO3 | D18: =CS303!F31 -> 0.77289 | E18: 2 | F18: 3 | G18: 3 | H18: 2 | I18: 2 | J18: 1 | K18: 1 | L18: 0 | M18: 0 | N18: 1 | O18: 0 | P18: 1 | Q18: 2 | R18: 2 | S18: 2
C19: CO4 | D19: =CS303!G31 -> 0.73717 | E19: 3 | F19: 2 | G19: 2 | H19: 3 | I19: 2 | J19: 0 | K19: 0 | L19: 0 | M19: 1 | N19: 0 | O19: 0 | P19: 2 | Q19: 3 | R19: 2 | S19: 1
C20: CO5 | D20: =CS303!H31 -> 0.73067667 | E20: 2 | F20: 3 | G20: 2 | H20: 2 | I20: 3 | J20: 0 | K20: 0 | L20: 0 | M20: 0 | N20: 1 | O20: 0 | P20: 2 | Q20: 2 | R20: 3 | S20: 2
A21: Operating Systems | B21: CS304 | C21: CO1 | D21: =CS304!D31 -> 0.75902833 | E21: 3 | F21: 3 | G21: 1 | H21: 2 | I21: 2 | J21: 0 | K21: 0 | L21: 0 | M21: 0 | N21: 0 | O21: 0 | P21: 2 | Q21: 3 | R21: 2 | S21: 2
C22: CO2 | D22: =CS304!E31 -> 0.77700333 | E22: 3 | F22: 3 | G22: 2 | H22: 2 | I22: 2 | J22: 0 | K22: 0 | L22: 0 | M22: 1 | N22: 0 | O22: 0 | P22: 2 | Q22: 3 | R22: 3 | S22: 1
C23: CO3 | D23: =CS304!F31 -> 0.73537667 | E23: 2 | F23: 3 | G23: 3 | H23: 3 | I23: 2 | J23: 0 | K23: 0 | L23: 0 | M23: 0 | N23: 1 | O23: 0 | P23: 1 | Q23: 2 | R23: 2 | S23: 2
C24: CO4 | D24: =CS304!G31 -> 0.74555667 | E24: 2 | F24: 2 | G24: 2 | H24: 3 | I24: 1 | J24: 0 | K24: 0 | L24: 0 | M24: 1 | N24: 0 | O24: 0 | P24: 2 | Q24: 2 | R24: 2 | S24: 2
C25: CO5 | D25: =CS304!H31 -> 0.75619667 | E25: 3 | F25: 3 | G25: 2 | H25: 2 | I25: 3 | J25: 0 | K25: 0 | L25: 0 | M25: 0 | N25: 0 | O25: 0 | P25: 2 | Q25: 3 | R25: 3 | S25: 2
A26: Machine Learning | B26: CS305 | C26: CO1 | D26: =CS305!D31 -> 0.72408173 | E26: 3 | F26: 3 | G26: 2 | H26: 2 | I26: 3 | J26: 0 | K26: 0 | L26: 0 | M26: 0 | N26: 1 | O26: 0 | P26: 3 | Q26: 3 | R26: 3 | S26: 2
C27: CO2 | D27: =CS305!E31 -> 0.76603884 | E27: 2 | F27: 3 | G27: 3 | H27: 2 | I27: 3 | J27: 0 | K27: 0 | L27: 0 | M27: 1 | N27: 0 | O27: 0 | P27: 2 | Q27: 2 | R27: 3 | S27: 2
C28: CO3 | D28: =CS305!F31 -> 0.75570953 | E28: 3 | F28: 3 | G28: 3 | H28: 3 | I28: 2 | J28: 0 | K28: 0 | L28: 0 | M28: 0 | N28: 0 | O28: 0 | P28: 3 | Q28: 3 | R28: 3 | S28: 3
C29: CO4 | D29: =CS305!G31 -> 0.76194972 | E29: 2 | F29: 3 | G29: 2 | H29: 3 | I29: 3 | J29: 0 | K29: 0 | L29: 0 | M29: 1 | N29: 0 | O29: 0 | P29: 2 | Q29: 2 | R29: 3 | S29: 2
