Workbook

Sheet Master Dashboard
A1: CO & PO ATTAINMENT MASTER REPORT — B.Tech Computer Science & Engineering | Academic Year 2024-25
A2: Integrated Report: CO Attainment → CO-PO Mapping → PO Direct Attainment → PO Indirect Attainment → PO Total Attainment
A4: SECTION A — CO ATTAINMENT SUMMARY (Course-wise) | I4: SECTION B — PO / PSO TOTAL ATTAINMENT SUMMARY
A5: # | B5: Course | C5: Code | D5: Credits | E5: CO Att% (Avg) | F5: CIE% | G5: SEE% | H5: Level | I5: PO/PSO | J5: Description | K5: Direct Att% | L5: Indirect Att% | M5: Total Att% | N5: Level | O5: Target | P5: Gap | Q5: Status
A6: 1 | B6: Data Structures & Algorithms | C6: CS301 | D6: 4 | E6: 0.718 | F6: 0.7216 | G6: 0.6956 | H6: =IF(E6>=0.6,3,IF(E6>=0.4,2,1)) -> 3 | I6: PO1 | J6: Engineering Knowledge | K6: 0.6077 | L6: 0.743 | M6: 0.63476 | N6: =IF(M6>=0.6,3,IF(M6>=0.4,2,1)) -> 3 | O6: 0.6 | P6: =M6-O6 -> 0.03476 | Q6: =IF(M6>=O6,"✔ Met","✘ Not Met") -> ✔ Met
A7: 2 | B7: Database Management Systems | C7: CS302 | D7: 4 | E7: 0.486 | F7: 0.4931 | G7: 0.5108 | H7: =IF(E7>=0.6,3,IF(E7>=0.4,2,1)) -> 2 | I7: PO2 | J7: Problem Analysis | K7: 0.5297 | L7: 0.5095 | M7: 0.52566 | N7: =IF(M7>=0.6,3,IF(M7>=0.4,2,1)) -> 2 | O7: 0.6 | P7: =M7-O7 -> -0.07434 | Q7: =IF(M7>=O7,"✔ Met","✘ Not Met") -> ✘ Not Met
A8: 3 | B8: Computer Networks | C8: CS303 | D8: 4 | E8: 0.67 | F8: 0.6305 | G8: 0.6945 | H8: =IF(E8>=0.6,3,IF(E8>=0.4,2,1)) -> 3 | I8: PO3 | J8: Design/Development of Solutions | K8: 0.5309 | L8: 0.6045 | M8: 0.54562 | N8: =IF(M8>=0.6,3,IF(M8>=0.4,2,1)) -> 2 | O8: 0.6 | P8: =M8-O8 -> -0.05438 | Q8: =IF(M8>=O8,"✔ Met","✘ Not Met") -> ✘ Not Met
A9: 4 | B9: Operating Systems | C9: CS304 | D9: 4 | E9: 0.628 | F9: 0.6439 | G9: 0.6152 | H9: =IF(E9>=0.6,3,IF(E9>=0.4,2,1)) -> 3 | I9: PO4 | J9: Conduct Investigations of Complex Problems | K9: 0.7712 | L9: 0.5848 | M9: 0.73392 | N9: =IF(M9>=0.6,3,IF(M9>=0.4,2,1)) -> 3 | O9: 0.6 | P9: =M9-O9 -> 0.13392 | Q9: =IF(M9>=O9,"✔ Met","✘ Not Met") -> ✔ Met
A10: 5 | B10: Machine Learning | C10: CS305 | D10: 4 | E10: 0.70666667 | F10: 0.67906667 | G10: 0.74326667 | H10: =IF(E10>=0.6,3,IF(E10>=0.4,2,1)) -> 3 | I10: PO5 | J10: Modern Tool Usage | K10: 0.6932 | L10: 0.7799 | M10: 0.71054 | N10: =IF(M10>=0.6,3,IF(M10>=0.4,2,1)) -> 3 | O10: 0.6 | P10: =M10-O10 -> 0.11054 | Q10: =IF(M10>=O10,"✔ Met","✘ Not Met") -> ✔ Met
I11: PO6 | J11: The Engineer and Society | K11: 0.7583 | L11: 0.7571 | M11: 0.75806 | N11: =IF(M11>=0.6,3,IF(M11>=0.4,2,1)) -> 3 | O11: 0.6 | P11: =M11-O11 -> 0.15806 | Q11: =IF(M11>=O11,"✔ Met","✘ Not Met") -> ✔ Met
I12: PO7 | J12: Environment and Sustainability | K12: 0.7335 | L12: 0.839 | M12: 0.7546 | N12: =IF(M12>=0.6,3,IF(M12>=0.4,2,1)) -> 3 | O12: 0.6 | P12: =M12-O12 -> 0.1546 | Q12: =IF(M12>=O12,"✔ Met","✘ Not Met") -> ✔ Met
I13: PO8 | J13: Ethics | K13: 0.6716 | L13: 0.533 | M13: 0.64388 | N13: =IF(M13>=0.6,3,IF(M13>=0.4,2,1)) -> 3 | O13: 0.6 | P13: =M13-O13 -> 0.04388 | Q13: =IF(M13>=O13,"✔ Met","✘ Not Met") -> ✔ Met
I14: PO9 | J14: Individual and Team Work | K14: 0.8114 | L14: 0.6603 | M14: 0.78118 | N14: =IF(M14>=0.6,3,IF(M14>=0.4,2,1)) -> 3 | O14: 0.6 | P14: =M14-O14 -> 0.18118 | Q14: =IF(M14>=O14,"✔ Met","✘ Not Met") -> ✔ Met
I15: PO10 | J15: Communication | K15: 0.6211 | L15: 0.5113 | M15: 0.59914 | N15: =IF(M15>=0.6,3,IF(M15>=0.4,2,1)) -> 2 | O15: 0.6 | P15: =M15-O15 -> -0.00086 | Q15: =IF(M15>=O15,"✔ Met","✘ Not Met") -> ✘ Not Met
I16: PO11 | J16: Project Management and Finance | K16: 0.6767 | L16: 0.5831 | M16: 0.65798 | N16: =IF(M16>=0.6,3,IF(M16>=0.4,2,1)) -> 3 | O16: 0.6 | P16: =M16-O16 -> 0.05798 | Q16: =IF(M16>=O16,"✔ Met","✘ Not Met") -> ✔ Met
I17: PO12 | J17: Life-long Learning | K17: 0.7654 | L17: 0.692 | M17: 0.75072 | N17: =IF(M17>=0.6,3,IF(M17>=0.4,2,1)) -> 3 | O17: 0.6 | P17: =M17-O17 -> 0.15072 | Q17: =IF(M17>=O17,"✔ Met","✘ Not Met") -> ✔ Met
I18: PSO1 | J18: Apply core CS concepts to design software systems | K18: 0.6979 | L18: 0.5101 | M18: 0.66034 | N18: =IF(M18>=0.6,3,IF(M18>=0.4,2,1)) -> 3 | O18: 0.6 | P18: =M18-O18 -> 0.06034 | Q18: =IF(M18>=O18,"✔ Met","✘ Not Met") -> ✔ Met
I19: PSO2 | J19: Use modern tools to solve real-world engineering problems | K19: 0.7757 | L19: 0.5756 | M19: 0.73568 | N19: =IF(M19>=0.6,3,IF(M19>=0.4,2,1)) -> 3 | O19: 0.6 | P19: =M19-O19 -> 0.13568 | Q19: =IF(M19>=O19,"✔ Met","✘ Not Met") -> ✔ Met
I20: PSO3 | J20: Demonstrate professional skills for industry/research | K20: 0.6848 | L20: 0.747 | M20: 0.69724 | N20: =IF(M20>=0.6,3,IF(M20>=0.4,2,1)) -> 3 | O20: 0.6 | P20: =M20-O20 -> 0.09724 | Q20: =IF(M20>=O20,"✔ Met","✘ Not Met") -> ✔ Met

Sheet CS301
A1: CO ATTAINMENT — Data Structures & Algorithms (CS301)
A2: CIE=(Mid-1+Mid-2)/2+Assignment+Quiz → 50M | SEE=100M→50M | Total=100M
A4: Student Info | D4: MID-1 (30M) | I4: MID-2 (30M) | N4: ASSIGNMENT (10M) | S4: QUIZ (10M) | X4: SEE (100M) | AC4: CIE (50M) | AD4: SEE (50M) | AE4: TOTAL (100M)
A5: S.No | B5: Reg No | C5: Name | D5: CO1 | E5: CO2 | F5: CO3 | G5: CO4 | H5: CO5 | I5: CO1 | J5: CO2 | K5: CO3 | L5: CO4 | M5: CO5 | N5: CO1 | O5: CO2 | P5: CO3 | Q5: CO4 | R5: CO5 | S5: CO1 | T5: CO2 | U5: CO3 | V5: CO4 | W5: CO5 | X5: CO1 | Y5: CO2 | Z5: CO3 | AA5: CO4 | AB5: CO5 | AC5: Formula | AD5: Formula | AE5: Formula
A6: MAX MARKS (Edit) | D6: 6 | E6: 6 | F6: 6 | G6: 6 | H6: 6 | I6: 6 | J6: 6 | K6: 6 | L6: 6 | M6: 6 | N6: 2 | O6: 2 | P6: 2 | Q6: 2 | R6: 2 | S6: 2 | T6: 2 | U6: 2 | V6: 2 | W6: 2 | X6: 20 | Y6: 20 | Z6: 20 | AA6: 20 | AB6: 20 | AC6: 50 | AD6: 50 | AE6: 100
A7: 1 | B7: S001 | C7: Aarav Sharma | D7: 5.1 | E7: 3.1 | F7: 3.7 | G7: 3.9 | H7: 3.2 | I7: 3.7 | J7: 3.3 | K7: 3.8 | L7: 4.9 | M7: 4.1 | N7: 1.4 | O7: 1.2 | P7: 1.3 | Q7: 1.9 | R7: 1.6 | S7: 1.6 | T7: 1.2 | U7: 1.7 | V7: 1.2 | W7: 1.4 | X7: 19.9 | Y7: 16.4 | Z7: 15.6 | AA7: 16.8 | AB7: 18.4 | AC7: =(SUM(D7:H7)+SUM(I7:M7))/2+SUM(N7:R7)+SUM(S7:W7) -> 33.9 | AD7: =SUM(X7:AB7)/100*50 -> 43.55 | AE7: =AC7+AD7 -> 77.45
A8: 2 | B8: S002 | C8: Priya Patel | D8: 5.3 | E8: 3.7 | F8: 3.1 | G8: 3.9 | H8: 3.8 | I8: 3.6 | J8: 5.8 | K8: 5.6 | L8: 3.9 | M8: 5 | N8: 1.4 | O8: 1.9 | P8: 1.5 | Q8: 1.3 | R8: 1.2 | S8: 1.6 | T8: 1.3 | U8: 1.6 | V8: 1.9 | W8: 1.4 | X8: 12.2 | Y8: 20 | Z8: 15.1 | AA8: 10.9 | AB8: 10.5 | AC8: =(SUM(D8:H8)+SUM(I8:M8))/2+SUM(N8:R8)+SUM(S8:W8) -> 36.95 | AD8: =SUM(X8:AB8)/100*50 -> 34.35 | AE8: =AC8+AD8 -> 71.3
A9: 3 | B9: S003 | C9: Rohan Mehta | D9: 3.3 | E9: 4.9 | F9: 5.4 | G9: 4.3 | H9: 3.2 | I9: 4.1 | J9: 6 | K9: 4.6 | L9: 5.9 | M9: 5.6 | N9: 1 | O9: 1.7 | P9: 1.7 | Q9: 1.5 | R9: 1.3 | S9: 1.6 | T9: 1.1 | U9: 1.4 | V9: 1.5 | W9: 2 | X9: 18.8 | Y9: 12.6 | Z9: 15 | AA9: 11.8 | AB9: 19.1 | AC9: =(SUM(D9:H9)+SUM(I9:M9))/2+SUM(N9:R9)+SUM(S9:W9) -> 38.45 | AD9: =SUM(X9:AB9)/100*50 -> 38.65 | AE9: =AC9+AD9 -> 77.1
A10: 4 | B10: S004 | C10: Sneha Reddy | D10: 5.6 | E10: 3.9 | F10: 4.9 | G10: 4.8 | H10: 3.5 | I10: 5.3 | J10: 4.6 | K10: 5.3 | L10: 4.6 | M10: 3 | N10: 1.3 | O10: 1 | P10: 1.9 | Q10: 1.9 | R10: 1.8 | S10: 1.3 | T10: 1.1 | U10: 1.9 | V10: 1.9 | W10: 1.1 | X10: 14.9 | Y10: 10.7 | Z10: 17.6 | AA10: 17.7 | AB10: 11.3 | AC10: =(SUM(D10:H10)+SUM(I10:M10))/2+SUM(N10:R10)+SUM(S10:W10) -> 37.95 | AD10: =SUM(X10:AB10)/100*50 -> 36.1 | AE10: =AC10+AD10 -> 74.05
A11: 5 | B11: S005 | C11: Vikram Singh | D11: 4.4 | E11: 4.6 | F11: 3.8 | G11: 5.6 | H11: 4.3 | I11: 3.6 | J11: 4.6 | K11: 5.2 | L11: 3.6 | M11: 3.9 | N11: 2 | O11: 1.6 | P11: 1.4 | Q11: 1.5 | R11: 1.1 | S11: 1.2 | T11: 1.3 | U11: 1.6 | V11: 1.2 | W11: 1.2 | X11: 10.7 | Y11: 16.3 | Z11: 12.3 | AA11: 19.1 | AB11: 18.6 | AC11: =(SUM(D11:H11)+SUM(I11:M11))/2+SUM(N11:R11)+SUM(S11:W11) -> 35.9 | AD11: =SUM(X11:AB11)/100*50 -> 38.5 | AE11: =AC11+AD11 -> 74.4
A12: 6 | B12: S006 | C12: Anjali Nair | D12: 3.2 | E12: 3.7 | F12: 5 | G12: 3.6 | H12: 3.4 | I12: 5.8 | J12: 4.7 | K12: 4.4 | L12: 5.4 | M12: 5.4 | N12: 1.2 | O12: 1.1 | P12: 1.4 | Q12: 1.4 | R12: 1.5 | S12: 1.7 | T12: 1.7 | U12: 2 | V12: 1.1 | W12: 1.4 | X12: 13.4 | Y12: 18.6 | Z12: 12.5 | AA12: 11.9 | AB12: 14.5 | AC12: =(SUM(D12:H12)+SUM(I12:M12))/2+SUM(N12:R12)+SUM(S12:W12) -> 36.8 | AD12: =SUM(X12:AB12)/100*50 -> 35.45 | AE12: =AC12+AD12 -> 72.25
A13: 7 | B13: S007 | C13: Kiran Kumar | D13: 4.3 | E13: 3.8 | F13: 3.7 | G13: 5.8 | H13: 4.3 | I13: 5.6 | J13: 4.7 | K13: 3.2 | L13: 6 | M13: 5.5 | N13: 2 | O13: 1.9 | P13: 1.8 | Q13: 1.2 | R13: 1.5 | S13: 1.2 | T13: 1.4 | U13: 1.1 | V13: 1.4 | W13: 2 | X13: 12.7 | Y13: 17.8 | Z13: 14.6 | AA13: 14.2 | AB13: 19.6 | AC13: =(SUM(D13:H13)+SUM(I13:M13))/2+SUM(N13:R13)+SUM(S13:W13) -> 38.95 | AD13: =SUM(X13:AB13)/100*50 -> 39.45 | AE13: =AC13+AD13 -> 78.4
A14: 8 | B14: S008 | C14: Divya Rao | D14: 6 | E14: 4.7 | F14: 5.2 | G14: 3.5 | H14: 3.9 | I14: 5.9 | J14: 4.7 | K14: 4.6 | L14: 5.2 | M14: 3.2 | N14: 1.6 | O14: 1.5 | P14: 1.9 | Q14: 1.2 | R14: 2 | S14: 1.1 | T14: 1.2 | U14: 1.6 | V14: 1.7 | W14: 1.2 | X14: 11.2 | Y14: 18.9 | Z14: 12.5 | AA14: 15.9 | AB14: 16.2 | AC14: =(SUM(D14:H14)+SUM(I14:M14))/2+SUM(N14:R14)+SUM(S14:W14) -> 38.45 | AD14: =SUM(X14:AB14)/100*50 -> 37.35 | AE14: =AC14+AD14 -> 75.8
A15: 9 | B15: S009 | C15: Arjun Gupta | D15: 4.3 | E15: 4.8 | F15: 4.6 | G15: 5.8 | H15: 3.6 | I15: 5.1 | J15: 3.7 | K15: 4.2 | L15: 5 | M15: 3.9 | N15: 1.3 | O15: 1.8 | P15: 1.1 | Q15: 1.5 | R15: 2 | S15: 2 | T15: 1.1 | U15: 1.2 | V15: 1.3 | W15: 1.9 | X15: 18.8 | Y15: 18.8 | Z15: 13.7 | AA15: 11.6 | AB15: 18.3 | AC15: =(SUM(D15:H15)+SUM(I15:M15))/2+SUM(N15:R15)+SUM(S15:W15) -> 37.7 | AD15: =SUM(X15:AB15)/100*50 -> 40.6 | AE15: =AC15+AD15 -> 78.3
A16: 10 | B16: S010 | C16: Pooja Iyer | D16: 5.1 | E16: 4.8 | F16: 6 | G16: 5 | H16: 3 | I16: 5.5 | J16: 3.9 | K16: 5 | L16: 5.8 | M16: 3.4 | N16: 1.1 | O16: 1.1 | P16: 1.6 | Q16: 1.3 | R16: 1.6 | S16: 1.7 | T16: 1.2 | U16: 1.6 | V16: 1.3 | W16: 1.5 | X16: 19.1 | Y16: 18.5 | Z16: 10.9 | AA16: 14.2 | AB16: 12.8 | AC16: =(SUM(D16:H16)+SUM(I16:M16))/2+SUM(N16:R16)+SUM(S16:W16) -> 37.75 | AD16: =SUM(X16:AB16)/100*50 -> 37.75 | AE16: =AC16+AD16 -> 75.5
A17: 11 | B17: S011 | C17: Rahul Verma | D17: 3 | E17: 5.3 | F17: 4.9 | G17: 3.8 | H17: 5.2 | I17: 4.7 | J17: 4.3 | K17: 3 | L17: 3.2 | M17: 5.6 | N17: 1.9 | O17: 1.5 | P17: 1.8 | Q17: 1.6 | R17: 1.1 | S17: 1.1 | T17: 1.3 | U17: 1.9 | V17: 1.8 | W17: 1.9 | X17: 19 | Y17: 12.1 | Z17: 12.5 | AA17: 11 | AB17: 17.8 | AC17: =(SUM(D17:H17)+SUM(I17:M17))/2+SUM(N17:R17)+SUM(S17:W17) -> 37.4 | AD17: =SUM(X17:AB17)/100*50 -> 36.2 | AE17: =AC17+AD17 -> 73.6
A18: 12 | B18: S012 | C18: Meera Joshi | D18: 5.7 | E18: 4.2 | F18: 4.9 | G18: 3.5 | H18: 5.8 | I18: 5.6 | J18: 5.9 | K18: 5.4 | L18: 5.6 | M18: 3.1 | N18: 1.7 | O18: 1.3 | P18: 1.9 | Q18: 1.8 | R18: 1.9 | S18: 1.8 | T18: 1.3 | U18: 1.8 | V18: 1.1 | W18: 1.9 | X18: 18.6 | Y18: 12.2 | Z18: 18.2 | AA18: 14.6 | AB18: 13.1 | AC18: =(SUM(D18:H18)+SUM(I18:M18))/2+SUM(N18:R18)+SUM(S18:W18) -> 41.35 | AD18: =SUM(X18:AB18)/100*50 -> 38.35 | AE18: =AC18+AD18 -> 79.7
... A26: 20 | B26: S020 | C26: Deepa Nambiar | D26: 5.5 | E26: 3.8 | F26: 3.2 | G26: 3.1 | H26: 4.6 | I26: 6 | J26: 4.1 | K26: 5 | L26: 5.3 | M26: 5 | N26: 1.8 | O26: 1.9 | P26: 1.2 | Q26: 1 | R26: 1.2 | S26: 1.1 | T26: 1.7 | U26: 1.6 | V26: 1.2 | W26: 1.7 | X26: 17.7 | Y26: 11.7 | Z26: 16.1 | AA26: 17.5 | AB26: 11.1 | AC26: =(SUM(D26:H26)+SUM(I26:M26))/2+SUM(N26:R26)+SUM(S26:W26) -> 37.2 | AD26: =SUM(X26:AB26)/100*50 -> 37.05 | AE26: =AC26+AD26 -> 74.25
A28: CLASS AVERAGE | D28: =AVERAGE(D7:D26) -> 4.59 | E28: =AVERAGE(E7:E26) -> 4.235 | F28: =AVERAGE(F7:F26) -> 4.455 | G28: =AVERAGE(G7:G26) -> 4.365 | H28: =AVERAGE(H7:H26) -> 4.035 | I28: =AVERAGE(I7:I26) -> 4.84 | J28: =AVERAGE(J7:J26) -> 4.73 | K28: =AVERAGE(K7:K26) -> 4.44 | ... AE28: =AVERAGE(AE7:AE26) -> 75.1275
A30: CO ATTAINMENT % | D30: =IFERROR((D28/D6+I28/I6+N28/N6+S28/S6+X28/X6)/5,0) -> 0.76653333 | E30: =IFERROR((E28/E6+J28/J6+O28/O6+T28/T6+Y28/Y6)/5,0) -> 0.73103333 | F30: =IFERROR((F28/F6+K28/K6+P28/P6+U28/U6+Z28/Z6)/5,0) -> 0.75395 | G30: =IFERROR((G28/G6+L28/L6+Q28/Q6+V28/V6+AA28/AA6)/5,0) -> 0.75016667 | H30: =IFERROR((H28/H6+M28/M6+R28/R6+W28/W6+AB28/AB6)/5,0) -> 0.74361667
A31: LEVEL (3/2/1) | D31: =IF(D30>=0.6,3,IF(D30>=0.4,2,1)) -> 3 | E31: =IF(E30>=0.6,3,IF(E30>=0.4,2,1)) -> 3 | F31: =IF(F30>=0.6,3,IF(F30>=0.4,2,1)) -> 3 | G31: =IF(G30>=0.6,3,IF(G30>=0.4,2,1)) -> 3 | H31: =IF(H30>=0.6,3,IF(H30>=0.4,2,1)) -> 3

Sheet CS302
A1: CO ATTAINMENT — Database Management Systems (CS302)
A2: CIE=(Mid-1+Mid-2)/2+Assignment+Quiz → 50M | SEE=100M→50M | Total=100M
A4: Student Info | D4: MID-1 (30M) | I4: MID-2 (30M) | N4: ASSIGNMENT (10M) | S4: QUIZ (10M) | X4: SEE (100M) | AC4: CIE (50M) | AD4: SEE (50M) | AE4: TOTAL (100M)
A5: S.No | B5: Reg No | C5: Name | D5: CO1 | E5: CO2 | F5: CO3 | G5: CO4 | H5: CO5 | I5: CO1 | J5: CO2 | K5: CO3 | L5: CO4 | M5: CO5 | N5: CO1 | O5: CO2 | P5: CO3 | Q5: CO4 | R5: CO5 | S5: CO1 | T5: CO2 | U5: CO3 | V5: CO4 | W5: CO5 | X5: CO1 | Y5: CO2 | Z5: CO3 | AA5: CO4 | AB5: CO5 | AC5: Formula | AD5: Formula | AE5: Formula
A6: MAX MARKS (Edit) | D6: 6 | E6: 6 | F6: 6 | G6: 6 | H6: 6 | I6: 6 | J6: 6 | K6: 6 | L6: 6 | M6: 6 | N6: 2 | O6: 2 | P6: 2 | Q6: 2 | R6: 2 | S6: 2 | T6: 2 | U6: 2 | V6: 2 | W6: 2 | X6: 20 | Y6: 20 | Z6: 20 | AA6: 20 | AB6: 20 | AC6: 50 | AD6: 50 | AE6: 100
A7: 1 | B7: S001 | C7: Aarav Sharma | D7: 5.5 | E7: 5.9 | F7: 3.3 | G7: 3.1 | H7: 3.9 | I7: 5 | J7: 5.9 | K7: 4.2 | L7: 5.1 | M7: 3.2 | N7: 1.7 | O7: 1.6 | P7: 1.1 | Q7: 1.8 | R7: 1.9 | S7: 1.6 | T7: 1.1 | U7: 2 | V7: 1.8 | W7: 1.3 | X7: 14.3 | Y7: 13.7 | Z7: 15.1 | AA7: 13.4 | AB7: 18.5 | AC7: =(SUM(D7:H7)+SUM(I7:M7))/2+SUM(N7:R7)+SUM(S7:W7) -> 38.45 | AD7: =SUM(X7:AB7)/100*50 -> 37.5 | AE7: =AC7+AD7 -> 75.95
A8: 2 | B8: S002 | C8: Priya Patel | D8: 5.5 | E8: 3.3 | F8: 5.9 | G8: 4.9 | H8: 5.5 | I8: 5.1 | J8: 4.3 | K8: 5.2 | L8: 5.9 | M8: 3.8 | N8: 1.8 | O8: 1.5 | P8: 1.5 | Q8: 1.4 | R8: 1.7 | S8: 1.3 | T8: 1.9 | U8: 1.8 | V8: 1.1 | W8: 1.9 | X8: 12.4 | Y8: 14.6 | Z8: 16.1 | AA8: 13.8 | AB8: 10.3 | AC8: =(SUM(D8:H8)+SUM(I8:M8))/2+SUM(N8:R8)+SUM(S8:W8) -> 40.6 | AD8: =SUM(X8:AB8)/100*50 -> 33.6 | AE8: =AC8+AD8 -> 74.2
A9: 3 | B9: S003 | C9: Rohan Mehta | D9: 5.6 | E9: 3.5 | F9: 3.6 | G9: 5.4 | H9: 4 | I9: 5.6 | J9: 5.1 | K9: 3.8 | L9: 3 | M9: 5.8 | N9: 1.1 | O9: 1.7 | P9: 1.5 | Q9: 1.8 | R9: 1.7 | S9: 1.6 | T9: 1.5 | U9: 1.8 | V9: 1.1 | W9: 1.2 | X9: 16.9 | Y9: 13.1 | Z9: 15.8 | AA9: 14.7 | AB9: 15.3 | AC9: =(SUM(D9:H9)+SUM(I9:M9))/2+SUM(N9:R9)+SUM(S9:W9) -> 37.7 | AD9: =SUM(X9:AB9)/100*50 -> 37.9 | AE9: =AC9+AD9 -> 75.6
A10: 4 | B10: S004 | C10: Sneha Reddy | D10: 4.3 | E10: 5.2 | F10: 4 | G10: 5.1 | H10: 3.8 | I10: 3.8 | J10: 3.4 | K10: 3.6 | L10: 3.4 | M10: 4.6 | N10: 1.8 | O10: 1.2 | P10: 1.2 | Q10: 1.5 | R10: 1.7 | S10: 2 | T10: 1.5 | U10: 1.3 | V10: 1.1 | W10: 1.2 | X10: 12.3 | Y10: 11.8 | Z10: 10.1 | AA10: 15.3 | AB10: 12.7 | AC10: =(SUM(D10:H10)+SUM(I10:M10))/2+SUM(N10:R10)+SUM(S10:W10) -> 35.1 | AD10: =SUM(X10:AB10)/100*50 -> 31.1 | AE10: =AC10+AD10 -> 66.2
A11: 5 | B11: S005 | C11: Vikram Singh | D11: 5.9 | E11: 4.7 | F11: 5.1 | G11: 3.4 | H11: 5.6 | I11: 4.5 | J11: 5.6 | K11: 4.7 | L11: 4.4 | M11: 4.3 | N11: 1.2 | O11: 1.1 | P11: 1.9 | Q11: 1.5 | R11: 1.8 | S11: 1.4 | T11: 1.1 | U11: 1.6 | V11: 1.1 | W11: 1.1 | X11: 15.6 | Y11: 13 | Z11: 19.9 | AA11: 11.2 | AB11: 17.6 | AC11: =(SUM(D11:H11)+SUM(I11:M11))/2+SUM(N11:R11)+SUM(S11:W11) -> 37.9 | AD11: =SUM(X11:AB11)/100*50 -> 38.65 | AE11: =AC11+AD11 -> 76.55
A12: 6 | B12: S006 | C12: Anjali Nair | D12: 4.8 | E12: 5.4 | F12: 3.7 | G12: 4.6 | H12: 4.4 | I12: 4.3 | J12: 5.6 | K12: 6 | L12: 3.9 | M12: 4.9 | N12: 1.6 | O12: 1.7 | P12: 1.9 | Q12: 1.2 | R12: 1.2 | S12: 1.7 | T12: 1.2 | U12: 1.2 | V12: 1.1 | W12: 1 | X12: 14.5 | Y12: 15.9 | Z12: 12.9 | AA12: 12.3 | AB12: 17.1 | AC12: =(SUM(D12:H12)+SUM(I12:M12))/2+SUM(N12:R12)+SUM(S12:W12) -> 37.6 | AD12: =SUM(X12:AB12)/100*50 -> 36.35 | AE12: =AC12+AD12 -> 73.95
A13: 7 | B13: S007 | C13: Kiran Kumar | D13: 5.1 | E13: 4.4 | F13: 5.1 | G13: 5.8 | H13: 5.4 | I13: 4.9 | J13: 5 | K13: 5.8 | L13: 4.3 | M13: 4.6 | N13: 1.6 | O13: 1.9 | P13: 1.8 | Q13: 1.1 | R13: 1.2 | S13: 1.3 | T13: 1.7 | U13: 1.6 | V13: 1.3 | W13: 1.1 | X13: 16.9 | Y13: 17 | Z13: 19.4 | AA13: 15 | AB13: 14.9 | AC13: =(SUM(D13:H13)+SUM(I13:M13))/2+SUM(N13:R13)+SUM(S13:W13) -> 39.8 | AD13: =SUM(X13:AB13)/100*50 -> 41.6 | AE13: =AC13+AD13 -> 81.4
A14: 8 | B14: S008 | C14: Divya Rao | D14: 3.2 | E14: 3.1 | F14: 4.3 | G14: 4 | H14: 3.8 | I14: 3.3 | J14: 5.9 | K14: 5.5 | L14: 4.7 | M14: 5.9 | N14: 2 | O14: 1.7 | P14: 1.3 | Q14: 1 | R14: 1.8 | S14: 1.5 | T14: 1.7 | U14: 1.9 | V14: 1.2 | W14: 1.6 | X14: 16.3 | Y14: 14.9 | Z14: 10.9 | AA14: 13.5 | AB14: 13.3 | AC14: =(SUM(D14:H14)+SUM(I14:M14))/2+SUM(N14:R14)+SUM(S14:W14) -> 37.55 | AD14: =SUM(X14:AB14)/100*50 -> 34.45 | AE14: =AC14+AD14 -> 72
A15: 9 | B15: S009 | C15: Arjun Gupta | D15: 5 | E15: 5.6 | F15: 4 | G15: 5.1 | H15: 3.9 | I15: 5.8 | J15: 5.4 | K15: 4.7 | L15: 4.4 | M15: 3.9 | N15: 1.3 | O15: 2 | P15: 1.4 | Q15: 1.5 | R15: 2 | S15: 1.7 | T15: 1.5 | U15: 1.4 | V15: 1.2 | W15: 1.4 | X15: 17.6 | Y15: 16.3 | Z15: 17.6 | AA15: 12 | AB15: 15.5 | AC15: =(SUM(D15:H15)+SUM(I15:M15))/2+SUM(N15:R15)+SUM(S15:W15) -> 39.3 | AD15: =SUM(X15:AB15)/100*50 -> 39.5 | AE15: =AC15+AD15 -> 78.8
A16: 10 | B16: S010 | C16: Pooja Iyer | D16: 5.8 | E16: 4.3 | F16: 5.1 | G16: 3.4 | H16: 5.9 | I16: 4.8 | J16: 3.7 | K16: 3.5 | L16: 4.7 | M16: 4.7 | N16: 1.1 | O16: 2 | P16: 1.9 | Q16: 1.5 | R16: 1.1 | S16: 1.8 | T16: 1.5 | U16: 1.7 | V16: 1.5 | W16: 1.3 | X16: 18.3 | Y16: 19.8 | Z16: 12.4 | AA16: 15.5 | AB16: 13.8 | AC16: =(SUM(D16:H16)+SUM(I16:M16))/2+SUM(N16:R16)+SUM(S16:W16) -> 38.35 | AD16: =SUM(X16:AB16)/100*50 -> 39.9 | AE16: =AC16+AD16 -> 78.25
A17: 11 | B17: S011 | C17: Rahul Verma | D17: 5.8 | E17: 4.5 | F17: 5.6 | G17: 5.6 | H17: 3.8 | I17: 5.4 | J17: 4.2 | K17: 5.8 | L17: 4.5 | M17: 5.5 | N17: 1.3 | O17: 1.3 | P17: 1.6 | Q17: 2 | R17: 1.5 | S17: 1.1 | T17: 1.5 | U17: 1.3 | V17: 1.6 | W17: 1.5 | X17: 14.6 | Y17: 13.2 | Z17: 11.9 | AA17: 17 | AB17: 15.7 | AC17: =(SUM(D17:H17)+SUM(I17:M17))/2+SUM(N17:R17)+SUM(S17:W17) -> 40.05 | AD17: =SUM(X17:AB17)/100*50 -> 36.2 | AE17: =AC17+AD17 -> 76.25
A18: 12 | B18: S012 | C18: Meera Joshi | D18: 3.7 | E18: 5.3 | F18: 3.1 | G18: 5.2 | H18: 5.1 | I18: 5.4 | J18: 4.2 | K18: 5 | L18: 5.5 | M18: 5.9 | N18: 1.5 | O18: 1 | P18: 1.5 | Q18: 1.6 | R18: 1.9 | S18: 1.9 | T18: 1.4 | U18: 1.5 | V18: 1.5 | W18: 1.7 | X18: 14.1 | Y18: 16.5 | Z18: 11.5 | AA18: 14.7 | AB18: 19.7 | AC18: =(SUM(D18:H18)+SUM(I18:M18))/2+SUM(N18:R18)+SUM(S18:W18) -> 39.7 | AD18: =SUM(X18:AB18)/100*50 -> 38.25 | AE18: =AC18+AD18 -> 77.95
... A26: 20 | B26: S020 | C26: Deepa Nambiar | D26: 3.7 | E26: 3.4 | F26: 4.7 | G26: 3.2 | H26: 5.3 | I26: 3.6 | J26: 3.6 | K26: 5.6 | L26: 4 | M26: 3.4 | N26: 1.9 | O26: 1 | P26: 1.9 | Q26: 1.1 | R26: 1.1 | S26: 1.3 | T26: 1.2 | U26: 1.7 | V26: 1 | W26: 1 | X26: 17.9 | Y26: 12.4 | Z26: 13.2 | AA26: 11.7 | AB26: 10.5 | AC26: =(SUM(D26:H26)+SUM(I26:M26))/2+SUM(N26:R26)+SUM(S26:W26) -> 33.45 | AD26: =SUM(X26:AB26)/100*50 -> 32.85 | AE26: =AC26+AD26 -> 66.3
A28: CLASS AVERAGE | D28: =AVERAGE(D7:D26) -> 4.785 | E28: =AVERAGE(E7:E26) -> 4.38 | F28: =AVERAGE(F7:F26) -> 4.54 | G28: =AVERAGE(G7:G26) -> 4.62 | H28: =AVERAGE(H7:H26) -> 4.75 | I28: =AVERAGE(I7:I26) -> 4.555 | J28: =AVERAGE(J7:J26) -> 4.725 | K28: =AVERAGE(K7:K26) -> 4.63 | ... AE28: =AVERAGE(AE7:AE26) -> 75.975
A30: CO ATTAINMENT % | D30: =IFERROR((D28/D6+I28/I6+N28/N6+S28/S6+X28/X6)/5,0) -> 0.78063333 | E30: =IFERROR((E28/E6+J28/J6+O28/O6+T28/T6+Y28/Y6)/5,0) -> 0.7491 | F30: =IFERROR((F28/F6+K28/K6+P28/P6+U28/U6+Z28/Z6)/5,0) -> 0.76641667 | G30: =IFERROR((G28/G6+L28/L6+Q28/Q6+V28/V6+AA28/AA6)/5,0) -> 0.74178333 | H30: =IFERROR((H28/H6+M28/M6+R28/R6+W28/W6+AB28/AB6)/5,0) -> 0.76125
A31: LEVEL (3/2/1) | D31: =IF(D30>=0.6,3,IF(D30>=0.4,2,1)) -> 3 | E31: =IF(E30>=0.6,3,IF(E30>=0.4,2,1)) -> 3 | F31: =IF(F30>=0.6,3,IF(F30>=0.4,2,1)) -> 3 | G31: =IF(G30>=0.6,3,IF(G30>=0.4,2,1)) -> 3 | H31: =IF(H30>=0.6,3,IF(H30>=0.4,2,1)) -> 3

Sheet CS303
A1: CO ATTAINMENT — Computer Networks (CS303)
A2: CIE=(Mid-1+Mid-2)/2+Assignment+Quiz → 50M | SEE=100M→50M | Total=100M
A4: Student Info | D4: MID-1 (30M) | I4: MID-2 (30M) | N4: ASSIGNMENT (10M) | S4: QUIZ (10M) | X4: SEE (100M) | AC4: CIE (50M) | AD4: SEE (50M) | AE4: TOTAL (100M)
A5: S.No | B5: Reg No | C5: Name | D5: CO1 | E5: CO2 | F5: CO3 | G5: CO4 | H5: CO5 | I5: CO1 | J5: CO2 | K5: CO3 | L5: CO4 | M5: CO5 | N5: CO1 | O5: CO2 | P5: CO3 | Q5: CO4 | R5: CO5 | S5: CO1 | T5: CO2 | U5: CO3 | V5: CO4 | W5: CO5 | X5: CO1 | Y5: CO2 | Z5: CO3 | AA5: CO4 | AB5: CO5 | AC5: Formula | AD5: Formula | AE5: Formula
A6: MAX MARKS (Edit) | D6: 6 | E6: 6 | F6: 6 | G6: 6 | H6: 6 | I6: 6 | J6: 6 | K6: 6 | L6: 6 | M6: 6 | N6: 2 | O6: 2 | P6: 2 | Q6: 2 | R6: 2 | S6: 2 | T6: 2 | U6: 2 | V6: 2 | W6: 2 | X6: 20 | Y6: 20 | Z6: 20 | AA6: 20 | AB6: 20 | AC6: 50 | AD6: 50 | AE6: 100
A7: 1 | B7: S001 | C7: Aarav Sharma | D7: 5.2 | E7: 4.6 | F7: 5.2 | G7: 4.4 | H7: 5.3 | I7: 4.5 | J7: 3.3 | K7: 4.5 | L7: 5.8 | M7: 3.1 | N7: 1.8 | O7: 1.9 | P7: 1.5 | Q7: 1.5 | R7: 2 | S7: 1.1 | T7: 1.5 | U7: 1.4 | V7: 1.7 | W7: 1.5 | X7: 19.1 | Y7: 10.7 | Z7: 10.8 | AA7: 16.1 | AB7: 10.7 | AC7: =(SUM(D7:H7)+SUM(I7:M7))/2+SUM(N7:R7)+SUM(S7:W7) -> 38.85 | AD7: =SUM(X7:AB7)/100*50 -> 33.7 | AE7: =AC7+AD7 -> 72.55
A8: 2 | B8: S002 | C8: Priya Patel | D8: 3.8 | E8: 4.9 | F8: 4.6 | G8: 4 | H8: 6 | I8: 4.6 | J8: 4.4 | K8: 4.8 | L8: 3.3 | M8: 5.1 | N8: 1.9 | O8: 1.7 | P8: 1.8 | Q8: 1.7 | R8: 1.2 | S8: 1.5 | T8: 1.2 | U8: 1.3 | V8: 1.5 | W8: 1.4 | X8: 10.9 | Y8: 14.3 | Z8: 16.7 | AA8: 13.7 | AB8: 11.5 | AC8: =(SUM(D8:H8)+SUM(I8:M8))/2+SUM(N8:R8)+SUM(S8:W8) -> 37.95 | AD8: =SUM(X8:AB8)/100*50 -> 33.55 | AE8: =AC8+AD8 -> 71.5
A9: 3 | B9: S003 | C9: Rohan Mehta | D9: 5.8 | E9: 3.2 | F9: 5.5 | G9: 3.3 | H9: 3.3 | I9: 5.2 | J9: 5.4 | K9: 4.7 | L9: 4.8 | M9: 4.7 | N9: 1.3 | O9: 1.1 | P9: 1.4 | Q9: 1.7 | R9: 1.8 | S9: 1.9 | T9: 1.7 | U9: 2 | V9: 1.6 | W9: 1.4 | X9: 15.8 | Y9: 12.1 | Z9: 16.6 | AA9: 12.2 | AB9: 11.1 | AC9: =(SUM(D9:H9)+SUM(I9:M9))/2+SUM(N9:R9)+SUM(S9:W9) -> 38.85 | AD9: =SUM(X9:AB9)/100*50 -> 33.9 | AE9: =AC9+AD9 -> 72.75
A10: 4 | B10: S004 | C10: Sneha Reddy | D10: 5.5 | E10: 4.1 | F10: 5.3 | G10: 4.7 | H10: 5.4 | I10: 5.5 | J10: 5.9 | K10: 5.5 | L10: 4.8 | M10: 4.9 | N10: 1 | O10: 1.9 | P10: 1.8 | Q10: 1.3 | R10: 1.2 | S10: 1.7 | T10: 1.3 | U10: 1.3 | V10: 1 | W10: 1.9 | X10: 15.7 | Y10: 14 | Z10: 11.4 | AA10: 16.3 | AB10: 10.3 | AC10: =(SUM(D10:H10)+SUM(I10:M10))/2+SUM(N10:R10)+SUM(S10:W10) -> 40.2 | AD10: =SUM(X10:AB10)/100*50 -> 33.85 | AE10: =AC10+AD10 -> 74.05
A11: 5 | B11: S005 | C11: Vikram Singh | D11: 5.2 | E11: 3.6 | F11: 4.3 | G11: 4 | H11: 4.1 | I11: 5.2 | J11: 5.3 | K11: 4.7 | L11: 3.3 | M11: 3.2 | N11: 1.2 | O11: 1.6 | P11: 1.7 | Q11: 1.3 | R11: 1.7 | S11: 1.5 | T11: 1.4 | U11: 1.3 | V11: 1.8 | W11: 1.1 | X11: 14.3 | Y11: 12.8 | Z11: 16.8 | AA11: 14.9 | AB11: 16.7 | AC11: =(SUM(D11:H11)+SUM(I11:M11))/2+SUM(N11:R11)+SUM(S11:W11) -> 36.05 | AD11: =SUM(X11:AB11)/100*50 -> 37.75 | AE11: =AC11+AD11 -> 73.8
A12: 6 | B12: S006 | C12: Anjali Nair | D12: 3.1 | E12: 4.2 | F12: 4.8 | G12: 3 | H12: 3.9 | I12: 3.6 | J12: 3.4 | K12: 3.8 | L12: 4 | M12: 3 | N12: 1.7 | O12: 1.2 | P12: 1.4 | Q12: 1.7 | R12: 1.5 | S12: 1.8 | T12: 1.8 | U12: 1.1 | V12: 1.9 | W12: 1 | X12: 10.2 | Y12: 19.2 | Z12: 18.6 | AA12: 15.8 | AB12: 15.7 | AC12: =(SUM(D12:H12)+SUM(I12:M12))/2+SUM(N12:R12)+SUM(S12:W12) -> 33.5 | AD12: =SUM(X12:AB12)/100*50 -> 39.75 | AE12: =AC12+AD12 -> 73.25
A13: 7 | B13: S007 | C13: Kiran Kumar | D13: 5.1 | E13: 4.3 | F13: 3.3 | G13: 3.1 | H13: 4 | I13: 5.4 | J13: 4.9 | K13: 5.5 | L13: 5.8 | M13: 3.3 | N13: 1.8 | O13: 1.2 | P13: 1.6 | Q13: 1.5 | R13: 1.4 | S13: 1.3 | T13: 1.3 | U13: 1.3 | V13: 1.2 | W13: 1.5 | X13: 11.1 | Y13: 15.1 | Z13: 19.1 | AA13: 13.5 | AB13: 17.3 | AC13: =(SUM(D13:H13)+SUM(I13:M13))/2+SUM(N13:R13)+SUM(S13:W13) -> 36.45 | AD13: =SUM(X13:AB13)/100*50 -> 38.05 | AE13: =AC13+AD13 -> 74.5
A14: 8 | B14: S008 | C14: Divya Rao | D14: 5.5 | E14: 5.4 | F14: 3.7 | G14: 3.4 | H14: 3.6 | I14: 4.8 | J14: 5.3 | K14: 5 | L14: 3.5 | M14: 5.3 | N14: 1.5 | O14: 1.8 | P14: 1.8 | Q14: 1.4 | R14: 1.9 | S14: 1.6 | T14: 1.6 | U14: 1.6 | V14: 1.9 | W14: 1.6 | X14: 11.5 | Y14: 10.7 | Z14: 14.4 | AA14: 13 | AB14: 12.7 | AC14: =(SUM(D14:H14)+SUM(I14:M14))/2+SUM(N14:R14)+SUM(S14:W14) -> 39.45 | AD14: =SUM(X14:AB14)/100*50 -> 31.15 | AE14: =AC14+AD14 -> 70.6
A15: 9 | B15: S009 | C15: Arjun Gupta | D15: 3.2 | E15: 4.5 | F15: 3.9 | G15: 4.4 | H15: 3.2 | I15: 5.5 | J15: 3.2 | K15: 5.6 | L15: 5.6 | M15: 4.8 | N15: 1.5 | O15: 1.5 | P15: 1.6 | Q15: 1.8 | R15: 1.9 | S15: 1.4 | T15: 1.8 | U15: 1.7 | V15: 1.3 | W15: 1.5 | X15: 11.5 | Y15: 10.6 | Z15: 11 | AA15: 19 | AB15: 13.4 | AC15: =(SUM(D15:H15)+SUM(I15:M15))/2+SUM(N15:R15)+SUM(S15:W15) -> 37.95 | AD15: =SUM(X15:AB15)/100*50 -> 32.75 | AE15: =AC15+AD15 -> 70.7
A16: 10 | B16: S010 | C16: Pooja Iyer | D16: 5.1 | E16: 4.5 | F16: 3.5 | G16: 3.7 | H16: 4.3 | I16: 4.3 | J16: 4.6 | K16: 3.5 | L16: 4.1 | M16: 3.8 | N16: 1.4 | O16: 1.3 | P16: 1.6 | Q16: 1.8 | R16: 1.6 | S16: 1.1 | T16: 1.1 | U16: 1.7 | V16: 1.3 | W16: 1.7 | X16: 16.6 | Y16: 19.1 | Z16: 18.7 | AA16: 13.3 | AB16: 15.8 | AC16: =(SUM(D16:H16)+SUM(I16:M16))/2+SUM(N16:R16)+SUM(S16:W16) -> 35.3 | AD16: =SUM(X16:AB16)/100*50 -> 41.75 | AE16: =AC16+AD16 -> 77.05
A17: 11 | B17: S011 | C17: Rahul Verma | D17: 3.4 | E17: 4 | F17: 5.9 | G17: 5.1 | H17: 4.2 | I17: 4.8 | J17: 5.8 | K17: 3.9 | L17: 4.1 | M17: 5.4 | N17: 1.8 | O17: 1.7 | P17: 1.8 | Q17: 1.7 | R17: 1.7 | S17: 1.5 | T17: 1.6 | U17: 1.4 | V17: 1.4 | W17: 1.4 | X17: 11.8 | Y17: 12.1 | Z17: 19.5 | AA17: 14.9 | AB17: 12.3 | AC17: =(SUM(D17:H17)+SUM(I17:M17))/2+SUM(N17:R17)+SUM(S17:W17) -> 39.3 | AD17: =SUM(X17:AB17)/100*50 -> 35.3 | AE17: =AC17+AD17 -> 74.6
A18: 12 | B18: S012 | C18: Meera Joshi | D18: 3.4 | E18: 3.2 | F18: 5.5 | G18: 3.3 | H18: 5.3 | I18: 5.5 | J18: 5.7 | K18: 3.1 | L18: 4 | M18: 5.3 | N18: 1.1 | O18: 1.4 | P18: 1.2 | Q18: 1.8 | R18: 1.8 | S18: 1.8 | T18: 1.2 | U18: 1.4 | V18: 1.4 | W18: 1.7 | X18: 12.4 | Y18: 14.4 | Z18: 12.8 | AA18: 17.5 | AB18: 14.5 | AC18: =(SUM(D18:H18)+SUM(I18:M18))/2+SUM(N18:R18)+SUM(S18:W18) -> 36.95 | AD18: =SUM(X18:AB18)/100*50 -> 35.8 | AE18: =AC18+AD18 -> 72.75
... A26: 20 | B26: S020 | C26: Deepa Nambiar | D26: 5.3 | E26: 4.7 | F26: 4.6 | G26: 4.2 | H26: 4.9 | I26: 3.7 | J26: 3.3 | K26: 5.2 | L26: 4.5 | M26: 4.2 | N26: 1.6 | O26: 1.3 | P26: 1.3 | Q26: 1.4 | R26: 2 | S26: 1.3 | T26: 1.9 | U26: 1.5 | V26: 1.1 | W26: 1.9 | X26: 14.5 | Y26: 19 | Z26: 14.5 | AA26: 10.9 | AB26: 16.8 | AC26: =(SUM(D26:H26)+SUM(I26:M26))/2+SUM(N26:R26)+SUM(S26:W26) -> 37.6 | AD26: =SUM(X26:AB26)/100*50 -> 37.85 | AE26: =AC26+AD26 -> 75.45
A28: CLASS AVERAGE | D28: =AVERAGE(D7:D26) -> 4.485 | E28: =AVERAGE(E7:E26) -> 4.395 | F28: =AVERAGE(F7:F26) -> 4.55 | G28: =AVERAGE(G7:G26) -> 4.18 | H28: =AVERAGE(H7:H26) -> 4.625 | I28: =AVERAGE(I7:I26) -> 4.835 | J28: =AVERAGE(J7:J26) -> 4.565 | K28: =AVERAGE(K7:K26) -> 4.755 | ... AE28: =AVERAGE(AE7:AE26) -> 74.0475
A30: CO ATTAINMENT % | D30: =IFERROR((D28/D6+I28/I6+N28/N6+S28/S6+X28/X6)/5,0) -> 0.74636667 | E30: =IFERROR((E28/E6+J28/J6+O28/O6+T28/T6+Y28/Y6)/5,0) -> 0.74206667 | F30: =IFERROR((F28/F6+K28/K6+P28/P6+U28/U6+Z28/Z6)/5,0) -> 0.77091667 | G30: =IFERROR((G28/G6+L28/L6+Q28/Q6+V28/V6+AA28/AA6)/5,0) -> 0.7431 | H30: =IFERROR((H28/H6+M28/M6+R28/R6+W28/W6+AB28/AB6)/5,0) -> 0.74365
A31: LEVEL (3/2/1) | D31: =IF(D30>=0.6,3,IF(D30>=0.4,2,1)) -> 3 | E31: =IF(E30>=0.6,3,IF(E30>=0.4,2,1)) -> 3 | F31: =IF(F30>=0.6,3,IF(F30>=0.4,2,1)) -> 3 | G31: =IF(G30>=0.6,3,IF(G30>=0.4,2,1)) -> 3 | H31: =IF(H30>=0.6,3,IF(H30>=0.4,2,1)) -> 3

Sheet CS304
A1: CO ATTAINMENT — Operating Systems (CS304)
A2: CIE=(Mid-1+Mid-2)/2+Assignment+Quiz → 50M | SEE=100M→50M | Total=100M
A4: Student Info | D4: MID-1 (30M) | I4: MID-2 (30M) | N4: ASSIGNMENT (10M) | S4: QUIZ (10M) | X4: SEE (100M) | AC4: CIE (50M) | AD4: SEE (50M) | AE4: TOTAL (100M)
A5: S.No | B5: Reg No | C5: Name | D5: CO1 | E5: CO2 | F5: CO3 | G5: CO4 | H5: CO5 | I5: CO1 | J5: CO2 | K5: CO3 | L5: CO4 | M5: CO5 | N5: CO1 | O5: CO2 | P5: CO3 | Q5: CO4 | R5: CO5 | S5: CO1 | T5: CO2 | U5: CO3 | V5: CO4 | W5: CO5 | X5: CO1 | Y5: CO2 | Z5: CO3 | AA5: CO4 | AB5: CO5 | AC5: Formula | AD5: Formula | AE5: Formula
A6: MAX MARKS (Edit) | D6: 6 | E6: 6 | F6: 6 | G6: 6 | H6: 6 | I6: 6 | J6: 6 | K6: 6 | L6: 6 | M6: 6 | N6: 2 | O6: 2 | P6: 2 | Q6: 2 | R6: 2 | S6: 2 | T6: 2 | U6: 2 | V6: 2 | W6: 2 | X6: 20 | Y6: 20 | Z6: 20 | AA6: 20 | AB6: 20 | AC6: 50 | AD6: 50 | AE6: 100
A7: 1 | B7: S001 | C7: Aarav Sharma | D7: 5.5 | E7: 4 | F7: 4 | G7: 3.2 | H7: 4.6 | I7: 5.7 | J7: 5.6 | K7: 5.1 | L7: 5.8 | M7: 4.9 | N7: 1.8 | O7: 1.5 | P7: 1.1 | Q7: 1.2 | R7: 1.1 | S7: 1.8 | T7: 1 | U7: 1.6 | V7: 1.4 | W7: 1.8 | X7: 15.5 | Y7: 16.1 | Z7: 10.9 | AA7: 13.1 | AB7: 20 | AC7: =(SUM(D7:H7)+SUM(I7:M7))/2+SUM(N7:R7)+SUM(S7:W7) -> 38.5 | AD7: =SUM(X7:AB7)/100*50 -> 37.8 | AE7: =AC7+AD7 -> 76.3
A8: 2 | B8: S002 | C8: Priya Patel | D8: 5.2 | E8: 4.6 | F8: 5.3 | G8: 5.5 | H8: 3.2 | I8: 5.9 | J8: 4.9 | K8: 4.3 | L8: 5 | M8: 4 | N8: 1.9 | O8: 1.8 | P8: 1.6 | Q8: 1.2 | R8: 2 | S8: 1.4 | T8: 1.9 | U8: 1.1 | V8: 1.1 | W8: 1.2 | X8: 11.6 | Y8: 13.2 | Z8: 17.1 | AA8: 13.5 | AB8: 19.4 | AC8: =(SUM(D8:H8)+SUM(I8:M8))/2+SUM(N8:R8)+SUM(S8:W8) -> 39.15 | AD8: =SUM(X8:AB8)/100*50 -> 37.4 | AE8: =AC8+AD8 -> 76.55
A9: 3 | B9: S003 | C9: Rohan Mehta | D9: 5.7 | E9: 5.5 | F9: 3.8 | G9: 4.9 | H9: 4.7 | I9: 3.4 | J9: 3.9 | K9: 4.6 | L9: 4.5 | M9: 3.5 | N9: 1.9 | O9: 1.2 | P9: 1.7 | Q9: 1.7 | R9: 1.6 | S9: 1.8 | T9: 1.6 | U9: 1.8 | V9: 1 | W9: 1 | X9: 16.4 | Y9: 15.8 | Z9: 16.5 | AA9: 17.7 | AB9: 14.2 | AC9: =(SUM(D9:H9)+SUM(I9:M9))/2+SUM(N9:R9)+SUM(S9:W9) -> 37.55 | AD9: =SUM(X9:AB9)/100*50 -> 40.3 | AE9: =AC9+AD9 -> 77.85
A10: 4 | B10: S004 | C10: Sneha Reddy | D10: 4.9 | E10: 4.5 | F10: 4.9 | G10: 3.9 | H10: 5.9 | I10: 4.4 | J10: 5.4 | K10: 5.1 | L10: 3.9 | M10: 3.2 | N10: 1.1 | O10: 1.4 | P10: 1.5 | Q10: 1.2 | R10: 1.6 | S10: 1.3 | T10: 1.7 | U10: 1.7 | V10: 1.9 | W10: 2 | X10: 11.3 | Y10: 13.7 | Z10: 15.6 | AA10: 13.2 | AB10: 14.7 | AC10: =(SUM(D10:H10)+SUM(I10:M10))/2+SUM(N10:R10)+SUM(S10:W10) -> 38.45 | AD10: =SUM(X10:AB10)/100*50 -> 34.25 | AE10: =AC10+AD10 -> 72.7
A11: 5 | B11: S005 | C11: Vikram Singh | D11: 3.8 | E11: 3.7 | F11: 3.3 | G11: 3.9 | H11: 4.2 | I11: 4.8 | J11: 3.7 | K11: 5.6 | L11: 3.5 | M11: 4 | N11: 1.6 | O11: 1.3 | P11: 1.8 | Q11: 1.5 | R11: 1.5 | S11: 1.5 | T11: 1.3 | U11: 1 | V11: 1.9 | W11: 1.5 | X11: 19.7 | Y11: 12.2 | Z11: 13.5 | AA11: 10.5 | AB11: 14.9 | AC11: =(SUM(D11:H11)+SUM(I11:M11))/2+SUM(N11:R11)+SUM(S11:W11) -> 35.15 | AD11: =SUM(X11:AB11)/100*50 -> 35.4 | AE11: =AC11+AD11 -> 70.55
A12: 6 | B12: S006 | C12: Anjali Nair | D12: 5.6 | E12: 5 | F12: 4.4 | G12: 4.6 | H12: 5.5 | I12: 4.3 | J12: 5.6 | K12: 5.2 | L12: 5.3 | M12: 4.1 | N12: 1.4 | O12: 1.6 | P12: 1.2 | Q12: 1.6 | R12: 1.1 | S12: 1.5 | T12: 1.8 | U12: 1.3 | V12: 2 | W12: 1.7 | X12: 11.2 | Y12: 19.8 | Z12: 13.9 | AA12: 17.9 | AB12: 13.4 | AC12: =(SUM(D12:H12)+SUM(I12:M12))/2+SUM(N12:R12)+SUM(S12:W12) -> 40 | AD12: =SUM(X12:AB12)/100*50 -> 38.1 | AE12: =AC12+AD12 -> 78.1
A13: 7 | B13: S007 | C13: Kiran Kumar | D13: 5.8 | E13: 5.3 | F13: 3.6 | G13: 4.5 | H13: 4.5 | I13: 3.1 | J13: 3.4 | K13: 4 | L13: 4.4 | M13: 4.4 | N13: 1.6 | O13: 1.5 | P13: 1.3 | Q13: 1.6 | R13: 1.2 | S13: 2 | T13: 1.7 | U13: 1.3 | V13: 1.3 | W13: 1.8 | X13: 15.3 | Y13: 17.1 | Z13: 13 | AA13: 18.2 | AB13: 13.7 | AC13: =(SUM(D13:H13)+SUM(I13:M13))/2+SUM(N13:R13)+SUM(S13:W13) -> 36.8 | AD13: =SUM(X13:AB13)/100*50 -> 38.65 | AE13: =AC13+AD13 -> 75.45
A14: 8 | B14: S008 | C14: Divya Rao | D14: 5 | E14: 5.9 | F14: 4.8 | G14: 5.4 | H14: 5.2 | I14: 5.1 | J14: 3.1 | K14: 4.4 | L14: 5.9 | M14: 5.3 | N14: 1.8 | O14: 1.6 | P14: 1.7 | Q14: 1.6 | R14: 1.2 | S14: 1.6 | T14: 1.6 | U14: 1.8 | V14: 1.1 | W14: 1.7 | X14: 10.3 | Y14: 19.5 | Z14: 11.1 | AA14: 10.2 | AB14: 13.1 | AC14: =(SUM(D14:H14)+SUM(I14:M14))/2+SUM(N14:R14)+SUM(S14:W14) -> 40.75 | AD14: =SUM(X14:AB14)/100*50 -> 32.1 | AE14: =AC14+AD14 -> 72.85
A15: 9 | B15: S009 | C15: Arjun Gupta | D15: 3.5 | E15: 5.1 | F15: 4.2 | G15: 5.3 | H15: 5.8 | I15: 5.6 | J15: 5.2 | K15: 3.2 | L15: 3.4 | M15: 3.6 | N15: 1.3 | O15: 1.7 | P15: 1.5 | Q15: 1.3 | R15: 1.2 | S15: 1.9 | T15: 1.3 | U15: 1.4 | V15: 1.8 | W15: 1.7 | X15: 16.4 | Y15: 16.9 | Z15: 16.1 | AA15: 11.9 | AB15: 12.5 | AC15: =(SUM(D15:H15)+SUM(I15:M15))/2+SUM(N15:R15)+SUM(S15:W15) -> 37.55 | AD15: =SUM(X15:AB15)/100*50 -> 36.9 | AE15: =AC15+AD15 -> 74.45
A16: 10 | B16: S010 | C16: Pooja Iyer | D16: 4.7 | E16: 3.7 | F16: 5.9 | G16: 3.9 | H16: 3.9 | I16: 3.6 | J16: 5.1 | K16: 4 | L16: 4 | M16: 5.8 | N16: 1.8 | O16: 1.3 | P16: 1.1 | Q16: 1.7 | R16: 1.4 | S16: 2 | T16: 1.8 | U16: 2 | V16: 1.8 | W16: 1.3 | X16: 12.9 | Y16: 17.1 | Z16: 13.5 | AA16: 14.4 | AB16: 12.6 | AC16: =(SUM(D16:H16)+SUM(I16:M16))/2+SUM(N16:R16)+SUM(S16:W16) -> 38.5 | AD16: =SUM(X16:AB16)/100*50 -> 35.25 | AE16: =AC16+AD16 -> 73.75
A17: 11 | B17: S011 | C17: Rahul Verma | D17: 4.4 | E17: 3.6 | F17: 4.6 | G17: 5.8 | H17: 5.1 | I17: 3.4 | J17: 4.8 | K17: 4.8 | L17: 3.7 | M17: 5 | N17: 1.5 | O17: 1.6 | P17: 1.1 | Q17: 1.4 | R17: 1.7 | S17: 1.1 | T17: 1.8 | U17: 1 | V17: 1.6 | W17: 1.9 | X17: 14.1 | Y17: 19.4 | Z17: 18.8 | AA17: 14.8 | AB17: 12 | AC17: =(SUM(D17:H17)+SUM(I17:M17))/2+SUM(N17:R17)+SUM(S17:W17) -> 37.3 | AD17: =SUM(X17:AB17)/100*50 -> 39.55 | AE17: =AC17+AD17 -> 76.85
A18: 12 | B18: S012 | C18: Meera Joshi | D18: 5.9 | E18: 4 | F18: 4.9 | G18: 5.7 | H18: 3.3 | I18: 4.7 | J18: 4.6 | K18: 5.2 | L18: 5.8 | M18: 5.7 | N18: 1.2 | O18: 1.9 | P18: 1.2 | Q18: 1.9 | R18: 2 | S18: 1.4 | T18: 1.5 | U18: 1.9 | V18: 2 | W18: 1.9 | X18: 18.8 | Y18: 10.1 | Z18: 15.7 | AA18: 11.1 | AB18: 19.8 | AC18: =(SUM(D18:H18)+SUM(I18:M18))/2+SUM(N18:R18)+SUM(S18:W18) -> 41.8 | AD18: =SUM(X18:AB18)/100*50 -> 37.75 | AE18: =AC18+AD18 -> 79.55
... A26: 20 | B26: S020 | C26: Deepa Nambiar | D26: 4 | E26: 4.2 | F26: 3.4 | G26: 4.1 | H26: 5.3 | I26: 4.4 | J26: 5.5 | K26: 3.9 | L26: 5.1 | M26: 5.4 | N26: 1.9 | O26: 1.6 | P26: 2 | Q26: 1.6 | R26: 1.1 | S26: 1.2 | T26: 1.2 | U26: 1.6 | V26: 1.9 | W26: 1.8 | X26: 10.9 | Y26: 17.2 | Z26: 11.9 | AA26: 12.7 | AB26: 16.7 | AC26: =(SUM(D26:H26)+SUM(I26:M26))/2+SUM(N26:R26)+SUM(S26:W26) -> 38.55 | AD26: =SUM(X26:AB26)/100*50 -> 34.7 | AE26: =AC26+AD26 -> 73.25
A28: CLASS AVERAGE | D28: =AVERAGE(D7:D26) -> 4.5 | E28: =AVERAGE(E7:E26) -> 4.53 | F28: =AVERAGE(F7:F26) -> 4.5 | G28: =AVERAGE(G7:G26) -> 4.605 | H28: =AVERAGE(H7:H26) -> 4.675 | I28: =AVERAGE(I7:I26) -> 4.57 | J28: =AVERAGE(J7:J26) -> 4.825 | K28: =AVERAGE(K7:K26) -> 4.515 | ... AE28: =AVERAGE(AE7:AE26) -> 74.93
A30: CO ATTAINMENT % | D30: =IFERROR((D28/D6+I28/I6+N28/N6+S28/S6+X28/X6)/5,0) -> 0.75808333 | E30: =IFERROR((E28/E6+J28/J6+O28/O6+T28/T6+Y28/Y6)/5,0) -> 0.78293333 | F30: =IFERROR((F28/F6+K28/K6+P28/P6+U28/U6+Z28/Z6)/5,0) -> 0.73675 | G30: =IFERROR((G28/G6+L28/L6+Q28/Q6+V28/V6+AA28/AA6)/5,0) -> 0.74958333 | H30: =IFERROR((H28/H6+M28/M6+R28/R6+W28/W6+AB28/AB6)/5,0) -> 0.75218333
A31: LEVEL (3/2/1) | D31: =IF(D30>=0.6,3,IF(D30>=0.4,2,1)) -> 3 | E31: =IF(E30>=0.6,3,IF(E30>=0.4,2,1)) -> 3 | F31: =IF(F30>=0.6,3,IF(F30>=0.4,2,1)) -> 3 | G31: =IF(G30>=0.6,3,IF(G30>=0.4,2,1)) -> 3 | H31: =IF(H30>=0.6,3,IF(H30>=0.4,2,1)) -> 3

Sheet CS305
A1: CO ATTAINMENT — Machine Learning (CS305)
A2: CIE=(Mid-1+Mid-2)/2+Assignment+Quiz → 50M | SEE=100M→50M | Total=100M
A4: Student Info | D4: MID-1 (30M) | J4: MID-2 (30M) | P4: ASSIGNMENT (10M) | V4: QUIZ (10M) | AB4: SEE (100M) | AH4: CIE (50M) | AI4: SEE (50M) | AJ4: TOTAL (100M)
A5: S.No | B5: Reg No | C5: Name | D5: CO1 | E5: CO2 | F5: CO3 | G5: CO4 | H5: CO5 | I5: CO6 | J5: CO1 | K5: CO2 | L5: CO3 | M5: CO4 | N5: CO5 | O5: CO6 | P5: CO1 | Q5: CO2 | R5: CO3 | S5: CO4 | T5: CO5 | U5: CO6 | V5: CO1 | W5: CO2 | X5: CO3 | Y5: CO4 | Z5: CO5 | AA5: CO6 | AB5: CO1 | AC5: CO2 | AD5: CO3 | AE5: CO4 | AF5: CO5 | AG5: CO6 | AH5: Formula | AI5: Formula | AJ5: Formula
A6: MAX MARKS (Edit) | D6: 5 | E6: 5 | F6: 5 | G6: 5 | H6: 5 | I6: 5 | J6: 5 | K6: 5 | L6: 5 | M6: 5 | N6: 5 | O6: 5 | P6: 1.67 | Q6: 1.67 | R6: 1.67 | S6: 1.67 | T6: 1.67 | U6: 1.67 | V6: 1.67 | W6: 1.67 | X6: 1.67 | Y6: 1.67 | Z6: 1.67 | AA6: 1.67 | AB6: 16.67 | AC6: 16.67 | AD6: 16.67 | AE6: 16.67 | AF6: 16.67 | AG6: 16.67 | AH6: 50 | AI6: 50 | AJ6: 100
A7: 1 | B7: S001 | C7: Aarav Sharma | D7: 4 | E7: 4.7 | F7: 3 | G7: 4.4 | H7: 4.3 | I7: 3.9 | J7: 3.7 | K7: 4.7 | L7: 3.3 | M7: 4.9 | N7: 2.5 | O7: 4.8 | P7: 1.6 | Q7: 0.9 | R7: 1.7 | S7: 1.2 | T7: 1 | U7: 1.3 | V7: 1 | W7: 1.6 | X7: 1.3 | Y7: 1.5 | Z7: 1.2 | AA7: 1.3 | AB7: 11.3 | AC7: 10.5 | AD7: 12.6 | AE7: 12.5 | AF7: 9.2 | AG7: 16.5 | AH7: =(SUM(D7:I7)+SUM(J7:O7))/2+SUM(P7:U7)+SUM(V7:AA7) -> 39.7 | AI7: =SUM(AB7:AG7)/100*50 -> 36.3 | AJ7: =AH7+AI7 -> 76
A8: 2 | B8: S002 | C8: Priya Patel | D8: 3.7 | E8: 4.6 | F8: 4.8 | G8: 3.4 | H8: 3.5 | I8: 3.9 | J8: 3.1 | K8: 2.9 | L8: 3.2 | M8: 4.8 | N8: 3.9 | O8: 3.5 | P8: 1 | Q8: 1.1 | R8: 1.1 | S8: 1.5 | T8: 1.2 | U8: 1.4 | V8: 1.4 | W8: 1 | X8: 1.5 | Y8: 1.6 | Z8: 1.4 | AA8: 1.2 | AB8: 9.7 | AC8: 15 | AD8: 9.7 | AE8: 14.3 | AF8: 12.4 | AG8: 16 | AH8: =(SUM(D8:I8)+SUM(J8:O8))/2+SUM(P8:U8)+SUM(V8:AA8) -> 38.05 | AI8: =SUM(AB8:AG8)/100*50 -> 38.55 | AJ8: =AH8+AI8 -> 76.6
A9: 3 | B9: S003 | C9: Rohan Mehta | D9: 3.9 | E9: 4.1 | F9: 2.6 | G9: 2.6 | H9: 4.6 | I9: 4.9 | J9: 4.2 | K9: 4.4 | L9: 3.5 | M9: 4.6 | N9: 3.1 | O9: 4.3 | P9: 0.8 | Q9: 1.3 | R9: 1.1 | S9: 1.3 | T9: 1.4 | U9: 1.3 | V9: 1.2 | W9: 1.2 | X9: 0.8 | Y9: 1.3 | Z9: 0.8 | AA9: 1.3 | AB9: 10.6 | AC9: 16.5 | AD9: 8.5 | AE9: 15.1 | AF9: 14 | AG9: 15.1 | AH9: =(SUM(D9:I9)+SUM(J9:O9))/2+SUM(P9:U9)+SUM(V9:AA9) -> 37.2 | AI9: =SUM(AB9:AG9)/100*50 -> 39.9 | AJ9: =AH9+AI9 -> 77.1
A10: 4 | B10: S004 | C10: Sneha Reddy | D10: 4.8 | E10: 2.8 | F10: 2.7 | G10: 2.9 | H10: 3 | I10: 3.8 | J10: 4.5 | K10: 3.2 | L10: 3.5 | M10: 3.4 | N10: 3.5 | O10: 3.9 | P10: 1.7 | Q10: 1 | R10: 1.4 | S10: 1.5 | T10: 1.4 | U10: 1.5 | V10: 1.5 | W10: 0.9 | X10: 1.1 | Y10: 1.3 | Z10: 0.9 | AA10: 0.8 | AB10: 9.8 | AC10: 12.5 | AD10: 12 | AE10: 14.9 | AF10: 13 | AG10: 15.5 | AH10: =(SUM(D10:I10)+SUM(J10:O10))/2+SUM(P10:U10)+SUM(V10:AA10) -> 36 | AI10: =SUM(AB10:AG10)/100*50 -> 38.85 | AJ10: =AH10+AI10 -> 74.85
A11: 5 | B11: S005 | C11: Vikram Singh | D11: 2.7 | E11: 3.8 | F11: 2.6 | G11: 3 | H11: 4.7 | I11: 4.7 | J11: 3.7 | K11: 2.6 | L11: 2.7 | M11: 4.8 | N11: 4.7 | O11: 3.9 | P11: 0.9 | Q11: 1.6 | R11: 1.1 | S11: 1.6 | T11: 1.3 | U11: 1.5 | V11: 1.4 | W11: 1.2 | X11: 0.9 | Y11: 1 | Z11: 1 | AA11: 1.5 | AB11: 11.6 | AC11: 15.8 | AD11: 11.1 | AE11: 14.6 | AF11: 9.5 | AG11: 16.6 | AH11: =(SUM(D11:I11)+SUM(J11:O11))/2+SUM(P11:U11)+SUM(V11:AA11) -> 36.95 | AI11: =SUM(AB11:AG11)/100*50 -> 39.6 | AJ11: =AH11+AI11 -> 76.55
A12: 6 | B12: S006 | C12: Anjali Nair | D12: 4.3 | E12: 3.8 | F12: 4.9 | G12: 2.6 | H12: 3.6 | I12: 4.6 | J12: 3.4 | K12: 4.4 | L12: 4.9 | M12: 3.5 | N12: 4.4 | O12: 2.6 | P12: 1.1 | Q12: 1.7 | R12: 1.2 | S12: 1.1 | T12: 1.6 | U12: 1.2 | V12: 1.4 | W12: 1.4 | X12: 0.9 | Y12: 1.3 | Z12: 1.5 | AA12: 1.4 | AB12: 9 | AC12: 9.6 | AD12: 14.3 | AE12: 13.6 | AF12: 14.5 | AG12: 11 | AH12: =(SUM(D12:I12)+SUM(J12:O12))/2+SUM(P12:U12)+SUM(V12:AA12) -> 39.3 | AI12: =SUM(AB12:AG12)/100*50 -> 36 | AJ12: =AH12+AI12 -> 75.3
A13: 7 | B13: S007 | C13: Kiran Kumar | D13: 2.8 | E13: 2.5 | F13: 3.3 | G13: 3.4 | H13: 3.2 | I13: 2.8 | J13: 3 | K13: 3.6 | L13: 3.9 | M13: 3.5 | N13: 2.6 | O13: 3.4 | P13: 0.9 | Q13: 1.3 | R13: 1.1 | S13: 1.2 | T13: 1.1 | U13: 1.2 | V13: 0.9 | W13: 1.6 | X13: 1.6 | Y13: 1.6 | Z13: 1.3 | AA13: 1 | AB13: 11.5 | AC13: 9.5 | AD13: 10.8 | AE13: 12.4 | AF13: 8.9 | AG13: 12 | AH13: =(SUM(D13:I13)+SUM(J13:O13))/2+SUM(P13:U13)+SUM(V13:AA13) -> 33.8 | AI13: =SUM(AB13:AG13)/100*50 -> 32.55 | AJ13: =AH13+AI13 -> 66.35
A14: 8 | B14: S008 | C14: Divya Rao | D14: 3.6 | E14: 3.7 | F14: 2.7 | G14: 3.1 | H14: 3.1 | I14: 4.1 | J14: 4 | K14: 3 | L14: 2.8 | M14: 3.3 | N14: 4.9 | O14: 3.3 | P14: 1.4 | Q14: 1.5 | R14: 1.1 | S14: 1.1 | T14: 1.5 | U14: 1.5 | V14: 1.6 | W14: 0.9 | X14: 1.1 | Y14: 1.6 | Z14: 1 | AA14: 1.1 | AB14: 16.4 | AC14: 16.4 | AD14: 10.8 | AE14: 14.1 | AF14: 12.4 | AG14: 13.1 | AH14: =(SUM(D14:I14)+SUM(J14:O14))/2+SUM(P14:U14)+SUM(V14:AA14) -> 36.2 | AI14: =SUM(AB14:AG14)/100*50 -> 41.6 | AJ14: =AH14+AI14 -> 77.8
A15: 9 | B15: S009 | C15: Arjun Gupta | D15: 3.1 | E15: 3.4 | F15: 4.5 | G15: 3.5 | H15: 2.8 | I15: 3.9 | J15: 4 | K15: 3.9 | L15: 4.2 | M15: 3.9 | N15: 4.9 | O15: 3.7 | P15: 1.4 | Q15: 1.2 | R15: 1.1 | S15: 1.4 | T15: 1.5 | U15: 1.5 | V15: 1.2 | W15: 1.2 | X15: 1.4 | Y15: 1 | Z15: 1.4 | AA15: 1.4 | AB15: 14.9 | AC15: 9 | AD15: 16.6 | AE15: 12.3 | AF15: 11.7 | AG15: 12.6 | AH15: =(SUM(D15:I15)+SUM(J15:O15))/2+SUM(P15:U15)+SUM(V15:AA15) -> 38.6 | AI15: =SUM(AB15:AG15)/100*50 -> 38.55 | AJ15: =AH15+AI15 -> 77.15
A16: 10 | B16: S010 | C16: Pooja Iyer | D16: 4.8 | E16: 4.2 | F16: 3.9 | G16: 4.5 | H16: 3.4 | I16: 4.7 | J16: 3.8 | K16: 4.1 | L16: 2.7 | M16: 4.4 | N16: 4.1 | O16: 3.4 | P16: 1.4 | Q16: 0.9 | R16: 1.7 | S16: 1.4 | T16: 1.2 | U16: 1.5 | V16: 1.6 | W16: 1.2 | X16: 0.8 | Y16: 1 | Z16: 1.3 | AA16: 1.3 | AB16: 13.2 | AC16: 13.1 | AD16: 12 | AE16: 11.6 | AF16: 14.8 | AG16: 13.2 | AH16: =(SUM(D16:I16)+SUM(J16:O16))/2+SUM(P16:U16)+SUM(V16:AA16) -> 39.3 | AI16: =SUM(AB16:AG16)/100*50 -> 38.95 | AJ16: =AH16+AI16 -> 78.25
A17: 11 | B17: S011 | C17: Rahul Verma | D17: 3.8 | E17: 3.4 | F17: 2.6 | G17: 2.8 | H17: 3.5 | I17: 4.9 | J17: 2.8 | K17: 4.9 | L17: 2.9 | M17: 3.3 | N17: 3.6 | O17: 3 | P17: 1.2 | Q17: 1.2 | R17: 1.2 | S17: 1.4 | T17: 1.1 | U17: 1.1 | V17: 1.5 | W17: 0.9 | X17: 1.5 | Y17: 1.4 | Z17: 1.4 | AA17: 1 | AB17: 16.5 | AC17: 10.4 | AD17: 9.8 | AE17: 9.7 | AF17: 13 | AG17: 16.3 | AH17: =(SUM(D17:I17)+SUM(J17:O17))/2+SUM(P17:U17)+SUM(V17:AA17) -> 35.65 | AI17: =SUM(AB17:AG17)/100*50 -> 37.85 | AJ17: =AH17+AI17 -> 73.5
A18: 12 | B18: S012 | C18: Meera Joshi | D18: 3.1 | E18: 3.5 | F18: 3 | G18: 4.1 | H18: 3.6 | I18: 2.6 | J18: 4 | K18: 3 | L18: 4 | M18: 3.5 | N18: 4.3 | O18: 3 | P18: 1.5 | Q18: 1.5 | R18: 0.9 | S18: 0.9 | T18: 1.6 | U18: 1 | V18: 1.1 | W18: 1.2 | X18: 1.1 | Y18: 1.6 | Z18: 1.3 | AA18: 1.4 | AB18: 13.3 | AC18: 13.4 | AD18: 13.2 | AE18: 11.2 | AF18: 15.4 | AG18: 13.5 | AH18: =(SUM(D18:I18)+SUM(J18:O18))/2+SUM(P18:U18)+SUM(V18:AA18) -> 35.95 | AI18: =SUM(AB18:AG18)/100*50 -> 40 | AJ18: =AH18+AI18 -> 75.95
... A26: 20 | B26: S020 | C26: Deepa Nambiar | D26: 4.2 | E26: 4.6 | F26: 4.1 | G26: 3.3 | H26: 3.8 | I26: 3.8 | J26: 4.4 | K26: 3.2 | L26: 2.6 | M26: 4.7 | N26: 4.9 | O26: 3.7 | P26: 0.9 | Q26: 1.2 | R26: 1.3 | S26: 1.3 | T26: 1.6 | U26: 1.7 | V26: 1.6 | W26: 0.9 | X26: 1.6 | Y26: 1.3 | Z26: 1.1 | AA26: 1.4 | AB26: 14.7 | AC26: 16.3 | AD26: 14.8 | AE26: 8.5 | AF26: 8.9 | AG26: 10.5 | AH26: =(SUM(D26:I26)+SUM(J26:O26))/2+SUM(P26:U26)+SUM(V26:AA26) -> 39.55 | AI26: =SUM(AB26:AG26)/100*50 -> 36.85 | AJ26: =AH26+AI26 -> 76.4
A28: CLASS AVERAGE | D28: =AVERAGE(D7:D26) -> 3.82 | E28: =AVERAGE(E7:E26) -> 3.92 | F28: =AVERAGE(F7:F26) -> 3.62 | G28: =AVERAGE(G7:G26) -> 3.405 | H28: =AVERAGE(H7:H26) -> 3.79 | I28: =AVERAGE(I7:I26) -> 3.81 | J28: =AVERAGE(J7:J26) -> 3.705 | K28: =AVERAGE(K7:K26) -> 3.515 | ... AJ28: =AVERAGE(AJ7:AJ26) -> 75.205
A30: CO ATTAINMENT % | D30: =IFERROR((D28/D6+J28/J6+P28/P6+V28/V6+AB28/AB6)/5,0) -> 0.7512078 | E30: =IFERROR((E28/E6+K28/K6+Q28/Q6+W28/W6+AC28/AC6)/5,0) -> 0.73502864 | F30: =IFERROR((F28/F6+L28/L6+R28/R6+X28/X6+AD28/AD6)/5,0) -> 0.72288839 | G30: =IFERROR((G28/G6+M28/M6+S28/S6+Y28/Y6+AE28/AE6)/5,0) -> 0.76216046 | H30: =IFERROR((H28/H6+N28/N6+T28/T6+Z28/Z6+AF28/AF6)/5,0) -> 0.75633544 | I30: =IFERROR((I28/I6+O28/O6+U28/U6+AA28/AA6+AG28/AG6)/5,0) -> 0.75814119
A31: LEVEL (3/2/1) | D31: =IF(D30>=0.6,3,IF(D30>=0.4,2,1)) -> 3 | E31: =IF(E30>=0.6,3,IF(E30>=0.4,2,1)) -> 3 | F31: =IF(F30>=0.6,3,IF(F30>=0.4,2,1)) -> 3 | G31: =IF(G30>=0.6,3,IF(G30>=0.4,2,1)) -> 3 | H31: =IF(H30>=0.6,3,IF(H30>=0.4,2,1)) -> 3 | I31: =IF(I30>=0.6,3,IF(I30>=0.4,2,1)) -> 3

Sheet CO Comparison
A1: CO ATTAINMENT COMPARISON — ALL COURSES
A2: All values auto-linked from individual course sheets
A4: # | B4: Course | C4: Code | D4: CO1 | E4: CO2 | F4: CO3 | G4: CO4 | H4: CO5 | I4: CO6 | J4: CIE% | K4: SEE% | L4: Overall%
A5: 1 | B5: Data Structures & Algorithms | C5: CS301 | D5: =CS301!D30 -> 0.76653333 | E5: =CS301!E30 -> 0.73103333 | F5: =CS301!F30 -> 0.75395 | G5: =CS301!G30 -> 0.75016667 | H5: =CS301!H30 -> 0.74361667 | I5: — | J5: =AVERAGE(D5,E5,F5,G5,H5) -> 0.74906 | K5: =AVERAGE(D5,E5,F5,G5,H5) -> 0.74906 | L5: =AVERAGE(D5,E5,F5,G5,H5) -> 0.74906
A6: 2 | B6: Database Management Systems | C6: CS302 | D6: =CS302!D30 -> 0.78063333 | E6: =CS302!E30 -> 0.7491 | F6: =CS302!F30 -> 0.76641667 | G6: =CS302!G30 -> 0.74178333 | H6: =CS302!H30 -> 0.76125 | I6: — | J6: =AVERAGE(D6,E6,F6,G6,H6) -> 0.75983667 | K6: =AVERAGE(D6,E6,F6,G6,H6) -> 0.75983667 | L6: =AVERAGE(D6,E6,F6,G6,H6) -> 0.75983667
A7: 3 | B7: Computer Networks | C7: CS303 | D7: =CS303!D30 -> 0.74636667 | E7: =CS303!E30 -> 0.74206667 | F7: =CS303!F30 -> 0.77091667 | G7: =CS303!G30 -> 0.7431 | H7: =CS303!H30 -> 0.74365 | I7: — | J7: =AVERAGE(D7,E7,F7,G7,H7) -> 0.74922 | K7: =AVERAGE(D7,E7,F7,G7,H7) -> 0.74922 | L7: =AVERAGE(D7,E7,F7,G7,H7) -> 0.74922
A8: 4 | B8: Operating Systems | C8: CS304 | D8: =CS304!D30 -> 0.75808333 | E8: =CS304!E30 -> 0.78293333 | F8: =CS304!F30 -> 0.73675 | G8: =CS304!G30 -> 0.74958333 | H8: =CS304!H30 -> 0.75218333 | I8: — | J8: =AVERAGE(D8,E8,F8,G8,H8) -> 0.75590667 | K8: =AVERAGE(D8,E8,F8,G8,H8) -> 0.75590667 | L8: =AVERAGE(D8,E8,F8,G8,H8) -> 0.75590667
A9: 5 | B9: Machine Learning | C9: CS305 | D9: =CS305!D30 -> 0.7512078 | E9: =CS305!E30 -> 0.73502864 | F9: =CS305!F30 -> 0.72288839 | G9: =CS305!G30 -> 0.76216046 | H9: =CS305!H30 -> 0.75633544 | I9: =CS305!I30 -> 0.75814119 | J9: =AVERAGE(D9,E9,F9,G9,H9,I9) -> 0.74762699 | K9: =AVERAGE(D9,E9,F9,G9,H9,I9) -> 0.74762699 | L9: =AVERAGE(D9,E9,F9,G9,H9,I9) -> 0.74762699

Sheet CO-PO Mapping
A1: CO–PO / CO–PSO MAPPING MATRIX (3=High 2=Medium 1=Low 0=No Relation)
A2: Enter/edit correlation values (0-3) in yellow cells. PO Attainment sheet reads these automatically.
A3: Course | B3: Code | C3: CO | D3: CO Att% | E3: PROGRAMME OUTCOMES (PO1–PO12) | Q3: PROGRAMME SPECIFIC OUTCOMES
E4: PO1 | F4: PO2 | G4: PO3 | H4: PO4 | I4: PO5 | J4: PO6 | K4: PO7 | L4: PO8 | M4: PO9 | N4: PO10 | O4: PO11 | P4: PO12 | Q4: PSO1 | R4: PSO2 | S4: PSO3
A5: Data Structures & Algorithms | B5: CS301 | C5: CO1 | D5: =CS301!D30 -> 0.76653333 | E5: 3 | F5: 3 | G5: 2 | H5: 1 | I5: 0 | J5: 0 | K5: 0 | L5: 0 | M5: 1 | N5: 0 | O5: 0 | P5: 2 | Q5: 3 | R5: 2 | S5: 1
C6: CO2 | D6: =CS301!E30 -> 0.73103333 | E6: 3 | F6: 3 | G6: 3 | H6: 2 | I6: 1 | J6: 0 | K6: 0 | L6: 0 | M6: 1 | N6: 0 | O6: 0 | P6: 2 | Q6: 3 | R6: 2 | S6: 1
C7: CO3 | D7: =CS301!F30 -> 0.75395 | E7: 2 | F7: 3 | G7: 3 | H7: 2 | I7: 2 | J7: 0 | K7: 0 | L7: 0 | M7: 0 | N7: 1 | O7: 0 | P7: 1 | Q7: 3 | R7: 3 | S7: 2
C8: CO4 | D8: =CS301!G30 -> 0.75016667 | E8: 3 | F8: 3 | G8: 2 | H8: 3 | I8: 1 | J8: 0 | K8: 0 | L8: 0 | M8: 0 | N8: 0 | O8: 0 | P8: 2 | Q8: 3 | R8: 2 | S8: 1
C9: CO5 | D9: =CS301!H30 -> 0.74361667 | E9: 2 | F9: 2 | G9: 3 | H9: 2 | I9: 3 | J9: 0 | K9: 0 | L9: 0 | M9: 1 | N9: 0 | O9: 0 | P9: 2 | Q9: 2 | R9: 3 | S9: 2
A10: Database Management Systems | B10: CS302 | C10: CO1 | D10: =CS302!D30 -> 0.78063333 | E10: 3 | F10: 2 | G10: 2 | H10: 1 | I10: 2 | J10: 0 | K10: 0 | L10: 0 | M10: 0 | N10: 1 | O10: 0 | P10: 1 | Q10: 3 | R10: 2 | S10: 2
C11: CO2 | D11: =CS302!E30 -> 0.7491 | E11: 3 | F11: 3 | G11: 2 | H11: 2 | I11: 2 | J11: 0 | K11: 0 | L11: 0 | M11: 1 | N11: 0 | O11: 0 | P11: 1 | Q11: 3 | R11: 2 | S11: 1
C12: CO3 | D12: =CS302!F30 -> 0.76641667 | E12: 2 | F12: 3 | G12: 3 | H12: 2 | I12: 2 | J12: 0 | K12: 0 | L12: 0 | M12: 0 | N12: 1 | O12: 0 | P12: 2 | Q12: 2 | R12: 3 | S12: 2
C13: CO4 | D13: =CS302!G30 -> 0.74178333 | E13: 2 | F13: 2 | G13: 2 | H13: 3 | I13: 1 | J13: 0 | K13: 0 | L13: 0 | M13: 1 | N13: 0 | O13: 1 | P13: 1 | Q13: 3 | R13: 2 | S13: 1
C14: CO5 | D14: =CS302!H30 -> 0.76125 | E14: 3 | F14: 3 | G14: 2 | H14: 2 | I14: 3 | J14: 0 | K14: 0 | L14: 0 | M14: 0 | N14: 0 | O14: 0 | P14: 2 | Q14: 2 | R14: 3 | S14: 2
A15: Computer Networks | B15: CS303 | C15: CO1 | D15: =CS303!D30 -> 0.74636667 | E15: 3 | F15: 2 | G15: 1 | H15: 1 | I15: 3 | J15: 1 | K15: 0 | L15: 0 | M15: 0 | N15: 1 | O15: 0 | P15: 2 | Q15: 2 | R15: 3 | S15: 2
C16: CO2 | D16: =CS303!E30 -> 0.74206667 | E16: 3 | F16: 3 | G16: 2 | H16: 2 | I16: 3 | J16: 1 | K16: 0 | L16: 0 | M16: 1 | N16: 0 | O16: 0 | P16: 2 | Q16: 3 | R16: 3 | S16: 2
C17: CO3 | D17: =CS303!F30 -> 0.77091667 | E17: 2 | F17: 3 | G17: 3 | H17: 2 | I17: 2 | J17: 1 | K17: 1 | L17: 0 | M17: 0 | N17: 1 | O17: 0 | P17: 1 | Q17: 2 | R17: 2 | S17: 2
C18: CO4 | D18: =CS303!G30 -> 0.7431 | E18: 3 | F18: 2 | G18: 2 | H18: 3 | I18: 2 | J18: 0 | K18: 0 | L18: 0 | M18: 1 | N18: 0 | O18: 0 | P18: 2 | Q18: 3 | R18: 2 | S18: 1
C19: CO5 | D19: =CS303!H30 -> 0.74365 | E19: 2 | F19: 3 | G19: 2 | H19: 2 | I19: 3 | J19: 0 | K19: 0 | L19: 0 | M19: 0 | N19: 1 | O19: 0 | P19: 2 | Q19: 2 | R19: 3 | S19: 2
A20: Operating Systems | B20: CS304 | C20: CO1 | D20: =CS304!D30 -> 0.75808333 | E20: 3 | F20: 3 | G20: 1 | H20: 2 | I20: 2 | J20: 0 | K20: 0 | L20: 0 | M20: 0 | N20: 0 | O20: 0 | P20: 2 | Q20: 3 | R20: 2 | S20: 2
C21: CO2 | D21: =CS304!E30 -> 0.78293333 | E21: 3 | F21: 3 | G21: 2 | H21: 2 | I21: 2 | J21: 0 | K21: 0 | L21: 0 | M21: 1 | N21: 0 | O21: 0 | P21: 2 | Q21: 3 | R21: 3 | S21: 1
C22: CO3 | D22: =CS304!F30 -> 0.73675 | E22: 2 | F22: 3 | G22: 3 | H22: 3 | I22: 2 | J22: 0 | K22: 0 | L22: 0 | M22: 0 | N22: 1 | O22: 0 | P22: 1 | Q22: 2 | R22: 2 | S22: 2
C23: CO4 | D23: =CS304!G30 -> 0.74958333 | E23: 2 | F23: 2 | G23: 2 | H23: 3 | I23: 1 | J23: 0 | K23: 0 | L23: 0 | M23: 1 | N23: 0 | O23: 0 | P23: 2 | Q23: 2 | R23: 2 | S23: 2
C24: CO5 | D24: =CS304!H30 -> 0.75218333 | E24: 3 | F24: 3 | G24: 2 | H24: 2 | I24: 3 | J24: 0 | K24: 0 | L24: 0 | M24: 0 | N24: 0 | O24: 0 | P24: 2 | Q24: 3 | R24: 3 | S24: 2
A25: Machine Learning | B25: CS305 | C25: CO1 | D25: =CS305!D30 -> 0.7512078 | E25: 3 | F25: 3 | G25: 2 | H25: 2 | I25: 3 | J25: 0 | K25: 0 | L25: 0 | M25: 0 | N25: 1 | O25: 0 | P25: 3 | Q25: 3 | R25: 3 | S25: 2
C26: CO2 | D26: =CS305!E30 -> 0.73502864 | E26: 2 | F26: 3 | G26: 3 | H26: 2 | I26: 3 | J26: 0 | K26: 0 | L26: 0 | M26: 1 | N26: 0 | O26: 0 | P26: 2 | Q26: 2 | R26: 3 | S26: 2
C27: CO3 | D27: =CS305!F30 -> 0.72288839 | E27: 3 | F27: 3 | G27: 3 | H27: 3 | I27: 2 | J27: 0 | K27: 0 | L27: 0 | M27: 0 | N27: 0 | O27: 0 | P27: 3 | Q27: 3 | R27: 3 | S27: 3
C28: CO4 | D28: =CS305!G30 -> 0.76216046 | E28: 2 | F28: 3 | G28: 2 | H28: 3 | I28: 3 | J28: 0 | K28: 0 | L28: 0 | M28: 1 | N28: 0 | O28: 0 | P28: 2 | Q28: 2 | R28: 3 | S28: 2
C29: CO5 | D29: =CS305!H30 -> 0.75633544 | E29: 3 | F29: 2 | G29: 3 | H29: 2 | I29: 3 | J29: 0 | K29: 0 | L29: 0 | M29: 0 | N29: 1 | O29: 0 | P29: 3 | Q29: 3 | R29: 3 | S29: 3
C30: CO6 | D30: =CS305!I30 -> 0.75814119 | E30: 2 | F30: 3 | G30: 2 | H30: 2 | I30: 3 | J30: 1 | K30: 0 | L30: 0 | M30: 1 | N30: 0 | O30: 0 | P30: 3 | Q30: 2 | R30: 3 | S30: 3

Sheet PO Direct Attainment
A1: PO DIRECT ATTAINMENT — Course-wise (Formula: SUMPRODUCT(CO_Att × CO-PO Mapping) ÷ SUMIF(Mapping,>0))
A2: Values auto-calculated from CO-PO Mapping sheet. Credit-weighted average gives Programme-level PO attainment.
A4: # | B4: Course | C4: Code | D4: Credits | E4: PROGRAMME OUTCOMES | Q4: PSOs | T4: SUMMARY
E5: PO1 | F5: PO2 | G5: PO3 | H5: PO4 | I5: PO5 | J5: PO6 | K5: PO7 | L5: PO8 | M5: PO9 | N5: PO10 | O5: PO11 | P5: PO12 | Q5: PSO1 | R5: PSO2 | S5: PSO3 | T5: Avg PO% | U5: Avg PSO% | V5: Overall%
A6: 1 | B6: Data Structures & Algorithms | C6: CS301 | D6: 4 | E6: =IFERROR(SUMPRODUCT(('CO-PO Mapping'!D5:D9)*('CO-PO Mapping'!E5:E9))/SUMIF('CO-PO Mapping'!E5:E9,">0"),0) -> 0.74910256 | F6: =IFERROR(SUMPRODUCT(('CO-PO Mapping'!D5:D9)*('CO-PO Mapping'!F5:F9))/SUMIF('CO-PO Mapping'!F5:F9,">0"),0) -> 0.74944881 | G6: =IFERROR(SUMPRODUCT(('CO-PO Mapping'!D5:D9)*('CO-PO Mapping'!G5:G9))/SUMIF('CO-PO Mapping'!G5:G9,">0"),0) -> 0.74763077 | H6: =IFERROR(SUMPRODUCT(('CO-PO Mapping'!D5:D9)*('CO-PO Mapping'!H5:H9))/SUMIF('CO-PO Mapping'!H5:H9,">0"),0) -> 0.74742333 | I6: =IFERROR(SUMPRODUCT(('CO-PO Mapping'!D5:D9)*('CO-PO Mapping'!I5:I9))/SUMIF('CO-PO Mapping'!I5:I9,">0"),0) -> 0.74570714 | J6: =IFERROR(SUMPRODUCT(('CO-PO Mapping'!D5:D9)*('CO-PO Mapping'!J5:J9))/SUMIF('CO-PO Mapping'!J5:J9,">0"),0) -> 0 | K6: =IFERROR(SUMPRODUCT(('CO-PO Mapping'!D5:D9)*('CO-PO Mapping'!K5:K9))/SUMIF('CO-PO Mapping'!K5:K9,">0"),0) -> 0 | L6: =IFERROR(SUMPRODUCT(('CO-PO Mapping'!D5:D9)*('CO-PO Mapping'!L5:L9))/SUMIF('CO-PO Mapping'!L5:L9,">0"),0) -> 0 | M6: =IFERROR(SUMPRODUCT(('CO-PO Mapping'!D5:D9)*('CO-PO Mapping'!M5:M9))/SUMIF('CO-PO Mapping'!M5:M9,">0"),0) -> 0.74706111 | N6: =IFERROR(SUMPRODUCT(('CO-PO Mapping'!D5:D9)*('CO-PO Mapping'!N5:N9))/SUMIF('CO-PO Mapping'!N5:N9,">0"),0) -> 0.75395 | O6: =IFERROR(SUMPRODUCT(('CO-PO Mapping'!D5:D9)*('CO-PO Mapping'!O5:O9))/SUMIF('CO-PO Mapping'!O5:O9,">0"),0) -> 0 | P6: =IFERROR(SUMPRODUCT(('CO-PO Mapping'!D5:D9)*('CO-PO Mapping'!P5:P9))/SUMIF('CO-PO Mapping'!P5:P9,">0"),0) -> 0.74851667 | Q6: =IFERROR(SUMPRODUCT(('CO-PO Mapping'!D5:D9)*('CO-PO Mapping'!Q5:Q9))/SUMIF('CO-PO Mapping'!Q5:Q9,">0"),0) -> 0.74944881 | R6: =IFERROR(SUMPRODUCT(('CO-PO Mapping'!D5:D9)*('CO-PO Mapping'!R5:R9))/SUMIF('CO-PO Mapping'!R5:R9,">0"),0) -> 0.74901389 | S6: =IFERROR(SUMPRODUCT(('CO-PO Mapping'!D5:D9)*('CO-PO Mapping'!S5:S9))/SUMIF('CO-PO Mapping'!S5:S9,">0"),0) -> 0.74898095 | T6: =AVERAGE(E6:P6) -> 0.49907003 | U6: =AVERAGE(Q6:S6) -> 0.74914788 | V6: =(AVERAGE(E6:P6)+AVERAGE(Q6:S6))/2 -> 0.62410896
A7: 2 | B7: Database Management Systems | C7: CS302 | D7: 4 | E7: =IFERROR(SUMPRODUCT(('CO-PO Mapping'!D10:D14)*('CO-PO Mapping'!E10:E14))/SUMIF('CO-PO Mapping'!E10:E14,">0"),0) -> 0.76071923 | F7: =IFERROR(SUMPRODUCT(('CO-PO Mapping'!D10:D14)*('CO-PO Mapping'!F10:F14))/SUMIF('CO-PO Mapping'!F10:F14,">0"),0) -> 0.75962564 | G7: =IFERROR(SUMPRODUCT(('CO-PO Mapping'!D10:D14)*('CO-PO Mapping'!G10:G14))/SUMIF('CO-PO Mapping'!G10:G14,">0"),0) -> 0.76043485 | H7: =IFERROR(SUMPRODUCT(('CO-PO Mapping'!D10:D14)*('CO-PO Mapping'!H10:H14))/SUMIF('CO-PO Mapping'!H10:H14,">0"),0) -> 0.75595167 | I7: =IFERROR(SUMPRODUCT(('CO-PO Mapping'!D10:D14)*('CO-PO Mapping'!I10:I14))/SUMIF('CO-PO Mapping'!I10:I14,">0"),0) -> 0.76178333 | J7: =IFERROR(SUMPRODUCT(('CO-PO Mapping'!D10:D14)*('CO-PO Mapping'!J10:J14))/SUMIF('CO-PO Mapping'!J10:J14,">0"),0) -> 0 | K7: =IFERROR(SUMPRODUCT(('CO-PO Mapping'!D10:D14)*('CO-PO Mapping'!K10:K14))/SUMIF('CO-PO Mapping'!K10:K14,">0"),0) -> 0 | L7: =IFERROR(SUMPRODUCT(('CO-PO Mapping'!D10:D14)*('CO-PO Mapping'!L10:L14))/SUMIF('CO-PO Mapping'!L10:L14,">0"),0) -> 0 | M7: =IFERROR(SUMPRODUCT(('CO-PO Mapping'!D10:D14)*('CO-PO Mapping'!M10:M14))/SUMIF('CO-PO Mapping'!M10:M14,">0"),0) -> 0.74544167 | N7: =IFERROR(SUMPRODUCT(('CO-PO Mapping'!D10:D14)*('CO-PO Mapping'!N10:N14))/SUMIF('CO-PO Mapping'!N10:N14,">0"),0) -> 0.773525 | O7: =IFERROR(SUMPRODUCT(('CO-PO Mapping'!D10:D14)*('CO-PO Mapping'!O10:O14))/SUMIF('CO-PO Mapping'!O10:O14,">0"),0) -> 0.74178333 | P7: =IFERROR(SUMPRODUCT(('CO-PO Mapping'!D10:D14)*('CO-PO Mapping'!P10:P14))/SUMIF('CO-PO Mapping'!P10:P14,">0"),0) -> 0.76097857 | Q7: =IFERROR(SUMPRODUCT(('CO-PO Mapping'!D10:D14)*('CO-PO Mapping'!Q10:Q14))/SUMIF('CO-PO Mapping'!Q10:Q14,">0"),0) -> 0.75922179 | R7: =IFERROR(SUMPRODUCT(('CO-PO Mapping'!D10:D14)*('CO-PO Mapping'!R10:R14))/SUMIF('CO-PO Mapping'!R10:R14,">0"),0) -> 0.76050278 | S7: =IFERROR(SUMPRODUCT(('CO-PO Mapping'!D10:D14)*('CO-PO Mapping'!S10:S14))/SUMIF('CO-PO Mapping'!S10:S14,">0"),0) -> 0.76343542 | T7: =AVERAGE(E7:P7) -> 0.56835361 | U7: =AVERAGE(Q7:S7) -> 0.76105333 | V7: =(AVERAGE(E7:P7)+AVERAGE(Q7:S7))/2 -> 0.66470347
A8: 3 | B8: Computer Networks | C8: CS303 | D8: 4 | E8: =IFERROR(SUMPRODUCT(('CO-PO Mapping'!D15:D19)*('CO-PO Mapping'!E15:E19))/SUMIF('CO-PO Mapping'!E15:E19,">0"),0) -> 0.74797949 | F8: =IFERROR(SUMPRODUCT(('CO-PO Mapping'!D15:D19)*('CO-PO Mapping'!F15:F19))/SUMIF('CO-PO Mapping'!F15:F19,">0"),0) -> 0.74991026 | G8: =IFERROR(SUMPRODUCT(('CO-PO Mapping'!D15:D19)*('CO-PO Mapping'!G15:G19))/SUMIF('CO-PO Mapping'!G15:G19,">0"),0) -> 0.751675 | H8: =IFERROR(SUMPRODUCT(('CO-PO Mapping'!D15:D19)*('CO-PO Mapping'!H15:H19))/SUMIF('CO-PO Mapping'!H15:H19,">0"),0) -> 0.74889333 | I8: =IFERROR(SUMPRODUCT(('CO-PO Mapping'!D15:D19)*('CO-PO Mapping'!I15:I19))/SUMIF('CO-PO Mapping'!I15:I19,">0"),0) -> 0.74802179 | J8: =IFERROR(SUMPRODUCT(('CO-PO Mapping'!D15:D19)*('CO-PO Mapping'!J15:J19))/SUMIF('CO-PO Mapping'!J15:J19,">0"),0) -> 0.75311667 | K8: =IFERROR(SUMPRODUCT(('CO-PO Mapping'!D15:D19)*('CO-PO Mapping'!K15:K19))/SUMIF('CO-PO Mapping'!K15:K19,">0"),0) -> 0.77091667 | L8: =IFERROR(SUMPRODUCT(('CO-PO Mapping'!D15:D19)*('CO-PO Mapping'!L15:L19))/SUMIF('CO-PO Mapping'!L15:L19,">0"),0) -> 0 | M8: =IFERROR(SUMPRODUCT(('CO-PO Mapping'!D15:D19)*('CO-PO Mapping'!M15:M19))/SUMIF('CO-PO Mapping'!M15:M19,">0"),0) -> 0.74258333 | N8: =IFERROR(SUMPRODUCT(('CO-PO Mapping'!D15:D19)*('CO-PO Mapping'!N15:N19))/SUMIF('CO-PO Mapping'!N15:N19,">0"),0) -> 0.75364444 | O8: =IFERROR(SUMPRODUCT(('CO-PO Mapping'!D15:D19)*('CO-PO Mapping'!O15:O19))/SUMIF('CO-PO Mapping'!O15:O19,">0"),0) -> 0 | P8: =IFERROR(SUMPRODUCT(('CO-PO Mapping'!D15:D19)*('CO-PO Mapping'!P15:P19))/SUMIF('CO-PO Mapping'!P15:P19,">0"),0) -> 0.74680926 | Q8: =IFERROR(SUMPRODUCT(('CO-PO Mapping'!D15:D19)*('CO-PO Mapping'!Q15:Q19))/SUMIF('CO-PO Mapping'!Q15:Q19,">0"),0) -> 0.74811389 | R8: =IFERROR(SUMPRODUCT(('CO-PO Mapping'!D15:D19)*('CO-PO Mapping'!R15:R19))/SUMIF('CO-PO Mapping'!R15:R19,">0"),0) -> 0.74802179 | S8: =IFERROR(SUMPRODUCT(('CO-PO Mapping'!D15:D19)*('CO-PO Mapping'!S15:S19))/SUMIF('CO-PO Mapping'!S15:S19,">0"),0) -> 0.7499 | T8: =AVERAGE(E8:P8) -> 0.62612919 | U8: =AVERAGE(Q8:S8) -> 0.74867856 | V8: =(AVERAGE(E8:P8)+AVERAGE(Q8:S8))/2 -> 0.68740387
A9: 4 | B9: Operating Systems | C9: CS304 | D9: 4 | E9: =IFERROR(SUMPRODUCT(('CO-PO Mapping'!D20:D24)*('CO-PO Mapping'!E20:E24))/SUMIF('CO-PO Mapping'!E20:E24,">0"),0) -> 0.75786667 | F9: =IFERROR(SUMPRODUCT(('CO-PO Mapping'!D20:D24)*('CO-PO Mapping'!F20:F24))/SUMIF('CO-PO Mapping'!F20:F24,">0"),0) -> 0.75635833 | G9: =IFERROR(SUMPRODUCT(('CO-PO Mapping'!D20:D24)*('CO-PO Mapping'!G20:G24))/SUMIF('CO-PO Mapping'!G20:G24,">0"),0) -> 0.75377333 | H9: =IFERROR(SUMPRODUCT(('CO-PO Mapping'!D20:D24)*('CO-PO Mapping'!H20:H24))/SUMIF('CO-PO Mapping'!H20:H24,">0"),0) -> 0.75378333 | I9: =IFERROR(SUMPRODUCT(('CO-PO Mapping'!D20:D24)*('CO-PO Mapping'!I20:I24))/SUMIF('CO-PO Mapping'!I20:I24,">0"),0) -> 0.75616667 | J9: =IFERROR(SUMPRODUCT(('CO-PO Mapping'!D20:D24)*('CO-PO Mapping'!J20:J24))/SUMIF('CO-PO Mapping'!J20:J24,">0"),0) -> 0 | K9: =IFERROR(SUMPRODUCT(('CO-PO Mapping'!D20:D24)*('CO-PO Mapping'!K20:K24))/SUMIF('CO-PO Mapping'!K20:K24,">0"),0) -> 0 | L9: =IFERROR(SUMPRODUCT(('CO-PO Mapping'!D20:D24)*('CO-PO Mapping'!L20:L24))/SUMIF('CO-PO Mapping'!L20:L24,">0"),0) -> 0 | M9: =IFERROR(SUMPRODUCT(('CO-PO Mapping'!D20:D24)*('CO-PO Mapping'!M20:M24))/SUMIF('CO-PO Mapping'!M20:M24,">0"),0) -> 0.76625833 | N9: =IFERROR(SUMPRODUCT(('CO-PO Mapping'!D20:D24)*('CO-PO Mapping'!N20:N24))/SUMIF('CO-PO Mapping'!N20:N24,">0"),0) -> 0.73675 | O9: =IFERROR(SUMPRODUCT(('CO-PO Mapping'!D20:D24)*('CO-PO Mapping'!O20:O24))/SUMIF('CO-PO Mapping'!O20:O24,">0"),0) -> 0 | P9: =IFERROR(SUMPRODUCT(('CO-PO Mapping'!D20:D24)*('CO-PO Mapping'!P20:P24))/SUMIF('CO-PO Mapping'!P20:P24,">0"),0) -> 0.75803519 | Q9: =IFERROR(SUMPRODUCT(('CO-PO Mapping'!D20:D24)*('CO-PO Mapping'!Q20:Q24))/SUMIF('CO-PO Mapping'!Q20:Q24,">0"),0) -> 0.75786667 | R9: =IFERROR(SUMPRODUCT(('CO-PO Mapping'!D20:D24)*('CO-PO Mapping'!R20:R24))/SUMIF('CO-PO Mapping'!R20:R24,">0"),0) -> 0.75784861 | S9: =IFERROR(SUMPRODUCT(('CO-PO Mapping'!D20:D24)*('CO-PO Mapping'!S20:S24))/SUMIF('CO-PO Mapping'!S20:S24,">0"),0) -> 0.7529037 | T9: =AVERAGE(E9:P9) -> 0.50324932 | U9: =AVERAGE(Q9:S9) -> 0.75620633 | V9: =(AVERAGE(E9:P9)+AVERAGE(Q9:S9))/2 -> 0.62972782
