Workbook

Sheet Guidelines
A1: CO–PO MAPPING: CRITICAL ASSESSMENT RECORD — PO5 to PO12 (Rubric-Based Method)
A2: Based on: NBA OBE Guidelines | Method E: Rubric-Based Critical Assessment Records for Skill-Based POs
A4: WHY RUBRICS FOR PO5–PO12 SPECIFICALLY?
A5: PO1–PO4: Technical/Core POs | F5: PO5–PO12: Professional/Skill-Based POs
A6: Assessed through: Exams, Assignments, Lab Reports → Covered by Methods A, B, C, D | F6: Require: Observation + Rubrics + Activities + Projects + Presentations → Written exams alone are NOT sufficient
A8: MAPPING LEVEL CRITERIA (from CO-PO Mapping Guidelines — Section E: Rubric-Based Mapping)
A9: Level | B9: Symbol | C9: Rubric Categories Used | D9: Condition | E9: Meaning | F9: Example
A10: No Mapping | B10: — | C10: 0 categories | D10: No rubric used | E10: No measurable evidence exists for CO-PO link | F10: Assignment submitted without evaluation criteria, rubric, or observation sheet
A11: Low | B11: 1 | C11: 1 category | D11: Only one rubric category evaluated | E11: Limited evidence — one dimension assessed | F11: Seminar: only 'Communication' assessed, no technical/teamwork evaluation
A12: Medium | B12: 2 | C12: 2 categories | D12: Two rubric categories evaluated | E12: Moderate depth — two competency dimensions measured | F12: Project: 'Technical Implementation' + 'Communication' both assessed
A13: High | B13: 3 | C13: 3+ categories | D13: Three or more rubric categories evaluated | E13: Comprehensive — multidimensional assessment with strong evidence | F13: Mini Project: Problem ID + Design + Tool Usage + Teamwork + Presentation (5 categories)
A15: PO5–PO12: RUBRIC CATEGORIES REFERENCE (from Section E of document)
A16: PO | B16: PO Name | C16: Rubric Categories Used in Assessment
A17: PO5 | B17: Modern Tool Usage | C17: (1) Tool Selection | (2) Simulation Accuracy | (3) Result Interpretation | (4) Software Proficiency
A18: PO6 | B18: The Engineer and Society | C18: (1) Social Impact Analysis | (2) Safety Considerations | (3) Community Awareness | (4) Professional Practice
A19: PO7 | B19: Environment and Sustainability | C19: (1) Energy Efficiency | (2) Environmental Impact | (3) Sustainable Solution Design | (4) Conservation
A20: PO8 | B20: Ethics | C20: (1) Professional Ethics | (2) Integrity | (3) Ethical Decision Making | (4) Responsibility
A21: PO9 | B21: Individual and Team Work | C21: (1) Collaboration | (2) Participation | (3) Leadership | (4) Responsibility
A22: PO10 | B22: Communication | C22: (1) Oral Presentation | (2) Technical Writing | (3) Clarity | (4) Confidence
A23: PO11 | B23: Project Management and Finance | C23: (1) Planning | (2) Resource Management | (3) Scheduling | (4) Cost Analysis
A24: PO12 | B24: Life-long Learning | C24: (1) Self-Learning Ability | (2) Research Orientation | (3) Adaptability | (4) Independent Study
A26: EXCEL FORMULA LOGIC USED IN THIS WORKBOOK
A27: Step | B27: Logic | C27: Notes
A28: Rubric Score Input | B28: Enter score 1–3 per rubric category per CO per activity (YELLOW cells) | C28: 1=Poor 2=Average 3=Good
A29: Categories Used | B29: Enter score 1, 2, or 3 per rubric category per CO per assessment activity | C29: Counts how many rubric categories are actually assessed
A30: Average Rubric Score | B30: COUNTIF(rubric_range, ">0") — counts categories with score greater than 0 | C30: Average of scores for categories that are used (>0)
A31: Mapping Level | B31: AVERAGEIF(rubric_range, ">0") — average of scores for assessed categories only | C31: 0=No Map | 1=Low(1 cat) | 2=Medium(2 cats) | 3=High(3+ cats)
A32: PO Attainment % | B32: IF(cats>=3, 3, IF(cats>=2, 2, IF(cats>=1, 1, 0))) | C32: Since max rubric score is 3
A33: Symbol | B33: AVERAGEIF(rubric_range, ">0") / 3 * 100 | C33: Shown in mapping matrix
A34: NBA Justification | B34: Auto-generated text from rubric categories and scores | C34: Ready for NBA documentation
A36: HOW TO USE THIS WORKBOOK
A37: 1. Open any course sheet (CS301–CS305) → For each CO and each assessment activity, rubric categories are shown
A38: 2. Enter rubric score (1=Poor, 2=Average, 3=Good) for each rubric category in YELLOW cells per CO
A39: 3. Categories Used auto-counts: how many rubric categories have score > 0
A40: 4. Mapping Level auto-calculates: 0=None, 1=Low(1 cat), 2=Medium(2 cats), 3=High(3+ cats)
A41: 5. PO Attainment % auto-calculates: Average Score / 3 × 100
A42: 6. Open 'PO5-PO12 Matrix' sheet — full CO-PO mapping auto-linked from all course sheets
A43: 7. Open 'Rubric Records' sheet — complete rubric documentation for NBA accreditation
A44: 8. Open 'PO Attainment Summary' — programme-level PO5-PO12 attainment dashboard
A45: 9. Change any rubric score → all mapping levels, attainment %, and summaries update instantly

Sheet CS301
A1: CRITICAL ASSESSMENT RECORD (Rubric-Based) — Data Structures & Algorithms (CS301)
A2: Method E: Enter Rubric Score (1=Poor / 2=Average / 3=Good) in YELLOW cells per CO per rubric category | Categories Used auto-counts | Level: 0=— 1=Low(1 cat) 2=Medium(2 cats) 3=High(3+ cats)
A4: Score Guide → | D4: 0 = Not Assessed | E4: 1 = Poor | F4: 2 = Average | G4: 3 = Good | H4: Mapping Level: 0 categories → No Map | 1 cat → Low(1) | 2 cats → Medium(2) | 3+ cats → High(3)
A5: PO | B5: Rubric Category | C5: Max Score | D5: CO1 Score (0–3) | E5: CO1 Level | F5: CO1 Att% | G5: CO2 Score (0–3) | H5: CO2 Level | I5: CO2 Att% | J5: CO3 Score (0–3) | K5: CO3 Level | L5: CO3 Att% | M5: CO4 Score (0–3) | N5: CO4 Level | O5: CO4 Att% | P5: CO5 Score (0–3) | Q5: CO5 Level | R5: CO5 Att%
A6: PO5 — Modern Tool Usage | Use modern engineering tools, techniques and IT tools for engineering practice
A7: PO5 | B7: (1) Tool Selection | C7: 3 | D7: 1 | G7: 1 | J7: 1 | M7: 1 | P7: 1
B8: (2) Simulation Accuracy | C8: 3 | D8: 2 | G8: 2 | J8: 2 | M8: 2 | P8: 2
B9: (3) Result Interpretation | C9: 3 | D9: 3 | G9: 3 | J9: 3 | M9: 3 | P9: 3
B10: (4) Software Proficiency | C10: 3 | D10: 1 | G10: 1 | J10: 1 | M10: 1 | P10: 1
A11: Categories Used → Level | D11: =COUNTIF(D7:D10,">0") -> 4 | E11: =IF(COUNTIF(D7:D10,">0")>=3,3,IF(COUNTIF(D7:D10,">0")>=2,2,IF(COUNTIF(D7:D10,">0")>=1,1,0))) -> 3 | F11: =IFERROR(AVERAGEIF(D7:D10,">0")/3*100,0) -> 58.333333 | G11: =COUNTIF(G7:G10,">0") -> 4 | H11: =IF(COUNTIF(G7:G10,">0")>=3,3,IF(COUNTIF(G7:G10,">0")>=2,2,IF(COUNTIF(G7:G10,">0")>=1,1,0))) -> 3 | I11: =IFERROR(AVERAGEIF(G7:G10,">0")/3*100,0) -> 58.333333 | J11: =COUNTIF(J7:J10,">0") -> 4 | K11: =IF(COUNTIF(J7:J10,">0")>=3,3,IF(COUNTIF(J7:J10,">0")>=2,2,IF(COUNTIF(J7:J10,">0")>=1,1,0))) -> 3 | L11: =IFERROR(AVERAGEIF(J7:J10,">0")/3*100,0) -> 58.333333 | M11: =COUNTIF(M7:M10,">0") -> 4 | N11: =IF(COUNTIF(M7:M10,">0")>=3,3,IF(COUNTIF(M7:M10,">0")>=2,2,IF(COUNTIF(M7:M10,">0")>=1,1,0))) -> 3 | O11: =IFERROR(AVERAGEIF(M7:M10,">0")/3*100,0) -> 58.333333 | P11: =COUNTIF(P7:P10,">0") -> 4 | Q11: =IF(COUNTIF(P7:P10,">0")>=3,3,IF(COUNTIF(P7:P10,">0")>=2,2,IF(COUNTIF(P7:P10,">0")>=1,1,0))) -> 3 | R11: =IFERROR(AVERAGEIF(P7:P10,">0")/3*100,0) -> 58.333333
A13: PO6 — The Engineer and Society | Apply reasoning to assess societal, health, safety, legal and cultural issues
A14: PO6 | B14: (1) Social Impact Analysis | C14: 3 | D14: 1 | G14: 0 | J14: 0 | M14: 0 | P14: 0
B15: (2) Safety Considerations | C15: 3 | D15: 2 | G15: 0 | J15: 0 | M15: 0 | P15: 0
B16: (3) Community Awareness | C16: 3 | D16: 3 | G16: 0 | J16: 0 | M16: 0 | P16: 0
B17: (4) Professional Practice | C17: 3 | D17: 1 | G17: 0 | J17: 0 | M17: 0 | P17: 0
A18: Categories Used → Level | D18: =COUNTIF(D14:D17,">0") -> 4 | E18: =IF(COUNTIF(D14:D17,">0")>=3,3,IF(COUNTIF(D14:D17,">0")>=2,2,IF(COUNTIF(D14:D17,">0")>=1,1,0))) -> 3 | F18: =IFERROR(AVERAGEIF(D14:D17,">0")/3*100,0) -> 58.333333 | G18: =COUNTIF(G14:G17,">0") -> 0 | H18: =IF(COUNTIF(G14:G17,">0")>=3,3,IF(COUNTIF(G14:G17,">0")>=2,2,IF(COUNTIF(G14:G17,">0")>=1,1,0))) -> 0 | I18: =IFERROR(AVERAGEIF(G14:G17,">0")/3*100,0) -> 0 | J18: =COUNTIF(J14:J17,">0") -> 0 | K18: =IF(COUNTIF(J14:J17,">0")>=3,3,IF(COUNTIF(J14:J17,">0")>=2,2,IF(COUNTIF(J14:J17,">0")>=1,1,0))) -> 0 | L18: =IFERROR(AVERAGEIF(J14:J17,">0")/3*100,0) -> 0 | M18: =COUNTIF(M14:M17,">0") -> 0 | N18: =IF(COUNTIF(M14:M17,">0")>=3,3,IF(COUNTIF(M14:M17,">0")>=2,2,IF(COUNTIF(M14:M17,">0")>=1,1,0))) -> 0 | O18: =IFERROR(AVERAGEIF(M14:M17,">0")/3*100,0) -> 0 | P18: =COUNTIF(P14:P17,">0") -> 0 | Q18: =IF(COUNTIF(P14:P17,">0")>=3,3,IF(COUNTIF(P14:P17,">0")>=2,2,IF(COUNTIF(P14:P17,">0")>=1,1,0))) -> 0 | R18: =IFERROR(AVERAGEIF(P14:P17,">0")/3*100,0) -> 0
A20: PO7 — Environment and Sustainability | Understand the impact of engineering solutions in societal and environmental contexts
A21: PO7 | B21: (1) Energy Efficiency | C21: 3 | D21: 0 | G21: 0 | J21: 0 | M21: 0 | P21: 0
B22: (2) Environmental Impact | C22: 3 | D22: 0 | G22: 0 | J22: 0 | M22: 0 | P22: 0
B23: (3) Sustainable Solution Design | C23: 3 | D23: 0 | G23: 0 | J23: 0 | M23: 0 | P23: 0
B24: (4) Conservation | C24: 3 | D24: 0 | G24: 0 | J24: 0 | M24: 0 | P24: 0
A25: Categories Used → Level | D25: =COUNTIF(D21:D24,">0") -> 0 | E25: =IF(COUNTIF(D21:D24,">0")>=3,3,IF(COUNTIF(D21:D24,">0")>=2,2,IF(COUNTIF(D21:D24,">0")>=1,1,0))) -> 0 | F25: =IFERROR(AVERAGEIF(D21:D24,">0")/3*100,0) -> 0 | G25: =COUNTIF(G21:G24,">0") -> 0 | H25: =IF(COUNTIF(G21:G24,">0")>=3,3,IF(COUNTIF(G21:G24,">0")>=2,2,IF(COUNTIF(G21:G24,">0")>=1,1,0))) -> 0 | I25: =IFERROR(AVERAGEIF(G21:G24,">0")/3*100,0) -> 0 | J25: =COUNTIF(J21:J24,">0") -> 0 | K25: =IF(COUNTIF(J21:J24,">0")>=3,3,IF(COUNTIF(J21:J24,">0")>=2,2,IF(COUNTIF(J21:J24,">0")>=1,1,0))) -> 0 | L25: =IFERROR(AVERAGEIF(J21:J24,">0")/3*100,0) -> 0 | M25: =COUNTIF(M21:M24,">0") -> 0 | N25: =IF(COUNTIF(M21:M24,">0")>=3,3,IF(COUNTIF(M21:M24,">0")>=2,2,IF(COUNTIF(M21:M24,">0")>=1,1,0))) -> 0 | O25: =IFERROR(AVERAGEIF(M21:M24,">0")/3*100,0) -> 0 | P25: =COUNTIF(P21:P24,">0") -> 0 | Q25: =IF(COUNTIF(P21:P24,">0")>=3,3,IF(COUNTIF(P21:P24,">0")>=2,2,IF(COUNTIF(P21:P24,">0")>=1,1,0))) -> 0 | R25: =IFERROR(AVERAGEIF(P21:P24,">0")/3*100,0) -> 0
A27: PO8 — Ethics | Apply ethical principles and commit to professional ethics, responsibilities and norms
A28: PO8 | B28: (1) Professional Ethics | C28: 3 | D28: 1 | G28: 1 | J28: 1 | M28: 0 | P28: 1
B29: (2) Integrity | C29: 3 | D29: 2 | G29: 2 | J29: 2 | M29: 0 | P29: 2
B30: (3) Ethical Decision Making | C30: 3 | D30: 3 | G30: 3 | J30: 3 | M30: 0 | P30: 3
B31: (4) Responsibility | C31: 3 | D31: 1 | G31: 1 | J31: 1 | M31: 0 | P31: 1
A32: Categories Used → Level | D32: =COUNTIF(D28:D31,">0") -> 4 | E32: =IF(COUNTIF(D28:D31,">0")>=3,3,IF(COUNTIF(D28:D31,">0")>=2,2,IF(COUNTIF(D28:D31,">0")>=1,1,0))) -> 3 | F32: =IFERROR(AVERAGEIF(D28:D31,">0")/3*100,0) -> 58.333333 | G32: =COUNTIF(G28:G31,">0") -> 4 | H32: =IF(COUNTIF(G28:G31,">0")>=3,3,IF(COUNTIF(G28:G31,">0")>=2,2,IF(COUNTIF(G28:G31,">0")>=1,1,0))) -> 3 | I32: =IFERROR(AVERAGEIF(G28:G31,">0")/3*100,0) -> 58.333333 | J32: =COUNTIF(J28:J31,">0") -> 4 | K32: =IF(COUNTIF(J28:J31,">0")>=3,3,IF(COUNTIF(J28:J31,">0")>=2,2,IF(COUNTIF(J28:J31,">0")>=1,1,0))) -> 3 | L32: =IFERROR(AVERAGEIF(J28:J31,">0")/3*100,0) -> 58.333333 | M32: =COUNTIF(M28:M31,">0") -> 0 | N32: =IF(COUNTIF(M28:M31,">0")>=3,3,IF(COUNTIF(M28:M31,">0")>=2,2,IF(COUNTIF(M28:M31,">0")>=1,1,0))) -> 0 | O32: =IFERROR(AVERAGEIF(M28:M31,">0")/3*100,0) -> 0 | P32: =COUNTIF(P28:P31,">0") -> 4 | Q32: =IF(COUNTIF(P28:P31,">0")>=3,3,IF(COUNTIF(P28:P31,">0")>=2,2,IF(COUNTIF(P28:P31,">0")>=1,1,0))) -> 3 | R32: =IFERROR(AVERAGEIF(P28:P31,">0")/3*100,0) -> 58.333333
A34: PO9 — Individual and Team Work | Function effectively as an individual, and as a member or leader in diverse teams
A35: PO9 | B35: (1) Collaboration | C35: 3 | D35: 1 | G35: 1 | J35: 1 | M35: 1 | P35: 1
B36: (2) Participation | C36: 3 | D36: 2 | G36: 2 | J36: 2 | M36: 2 | P36: 2
B37: (3) Leadership | C37: 3 | D37: 3 | G37: 3 | J37: 3 | M37: 3 | P37: 3
B38: (4) Responsibility | C38: 3 | D38: 1 | G38: 1 | J38: 1 | M38: 1 | P38: 1
A39: Categories Used → Level | D39: =COUNTIF(D35:D38,">0") -> 4 | E39: =IF(COUNTIF(D35:D38,">0")>=3,3,IF(COUNTIF(D35:D38,">0")>=2,2,IF(COUNTIF(D35:D38,">0")>=1,1,0))) -> 3 | F39: =IFERROR(AVERAGEIF(D35:D38,">0")/3*100,0) -> 58.333333 | G39: =COUNTIF(G35:G38,">0") -> 4 | H39: =IF(COUNTIF(G35:G38,">0")>=3,3,IF(COUNTIF(G35:G38,">0")>=2,2,IF(COUNTIF(G35:G38,">0")>=1,1,0))) -> 3 | I39: =IFERROR(AVERAGEIF(G35:G38,">0")/3*100,0) -> 58.333333 | J39: =COUNTIF(J35:J38,">0") -> 4 | K39: =IF(COUNTIF(J35:J38,">0")>=3,3,IF(COUNTIF(J35:J38,">0")>=2,2,IF(COUNTIF(J35:J38,">0")>=1,1,0))) -> 3 | L39: =IFERROR(AVERAGEIF(J35:J38,">0")/3*100,0) -> 58.333333 | M39: =COUNTIF(M35:M38,">0") -> 4 | N39: =IF(COUNTIF(M35:M38,">0")>=3,3,IF(COUNTIF(M35:M38,">0")>=2,2,IF(COUNTIF(M35:M38,">0")>=1,1,0))) -> 3 | O39: =IFERROR(AVERAGEIF(M35:M38,">0")/3*100,0) -> 58.333333 | P39: =COUNTIF(P35:P38,">0") -> 4 | Q39: =IF(COUNTIF(P35:P38,">0")>=3,3,IF(COUNTIF(P35:P38,">0")>=2,2,IF(COUNTIF(P35:P38,">0")>=1,1,0))) -> 3 | R39: =IFERROR(AVERAGEIF(P35:P38,">0")/3*100,0) -> 58.333333
A41: PO10 — Communication | Communicate effectively on complex engineering activities
A42: PO10 | B42: (1) Oral Presentation | C42: 3 | D42: 1 | G42: 1 | J42: 1 | M42: 1 | P42: 1
B43: (2) Technical Writing | C43: 3 | D43: 2 | G43: 2 | J43: 2 | M43: 2 | P43: 2
B44: (3) Clarity | C44: 3 | D44: 3 | G44: 3 | J44: 3 | M44: 3 | P44: 3
B45: (4) Confidence | C45: 3 | D45: 1 | G45: 1 | J45: 1 | M45: 1 | P45: 1
A46: Categories Used → Level | D46: =COUNTIF(D42:D45,">0") -> 4 | E46: =IF(COUNTIF(D42:D45,">0")>=3,3,IF(COUNTIF(D42:D45,">0")>=2,2,IF(COUNTIF(D42:D45,">0")>=1,1,0))) -> 3 | F46: =IFERROR(AVERAGEIF(D42:D45,">0")/3*100,0) -> 58.333333 | G46: =COUNTIF(G42:G45,">0") -> 4 | H46: =IF(COUNTIF(G42:G45,">0")>=3,3,IF(COUNTIF(G42:G45,">0")>=2,2,IF(COUNTIF(G42:G45,">0")>=1,1,0))) -> 3 | I46: =IFERROR(AVERAGEIF(G42:G45,">0")/3*100,0) -> 58.333333 | J46: =COUNTIF(J42:J45,">0") -> 4 | K46: =IF(COUNTIF(J42:J45,">0")>=3,3,IF(COUNTIF(J42:J45,">0")>=2,2,IF(COUNTIF(J42:J45,">0")>=1,1,0))) -> 3 | L46: =IFERROR(AVERAGEIF(J42:J45,">0")/3*100,0) -> 58.333333 | M46: =COUNTIF(M42:M45,">0") -> 4 | N46: =IF(COUNTIF(M42:M45,">0")>=3,3,IF(COUNTIF(M42:M45,">0")>=2,2,IF(COUNTIF(M42:M45,">0")>=1,1,0))) -> 3 | O46: =IFERROR(AVERAGEIF(M42:M45,">0")/3*100,0) -> 58.333333 | P46: =COUNTIF(P42:P45,">0") -> 4 | Q46: =IF(COUNTIF(P42:P45,">0")>=3,3,IF(COUNTIF(P42:P45,">0")>=2,2,IF(COUNTIF(P42:P45,">0")>=1,1,0))) -> 3 | R46: =IFERROR(AVERAGEIF(P42:P45,">0")/3*100,0) -> 58.333333
...

Sheet CS302
A1: CRITICAL ASSESSMENT RECORD (Rubric-Based) — Database Management Systems (CS302)
A2: Method E: Enter Rubric Score (1=Poor / 2=Average / 3=Good) in YELLOW cells per CO per rubric category | Categories Used auto-counts | Level: 0=— 1=Low(1 cat) 2=Medium(2 cats) 3=High(3+ cats)
A4: Score Guide → | D4: 0 = Not Assessed | E4: 1 = Poor | F4: 2 = Average | G4: 3 = Good | H4: Mapping Level: 0 categories → No Map | 1 cat → Low(1) | 2 cats → Medium(2) | 3+ cats → High(3)
A5: PO | B5: Rubric Category | C5: Max Score | D5: CO1 Score (0–3) | E5: CO1 Level | F5: CO1 Att% | G5: CO2 Score (0–3) | H5: CO2 Level | I5: CO2 Att% | J5: CO3 Score (0–3) | K5: CO3 Level | L5: CO3 Att% | M5: CO4 Score (0–3) | N5: CO4 Level | O5: CO4 Att% | P5: CO5 Score (0–3) | Q5: CO5 Level | R5: CO5 Att%
A6: PO5 — Modern Tool Usage | Use modern engineering tools, techniques and IT tools for engineering practice
A7: PO5 | B7: (1) Tool Selection | C7: 3 | D7: 1 | G7: 1 | J7: 1 | M7: 1 | P7: 1
B8: (2) Simulation Accuracy | C8: 3 | D8: 2 | G8: 2 | J8: 2 | M8: 2 | P8: 2
B9: (3) Result Interpretation | C9: 3 | D9: 3 | G9: 3 | J9: 3 | M9: 3 | P9: 3
B10: (4) Software Proficiency | C10: 3 | D10: 1 | G10: 1 | J10: 1 | M10: 1 | P10: 1
A11: Categories Used → Level | D11: =COUNTIF(D7:D10,">0") -> 4 | E11: =IF(COUNTIF(D7:D10,">0")>=3,3,IF(COUNTIF(D7:D10,">0")>=2,2,IF(COUNTIF(D7:D10,">0")>=1,1,0))) -> 3 | F11: =IFERROR(AVERAGEIF(D7:D10,">0")/3*100,0) -> 58.333333 | G11: =COUNTIF(G7:G10,">0") -> 4 | H11: =IF(COUNTIF(G7:G10,">0")>=3,3,IF(COUNTIF(G7:G10,">0")>=2,2,IF(COUNTIF(G7:G10,">0")>=1,1,0))) -> 3 | I11: =IFERROR(AVERAGEIF(G7:G10,">0")/3*100,0) -> 58.333333 | J11: =COUNTIF(J7:J10,">0") -> 4 | K11: =IF(COUNTIF(J7:J10,">0")>=3,3,IF(COUNTIF(J7:J10,">0")>=2,2,IF(COUNTIF(J7:J10,">0")>=1,1,0))) -> 3 | L11: =IFERROR(AVERAGEIF(J7:J10,">0")/3*100,0) -> 58.333333 | M11: =COUNTIF(M7:M10,">0") -> 4 | N11: =IF(COUNTIF(M7:M10,">0")>=3,3,IF(COUNTIF(M7:M10,">0")>=2,2,IF(COUNTIF(M7:M10,">0")>=1,1,0))) -> 3 | O11: =IFERROR(AVERAGEIF(M7:M10,">0")/3*100,0) -> 58.333333 | P11: =COUNTIF(P7:P10,">0") -> 4 | Q11: =IF(COUNTIF(P7:P10,">0")>=3,3,IF(COUNTIF(P7:P10,">0")>=2,2,IF(COUNTIF(P7:P10,">0")>=1,1,0))) -> 3 | R11: =IFERROR(AVERAGEIF(P7:P10,">0")/3*100,0) -> 58.333333
A13: PO6 — The Engineer and Society | Apply reasoning to assess societal, health, safety, legal and cultural issues
A14: PO6 | B14: (1) Social Impact Analysis | C14: 3 | D14: 0 | G14: 0 | J14: 1 | M14: 1 | P14: 0
B15: (2) Safety Considerations | C15: 3 | D15: 0 | G15: 0 | J15: 2 | M15: 2 | P15: 0
B16: (3) Community Awareness | C16: 3 | D16: 0 | G16: 0 | J16: 3 | M16: 3 | P16: 0
B17: (4) Professional Practice | C17: 3 | D17: 0 | G17: 0 | J17: 1 | M17: 1 | P17: 0
A18: Categories Used → Level | D18: =COUNTIF(D14:D17,">0") -> 0 | E18: =IF(COUNTIF(D14:D17,">0")>=3,3,IF(COUNTIF(D14:D17,">0")>=2,2,IF(COUNTIF(D14:D17,">0")>=1,1,0))) -> 0 | F18: =IFERROR(AVERAGEIF(D14:D17,">0")/3*100,0) -> 0 | G18: =COUNTIF(G14:G17,">0") -> 0 | H18: =IF(COUNTIF(G14:G17,">0")>=3,3,IF(COUNTIF(G14:G17,">0")>=2,2,IF(COUNTIF(G14:G17,">0")>=1,1,0))) -> 0 | I18: =IFERROR(AVERAGEIF(G14:G17,">0")/3*100,0) -> 0 | J18: =COUNTIF(J14:J17,">0") -> 4 | K18: =IF(COUNTIF(J14:J17,">0")>=3,3,IF(COUNTIF(J14:J17,">0")>=2,2,IF(COUNTIF(J14:J17,">0")>=1,1,0))) -> 3 | L18: =IFERROR(AVERAGEIF(J14:J17,">0")/3*100,0) -> 58.333333 | M18: =COUNTIF(M14:M17,">0") -> 4 | N18: =IF(COUNTIF(M14:M17,">0")>=3,3,IF(COUNTIF(M14:M17,">0")>=2,2,IF(COUNTIF(M14:M17,">0")>=1,1,0))) -> 3 | O18: =IFERROR(AVERAGEIF(M14:M17,">0")/3*100,0) -> 58.333333 | P18: =COUNTIF(P14:P17,">0") -> 0 | Q18: =IF(COUNTIF(P14:P17,">0")>=3,3,IF(COUNTIF(P14:P17,">0")>=2,2,IF(COUNTIF(P14:P17,">0")>=1,1,0))) -> 0 | R18: =IFERROR(AVERAGEIF(P14:P17,">0")/3*100,0) -> 0
A20: PO7 — Environment and Sustainability | Understand the impact of engineering solutions in societal and environmental contexts
A21: PO7 | B21: (1) Energy Efficiency | C21: 3 | D21: 0 | G21: 0 | J21: 0 | M21: 0 | P21: 0
B22: (2) Environmental Impact | C22: 3 | D22: 0 | G22: 0 | J22: 0 | M22: 0 | P22: 0
B23: (3) Sustainable Solution Design | C23: 3 | D23: 0 | G23: 0 | J23: 0 | M23: 0 | P23: 0
B24: (4) Conservation | C24: 3 | D24: 0 | G24: 0 | J24: 0 | M24: 0 | P24: 0
A25: Categories Used → Level | D25: =COUNTIF(D21:D24,">0") -> 0 | E25: =IF(COUNTIF(D21:D24,">0")>=3,3,IF(COUNTIF(D21:D24,">0")>=2,2,IF(COUNTIF(D21:D24,">0")>=1,1,0))) -> 0 | F25: =IFERROR(AVERAGEIF(D21:D24,">0")/3*100,0) -> 0 | G25: =COUNTIF(G21:G24,">0") -> 0 | H25: =IF(COUNTIF(G21:G24,">0")>=3,3,IF(COUNTIF(G21:G24,">0")>=2,2,IF(COUNTIF(G21:G24,">0")>=1,1,0))) -> 0 | I25: =IFERROR(AVERAGEIF(G21:G24,">0")/3*100,0) -> 0 | J25: =COUNTIF(J21:J24,">0") -> 0 | K25: =IF(COUNTIF(J21:J24,">0")>=3,3,IF(COUNTIF(J21:J24,">0")>=2,2,IF(COUNTIF(J21:J24,">0")>=1,1,0))) -> 0 | L25: =IFERROR(AVERAGEIF(J21:J24,">0")/3*100,0) -> 0 | M25: =COUNTIF(M21:M24,">0") -> 0 | N25: =IF(COUNTIF(M21:M24,">0")>=3,3,IF(COUNTIF(M21:M24,">0")>=2,2,IF(COUNTIF(M21:M24,">0")>=1,1,0))) -> 0 | O25: =IFERROR(AVERAGEIF(M21:M24,">0")/3*100,0) -> 0 | P25: =COUNTIF(P21:P24,">0") -> 0 | Q25: =IF(COUNTIF(P21:P24,">0")>=3,3,IF(COUNTIF(P21:P24,">0")>=2,2,IF(COUNTIF(P21:P24,">0")>=1,1,0))) -> 0 | R25: =IFERROR(AVERAGEIF(P21:P24,">0")/3*100,0) -> 0
A27: PO8 — Ethics | Apply ethical principles and commit to professional ethics, responsibilities and norms
A28: PO8 | B28: (1) Professional Ethics | C28: 3 | D28: 1 | G28: 1 | J28: 1 | M28: 1 | P28: 1
B29: (2) Integrity | C29: 3 | D29: 2 | G29: 2 | J29: 2 | M29: 2 | P29: 2
B30: (3) Ethical Decision Making | C30: 3 | D30: 3 | G30: 3 | J30: 3 | M30: 3 | P30: 3
B31: (4) Responsibility | C31: 3 | D31: 1 | G31: 1 | J31: 1 | M31: 1 | P31: 1
A32: Categories Used → Level | D32: =COUNTIF(D28:D31,">0") -> 4 | E32: =IF(COUNTIF(D28:D31,">0")>=3,3,IF(COUNTIF(D28:D31,">0")>=2,2,IF(COUNTIF(D28:D31,">0")>=1,1,0))) -> 3 | F32: =IFERROR(AVERAGEIF(D28:D31,">0")/3*100,0) -> 58.333333 | G32: =COUNTIF(G28:G31,">0") -> 4 | H32: =IF(COUNTIF(G28:G31,">0")>=3,3,IF(COUNTIF(G28:G31,">0")>=2,2,IF(COUNTIF(G28:G31,">0")>=1,1,0))) -> 3 | I32: =IFERROR(AVERAGEIF(G28:G31,">0")/3*100,0) -> 58.333333 | J32: =COUNTIF(J28:J31,">0") -> 4 | K32: =IF(COUNTIF(J28:J31,">0")>=3,3,IF(COUNTIF(J28:J31,">0")>=2,2,IF(COUNTIF(J28:J31,">0")>=1,1,0))) -> 3 | L32: =IFERROR(AVERAGEIF(J28:J31,">0")/3*100,0) -> 58.333333 | M32: =COUNTIF(M28:M31,">0") -> 4 | N32: =IF(COUNTIF(M28:M31,">0")>=3,3,IF(COUNTIF(M28:M31,">0")>=2,2,IF(COUNTIF(M28:M31,">0")>=1,1,0))) -> 3 | O32: =IFERROR(AVERAGEIF(M28:M31,">0")/3*100,0) -> 58.333333 | P32: =COUNTIF(P28:P31,">0") -> 4 | Q32: =IF(COUNTIF(P28:P31,">0")>=3,3,IF(COUNTIF(P28:P31,">0")>=2,2,IF(COUNTIF(P28:P31,">0")>=1,1,0))) -> 3 | R32: =IFERROR(AVERAGEIF(P28:P31,">0")/3*100,0) -> 58.333333
A34: PO9 — Individual and Team Work | Function effectively as an individual, and as a member or leader in diverse teams
A35: PO9 | B35: (1) Collaboration | C35: 3 | D35: 1 | G35: 1 | J35: 1 | M35: 1 | P35: 1
B36: (2) Participation | C36: 3 | D36: 2 | G36: 2 | J36: 2 | M36: 2 | P36: 2
B37: (3) Leadership | C37: 3 | D37: 3 | G37: 3 | J37: 3 | M37: 3 | P37: 3
B38: (4) Responsibility | C38: 3 | D38: 1 | G38: 1 | J38: 1 | M38: 1 | P38: 1
A39: Categories Used → Level | D39: =COUNTIF(D35:D38,">0") -> 4 | E39: =IF(COUNTIF(D35:D38,">0")>=3,3,IF(COUNTIF(D35:D38,">0")>=2,2,IF(COUNTIF(D35:D38,">0")>=1,1,0))) -> 3 | F39: =IFERROR(AVERAGEIF(D35:D38,">0")/3*100,0) -> 58.333333 | G39: =COUNTIF(G35:G38,">0") -> 4 | H39: =IF(COUNTIF(G35:G38,">0")>=3,3,IF(COUNTIF(G35:G38,">0")>=2,2,IF(COUNTIF(G35:G38,">0")>=1,1,0))) -> 3 | I39: =IFERROR(AVERAGEIF(G35:G38,">0")/3*100,0) -> 58.333333 | J39: =COUNTIF(J35:J38,">0") -> 4 | K39: =IF(COUNTIF(J35:J38,">0")>=3,3,IF(COUNTIF(J35:J38,">0")>=2,2,IF(COUNTIF(J35:J38,">0")>=1,1,0))) -> 3 | L39: =IFERROR(AVERAGEIF(J35:J38,">0")/3*100,0) -> 58.333333 | M39: =COUNTIF(M35:M38,">0") -> 4 | N39: =IF(COUNTIF(M35:M38,">0")>=3,3,IF(COUNTIF(M35:M38,">0")>=2,2,IF(COUNTIF(M35:M38,">0")>=1,1,0))) -> 3 | O39: =IFERROR(AVERAGEIF(M35:M38,">0")/3*100,0) -> 58.333333 | P39: =COUNTIF(P35:P38,">0") -> 4 | Q39: =IF(COUNTIF(P35:P38,">0")>=3,3,IF(COUNTIF(P35:P38,">0")>=2,2,IF(COUNTIF(P35:P38,">0")>=1,1,0))) -> 3 | R39: =IFERROR(AVERAGEIF(P35:P38,">0")/3*100,0) -> 58.333333
A41: PO10 — Communication | Communicate effectively on complex engineering activities
A42: PO10 | B42: (1) Oral Presentation | C42: 3 | D42: 1 | G42: 1 | J42: 1 | M42: 1 | P42: 1
B43: (2) Technical Writing | C43: 3 | D43: 2 | G43: 2 | J43: 2 | M43: 2 | P43: 2
B44: (3) Clarity | C44: 3 | D44: 3 | G44: 3 | J44: 3 | M44: 3 | P44: 3
B45: (4) Confidence | C45: 3 | D45: 1 | G45: 1 | J45: 1 | M45: 1 | P45: 1
A46: Categories Used → Level | D46: =COUNTIF(D42:D45,">0") -> 4 | E46: =IF(COUNTIF(D42:D45,">0")>=3,3,IF(COUNTIF(D42:D45,">0")>=2,2,IF(COUNTIF(D42:D45,">0")>=1,1,0))) -> 3 | F46: =IFERROR(AVERAGEIF(D42:D45,">0")/3*100,0) -> 58.333333 | G46: =COUNTIF(G42:G45,">0") -> 4 | H46: =IF(COUNTIF(G42:G45,">0")>=3,3,IF(COUNTIF(G42:G45,">0")>=2,2,IF(COUNTIF(G42:G45,">0")>=1,1,0))) -> 3 | I46: =IFERROR(AVERAGEIF(G42:G45,">0")/3*100,0) -> 58.333333 | J46: =COUNTIF(J42:J45,">0") -> 4 | K46: =IF(COUNTIF(J42:J45,">0")>=3,3,IF(COUNTIF(J42:J45,">0")>=2,2,IF(COUNTIF(J42:J45,">0")>=1,1,0))) -> 3 | L46: =IFERROR(AVERAGEIF(J42:J45,">0")/3*100,0) -> 58.333333 | M46: =COUNTIF(M42:M45,">0") -> 4 | N46: =IF(COUNTIF(M42:M45,">0")>=3,3,IF(COUNTIF(M42:M45,">0")>=2,2,IF(COUNTIF(M42:M45,">0")>=1,1,0))) -> 3 | O46: =IFERROR(AVERAGEIF(M42:M45,">0")/3*100,0) -> 58.333333 | P46: =COUNTIF(P42:P45,">0") -> 4 | Q46: =IF(COUNTIF(P42:P45,">0")>=3,3,IF(COUNTIF(P42:P45,">0")>=2,2,IF(COUNTIF(P42:P45,">0")>=1,1,0))) -> 3 | R46: =IFERROR(AVERAGEIF(P42:P45,">0")/3*100,0) -> 58.333333
...

Sheet PO5-PO12 Matrix
A1: CO–PO5 to PO12 MAPPING MATRIX (Rubric-Based Critical Assessment) — Auto-linked from course sheets
A2: Level: — No Mapping (0 cats) | 1 Low (1 rubric category) | 2 Medium (2 categories) | 3 High (3+ categories) | All values auto-linked from course rubric sheets
A4: LEGEND → | F4: — No Mapping | G4: 1 Low (1 cat) | H4: 2 Medium (2 cats) | I4: 3 High (3+ cats)
A5: # | B5: Course | C5: Code | D5: CO | E5: Topic | F5: SKILL-BASED PROGRAMME OUTCOMES (PO5–PO12) — Rubric Assessment | N5: PSOs
F6: PO5 | G6: PO6 | H6: PO7 | I6: PO8 | J6: PO9 | K6: PO10 | L6: PO11 | M6: PO12 | N6: PSO1 | O6: PSO2 | P6: PSO3
A7: 1 | B7: Data Structures & Algorithms | C7: CS301 | D7: CO1 | E7: Arrays, Linked Lists, Stacks, Queues | F7: =IF(CS301!E11=0,"—",TEXT(CS301!E11,"0")) -> 3 | G7: =IF(CS301!E18=0,"—",TEXT(CS301!E18,"0")) -> 3 | H7: =IF(CS301!E25=0,"—",TEXT(CS301!E25,"0")) -> — | I7: =IF(CS301!E32=0,"—",TEXT(CS301!E32,"0")) -> 3 | J7: =IF(CS301!E39=0,"—",TEXT(CS301!E39,"0")) -> 3 | K7: =IF(CS301!E46=0,"—",TEXT(CS301!E46,"0")) -> 3 | L7: =IF(CS301!E53=0,"—",TEXT(CS301!E53,"0")) -> — | M7: =IF(CS301!E60=0,"—",TEXT(CS301!E60,"0")) -> — | N7: — | O7: — | P7: —
D8: CO2 | E8: Trees and Binary Search Trees | F8: =IF(CS301!H11=0,"—",TEXT(CS301!H11,"0")) -> 3 | G8: =IF(CS301!H18=0,"—",TEXT(CS301!H18,"0")) -> — | H8: =IF(CS301!H25=0,"—",TEXT(CS301!H25,"0")) -> — | I8: =IF(CS301!H32=0,"—",TEXT(CS301!H32,"0")) -> 3 | J8: =IF(CS301!H39=0,"—",TEXT(CS301!H39,"0")) -> 3 | K8: =IF(CS301!H46=0,"—",TEXT(CS301!H46,"0")) -> 3 | L8: =IF(CS301!H53=0,"—",TEXT(CS301!H53,"0")) -> — | M8: =IF(CS301!H60=0,"—",TEXT(CS301!H60,"0")) -> 3 | N8: — | O8: — | P8: —
D9: CO3 | E9: Graphs: BFS, DFS, Shortest Paths | F9: =IF(CS301!K11=0,"—",TEXT(CS301!K11,"0")) -> 3 | G9: =IF(CS301!K18=0,"—",TEXT(CS301!K18,"0")) -> — | H9: =IF(CS301!K25=0,"—",TEXT(CS301!K25,"0")) -> — | I9: =IF(CS301!K32=0,"—",TEXT(CS301!K32,"0")) -> 3 | J9: =IF(CS301!K39=0,"—",TEXT(CS301!K39,"0")) -> 3 | K9: =IF(CS301!K46=0,"—",TEXT(CS301!K46,"0")) -> 3 | L9: =IF(CS301!K53=0,"—",TEXT(CS301!K53,"0")) -> 3 | M9: =IF(CS301!K60=0,"—",TEXT(CS301!K60,"0")) -> 3 | N9: — | O9: — | P9: —
D10: CO4 | E10: Sorting and Searching Algorithms | F10: =IF(CS301!N11=0,"—",TEXT(CS301!N11,"0")) -> 3 | G10: =IF(CS301!N18=0,"—",TEXT(CS301!N18,"0")) -> — | H10: =IF(CS301!N25=0,"—",TEXT(CS301!N25,"0")) -> — | I10: =IF(CS301!N32=0,"—",TEXT(CS301!N32,"0")) -> — | J10: =IF(CS301!N39=0,"—",TEXT(CS301!N39,"0")) -> 3 | K10: =IF(CS301!N46=0,"—",TEXT(CS301!N46,"0")) -> 3 | L10: =IF(CS301!N53=0,"—",TEXT(CS301!N53,"0")) -> — | M10: =IF(CS301!N60=0,"—",TEXT(CS301!N60,"0")) -> 3 | N10: — | O10: — | P10: —
D11: CO5 | E11: Hashing and Complexity Analysis | F11: =IF(CS301!Q11=0,"—",TEXT(CS301!Q11,"0")) -> 3 | G11: =IF(CS301!Q18=0,"—",TEXT(CS301!Q18,"0")) -> — | H11: =IF(CS301!Q25=0,"—",TEXT(CS301!Q25,"0")) -> — | I11: =IF(CS301!Q32=0,"—",TEXT(CS301!Q32,"0")) -> 3 | J11: =IF(CS301!Q39=0,"—",TEXT(CS301!Q39,"0")) -> 3 | K11: =IF(CS301!Q46=0,"—",TEXT(CS301!Q46,"0")) -> 3 | L11: =IF(CS301!Q53=0,"—",TEXT(CS301!Q53,"0")) -> 3 | M11: =IF(CS301!Q60=0,"—",TEXT(CS301!Q60,"0")) -> 3 | N11: — | O11: — | P11: —
A12: 2 | B12: Database Management Systems | C12: CS302 | D12: CO1 | E12: ER Model and Relational Algebra | F12: =IF(CS302!E11=0,"—",TEXT(CS302!E11,"0")) -> 3 | G12: =IF(CS302!E18=0,"—",TEXT(CS302!E18,"0")) -> — | H12: =IF(CS302!E25=0,"—",TEXT(CS302!E25,"0")) -> — | I12: =IF(CS302!E32=0,"—",TEXT(CS302!E32,"0")) -> 3 | J12: =IF(CS302!E39=0,"—",TEXT(CS302!E39,"0")) -> 3 | K12: =IF(CS302!E46=0,"—",TEXT(CS302!E46,"0")) -> 3 | L12: =IF(CS302!E53=0,"—",TEXT(CS302!E53,"0")) -> — | M12: =IF(CS302!E60=0,"—",TEXT(CS302!E60,"0")) -> — | N12: — | O12: — | P12: —
D13: CO2 | E13: SQL: DDL, DML, Complex Queries | F13: =IF(CS302!H11=0,"—",TEXT(CS302!H11,"0")) -> 3 | G13: =IF(CS302!H18=0,"—",TEXT(CS302!H18,"0")) -> — | H13: =IF(CS302!H25=0,"—",TEXT(CS302!H25,"0")) -> — | I13: =IF(CS302!H32=0,"—",TEXT(CS302!H32,"0")) -> 3 | J13: =IF(CS302!H39=0,"—",TEXT(CS302!H39,"0")) -> 3 | K13: =IF(CS302!H46=0,"—",TEXT(CS302!H46,"0")) -> 3 | L13: =IF(CS302!H53=0,"—",TEXT(CS302!H53,"0")) -> 3 | M13: =IF(CS302!H60=0,"—",TEXT(CS302!H60,"0")) -> 3 | N13: — | O13: — | P13: —
D14: CO3 | E14: Normalization: 1NF to BCNF | F14: =IF(CS302!K11=0,"—",TEXT(CS302!K11,"0")) -> 3 | G14: =IF(CS302!K18=0,"—",TEXT(CS302!K18,"0")) -> 3 | H14: =IF(CS302!K25=0,"—",TEXT(CS302!K25,"0")) -> — | I14: =IF(CS302!K32=0,"—",TEXT(CS302!K32,"0")) -> 3 | J14: =IF(CS302!K39=0,"—",TEXT(CS302!K39,"0")) -> 3 | K14: =IF(CS302!K46=0,"—",TEXT(CS302!K46,"0")) -> 3 | L14: =IF(CS302!K53=0,"—",TEXT(CS302!K53,"0")) -> 3 | M14: =IF(CS302!K60=0,"—",TEXT(CS302!K60,"0")) -> 3 | N14: — | O14: — | P14: —
D15: CO4 | E15: Transaction Management & Concurrency | F15: =IF(CS302!N11=0,"—",TEXT(CS302!N11,"0")) -> 3 | G15: =IF(CS302!N18=0,"—",TEXT(CS302!N18,"0")) -> 3 | H15: =IF(CS302!N25=0,"—",TEXT(CS302!N25,"0")) -> — | I15: =IF(CS302!N32=0,"—",TEXT(CS302!N32,"0")) -> 3 | J15: =IF(CS302!N39=0,"—",TEXT(CS302!N39,"0")) -> 3 | K15: =IF(CS302!N46=0,"—",TEXT(CS302!N46,"0")) -> 3 | L15: =IF(CS302!N53=0,"—",TEXT(CS302!N53,"0")) -> 3 | M15: =IF(CS302!N60=0,"—",TEXT(CS302!N60,"0")) -> 3 | N15: — | O15: — | P15: —
D16: CO5 | E16: Indexing & Query Optimization | F16: =IF(CS302!Q11=0,"—",TEXT(CS302!Q11,"0")) -> 3 | G16: =IF(CS302!Q18=0,"—",TEXT(CS302!Q18,"0")) -> — | H16: =IF(CS302!Q25=0,"—",TEXT(CS302!Q25,"0")) -> — | I16: =IF(CS302!Q32=0,"—",TEXT(CS302!Q32,"0")) -> 3 | J16: =IF(CS302!Q39=0,"—",TEXT(CS302!Q39,"0")) -> 3 | K16: =IF(CS302!Q46=0,"—",TEXT(CS302!Q46,"0")) -> 3 | L16: =IF(CS302!Q53=0,"—",TEXT(CS302!Q53,"0")) -> 3 | M16: =IF(CS302!Q60=0,"—",TEXT(CS302!Q60,"0")) -> 3 | N16: — | O16: — | P16: —
A17: 3 | B17: Computer Networks | C17: CS303 | D17: CO1 | E17: OSI and TCP/IP Model | F17: =IF(CS303!E11=0,"—",TEXT(CS303!E11,"0")) -> 3 | G17: =IF(CS303!E18=0,"—",TEXT(CS303!E18,"0")) -> — | H17: =IF(CS303!E25=0,"—",TEXT(CS303!E25,"0")) -> — | I17: =IF(CS303!E32=0,"—",TEXT(CS303!E32,"0")) -> 3 | J17: =IF(CS303!E39=0,"—",TEXT(CS303!E39,"0")) -> 3 | K17: =IF(CS303!E46=0,"—",TEXT(CS303!E46,"0")) -> 3 | L17: =IF(CS303!E53=0,"—",TEXT(CS303!E53,"0")) -> — | M17: =IF(CS303!E60=0,"—",TEXT(CS303!E60,"0")) -> — | N17: — | O17: — | P17: —
D18: CO2 | E18: Data Link Layer Protocols | F18: =IF(CS303!H11=0,"—",TEXT(CS303!H11,"0")) -> 3 | G18: =IF(CS303!H18=0,"—",TEXT(CS303!H18,"0")) -> — | H18: =IF(CS303!H25=0,"—",TEXT(CS303!H25,"0")) -> — | I18: =IF(CS303!H32=0,"—",TEXT(CS303!H32,"0")) -> 3 | J18: =IF(CS303!H39=0,"—",TEXT(CS303!H39,"0")) -> 3 | K18: =IF(CS303!H46=0,"—",TEXT(CS303!H46,"0")) -> 3 | L18: =IF(CS303!H53=0,"—",TEXT(CS303!H53,"0")) -> 3 | M18: =IF(CS303!H60=0,"—",TEXT(CS303!H60,"0")) -> 3 | N18: — | O18: — | P18: —
D19: CO3 | E19: Network Layer: IP & Routing | F19: =IF(CS303!K11=0,"—",TEXT(CS303!K11,"0")) -> 3 | G19: =IF(CS303!K18=0,"—",TEXT(CS303!K18,"0")) -> 3 | H19: =IF(CS303!K25=0,"—",TEXT(CS303!K25,"0")) -> — | I19: =IF(CS303!K32=0,"—",TEXT(CS303!K32,"0")) -> 3 | J19: =IF(CS303!K39=0,"—",TEXT(CS303!K39,"0")) -> 3 | K19: =IF(CS303!K46=0,"—",TEXT(CS303!K46,"0")) -> 3 | L19: =IF(CS303!K53=0,"—",TEXT(CS303!K53,"0")) -> 3 | M19: =IF(CS303!K60=0,"—",TEXT(CS303!K60,"0")) -> 3 | N19: — | O19: — | P19: —
D20: CO4 | E20: Transport Layer: TCP & UDP | F20: =IF(CS303!N11=0,"—",TEXT(CS303!N11,"0")) -> 3 | G20: =IF(CS303!N18=0,"—",TEXT(CS303!N18,"0")) -> — | H20: =IF(CS303!N25=0,"—",TEXT(CS303!N25,"0")) -> — | I20: =IF(CS303!N32=0,"—",TEXT(CS303!N32,"0")) -> 3 | J20: =IF(CS303!N39=0,"—",TEXT(CS303!N39,"0")) -> 3 | K20: =IF(CS303!N46=0,"—",TEXT(CS303!N46,"0")) -> 3 | L20: =IF(CS303!N53=0,"—",TEXT(CS303!N53,"0")) -> — | M20: =IF(CS303!N60=0,"—",TEXT(CS303!N60,"0")) -> — | N20: — | O20: — | P20: —
D21: CO5 | E21: Application Layer Protocols | F21: =IF(CS303!Q11=0,"—",TEXT(CS303!Q11,"0")) -> 3 | G21: =IF(CS303!Q18=0,"—",TEXT(CS303!Q18,"0")) -> — | H21: =IF(CS303!Q25=0,"—",TEXT(CS303!Q25,"0")) -> — | I21: =IF(CS303!Q32=0,"—",TEXT(CS303!Q32,"0")) -> 3 | J21: =IF(CS303!Q39=0,"—",TEXT(CS303!Q39,"0")) -> 3 | K21: =IF(CS303!Q46=0,"—",TEXT(CS303!Q46,"0")) -> 3 | L21: =IF(CS303!Q53=0,"—",TEXT(CS303!Q53,"0")) -> 3 | M21: =IF(CS303!Q60=0,"—",TEXT(CS303!Q60,"0")) -> 3 | N21: — | O21: — | P21: —
A22: 4 | B22: Operating Systems | C22: CS304 | D22: CO1 | E22: Process Management & Scheduling | F22: =IF(CS304!E11=0,"—",TEXT(CS304!E11,"0")) -> 3 | G22: =IF(CS304!E18=0,"—",TEXT(CS304!E18,"0")) -> — | H22: =IF(CS304!E25=0,"—",TEXT(CS304!E25,"0")) -> — | I22: =IF(CS304!E32=0,"—",TEXT(CS304!E32,"0")) -> 3 | J22: =IF(CS304!E39=0,"—",TEXT(CS304!E39,"0")) -> 3 | K22: =IF(CS304!E46=0,"—",TEXT(CS304!E46,"0")) -> 3 | L22: =IF(CS304!E53=0,"—",TEXT(CS304!E53,"0")) -> — | M22: =IF(CS304!E60=0,"—",TEXT(CS304!E60,"0")) -> — | N22: — | O22: — | P22: —
D23: CO2 | E23: Synchronization & Deadlock | F23: =IF(CS304!H11=0,"—",TEXT(CS304!H11,"0")) -> 3 | G23: =IF(CS304!H18=0,"—",TEXT(CS304!H18,"0")) -> 3 | H23: =IF(CS304!H25=0,"—",TEXT(CS304!H25,"0")) -> — | I23: =IF(CS304!H32=0,"—",TEXT(CS304!H32,"0")) -> 3 | J23: =IF(CS304!H39=0,"—",TEXT(CS304!H39,"0")) -> 3 | K23: =IF(CS304!H46=0,"—",TEXT(CS304!H46,"0")) -> 3 | L23: =IF(CS304!H53=0,"—",TEXT(CS304!H53,"0")) -> 3 | M23: =IF(CS304!H60=0,"—",TEXT(CS304!H60,"0")) -> 3 | N23: — | O23: — | P23: —
D24: CO3 | E24: Memory Management: Paging & Segmentation | F24: =IF(CS304!K11=0,"—",TEXT(CS304!K11,"0")) -> 3 | G24: =IF(CS304!K18=0,"—",TEXT(CS304!K18,"0")) -> — | H24: =IF(CS304!K25=0,"—",TEXT(CS304!K25,"0")) -> — | I24: =IF(CS304!K32=0,"—",TEXT(CS304!K32,"0")) -> 3 | J24: =IF(CS304!K39=0,"—",TEXT(CS304!K39,"0")) -> 3 | K24: =IF(CS304!K46=0,"—",TEXT(CS304!K46,"0")) -> 3 | L24: =IF(CS304!K53=0,"—",TEXT(CS304!K53,"0")) -> — | M24: =IF(CS304!K60=0,"—",TEXT(CS304!K60,"0")) -> — | N24: — | O24: — | P24: —
D25: CO4 | E25: File System Management | F25: =IF(CS304!N11=0,"—",TEXT(CS304!N11,"0")) -> 3 | G25: =IF(CS304!N18=0,"—",TEXT(CS304!N18,"0")) -> — | H25: =IF(CS304!N25=0,"—",TEXT(CS304!N25,"0")) -> — | I25: =IF(CS304!N32=0,"—",TEXT(CS304!N32,"0")) -> 3 | J25: =IF(CS304!N39=0,"—",TEXT(CS304!N39,"0")) -> 3 | K25: =IF(CS304!N46=0,"—",TEXT(CS304!N46,"0")) -> 3 | L25: =IF(CS304!N53=0,"—",TEXT(CS304!N53,"0")) -> — | M25: =IF(CS304!N60=0,"—",TEXT(CS304!N60,"0")) -> 3 | N25: — | O25: — | P25: —
D26: CO5 | E26: I/O Management & Disk Scheduling | F26: =IF(CS304!Q11=0,"—",TEXT(CS304!Q11,"0")) -> 3 | G26: =IF(CS304!Q18=0,"—",TEXT(CS304!Q18,"0")) -> — | H26: =IF(CS304!Q25=0,"—",TEXT(CS304!Q25,"0")) -> — | I26: =IF(CS304!Q32=0,"—",TEXT(CS304!Q32,"0")) -> — | J26: =IF(CS304!Q39=0,"—",TEXT(CS304!Q39,"0")) -> 3 | K26: =IF(CS304!Q46=0,"—",TEXT(CS304!Q46,"0")) -> 3 | L26: =IF(CS304!Q53=0,"—",TEXT(CS304!Q53,"0")) -> 3 | M26: =IF(CS304!Q60=0,"—",TEXT(CS304!Q60,"0")) -> 3 | N26: — | O26: — | P26: —
A27: 5 | B27: Machine Learning | C27: CS305 | D27: CO1 | E27: Supervised Learning: Regression & SVM | F27: =IF(CS305!E11=0,"—",TEXT(CS305!E11,"0")) -> 3 | G27: =IF(CS305!E18=0,"—",TEXT(CS305!E18,"0")) -> — | H27: =IF(CS305!E25=0,"—",TEXT(CS305!E25,"0")) -> — | I27: =IF(CS305!E32=0,"—",TEXT(CS305!E32,"0")) -> — | J27: =IF(CS305!E39=0,"—",TEXT(CS305!E39,"0")) -> 3 | K27: =IF(CS305!E46=0,"—",TEXT(CS305!E46,"0")) -> 3 | L27: =IF(CS305!E53=0,"—",TEXT(CS305!E53,"0")) -> 3 | M27: =IF(CS305!E60=0,"—",TEXT(CS305!E60,"0")) -> 3 | N27: — | O27: — | P27: —
D28: CO2 | E28: Classification: Decision Trees & KNN | F28: =IF(CS305!H11=0,"—",TEXT(CS305!H11,"0")) -> 3 | G28: =IF(CS305!H18=0,"—",TEXT(CS305!H18,"0")) -> — | H28: =IF(CS305!H25=0,"—",TEXT(CS305!H25,"0")) -> — | I28: =IF(CS305!H32=0,"—",TEXT(CS305!H32,"0")) -> 3 | J28: =IF(CS305!H39=0,"—",TEXT(CS305!H39,"0")) -> 3 | K28: =IF(CS305!H46=0,"—",TEXT(CS305!H46,"0")) -> 3 | L28: =IF(CS305!H53=0,"—",TEXT(CS305!H53,"0")) -> 3 | M28: =IF(CS305!H60=0,"—",TEXT(CS305!H60,"0")) -> 3 | N28: — | O28: — | P28: —
D29: CO3 | E29: Neural Networks & Deep Learning | F29: =IF(CS305!K11=0,"—",TEXT(CS305!K11,"0")) -> 3 | G29: =IF(CS305!K18=0,"—",TEXT(CS305!K18,"0")) -> 3 | H29: =IF(CS305!K25=0,"—",TEXT(CS305!K25,"0")) -> 3 | I29: =IF(CS305!K32=0,"—",TEXT(CS305!K32,"0")) -> 3 | J29: =IF(CS305!K39=0,"—",TEXT(CS305!K39,"0")) -> 3 | K29: =IF(CS305!K46=0,"—",TEXT(CS305!K46,"0")) -> 3 | L29: =IF(CS305!K53=0,"—",TEXT(CS305!K53,"0")) -> 3 | M29: =IF(CS305!K60=0,"—",TEXT(CS305!K60,"0")) -> 3 | N29: — | O29: — | P29: —
D30: CO4 | E30: Unsupervised Learning: Clustering & PCA | F30: =IF(CS305!N11=0,"—",TEXT(CS305!N11,"0")) -> 3 | G30: =IF(CS305!N18=0,"—",TEXT(CS305!N18,"0")) -> — | H30: =IF(CS305!N25=0,"—",TEXT(CS305!N25,"0")) -> — | I30: =IF(CS305!N32=0,"—",TEXT(CS305!N32,"0")) -> 3 | J30: =IF(CS305!N39=0,"—",TEXT(CS305!N39,"0")) -> 3 | K30: =IF(CS305!N46=0,"—",TEXT(CS305!N46,"0")) -> 3 | L30: =IF(CS305!N53=0,"—",TEXT(CS305!N53,"0")) -> 3 | M30: =IF(CS305!N60=0,"—",TEXT(CS305!N60,"0")) -> 3 | N30: — | O30: — | P30: —
D31: CO5 | E31: Model Evaluation & Optimization | F31: =IF(CS305!Q11=0,"—",TEXT(CS305!Q11,"0")) -> 3 | G31: =IF(CS305!Q18=0,"—",TEXT(CS305!Q18,"0")) -> 3 | H31: =IF(CS305!Q25=0,"—",TEXT(CS305!Q25,"0")) -> — | I31: =IF(CS305!Q32=0,"—",TEXT(CS305!Q32,"0")) -> 3 | J31: =IF(CS305!Q39=0,"—",TEXT(CS305!Q39,"0")) -> 3 | K31: =IF(CS305!Q46=0,"—",TEXT(CS305!Q46,"0")) -> 3 | L31: =IF(CS305!Q53=0,"—",TEXT(CS305!Q53,"0")) -> 3 | M31: =IF(CS305!Q60=0,"—",TEXT(CS305!Q60,"0")) -> 3 | N31: — | O31: — | P31: —
D32: CO6 | E32: Applied ML Projects & Case Studies | F32: =IF(CS305!T11=0,"—",TEXT(CS305!T11,"0")) -> 3 | G32: =IF(CS305!T18=0,"—",TEXT(CS305!T18,"0")) -> 3 | H32: =IF(CS305!T25=0,"—",TEXT(CS305!T25,"0")) -> 3 | I32: =IF(CS305!T32=0,"—",TEXT(CS305!T32,"0")) -> 3 | J32: =IF(CS305!T39=0,"—",TEXT(CS305!T39,"0")) -> 3 | K32: =IF(CS305!T46=0,"—",TEXT(CS305!T46,"0")) -> 3 | L32: =IF(CS305!T53=0,"—",TEXT(CS305!T53,"0")) -> 3 | M32: =IF(CS305!T60=0,"—",TEXT(CS305!T60,"0")) -> 3 | N32: — | O32: — | P32: —
A34: DEPT AVERAGE (all COs) | F34: =IFERROR(AVERAGEIF(F7:F32,"<>—"),"") | G34: =IFERROR(AVERAGEIF(G7:G32,"<>—"),"") | H34: =IFERROR(AVERAGEIF(H7:H32,"<>—"),"") | I34: =IFERROR(AVERAGEIF(I7:I32,"<>—"),"") | J34: =IFERROR(AVERAGEIF(J7:J32,"<>—"),"") | K34: =IFERROR(AVERAGEIF(K7:K32,"<>—"),"") | L34: =IFERROR(AVERAGEIF(L7:L32,"<>—"),"") | M34: =IFERROR(AVERAGEIF(M7:M32,"<>—"),"")

Sheet CS303
A1: CRITICAL ASSESSMENT RECORD (Rubric-Based) — Computer Networks (CS303)
A2: Method E: Enter Rubric Score (1=Poor / 2=Average / 3=Good) in YELLOW cells per CO per rubric category | Categories Used auto-counts | Level: 0=— 1=Low(1 cat) 2=Medium(2 cats) 3=High(3+ cats)
A4: Score Guide → | D4: 0 = Not Assessed | E4: 1 = Poor | F4: 2 = Average | G4: 3 = Good | H4: Mapping Level: 0 categories → No Map | 1 cat → Low(1) | 2 cats → Medium(2) | 3+ cats → High(3)
A5: PO | B5: Rubric Category | C5: Max Score | D5: CO1 Score (0–3) | E5: CO1 Level | F5: CO1 Att% | G5: CO2 Score (0–3) | H5: CO2 Level | I5: CO2 Att% | J5: CO3 Score (0–3) | K5: CO3 Level | L5: CO3 Att% | M5: CO4 Score (0–3) | N5: CO4 Level | O5: CO4 Att% | P5: CO5 Score (0–3) | Q5: CO5 Level | R5: CO5 Att%
A6: PO5 — Modern Tool Usage | Use modern engineering tools, techniques and IT tools for engineering practice
A7: PO5 | B7: (1) Tool Selection | C7: 3 | D7: 1 | G7: 1 | J7: 1 | M7: 1 | P7: 1
B8: (2) Simulation Accuracy | C8: 3 | D8: 2 | G8: 2 | J8: 2 | M8: 2 | P8: 2
B9: (3) Result Interpretation | C9: 3 | D9: 3 | G9: 3 | J9: 3 | M9: 3 | P9: 3
B10: (4) Software Proficiency | C10: 3 | D10: 1 | G10: 1 | J10: 1 | M10: 1 | P10: 1
A11: Categories Used → Level | D11: =COUNTIF(D7:D10,">0") -> 4 | E11: =IF(COUNTIF(D7:D10,">0")>=3,3,IF(COUNTIF(D7:D10,">0")>=2,2,IF(COUNTIF(D7:D10,">0")>=1,1,0))) -> 3 | F11: =IFERROR(AVERAGEIF(D7:D10,">0")/3*100,0) -> 58.333333 | G11: =COUNTIF(G7:G10,">0") -> 4 | H11: =IF(COUNTIF(G7:G10,">0")>=3,3,IF(COUNTIF(G7:G10,">0")>=2,2,IF(COUNTIF(G7:G10,">0")>=1,1,0))) -> 3 | I11: =IFERROR(AVERAGEIF(G7:G10,">0")/3*100,0) -> 58.333333 | J11: =COUNTIF(J7:J10,">0") -> 4 | K11: =IF(COUNTIF(J7:J10,">0")>=3,3,IF(COUNTIF(J7:J10,">0")>=2,2,IF(COUNTIF(J7:J10,">0")>=1,1,0))) -> 3 | L11: =IFERROR(AVERAGEIF(J7:J10,">0")/3*100,0) -> 58.333333 | M11: =COUNTIF(M7:M10,">0") -> 4 | N11: =IF(COUNTIF(M7:M10,">0")>=3,3,IF(COUNTIF(M7:M10,">0")>=2,2,IF(COUNTIF(M7:M10,">0")>=1,1,0))) -> 3 | O11: =IFERROR(AVERAGEIF(M7:M10,">0")/3*100,0) -> 58.333333 | P11: =COUNTIF(P7:P10,">0") -> 4 | Q11: =IF(COUNTIF(P7:P10,">0")>=3,3,IF(COUNTIF(P7:P10,">0")>=2,2,IF(COUNTIF(P7:P10,">0")>=1,1,0))) -> 3 | R11: =IFERROR(AVERAGEIF(P7:P10,">0")/3*100,0) -> 58.333333
A13: PO6 — The Engineer and Society | Apply reasoning to assess societal, health, safety, legal and cultural issues
A14: PO6 | B14: (1) Social Impact Analysis | C14: 3 | D14: 0 | G14: 0 | J14: 1 | M14: 0 | P14: 0
B15: (2) Safety Considerations | C15: 3 | D15: 0 | G15: 0 | J15: 2 | M15: 0 | P15: 0
B16: (3) Community Awareness | C16: 3 | D16: 0 | G16: 0 | J16: 3 | M16: 0 | P16: 0
B17: (4) Professional Practice | C17: 3 | D17: 0 | G17: 0 | J17: 1 | M17: 0 | P17: 0
A18: Categories Used → Level | D18: =COUNTIF(D14:D17,">0") -> 0 | E18: =IF(COUNTIF(D14:D17,">0")>=3,3,IF(COUNTIF(D14:D17,">0")>=2,2,IF(COUNTIF(D14:D17,">0")>=1,1,0))) -> 0 | F18: =IFERROR(AVERAGEIF(D14:D17,">0")/3*100,0) -> 0 | G18: =COUNTIF(G14:G17,">0") -> 0 | H18: =IF(COUNTIF(G14:G17,">0")>=3,3,IF(COUNTIF(G14:G17,">0")>=2,2,IF(COUNTIF(G14:G17,">0")>=1,1,0))) -> 0 | I18: =IFERROR(AVERAGEIF(G14:G17,">0")/3*100,0) -> 0 | J18: =COUNTIF(J14:J17,">0") -> 4 | K18: =IF(COUNTIF(J14:J17,">0")>=3,3,IF(COUNTIF(J14:J17,">0")>=2,2,IF(COUNTIF(J14:J17,">0")>=1,1,0))) -> 3 | L18: =IFERROR(AVERAGEIF(J14:J17,">0")/3*100,0) -> 58.333333 | M18: =COUNTIF(M14:M17,">0") -> 0 | N18: =IF(COUNTIF(M14:M17,">0")>=3,3,IF(COUNTIF(M14:M17,">0")>=2,2,IF(COUNTIF(M14:M17,">0")>=1,1,0))) -> 0 | O18: =IFERROR(AVERAGEIF(M14:M17,">0")/3*100,0) -> 0 | P18: =COUNTIF(P14:P17,">0") -> 0 | Q18: =IF(COUNTIF(P14:P17,">0")>=3,3,IF(COUNTIF(P14:P17,">0")>=2,2,IF(COUNTIF(P14:P17,">0")>=1,1,0))) -> 0 | R18: =IFERROR(AVERAGEIF(P14:P17,">0")/3*100,0) -> 0
A20: PO7 — Environment and Sustainability | Understand the impact of engineering solutions in societal and environmental contexts
A21: PO7 | B21: (1) Energy Efficiency | C21: 3 | D21: 0 | G21: 0 | J21: 0 | M21: 0 | P21: 0
B22: (2) Environmental Impact | C22: 3 | D22: 0 | G22: 0 | J22: 0 | M22: 0 | P22: 0
B23: (3) Sustainable Solution Design | C23: 3 | D23: 0 | G23: 0 | J23: 0 | M23: 0 | P23: 0
B24: (4) Conservation | C24: 3 | D24: 0 | G24: 0 | J24: 0 | M24: 0 | P24: 0
A25: Categories Used → Level | D25: =COUNTIF(D21:D24,">0") -> 0 | E25: =IF(COUNTIF(D21:D24,">0")>=3,3,IF(COUNTIF(D21:D24,">0")>=2,2,IF(COUNTIF(D21:D24,">0")>=1,1,0))) -> 0 | F25: =IFERROR(AVERAGEIF(D21:D24,">0")/3*100,0) -> 0 | G25: =COUNTIF(G21:G24,">0") -> 0 | H25: =IF(COUNTIF(G21:G24,">0")>=3,3,IF(COUNTIF(G21:G24,">0")>=2,2,IF(COUNTIF(G21:G24,">0")>=1,1,0))) -> 0 | I25: =IFERROR(AVERAGEIF(G21:G24,">0")/3*100,0) -> 0 | J25: =COUNTIF(J21:J24,">0") -> 0 | K25: =IF(COUNTIF(J21:J24,">0")>=3,3,IF(COUNTIF(J21:J24,">0")>=2,2,IF(COUNTIF(J21:J24,">0")>=1,1,0))) -> 0 | L25: =IFERROR(AVERAGEIF(J21:J24,">0")/3*100,0) -> 0 | M25: =COUNTIF(M21:M24,">0") -> 0 | N25: =IF(COUNTIF(M21:M24,">0")>=3,3,IF(COUNTIF(M21:M24,">0")>=2,2,IF(COUNTIF(M21:M24,">0")>=1,1,0))) -> 0 | O25: =IFERROR(AVERAGEIF(M21:M24,">0")/3*100,0) -> 0 | P25: =COUNTIF(P21:P24,">0") -> 0 | Q25: =IF(COUNTIF(P21:P24,">0")>=3,3,IF(COUNTIF(P21:P24,">0")>=2,2,IF(COUNTIF(P21:P24,">0")>=1,1,0))) -> 0 | R25: =IFERROR(AVERAGEIF(P21:P24,">0")/3*100,0) -> 0
A27: PO8 — Ethics | Apply ethical principles and commit to professional ethics, responsibilities and norms
A28: PO8 | B28: (1) Professional Ethics | C28: 3 | D28: 1 | G28: 1 | J28: 1 | M28: 1 | P28: 1
B29: (2) Integrity | C29: 3 | D29: 2 | G29: 2 | J29: 2 | M29: 2 | P29: 2
B30: (3) Ethical Decision Making | C30: 3 | D30: 3 | G30: 3 | J30: 3 | M30: 3 | P30: 3
B31: (4) Responsibility | C31: 3 | D31: 1 | G31: 1 | J31: 1 | M31: 1 | P31: 1
A32: Categories Used → Level | D32: =COUNTIF(D28:D31,">0") -> 4 | E32: =IF(COUNTIF(D28:D31,">0")>=3,3,IF(COUNTIF(D28:D31,">0")>=2,2,IF(COUNTIF(D28:D31,">0")>=1,1,0))) -> 3 | F32: =IFERROR(AVERAGEIF(D28:D31,">0")/3*100,0) -> 58.333333 | G32: =COUNTIF(G28:G31,">0") -> 4 | H32: =IF(COUNTIF(G28:G31,">0")>=3,3,IF(COUNTIF(G28:G31,">0")>=2,2,IF(COUNTIF(G28:G31,">0")>=1,1,0))) -> 3 | I32: =IFERROR(AVERAGEIF(G28:G31,">0")/3*100,0) -> 58.333333 | J32: =COUNTIF(J28:J31,">0") -> 4 | K32: =IF(COUNTIF(J28:J31,">0")>=3,3,IF(COUNTIF(J28:J31,">0")>=2,2,IF(COUNTIF(J28:J31,">0")>=1,1,0))) -> 3 | L32: =IFERROR(AVERAGEIF(J28:J31,">0")/3*100,0) -> 58.333333 | M32: =COUNTIF(M28:M31,">0") -> 4 | N32: =IF(COUNTIF(M28:M31,">0")>=3,3,IF(COUNTIF(M28:M31,">0")>=2,2,IF(COUNTIF(M28:M31,">0")>=1,1,0))) -> 3 | O32: =IFERROR(AVERAGEIF(M28:M31,">0")/3*100,0) -> 58.333333 | P32: =COUNTIF(P28:P31,">0") -> 4 | Q32: =IF(COUNTIF(P28:P31,">0")>=3,3,IF(COUNTIF(P28:P31,">0")>=2,2,IF(COUNTIF(P28:P31,">0")>=1,1,0))) -> 3 | R32: =IFERROR(AVERAGEIF(P28:P31,">0")/3*100,0) -> 58.333333
A34: PO9 — Individual and Team Work | Function effectively as an individual, and as a member or leader in diverse teams
A35: PO9 | B35: (1) Collaboration | C35: 3 | D35: 1 | G35: 1 | J35: 1 | M35: 1 | P35: 1
B36: (2) Participation | C36: 3 | D36: 2 | G36: 2 | J36: 2 | M36: 2 | P36: 2
B37: (3) Leadership | C37: 3 | D37: 3 | G37: 3 | J37: 3 | M37: 3 | P37: 3
B38: (4) Responsibility | C38: 3 | D38: 1 | G38: 1 | J38: 1 | M38: 1 | P38: 1
A39: Categories Used → Level | D39: =COUNTIF(D35:D38,">0") -> 4 | E39: =IF(COUNTIF(D35:D38,">0")>=3,3,IF(COUNTIF(D35:D38,">0")>=2,2,IF(COUNTIF(D35:D38,">0")>=1,1,0))) -> 3 | F39: =IFERROR(AVERAGEIF(D35:D38,">0")/3*100,0) -> 58.333333 | G39: =COUNTIF(G35:G38,">0") -> 4 | H39: =IF(COUNTIF(G35:G38,">0")>=3,3,IF(COUNTIF(G35:G38,">0")>=2,2,IF(COUNTIF(G35:G38,">0")>=1,1,0))) -> 3 | I39: =IFERROR(AVERAGEIF(G35:G38,">0")/3*100,0) -> 58.333333 | J39: =COUNTIF(J35:J38,">0") -> 4 | K39: =IF(COUNTIF(J35:J38,">0")>=3,3,IF(COUNTIF(J35:J38,">0")>=2,2,IF(COUNTIF(J35:J38,">0")>=1,1,0))) -> 3 | L39: =IFERROR(AVERAGEIF(J35:J38,">0")/3*100,0) -> 58.333333 | M39: =COUNTIF(M35:M38,">0") -> 4 | N39: =IF(COUNTIF(M35:M38,">0")>=3,3,IF(COUNTIF(M35:M38,">0")>=2,2,IF(COUNTIF(M35:M38,">0")>=1,1,0))) -> 3 | O39: =IFERROR(AVERAGEIF(M35:M38,">0")/3*100,0) -> 58.333333 | P39: =COUNTIF(P35:P38,">0") -> 4 | Q39: =IF(COUNTIF(P35:P38,">0")>=3,3,IF(COUNTIF(P35:P38,">0")>=2,2,IF(COUNTIF(P35:P38,">0")>=1,1,0))) -> 3 | R39: =IFERROR(AVERAGEIF(P35:P38,">0")/3*100,0) -> 58.333333
A41: PO10 — Communication | Communicate effectively on complex engineering activities
A42: PO10 | B42: (1) Oral Presentation | C42: 3 | D42: 1 | G42: 1 | J42: 1 | M42: 1 | P42: 1
B43: (2) Technical Writing | C43: 3 | D43: 2 | G43: 2 | J43: 2 | M43: 2 | P43: 2
B44: (3) Clarity | C44: 3 | D44: 3 | G44: 3 | J44: 3 | M44: 3 | P44: 3
B45: (4) Confidence | C45: 3 | D45: 1 | G45: 1 | J45: 1 | M45: 1 | P45: 1
A46: Categories Used → Level | D46: =COUNTIF(D42:D45,">0") -> 4 | E46: =IF(COUNTIF(D42:D45,">0")>=3,3,IF(COUNTIF(D42:D45,">0")>=2,2,IF(COUNTIF(D42:D45,">0")>=1,1,0))) -> 3 | F46: =IFERROR(AVERAGEIF(D42:D45,">0")/3*100,0) -> 58.333333 | G46: =COUNTIF(G42:G45,">0") -> 4 | H46: =IF(COUNTIF(G42:G45,">0")>=3,3,IF(COUNTIF(G42:G45,">0")>=2,2,IF(COUNTIF(G42:G45,">0")>=1,1,0))) -> 3 | I46: =IFERROR(AVERAGEIF(G42:G45,">0")/3*100,0) -> 58.333333 | J46: =COUNTIF(J42:J45,">0") -> 4 | K46: =IF(COUNTIF(J42:J45,">0")>=3,3,IF(COUNTIF(J42:J45,">0")>=2,2,IF(COUNTIF(J42:J45,">0")>=1,1,0))) -> 3 | L46: =IFERROR(AVERAGEIF(J42:J45,">0")/3*100,0) -> 58.333333 | M46: =COUNTIF(M42:M45,">0") -> 4 | N46: =IF(COUNTIF(M42:M45,">0")>=3,3,IF(COUNTIF(M42:M45,">0")>=2,2,IF(COUNTIF(M42:M45,">0")>=1,1,0))) -> 3 | O46: =IFERROR(AVERAGEIF(M42:M45,">0")/3*100,0) -> 58.333333 | P46: =COUNTIF(P42:P45,">0") -> 4 | Q46: =IF(COUNTIF(P42:P45,">0")>=3,3,IF(COUNTIF(P42:P45,">0")>=2,2,IF(COUNTIF(P42:P45,">0")>=1,1,0))) -> 3 | R46: =IFERROR(AVERAGEIF(P42:P45,">0")/3*100,0) -> 58.333333
...

Sheet PO Attainment Summary
A1: PO5–PO12 ATTAINMENT SUMMARY — Rubric-Based Critical Assessment
A2: All values auto-linked from course rubric sheets. Shows average mapping level and attainment % per PO per course.
A4: ATTAINMENT LEVELS → | D4: Level 3 ≥66% HIGH | E4: Level 2 33–66% MEDIUM | F4: Level 1 <33% LOW | G4: — Not Mapped
A5: # | B5: PO | C5: PO Name | D5: Description | E5: CS301 | G5: CS302 | I5: CS303 | K5: CS304 | M5: CS305 | O5: Dept Avg Lvl | P5: Dept Att%
E6: Avg Level | F6: Att% | G6: Avg Level | H6: Att% | I6: Avg Level | J6: Att% | K6: Avg Level | L6: Att% | M6: Avg Level | N6: Att%
A7: 1 | B7: PO5 | C7: Modern Tool Usage | D7: Use modern engineering tools, techniques and IT tools for engineering practice | E7: =IFERROR(AVERAGE(CS301!E11,CS301!H11,CS301!K11,CS301!N11,CS301!Q11),0) -> 3 | F7: =IFERROR(AVERAGE(CS301!E11,CS301!H11,CS301!K11,CS301!N11,CS301!Q11)/3*100,0) -> 100 | G7: =IFERROR(AVERAGE(CS302!E11,CS302!H11,CS302!K11,CS302!N11,CS302!Q11),0) -> 3 | H7: =IFERROR(AVERAGE(CS302!E11,CS302!H11,CS302!K11,CS302!N11,CS302!Q11)/3*100,0) -> 100 | I7: =IFERROR(AVERAGE(CS303!E11,CS303!H11,CS303!K11,CS303!N11,CS303!Q11),0) -> 3 | J7: =IFERROR(AVERAGE(CS303!E11,CS303!H11,CS303!K11,CS303!N11,CS303!Q11)/3*100,0) -> 100 | K7: =IFERROR(AVERAGE(CS304!E11,CS304!H11,CS304!K11,CS304!N11,CS304!Q11),0) -> 3 | L7: =IFERROR(AVERAGE(CS304!E11,CS304!H11,CS304!K11,CS304!N11,CS304!Q11)/3*100,0) -> 100 | M7: =IFERROR(AVERAGE(CS305!E11,CS305!H11,CS305!K11,CS305!N11,CS305!Q11,CS305!T11),0) -> 3 | N7: =IFERROR(AVERAGE(CS305!E11,CS305!H11,CS305!K11,CS305!N11,CS305!Q11,CS305!T11)/3*100,0) -> 100 | O7: =IFERROR(AVERAGE(CS301!E11,CS301!H11,CS301!K11,CS301!N11,CS301!Q11,CS302!E11,CS302!H11,CS302!K11,CS302!N11,CS302!Q11,CS303!E11,CS303!H11,CS303!K11,CS303!N11,CS303!Q11,CS304!E11,CS304!H11,CS304!K11,CS304!N11,CS304!Q11,CS305!E11,CS305!H11,CS305!K11,CS305!N11,CS305!Q11,CS305!T11),0) -> 3 | P7: =IFERROR(O7/3*100,0) -> 100
A8: 2 | B8: PO6 | C8: The Engineer and Society | D8: Apply reasoning to assess societal, health, safety, legal and cultural issues | E8: =IFERROR(AVERAGE(CS301!E18,CS301!H18,CS301!K18,CS301!N18,CS301!Q18),0) -> 0.6 | F8: =IFERROR(AVERAGE(CS301!E18,CS301!H18,CS301!K18,CS301!N18,CS301!Q18)/3*100,0) -> 20 | G8: =IFERROR(AVERAGE(CS302!E18,CS302!H18,CS302!K18,CS302!N18,CS302!Q18),0) -> 1.2 | H8: =IFERROR(AVERAGE(CS302!E18,CS302!H18,CS302!K18,CS302!N18,CS302!Q18)/3*100,0) -> 40 | I8: =IFERROR(AVERAGE(CS303!E18,CS303!H18,CS303!K18,CS303!N18,CS303!Q18),0) -> 0.6 | J8: =IFERROR(AVERAGE(CS303!E18,CS303!H18,CS303!K18,CS303!N18,CS303!Q18)/3*100,0) -> 20 | K8: =IFERROR(AVERAGE(CS304!E18,CS304!H18,CS304!K18,CS304!N18,CS304!Q18),0) -> 0.6 | L8: =IFERROR(AVERAGE(CS304!E18,CS304!H18,CS304!K18,CS304!N18,CS304!Q18)/3*100,0) -> 20 | M8: =IFERROR(AVERAGE(CS305!E18,CS305!H18,CS305!K18,CS305!N18,CS305!Q18,CS305!T18),0) -> 1.5 | N8: =IFERROR(AVERAGE(CS305!E18,CS305!H18,CS305!K18,CS305!N18,CS305!Q18,CS305!T18)/3*100,0) -> 50 | O8: =IFERROR(AVERAGE(CS301!E18,CS301!H18,CS301!K18,CS301!N18,CS301!Q18,CS302!E18,CS302!H18,CS302!K18,CS302!N18,CS302!Q18,CS303!E18,CS303!H18,CS303!K18,CS303!N18,CS303!Q18,CS304!E18,CS304!H18,CS304!K18,CS304!N18,CS304!Q18,CS305!E18,CS305!H18,CS305!K18,CS305!N18,CS305!Q18,CS305!T18),0) -> 0.92307692 | P8: =IFERROR(O8/3*100,0) -> 30.769231
A9: 3 | B9: PO7 | C9: Environment and Sustainability | D9: Understand the impact of engineering solutions in societal and environmental contexts | E9: =IFERROR(AVERAGE(CS301!E25,CS301!H25,CS301!K25,CS301!N25,CS301!Q25),0) -> 0 | F9: =IFERROR(AVERAGE(CS301!E25,CS301!H25,CS301!K25,CS301!N25,CS301!Q25)/3*100,0) -> 0 | G9: =IFERROR(AVERAGE(CS302!E25,CS302!H25,CS302!K25,CS302!N25,CS302!Q25),0) -> 0 | H9: =IFERROR(AVERAGE(CS302!E25,CS302!H25,CS302!K25,CS302!N25,CS302!Q25)/3*100,0) -> 0 | I9: =IFERROR(AVERAGE(CS303!E25,CS303!H25,CS303!K25,CS303!N25,CS303!Q25),0) -> 0 | J9: =IFERROR(AVERAGE(CS303!E25,CS303!H25,CS303!K25,CS303!N25,CS303!Q25)/3*100,0) -> 0 | K9: =IFERROR(AVERAGE(CS304!E25,CS304!H25,CS304!K25,CS304!N25,CS304!Q25),0) -> 0 | L9: =IFERROR(AVERAGE(CS304!E25,CS304!H25,CS304!K25,CS304!N25,CS304!Q25)/3*100,0) -> 0 | M9: =IFERROR(AVERAGE(CS305!E25,CS305!H25,CS305!K25,CS305!N25,CS305!Q25,CS305!T25),0) -> 1 | N9: =IFERROR(AVERAGE(CS305!E25,CS305!H25,CS305!K25,CS305!N25,CS305!Q25,CS305!T25)/3*100,0) -> 33.333333 | O9: =IFERROR(AVERAGE(CS301!E25,CS301!H25,CS301!K25,CS301!N25,CS301!Q25,CS302!E25,CS302!H25,CS302!K25,CS302!N25,CS302!Q25,CS303!E25,CS303!H25,CS303!K25,CS303!N25,CS303!Q25,CS304!E25,CS304!H25,CS304!K25,CS304!N25,CS304!Q25,CS305!E25,CS305!H25,CS305!K25,CS305!N25,CS305!Q25,CS305!T25),0) -> 0.23076923 | P9: =IFERROR(O9/3*100,0) -> 7.6923077
A10: 4 | B10: PO8 | C10: Ethics | D10: Apply ethical principles and commit to professional ethics, responsibilities and norms | E10: =IFERROR(AVERAGE(CS301!E32,CS301!H32,CS301!K32,CS301!N32,CS301!Q32),0) -> 2.4 | F10: =IFERROR(AVERAGE(CS301!E32,CS301!H32,CS301!K32,CS301!N32,CS301!Q32)/3*100,0) -> 80 | G10: =IFERROR(AVERAGE(CS302!E32,CS302!H32,CS302!K32,CS302!N32,CS302!Q32),0) -> 3 | H10: =IFERROR(AVERAGE(CS302!E32,CS302!H32,CS302!K32,CS302!N32,CS302!Q32)/3*100,0) -> 100 | I10: =IFERROR(AVERAGE(CS303!E32,CS303!H32,CS303!K32,CS303!N32,CS303!Q32),0) -> 3 | J10: =IFERROR(AVERAGE(CS303!E32,CS303!H32,CS303!K32,CS303!N32,CS303!Q32)/3*100,0) -> 100 | K10: =IFERROR(AVERAGE(CS304!E32,CS304!H32,CS304!K32,CS304!N32,CS304!Q32),0) -> 2.4 | L10: =IFERROR(AVERAGE(CS304!E32,CS304!H32,CS304!K32,CS304!N32,CS304!Q32)/3*100,0) -> 80 | M10: =IFERROR(AVERAGE(CS305!E32,CS305!H32,CS305!K32,CS305!N32,CS305!Q32,CS305!T32),0) -> 2.5 | N10: =IFERROR(AVERAGE(CS305!E32,CS305!H32,CS305!K32,CS305!N32,CS305!Q32,CS305!T32)/3*100,0) -> 83.333333 | O10: =IFERROR(AVERAGE(CS301!E32,CS301!H32,CS301!K32,CS301!N32,CS301!Q32,CS302!E32,CS302!H32,CS302!K32,CS302!N32,CS302!Q32,CS303!E32,CS303!H32,CS303!K32,CS303!N32,CS303!Q32,CS304!E32,CS304!H32,CS304!K32,CS304!N32,CS304!Q32,CS305!E32,CS305!H32,CS305!K32,CS305!N32,CS305!Q32,CS305!T32),0) -> 2.6538462 | P10: =IFERROR(O10/3*100,0) -> 88.461538
A11: 5 | B11: PO9 | C11: Individual and Team Work | D11: Function effectively as an individual, and as a member or leader in diverse teams | E11: =IFERROR(AVERAGE(CS301!E39,CS301!H39,CS301!K39,CS301!N39,CS301!Q39),0) -> 3 | F11: =IFERROR(AVERAGE(CS301!E39,CS301!H39,CS301!K39,CS301!N39,CS301!Q39)/3*100,0) -> 100 | G11: =IFERROR(AVERAGE(CS302!E39,CS302!H39,CS302!K39,CS302!N39,CS302!Q39),0) -> 3 | H11: =IFERROR(AVERAGE(CS302!E39,CS302!H39,CS302!K39,CS302!N39,CS302!Q39)/3*100,0) -> 100 | I11: =IFERROR(AVERAGE(CS303!E39,CS303!H39,CS303!K39,CS303!N39,CS303!Q39),0) -> 3 | J11: =IFERROR(AVERAGE(CS303!E39,CS303!H39,CS303!K39,CS303!N39,CS303!Q39)/3*100,0) -> 100 | K11: =IFERROR(AVERAGE(CS304!E39,CS304!H39,CS304!K39,CS304!N39,CS304!Q39),0) -> 3 | L11: =IFERROR(AVERAGE(CS304!E39,CS304!H39,CS304!K39,CS304!N39,CS304!Q39)/3*100,0) -> 100 | M11: =IFERROR(AVERAGE(CS305!E39,CS305!H39,CS305!K39,CS305!N39,CS305!Q39,CS305!T39),0) -> 3 | N11: =IFERROR(AVERAGE(CS305!E39,CS305!H39,CS305!K39,CS305!N39,CS305!Q39,CS305!T39)/3*100,0) -> 100 | O11: =IFERROR(AVERAGE(CS301!E39,CS301!H39,CS301!K39,CS301!N39,CS301!Q39,CS302!E39,CS302!H39,CS302!K39,CS302!N39,CS302!Q39,CS303!E39,CS303!H39,CS303!K39,CS303!N39,CS303!Q39,CS304!E39,CS304!H39,CS304!K39,CS304!N39,CS304!Q39,CS305!E39,CS305!H39,CS305!K39,CS305!N39,CS305!Q39,CS305!T39),0) -> 3 | P11: =IFERROR(O11/3*100,0) -> 100
A12: 6 | B12: PO10 | C12: Communication | D12: Communicate effectively on complex engineering activities | E12: =IFERROR(AVERAGE(CS301!E46,CS301!H46,CS301!K46,CS301!N46,CS301!Q46),0) -> 3 | F12: =IFERROR(AVERAGE(CS301!E46,CS301!H46,CS301!K46,CS301!N46,CS301!Q46)/3*100,0) -> 100 | G12: =IFERROR(AVERAGE(CS302!E46,CS302!H46,CS302!K46,CS302!N46,CS302!Q46),0) -> 3 | H12: =IFERROR(AVERAGE(CS302!E46,CS302!H46,CS302!K46,CS302!N46,CS302!Q46)/3*100,0) -> 100 | I12: =IFERROR(AVERAGE(CS303!E46,CS303!H46,CS303!K46,CS303!N46,CS303!Q46),0) -> 3 | J12: =IFERROR(AVERAGE(CS303!E46,CS303!H46,CS303!K46,CS303!N46,CS303!Q46)/3*100,0) -> 100 | K12: =IFERROR(AVERAGE(CS304!E46,CS304!H46,CS304!K46,CS304!N46,CS304!Q46),0) -> 3 | L12: =IFERROR(AVERAGE(CS304!E46,CS304!H46,CS304!K46,CS304!N46,CS304!Q46)/3*100,0) -> 100 | M12: =IFERROR(AVERAGE(CS305!E46,CS305!H46,CS305!K46,CS305!N46,CS305!Q46,CS305!T46),0) -> 3 | N12: =IFERROR(AVERAGE(CS305!E46,CS305!H46,CS305!K46,CS305!N46,CS305!Q46,CS305!T46)/3*100,0) -> 100 | O12: =IFERROR(AVERAGE(CS301!E46,CS301!H46,CS301!K46,CS301!N46,CS301!Q46,CS302!E46,CS302!H46,CS302!K46,CS302!N46,CS302!Q46,CS303!E46,CS303!H46,CS303!K46,CS303!N46,CS303!Q46,CS304!E46,CS304!H46,CS304!K46,CS304!N46,CS304!Q46,CS305!E46,CS305!H46,CS305!K46,CS305!N46,CS305!Q46,CS305!T46),0) -> 3 | P12: =IFERROR(O12/3*100,0) -> 100
A13: 7 | B13: PO11 | C13: Project Management and Finance | D13: Demonstrate knowledge and understanding of engineering management and financial principles | E13: =IFERROR(AVERAGE(CS301!E53,CS301!H53,CS301!K53,CS301!N53,CS301!Q53),0) -> 1.2 | F13: =IFERROR(AVERAGE(CS301!E53,CS301!H53,CS301!K53,CS301!N53,CS301!Q53)/3*100,0) -> 40 | G13: =IFERROR(AVERAGE(CS302!E53,CS302!H53,CS302!K53,CS302!N53,CS302!Q53),0) -> 2.4 | H13: =IFERROR(AVERAGE(CS302!E53,CS302!H53,CS302!K53,CS302!N53,CS302!Q53)/3*100,0) -> 80 | I13: =IFERROR(AVERAGE(CS303!E53,CS303!H53,CS303!K53,CS303!N53,CS303!Q53),0) -> 1.8 | J13: =IFERROR(AVERAGE(CS303!E53,CS303!H53,CS303!K53,CS303!N53,CS303!Q53)/3*100,0) -> 60 | K13: =IFERROR(AVERAGE(CS304!E53,CS304!H53,CS304!K53,CS304!N53,CS304!Q53),0) -> 1.2 | L13: =IFERROR(AVERAGE(CS304!E53,CS304!H53,CS304!K53,CS304!N53,CS304!Q53)/3*100,0) -> 40 | M13: =IFERROR(AVERAGE(CS305!E53,CS305!H53,CS305!K53,CS305!N53,CS305!Q53,CS305!T53),0) -> 3 | N13: =IFERROR(AVERAGE(CS305!E53,CS305!H53,CS305!K53,CS305!N53,CS305!Q53,CS305!T53)/3*100,0) -> 100 | O13: =IFERROR(AVERAGE(CS301!E53,CS301!H53,CS301!K53,CS301!N53,CS301!Q53,CS302!E53,CS302!H53,CS302!K53,CS302!N53,CS302!Q53,CS303!E53,CS303!H53,CS303!K53,CS303!N53,CS303!Q53,CS304!E53,CS304!H53,CS304!K53,CS304!N53,CS304!Q53,CS305!E53,CS305!H53,CS305!K53,CS305!N53,CS305!Q53,CS305!T53),0) -> 1.9615385 | P13: =IFERROR(O13/3*100,0) -> 65.384615
A14: 8 | B14: PO12 | C14: Life-long Learning | D14: Recognize the need for and engage in independent learning for continual professional development | E14: =IFERROR(AVERAGE(CS301!E60,CS301!H60,CS301!K60,CS301!N60,CS301!Q60),0) -> 2.4 | F14: =IFERROR(AVERAGE(CS301!E60,CS301!H60,CS301!K60,CS301!N60,CS301!Q60)/3*100,0) -> 80 | G14: =IFERROR(AVERAGE(CS302!E60,CS302!H60,CS302!K60,CS302!N60,CS302!Q60),0) -> 2.4 | H14: =IFERROR(AVERAGE(CS302!E60,CS302!H60,CS302!K60,CS302!N60,CS302!Q60)/3*100,0) -> 80 | I14: =IFERROR(AVERAGE(CS303!E60,CS303!H60,CS303!K60,CS303!N60,CS303!Q60),0) -> 1.8 | J14: =IFERROR(AVERAGE(CS303!E60,CS303!H60,CS303!K60,CS303!N60,CS303!Q60)/3*100,0) -> 60 | K14: =IFERROR(AVERAGE(CS304!E60,CS304!H60,CS304!K60,CS304!N60,CS304!Q60),0) -> 1.8 | L14: =IFERROR(AVERAGE(CS304!E60,CS304!H60,CS304!K60,CS304!N60,CS304!Q60)/3*100,0) -> 60 | M14: =IFERROR(AVERAGE(CS305!E60,CS305!H60,CS305!K60,CS305!N60,CS305!Q60,CS305!T60),0) -> 3 | N14: =IFERROR(AVERAGE(CS305!E60,CS305!H60,CS305!K60,CS305!N60,CS305!Q60,CS305!T60)/3*100,0) -> 100 | O14: =IFERROR(AVERAGE(CS301!E60,CS301!H60,CS301!K60,CS301!N60,CS301!Q60,CS302!E60,CS302!H60,CS302!K60,CS302!N60,CS302!Q60,CS303!E60,CS303!H60,CS303!K60,CS303!N60,CS303!Q60,CS304!E60,CS304!H60,CS304!K60,CS304!N60,CS304!Q60,CS305!E60,CS305!H60,CS305!K60,CS305!N60,CS305!Q60,CS305!T60),0) -> 2.3076923 | P14: =IFERROR(O14/3*100,0) -> 76.923077
