Workbook

Sheet Guidelines
A1: CO–PO MAPPING: KEYWORDS / ACTION VERBS METHOD — Auto-Calculation Workbook
A2: Based on: NBA OBE Guidelines | Method D: Keyword-Based CO–PO Mapping | Action verbs in CO statements determine mapping strength
A4: MAPPING LEVEL CRITERIA (from CO-PO Mapping Guidelines Document — Section D: Keywords Method)
A5: Level | B5: Symbol | C5: Bloom's Level | D5: CO Keyword Match | E5: Meaning | F5: Example
A6: No Mapping | B6: — | C6: LOTS (1–2) | D6: Keywords unrelated to PO | E6: CO keyword has no connection to PO competency | F6: CO: 'List definitions of microwave components' → PO3(Design): No Mapping
A7: Low | B7: 1 | C7: LOTS (1–2) | D7: Partial PO reflection through action verbs | E7: Small portion of PO reflected through keyword | F7: CO: 'Explain MATLAB tools' → PO5(Modern Tool): Low (explain is partial, not using)
A8: Medium | B8: 2 | C8: HOTS (3–4) | D8: Major part of PO reflected, moderate performance | E8: Action verb matches major PO competency | F8: CO: 'Analyze segmentation techniques' → PO2(Problem Analysis): Medium
A9: High | B9: 3 | C9: HOTS (5–6) | D9: Exact PO action verb + critical performance | E9: Exact keyword of PO and high-level performance expected | F9: CO: 'Design a digital system' → PO3(Design/Development): High
A11: BLOOM'S TAXONOMY — ACTION VERBS REFERENCE
A12: Level | B12: Name | C12: Order | D12: Action Verbs | E12: Typical Mapping
A13: L1 | B13: Remember | C13: LOTS | D13: Define | List | Recall | State | Identify | Name | Label | Describe | Recognize | I13: Low (1) or No Map
A14: L2 | B14: Understand | C14: LOTS | D14: Explain | Summarize | Interpret | Classify | Compare | Discuss | Paraphrase | Predict | I14: Low (1) or No Map
A15: L3 | B15: Apply | C15: HOTS | D15: Apply | Use | Implement | Solve | Demonstrate | Calculate | Execute | Operate | I15: Medium (2)
A16: L4 | B16: Analyze | C16: HOTS | D16: Analyze | Differentiate | Examine | Compare | Contrast | Break down | Organize | Attribute | I16: Medium (2)
A17: L5 | B17: Evaluate | C17: HOTS | D17: Evaluate | Assess | Judge | Justify | Critique | Test | Defend | Prioritize | I17: High (3)
A18: L6 | B18: Create | C18: HOTS | D18: Design | Develop | Construct | Formulate | Produce | Plan | Create | Invent | Build | I18: High (3)
A20: PO KEYWORDS REFERENCE (Key competency verbs per Programme Outcome)
A21: PO | B21: Description | C21: Key Matching Keywords
A22: PO1 | B22: Engineering Knowledge | C22: Apply | Knowledge | Engineering principles | Fundamentals | Concepts
A23: PO2 | B23: Problem Analysis | C23: Analyze | Problem | Complex | Investigate | Identify
A24: PO3 | B24: Design/Development of Solutions | C24: Design | Develop | Construct | Formulate | Create solutions
A25: PO4 | B25: Conduct Investigations | C25: Investigate | Experiment | Analyze data | Research | Conduct
A26: PO5 | B26: Modern Tool Usage | C26: Use tools | Implement | Simulate | Modern technology | Software
A27: PO6 | B27: The Engineer and Society | C27: Evaluate society | Social impact | Professional practice | Responsibility
A28: PO7 | B28: Environment and Sustainability | C28: Sustainability | Environment | Green | Eco-friendly | Conservation
A29: PO8 | B29: Ethics | C29: Ethics | Professional ethics | Integrity | Responsibility | Ethical
A30: PO9 | B30: Individual and Team Work | C30: Teamwork | Collaborate | Individual | Group | Lead
A31: PO10 | B31: Communication | C31: Communicate | Present | Report | Document | Write
A32: PO11 | B32: Project Management and Finance | C32: Project management | Plan | Finance | Schedule | Budget
A33: PO12 | B33: Life-long Learning | C33: Lifelong learning | Self-learn | Research | Adapt | Explore
A35: EXCEL FORMULA LOGIC USED IN THIS WORKBOOK
A36: Step | B36: Logic / Formula | C36: Notes
A37: Bloom Level Input | B37: Faculty enters Bloom level (1–6) in yellow cell | C37: Based on primary action verb in CO statement
A38: Keyword Match Score | B38: Faculty enters 0–3 per PO in yellow cell | C38: 0=No Match, 1=Partial, 2=Major, 3=Exact match
A39: Mapping Level | B39: IF(kw_score >= 4, 3, IF(kw_score >= 3, 2, IF(kw_score >= 1, 1, 0))) | C39: Bloom level gates the maximum possible mapping level
A40: Symbol | B40: IF(bloom_level <= 2, MIN(kw_score, 1), IF(bloom_level <= 4, MIN(kw_score, 2), kw_score)) | C40: Shown in CO-PO matrix
A41: Bloom Category | B41: IF(level = 0, "—", TEXT(level, "0")) | C41: Low/High Order Thinking Skills
A42: Justification | B42: Faculty types justification text in dedicated cell | C42: Required for NBA documentation
A44: HOW TO USE THIS WORKBOOK
A45: 1. Open any course sheet (CS301–CS305) → Read the pre-filled CO statement and keyword
...

Sheet CS301
A1: KEYWORDS CO–PO MAPPING — Data Structures & Algorithms (CS301)
A2: Method D: Enter Bloom Level (1–6) and Keyword Match Score (0–3) per PO in YELLOW cells | Level = IF(score=0, 0, IF(bloom≤2, min(score,1), IF(bloom≤4, min(score,2), score)))
A4: Score Guide → | C4: 0 = No Match | D4: 1 = Partial Match | E4: 2 = Major Match | F4: 3 = Exact Match | G4: Bloom: 1=Remember 2=Understand 3=Apply 4=Analyze 5=Evaluate 6=Create
A5: SECTION 1 — CO INFORMATION (Enter Bloom Level in yellow cell)
A6: CO | B6: CO Statement / Description | C6: Primary Keyword | D6: Bloom Level (1–6) | E6: Bloom Name | F6: Order (LOTS/HOTS) | G6: CO Statement Example justification
A7: CO1 | B7: Apply fundamental data structures including arrays, linked lists, stacks and queues to solve computational problems | C7: Apply | D7: 3 | E7: =CHOOSE(D7,"Remember","Understand","Apply","Analyze","Evaluate","Create") -> Apply | F7: =IF(D7<=2,"LOTS","HOTS") -> HOTS | G7: Apply (Apply) — Apply + engineering knowledge → Major PO1 reflection
A8: CO2 | B8: Analyze tree structures and binary search algorithms to evaluate their efficiency and performance | C8: Analyze | D8: 4 | E8: =CHOOSE(D8,"Remember","Understand","Apply","Analyze","Evaluate","Create") -> Analyze | F8: =IF(D8<=2,"LOTS","HOTS") -> HOTS | G8: Analyze (Analyze) — Analyze needs engineering knowledge
A9: CO3 | B9: Design and implement graph algorithms including BFS, DFS and shortest path algorithms | C9: Design | D9: 6 | E9: =CHOOSE(D9,"Remember","Understand","Apply","Analyze","Evaluate","Create") -> Create | F9: =IF(D9<=2,"LOTS","HOTS") -> HOTS | G9: Design (Create) — Design requires engineering knowledge
A10: CO4 | B10: Evaluate and compare sorting and searching algorithms based on time and space complexity | C10: Evaluate | D10: 5 | E10: =CHOOSE(D10,"Remember","Understand","Apply","Analyze","Evaluate","Create") -> Evaluate | F10: =IF(D10<=2,"LOTS","HOTS") -> HOTS | G10: Evaluate (Evaluate) — Evaluation needs engineering knowledge
A11: CO5 | B11: Implement hashing techniques and analyze algorithm complexity for real-world applications | C11: Implement | D11: 3 | E11: =CHOOSE(D11,"Remember","Understand","Apply","Analyze","Evaluate","Create") -> Apply | F11: =IF(D11<=2,"LOTS","HOTS") -> HOTS | G11: Implement (Apply) — Implementation needs engineering knowledge
A13: SECTION 2 — CO–PO/PSO KEYWORD MAPPING (Enter Keyword Match Score 0–3 in YELLOW cells per PO per CO)
A14: PO / PSO | B14: PO Description | C14: CO1 KW Score | D14: CO1 Level | E14: CO1 Justification | F14: CO2 KW Score | G14: CO2 Level | H14: CO2 Justification | I14: CO3 KW Score | J14: CO3 Level | K14: CO3 Justification | L14: CO4 KW Score | M14: CO4 Level | N14: CO4 Justification | O14: CO5 KW Score | P14: CO5 Level | Q14: CO5 Justification
A15: PO1 | B15: Engineering Knowledge | C15: 2 | D15: =IFERROR(IF(C15=0,0,IF(D7<=2,MIN(C15,1),IF(D7<=4,MIN(C15,2),C15))),0) -> 2 | E15: Apply + engineering knowledge → Major PO1 reflection | F15: 2 | G15: =IFERROR(IF(F15=0,0,IF(D8<=2,MIN(F15,1),IF(D8<=4,MIN(F15,2),F15))),0) -> 2 | H15: Analyze needs engineering knowledge | I15: 2 | J15: =IFERROR(IF(I15=0,0,IF(D9<=2,MIN(I15,1),IF(D9<=4,MIN(I15,2),I15))),0) -> 2 | K15: Design requires engineering knowledge | L15: 2 | M15: =IFERROR(IF(L15=0,0,IF(D10<=2,MIN(L15,1),IF(D10<=4,MIN(L15,2),L15))),0) -> 2 | N15: Evaluation needs engineering knowledge | O15: 2 | P15: =IFERROR(IF(O15=0,0,IF(D11<=2,MIN(O15,1),IF(D11<=4,MIN(O15,2),O15))),0) -> 2 | Q15: Implementation needs engineering knowledge
A16: PO2 | B16: Problem Analysis | C16: 2 | D16: =IFERROR(IF(C16=0,0,IF(D7<=2,MIN(C16,1),IF(D7<=4,MIN(C16,2),C16))),0) -> 2 | E16: Apply to solve problems → moderate PO2 contribution | F16: 3 | G16: =IFERROR(IF(F16=0,0,IF(D8<=2,MIN(F16,1),IF(D8<=4,MIN(F16,2),F16))),0) -> 2 | H16: Analyze exactly matches PO2 — problem analysis | I16: 2 | J16: =IFERROR(IF(I16=0,0,IF(D9<=2,MIN(I16,1),IF(D9<=4,MIN(I16,2),I16))),0) -> 2 | K16: Design involves problem analysis | L16: 3 | M16: =IFERROR(IF(L16=0,0,IF(D10<=2,MIN(L16,1),IF(D10<=4,MIN(L16,2),L16))),0) -> 3 | N16: Evaluate complex problems → exact PO2 match | O16: 2 | P16: =IFERROR(IF(O16=0,0,IF(D11<=2,MIN(O16,1),IF(D11<=4,MIN(O16,2),O16))),0) -> 2 | Q16: Implementation for problem solving
A17: PO3 | B17: Design/Development of Solutions | C17: 0 | D17: =IFERROR(IF(C17=0,0,IF(D7<=2,MIN(C17,1),IF(D7<=4,MIN(C17,2),C17))),0) -> 0 | F17: 0 | G17: =IFERROR(IF(F17=0,0,IF(D8<=2,MIN(F17,1),IF(D8<=4,MIN(F17,2),F17))),0) -> 0 | I17: 3 | J17: =IFERROR(IF(I17=0,0,IF(D9<=2,MIN(I17,1),IF(D9<=4,MIN(I17,2),I17))),0) -> 3 | K17: Design exactly matches PO3 — critical performance | L17: 0 | M17: =IFERROR(IF(L17=0,0,IF(D10<=2,MIN(L17,1),IF(D10<=4,MIN(L17,2),L17))),0) -> 0 | O17: 0 | P17: =IFERROR(IF(O17=0,0,IF(D11<=2,MIN(O17,1),IF(D11<=4,MIN(O17,2),O17))),0) -> 0
A18: PO4 | B18: Conduct Investigations | C18: 0 | D18: =IFERROR(IF(C18=0,0,IF(D7<=2,MIN(C18,1),IF(D7<=4,MIN(C18,2),C18))),0) -> 0 | F18: 2 | G18: =IFERROR(IF(F18=0,0,IF(D8<=2,MIN(F18,1),IF(D8<=4,MIN(F18,2),F18))),0) -> 2 | H18: Analysis involves investigation methods | I18: 0 | J18: =IFERROR(IF(I18=0,0,IF(D9<=2,MIN(I18,1),IF(D9<=4,MIN(I18,2),I18))),0) -> 0 | L18: 2 | M18: =IFERROR(IF(L18=0,0,IF(D10<=2,MIN(L18,1),IF(D10<=4,MIN(L18,2),L18))),0) -> 2 | N18: Evaluate through investigation | O18: 0 | P18: =IFERROR(IF(O18=0,0,IF(D11<=2,MIN(O18,1),IF(D11<=4,MIN(O18,2),O18))),0) -> 0
A19: PO5 | B19: Modern Tool Usage | C19: 1 | D19: =IFERROR(IF(C19=0,0,IF(D7<=2,MIN(C19,1),IF(D7<=4,MIN(C19,2),C19))),0) -> 1 | E19: Partial tool usage through implementation | F19: 0 | G19: =IFERROR(IF(F19=0,0,IF(D8<=2,MIN(F19,1),IF(D8<=4,MIN(F19,2),F19))),0) -> 0 | I19: 2 | J19: =IFERROR(IF(I19=0,0,IF(D9<=2,MIN(I19,1),IF(D9<=4,MIN(I19,2),I19))),0) -> 2 | K19: Implement using modern tools | L19: 0 | M19: =IFERROR(IF(L19=0,0,IF(D10<=2,MIN(L19,1),IF(D10<=4,MIN(L19,2),L19))),0) -> 0 | O19: 2 | P19: =IFERROR(IF(O19=0,0,IF(D11<=2,MIN(O19,1),IF(D11<=4,MIN(O19,2),O19))),0) -> 2 | Q19: Implement using modern CS tools
A20: PO6 | B20: The Engineer and Society | C20: 0 | D20: =IFERROR(IF(C20=0,0,IF(D7<=2,MIN(C20,1),IF(D7<=4,MIN(C20,2),C20))),0) -> 0 | F20: 0 | G20: =IFERROR(IF(F20=0,0,IF(D8<=2,MIN(F20,1),IF(D8<=4,MIN(F20,2),F20))),0) -> 0 | I20: 0 | J20: =IFERROR(IF(I20=0,0,IF(D9<=2,MIN(I20,1),IF(D9<=4,MIN(I20,2),I20))),0) -> 0 | L20: 0 | M20: =IFERROR(IF(L20=0,0,IF(D10<=2,MIN(L20,1),IF(D10<=4,MIN(L20,2),L20))),0) -> 0 | O20: 0 | P20: =IFERROR(IF(O20=0,0,IF(D11<=2,MIN(O20,1),IF(D11<=4,MIN(O20,2),O20))),0) -> 0
A21: PO7 | B21: Environment and Sustainability | C21: 0 | D21: =IFERROR(IF(C21=0,0,IF(D7<=2,MIN(C21,1),IF(D7<=4,MIN(C21,2),C21))),0) -> 0 | F21: 0 | G21: =IFERROR(IF(F21=0,0,IF(D8<=2,MIN(F21,1),IF(D8<=4,MIN(F21,2),F21))),0) -> 0 | I21: 0 | J21: =IFERROR(IF(I21=0,0,IF(D9<=2,MIN(I21,1),IF(D9<=4,MIN(I21,2),I21))),0) -> 0 | L21: 0 | M21: =IFERROR(IF(L21=0,0,IF(D10<=2,MIN(L21,1),IF(D10<=4,MIN(L21,2),L21))),0) -> 0 | O21: 0 | P21: =IFERROR(IF(O21=0,0,IF(D11<=2,MIN(O21,1),IF(D11<=4,MIN(O21,2),O21))),0) -> 0
A22: PO8 | B22: Ethics | C22: 0 | D22: =IFERROR(IF(C22=0,0,IF(D7<=2,MIN(C22,1),IF(D7<=4,MIN(C22,2),C22))),0) -> 0 | F22: 0 | G22: =IFERROR(IF(F22=0,0,IF(D8<=2,MIN(F22,1),IF(D8<=4,MIN(F22,2),F22))),0) -> 0 | I22: 0 | J22: =IFERROR(IF(I22=0,0,IF(D9<=2,MIN(I22,1),IF(D9<=4,MIN(I22,2),I22))),0) -> 0 | L22: 0 | M22: =IFERROR(IF(L22=0,0,IF(D10<=2,MIN(L22,1),IF(D10<=4,MIN(L22,2),L22))),0) -> 0 | O22: 0 | P22: =IFERROR(IF(O22=0,0,IF(D11<=2,MIN(O22,1),IF(D11<=4,MIN(O22,2),O22))),0) -> 0
A23: PO9 | B23: Individual and Team Work | C23: 0 | D23: =IFERROR(IF(C23=0,0,IF(D7<=2,MIN(C23,1),IF(D7<=4,MIN(C23,2),C23))),0) -> 0 | F23: 0 | G23: =IFERROR(IF(F23=0,0,IF(D8<=2,MIN(F23,1),IF(D8<=4,MIN(F23,2),F23))),0) -> 0 | I23: 0 | J23: =IFERROR(IF(I23=0,0,IF(D9<=2,MIN(I23,1),IF(D9<=4,MIN(I23,2),I23))),0) -> 0 | L23: 0 | M23: =IFERROR(IF(L23=0,0,IF(D10<=2,MIN(L23,1),IF(D10<=4,MIN(L23,2),L23))),0) -> 0 | O23: 0 | P23: =IFERROR(IF(O23=0,0,IF(D11<=2,MIN(O23,1),IF(D11<=4,MIN(O23,2),O23))),0) -> 0
A24: PO10 | B24: Communication | C24: 0 | D24: =IFERROR(IF(C24=0,0,IF(D7<=2,MIN(C24,1),IF(D7<=4,MIN(C24,2),C24))),0) -> 0 | F24: 0 | G24: =IFERROR(IF(F24=0,0,IF(D8<=2,MIN(F24,1),IF(D8<=4,MIN(F24,2),F24))),0) -> 0 | I24: 0 | J24: =IFERROR(IF(I24=0,0,IF(D9<=2,MIN(I24,1),IF(D9<=4,MIN(I24,2),I24))),0) -> 0 | L24: 0 | M24: =IFERROR(IF(L24=0,0,IF(D10<=2,MIN(L24,1),IF(D10<=4,MIN(L24,2),L24))),0) -> 0 | O24: 0 | P24: =IFERROR(IF(O24=0,0,IF(D11<=2,MIN(O24,1),IF(D11<=4,MIN(O24,2),O24))),0) -> 0
A25: PO11 | B25: Project Management and Finance | C25: 0 | D25: =IFERROR(IF(C25=0,0,IF(D7<=2,MIN(C25,1),IF(D7<=4,MIN(C25,2),C25))),0) -> 0 | F25: 0 | G25: =IFERROR(IF(F25=0,0,IF(D8<=2,MIN(F25,1),IF(D8<=4,MIN(F25,2),F25))),0) -> 0 | I25: 0 | J25: =IFERROR(IF(I25=0,0,IF(D9<=2,MIN(I25,1),IF(D9<=4,MIN(I25,2),I25))),0) -> 0 | L25: 0 | M25: =IFERROR(IF(L25=0,0,IF(D10<=2,MIN(L25,1),IF(D10<=4,MIN(L25,2),L25))),0) -> 0 | O25: 0 | P25: =IFERROR(IF(O25=0,0,IF(D11<=2,MIN(O25,1),IF(D11<=4,MIN(O25,2),O25))),0) -> 0
A26: PO12 | B26: Life-long Learning | C26: 1 | D26: =IFERROR(IF(C26=0,0,IF(D7<=2,MIN(C26,1),IF(D7<=4,MIN(C26,2),C26))),0) -> 1 | E26: Small contribution to lifelong learning | F26: 1 | G26: =IFERROR(IF(F26=0,0,IF(D8<=2,MIN(F26,1),IF(D8<=4,MIN(F26,2),F26))),0) -> 1 | H26: Research orientation for lifelong learning | I26: 2 | J26: =IFERROR(IF(I26=0,0,IF(D9<=2,MIN(I26,1),IF(D9<=4,MIN(I26,2),I26))),0) -> 2 | K26: Major lifelong learning contribution | L26: 2 | M26: =IFERROR(IF(L26=0,0,IF(D10<=2,MIN(L26,1),IF(D10<=4,MIN(L26,2),L26))),0) -> 2 | N26: Research-based evaluation contributes to PO12 | O26: 1 | P26: =IFERROR(IF(O26=0,0,IF(D11<=2,MIN(O26,1),IF(D11<=4,MIN(O26,2),O26))),0) -> 1 | Q26: Partial lifelong learning
A27: PSO1 | B27: Apply core CS concepts to design software systems | C27: 3 | D27: =IFERROR(IF(C27=0,0,IF(D7<=2,MIN(C27,1),IF(D7<=4,MIN(C27,2),C27))),0) -> 2 | E27: Direct CS concept application | F27: 3 | G27: =IFERROR(IF(F27=0,0,IF(D8<=2,MIN(F27,1),IF(D8<=4,MIN(F27,2),F27))),0) -> 2 | H27: Core CS analysis skill | I27: 3 | J27: =IFERROR(IF(I27=0,0,IF(D9<=2,MIN(I27,1),IF(D9<=4,MIN(I27,2),I27))),0) -> 3 | K27: Core design skill | L27: 3 | M27: =IFERROR(IF(L27=0,0,IF(D10<=2,MIN(L27,1),IF(D10<=4,MIN(L27,2),L27))),0) -> 3 | N27: CS evaluation skill | O27: 2 | P27: =IFERROR(IF(O27=0,0,IF(D11<=2,MIN(O27,1),IF(D11<=4,MIN(O27,2),O27))),0) -> 2 | Q27: CS implementation
A28: PSO2 | B28: Use modern tools to solve real-world engineering problems | C28: 2 | D28: =IFERROR(IF(C28=0,0,IF(D7<=2,MIN(C28,1),IF(D7<=4,MIN(C28,2),C28))),0) -> 2 | E28: Tool implementation | F28: 1 | G28: =IFERROR(IF(F28=0,0,IF(D8<=2,MIN(F28,1),IF(D8<=4,MIN(F28,2),F28))),0) -> 1 | H28: Partial tool relevance | I28: 3 | J28: =IFERROR(IF(I28=0,0,IF(D9<=2,MIN(I28,1),IF(D9<=4,MIN(I28,2),I28))),0) -> 3 | K28: Modern tool usage | L28: 2 | M28: =IFERROR(IF(L28=0,0,IF(D10<=2,MIN(L28,1),IF(D10<=4,MIN(L28,2),L28))),0) -> 2 | N28: Tool-based evaluation | O28: 3 | P28: =IFERROR(IF(O28=0,0,IF(D11<=2,MIN(O28,1),IF(D11<=4,MIN(O28,2),O28))),0) -> 2 | Q28: Modern tool implementation
A29: PSO3 | B29: Demonstrate professional skills for industry/research | C29: 0 | D29: =IFERROR(IF(C29=0,0,IF(D7<=2,MIN(C29,1),IF(D7<=4,MIN(C29,2),C29))),0) -> 0 | F29: 0 | G29: =IFERROR(IF(F29=0,0,IF(D8<=2,MIN(F29,1),IF(D8<=4,MIN(F29,2),F29))),0) -> 0 | I29: 2 | J29: =IFERROR(IF(I29=0,0,IF(D9<=2,MIN(I29,1),IF(D9<=4,MIN(I29,2),I29))),0) -> 2 | K29: Professional skill | L29: 0 | M29: =IFERROR(IF(L29=0,0,IF(D10<=2,MIN(L29,1),IF(D10<=4,MIN(L29,2),L29))),0) -> 0 | O29: 2 | P29: =IFERROR(IF(O29=0,0,IF(D11<=2,MIN(O29,1),IF(D11<=4,MIN(O29,2),O29))),0) -> 2 | Q29: Industry skill
A31: AVERAGE MAPPING LEVEL PER CO | D31: =IFERROR(AVERAGE(D15:D29),0) -> 0.66666667 | G31: =IFERROR(AVERAGE(G15:G29),0) -> 0.66666667 | J31: =IFERROR(AVERAGE(J15:J29),0) -> 1.2666667 | M31: =IFERROR(AVERAGE(M15:M29),0) -> 0.93333333 | P31: =IFERROR(AVERAGE(P15:P29),0) -> 0.86666667

Sheet CS302
A1: KEYWORDS CO–PO MAPPING — Database Management Systems (CS302)
A2: Method D: Enter Bloom Level (1–6) and Keyword Match Score (0–3) per PO in YELLOW cells | Level = IF(score=0, 0, IF(bloom≤2, min(score,1), IF(bloom≤4, min(score,2), score)))
A4: Score Guide → | C4: 0 = No Match | D4: 1 = Partial Match | E4: 2 = Major Match | F4: 3 = Exact Match | G4: Bloom: 1=Remember 2=Understand 3=Apply 4=Analyze 5=Evaluate 6=Create
A5: SECTION 1 — CO INFORMATION (Enter Bloom Level in yellow cell)
A6: CO | B6: CO Statement / Description | C6: Primary Keyword | D6: Bloom Level (1–6) | E6: Bloom Name | F6: Order (LOTS/HOTS) | G6: CO Statement Example justification
A7: CO1 | B7: Explain the relational model and apply relational algebra to formulate database queries | C7: Explain | D7: 2 | E7: =CHOOSE(D7,"Remember","Understand","Apply","Analyze","Evaluate","Create") -> Understand | F7: =IF(D7<=2,"LOTS","HOTS") -> LOTS | G7: Explain (Understand) — Explain is LOTS — partial PO1 reflection
A8: CO2 | B8: Design and implement SQL queries including DDL and DML statements for complex database operations | C8: Design | D8: 6 | E8: =CHOOSE(D8,"Remember","Understand","Apply","Analyze","Evaluate","Create") -> Create | F8: =IF(D8<=2,"LOTS","HOTS") -> HOTS | G8: Design (Create) — Design needs engineering knowledge
A9: CO3 | B9: Analyze functional dependencies and apply normalization techniques up to BCNF | C9: Analyze | D9: 4 | E9: =CHOOSE(D9,"Remember","Understand","Apply","Analyze","Evaluate","Create") -> Analyze | F9: =IF(D9<=2,"LOTS","HOTS") -> HOTS | G9: Analyze (Analyze) — Analysis needs engineering knowledge
A10: CO4 | B10: Evaluate transaction management techniques and implement concurrency control mechanisms | C10: Evaluate | D10: 5 | E10: =CHOOSE(D10,"Remember","Understand","Apply","Analyze","Evaluate","Create") -> Evaluate | F10: =IF(D10<=2,"LOTS","HOTS") -> HOTS | G10: Evaluate (Evaluate) — Evaluation uses engineering knowledge
A11: CO5 | B11: Design efficient database systems using indexing strategies and query optimization techniques | C11: Design | D11: 6 | E11: =CHOOSE(D11,"Remember","Understand","Apply","Analyze","Evaluate","Create") -> Create | F11: =IF(D11<=2,"LOTS","HOTS") -> HOTS | G11: Design (Create) — Design with engineering knowledge — high PO1
A13: SECTION 2 — CO–PO/PSO KEYWORD MAPPING (Enter Keyword Match Score 0–3 in YELLOW cells per PO per CO)
A14: PO / PSO | B14: PO Description | C14: CO1 KW Score | D14: CO1 Level | E14: CO1 Justification | F14: CO2 KW Score | G14: CO2 Level | H14: CO2 Justification | I14: CO3 KW Score | J14: CO3 Level | K14: CO3 Justification | L14: CO4 KW Score | M14: CO4 Level | N14: CO4 Justification | O14: CO5 KW Score | P14: CO5 Level | Q14: CO5 Justification
A15: PO1 | B15: Engineering Knowledge | C15: 1 | D15: =IFERROR(IF(C15=0,0,IF(D7<=2,MIN(C15,1),IF(D7<=4,MIN(C15,2),C15))),0) -> 1 | E15: Explain is LOTS — partial PO1 reflection | F15: 2 | G15: =IFERROR(IF(F15=0,0,IF(D8<=2,MIN(F15,1),IF(D8<=4,MIN(F15,2),F15))),0) -> 2 | H15: Design needs engineering knowledge | I15: 2 | J15: =IFERROR(IF(I15=0,0,IF(D9<=2,MIN(I15,1),IF(D9<=4,MIN(I15,2),I15))),0) -> 2 | K15: Analysis needs engineering knowledge | L15: 2 | M15: =IFERROR(IF(L15=0,0,IF(D10<=2,MIN(L15,1),IF(D10<=4,MIN(L15,2),L15))),0) -> 2 | N15: Evaluation uses engineering knowledge | O15: 3 | P15: =IFERROR(IF(O15=0,0,IF(D11<=2,MIN(O15,1),IF(D11<=4,MIN(O15,2),O15))),0) -> 3 | Q15: Design with engineering knowledge — high PO1
A16: PO2 | B16: Problem Analysis | C16: 1 | D16: =IFERROR(IF(C16=0,0,IF(D7<=2,MIN(C16,1),IF(D7<=4,MIN(C16,2),C16))),0) -> 1 | E16: Low contribution to problem analysis | F16: 0 | G16: =IFERROR(IF(F16=0,0,IF(D8<=2,MIN(F16,1),IF(D8<=4,MIN(F16,2),F16))),0) -> 0 | I16: 3 | J16: =IFERROR(IF(I16=0,0,IF(D9<=2,MIN(I16,1),IF(D9<=4,MIN(I16,2),I16))),0) -> 2 | K16: Analyze exactly matches PO2 | L16: 3 | M16: =IFERROR(IF(L16=0,0,IF(D10<=2,MIN(L16,1),IF(D10<=4,MIN(L16,2),L16))),0) -> 3 | N16: Evaluate complex problems — exact PO2 | O16: 2 | P16: =IFERROR(IF(O16=0,0,IF(D11<=2,MIN(O16,1),IF(D11<=4,MIN(O16,2),O16))),0) -> 2 | Q16: Design involves problem analysis
A17: PO3 | B17: Design/Development of Solutions | C17: 0 | D17: =IFERROR(IF(C17=0,0,IF(D7<=2,MIN(C17,1),IF(D7<=4,MIN(C17,2),C17))),0) -> 0 | F17: 3 | G17: =IFERROR(IF(F17=0,0,IF(D8<=2,MIN(F17,1),IF(D8<=4,MIN(F17,2),F17))),0) -> 3 | H17: Design exactly matches PO3 — major performance | I17: 0 | J17: =IFERROR(IF(I17=0,0,IF(D9<=2,MIN(I17,1),IF(D9<=4,MIN(I17,2),I17))),0) -> 0 | L17: 0 | M17: =IFERROR(IF(L17=0,0,IF(D10<=2,MIN(L17,1),IF(D10<=4,MIN(L17,2),L17))),0) -> 0 | O17: 3 | P17: =IFERROR(IF(O17=0,0,IF(D11<=2,MIN(O17,1),IF(D11<=4,MIN(O17,2),O17))),0) -> 3 | Q17: Design exactly matches PO3
A18: PO4 | B18: Conduct Investigations | C18: 0 | D18: =IFERROR(IF(C18=0,0,IF(D7<=2,MIN(C18,1),IF(D7<=4,MIN(C18,2),C18))),0) -> 0 | F18: 0 | G18: =IFERROR(IF(F18=0,0,IF(D8<=2,MIN(F18,1),IF(D8<=4,MIN(F18,2),F18))),0) -> 0 | I18: 2 | J18: =IFERROR(IF(I18=0,0,IF(D9<=2,MIN(I18,1),IF(D9<=4,MIN(I18,2),I18))),0) -> 2 | K18: Analysis involves investigation | L18: 2 | M18: =IFERROR(IF(L18=0,0,IF(D10<=2,MIN(L18,1),IF(D10<=4,MIN(L18,2),L18))),0) -> 2 | N18: Investigation of concurrency issues | O18: 0 | P18: =IFERROR(IF(O18=0,0,IF(D11<=2,MIN(O18,1),IF(D11<=4,MIN(O18,2),O18))),0) -> 0
A19: PO5 | B19: Modern Tool Usage | C19: 0 | D19: =IFERROR(IF(C19=0,0,IF(D7<=2,MIN(C19,1),IF(D7<=4,MIN(C19,2),C19))),0) -> 0 | F19: 3 | G19: =IFERROR(IF(F19=0,0,IF(D8<=2,MIN(F19,1),IF(D8<=4,MIN(F19,2),F19))),0) -> 3 | H19: Implement using modern DB tools — exact PO5 match | I19: 0 | J19: =IFERROR(IF(I19=0,0,IF(D9<=2,MIN(I19,1),IF(D9<=4,MIN(I19,2),I19))),0) -> 0 | L19: 0 | M19: =IFERROR(IF(L19=0,0,IF(D10<=2,MIN(L19,1),IF(D10<=4,MIN(L19,2),L19))),0) -> 0 | O19: 2 | P19: =IFERROR(IF(O19=0,0,IF(D11<=2,MIN(O19,1),IF(D11<=4,MIN(O19,2),O19))),0) -> 2 | Q19: Use modern optimization tools
A20: PO6 | B20: The Engineer and Society | C20: 0 | D20: =IFERROR(IF(C20=0,0,IF(D7<=2,MIN(C20,1),IF(D7<=4,MIN(C20,2),C20))),0) -> 0 | F20: 0 | G20: =IFERROR(IF(F20=0,0,IF(D8<=2,MIN(F20,1),IF(D8<=4,MIN(F20,2),F20))),0) -> 0 | I20: 0 | J20: =IFERROR(IF(I20=0,0,IF(D9<=2,MIN(I20,1),IF(D9<=4,MIN(I20,2),I20))),0) -> 0 | L20: 0 | M20: =IFERROR(IF(L20=0,0,IF(D10<=2,MIN(L20,1),IF(D10<=4,MIN(L20,2),L20))),0) -> 0 | O20: 0 | P20: =IFERROR(IF(O20=0,0,IF(D11<=2,MIN(O20,1),IF(D11<=4,MIN(O20,2),O20))),0) -> 0
A21: PO7 | B21: Environment and Sustainability | C21: 0 | D21: =IFERROR(IF(C21=0,0,IF(D7<=2,MIN(C21,1),IF(D7<=4,MIN(C21,2),C21))),0) -> 0 | F21: 0 | G21: =IFERROR(IF(F21=0,0,IF(D8<=2,MIN(F21,1),IF(D8<=4,MIN(F21,2),F21))),0) -> 0 | I21: 0 | J21: =IFERROR(IF(I21=0,0,IF(D9<=2,MIN(I21,1),IF(D9<=4,MIN(I21,2),I21))),0) -> 0 | L21: 0 | M21: =IFERROR(IF(L21=0,0,IF(D10<=2,MIN(L21,1),IF(D10<=4,MIN(L21,2),L21))),0) -> 0 | O21: 0 | P21: =IFERROR(IF(O21=0,0,IF(D11<=2,MIN(O21,1),IF(D11<=4,MIN(O21,2),O21))),0) -> 0
A22: PO8 | B22: Ethics | C22: 0 | D22: =IFERROR(IF(C22=0,0,IF(D7<=2,MIN(C22,1),IF(D7<=4,MIN(C22,2),C22))),0) -> 0 | F22: 0 | G22: =IFERROR(IF(F22=0,0,IF(D8<=2,MIN(F22,1),IF(D8<=4,MIN(F22,2),F22))),0) -> 0 | I22: 0 | J22: =IFERROR(IF(I22=0,0,IF(D9<=2,MIN(I22,1),IF(D9<=4,MIN(I22,2),I22))),0) -> 0 | L22: 0 | M22: =IFERROR(IF(L22=0,0,IF(D10<=2,MIN(L22,1),IF(D10<=4,MIN(L22,2),L22))),0) -> 0 | O22: 0 | P22: =IFERROR(IF(O22=0,0,IF(D11<=2,MIN(O22,1),IF(D11<=4,MIN(O22,2),O22))),0) -> 0
A23: PO9 | B23: Individual and Team Work | C23: 0 | D23: =IFERROR(IF(C23=0,0,IF(D7<=2,MIN(C23,1),IF(D7<=4,MIN(C23,2),C23))),0) -> 0 | F23: 0 | G23: =IFERROR(IF(F23=0,0,IF(D8<=2,MIN(F23,1),IF(D8<=4,MIN(F23,2),F23))),0) -> 0 | I23: 0 | J23: =IFERROR(IF(I23=0,0,IF(D9<=2,MIN(I23,1),IF(D9<=4,MIN(I23,2),I23))),0) -> 0 | L23: 0 | M23: =IFERROR(IF(L23=0,0,IF(D10<=2,MIN(L23,1),IF(D10<=4,MIN(L23,2),L23))),0) -> 0 | O23: 0 | P23: =IFERROR(IF(O23=0,0,IF(D11<=2,MIN(O23,1),IF(D11<=4,MIN(O23,2),O23))),0) -> 0
A24: PO10 | B24: Communication | C24: 0 | D24: =IFERROR(IF(C24=0,0,IF(D7<=2,MIN(C24,1),IF(D7<=4,MIN(C24,2),C24))),0) -> 0 | F24: 0 | G24: =IFERROR(IF(F24=0,0,IF(D8<=2,MIN(F24,1),IF(D8<=4,MIN(F24,2),F24))),0) -> 0 | I24: 0 | J24: =IFERROR(IF(I24=0,0,IF(D9<=2,MIN(I24,1),IF(D9<=4,MIN(I24,2),I24))),0) -> 0 | L24: 0 | M24: =IFERROR(IF(L24=0,0,IF(D10<=2,MIN(L24,1),IF(D10<=4,MIN(L24,2),L24))),0) -> 0 | O24: 0 | P24: =IFERROR(IF(O24=0,0,IF(D11<=2,MIN(O24,1),IF(D11<=4,MIN(O24,2),O24))),0) -> 0
A25: PO11 | B25: Project Management and Finance | C25: 0 | D25: =IFERROR(IF(C25=0,0,IF(D7<=2,MIN(C25,1),IF(D7<=4,MIN(C25,2),C25))),0) -> 0 | F25: 0 | G25: =IFERROR(IF(F25=0,0,IF(D8<=2,MIN(F25,1),IF(D8<=4,MIN(F25,2),F25))),0) -> 0 | I25: 0 | J25: =IFERROR(IF(I25=0,0,IF(D9<=2,MIN(I25,1),IF(D9<=4,MIN(I25,2),I25))),0) -> 0 | L25: 0 | M25: =IFERROR(IF(L25=0,0,IF(D10<=2,MIN(L25,1),IF(D10<=4,MIN(L25,2),L25))),0) -> 0 | O25: 0 | P25: =IFERROR(IF(O25=0,0,IF(D11<=2,MIN(O25,1),IF(D11<=4,MIN(O25,2),O25))),0) -> 0
A26: PO12 | B26: Life-long Learning | C26: 1 | D26: =IFERROR(IF(C26=0,0,IF(D7<=2,MIN(C26,1),IF(D7<=4,MIN(C26,2),C26))),0) -> 1 | E26: Small lifelong learning contribution | F26: 2 | G26: =IFERROR(IF(F26=0,0,IF(D8<=2,MIN(F26,1),IF(D8<=4,MIN(F26,2),F26))),0) -> 2 | H26: Major lifelong learning | I26: 0 | J26: =IFERROR(IF(I26=0,0,IF(D9<=2,MIN(I26,1),IF(D9<=4,MIN(I26,2),I26))),0) -> 0 | L26: 2 | M26: =IFERROR(IF(L26=0,0,IF(D10<=2,MIN(L26,1),IF(D10<=4,MIN(L26,2),L26))),0) -> 2 | N26: Research and adaptation — PO12 | O26: 2 | P26: =IFERROR(IF(O26=0,0,IF(D11<=2,MIN(O26,1),IF(D11<=4,MIN(O26,2),O26))),0) -> 2 | Q26: Lifelong learning through design
A27: PSO1 | B27: Apply core CS concepts to design software systems | C27: 2 | D27: =IFERROR(IF(C27=0,0,IF(D7<=2,MIN(C27,1),IF(D7<=4,MIN(C27,2),C27))),0) -> 1 | E27: Core DB concept | F27: 3 | G27: =IFERROR(IF(F27=0,0,IF(D8<=2,MIN(F27,1),IF(D8<=4,MIN(F27,2),F27))),0) -> 3 | H27: Core DB design skill | I27: 3 | J27: =IFERROR(IF(I27=0,0,IF(D9<=2,MIN(I27,1),IF(D9<=4,MIN(I27,2),I27))),0) -> 2 | K27: Core DB normalization | L27: 3 | M27: =IFERROR(IF(L27=0,0,IF(D10<=2,MIN(L27,1),IF(D10<=4,MIN(L27,2),L27))),0) -> 3 | N27: Advanced DB technique | O27: 3 | P27: =IFERROR(IF(O27=0,0,IF(D11<=2,MIN(O27,1),IF(D11<=4,MIN(O27,2),O27))),0) -> 3 | Q27: Advanced DB design
A28: PSO2 | B28: Use modern tools to solve real-world engineering problems | C28: 1 | D28: =IFERROR(IF(C28=0,0,IF(D7<=2,MIN(C28,1),IF(D7<=4,MIN(C28,2),C28))),0) -> 1 | E28: Partial tool understanding | F28: 3 | G28: =IFERROR(IF(F28=0,0,IF(D8<=2,MIN(F28,1),IF(D8<=4,MIN(F28,2),F28))),0) -> 3 | H28: Modern DB tool usage | I28: 1 | J28: =IFERROR(IF(I28=0,0,IF(D9<=2,MIN(I28,1),IF(D9<=4,MIN(I28,2),I28))),0) -> 1 | K28: Partial tool involvement | L28: 2 | M28: =IFERROR(IF(L28=0,0,IF(D10<=2,MIN(L28,1),IF(D10<=4,MIN(L28,2),L28))),0) -> 2 | N28: Implementation skill | O28: 3 | P28: =IFERROR(IF(O28=0,0,IF(D11<=2,MIN(O28,1),IF(D11<=4,MIN(O28,2),O28))),0) -> 3 | Q28: Tool-based optimization
A29: PSO3 | B29: Demonstrate professional skills for industry/research | C29: 0 | D29: =IFERROR(IF(C29=0,0,IF(D7<=2,MIN(C29,1),IF(D7<=4,MIN(C29,2),C29))),0) -> 0 | F29: 3 | G29: =IFERROR(IF(F29=0,0,IF(D8<=2,MIN(F29,1),IF(D8<=4,MIN(F29,2),F29))),0) -> 3 | H29: Industry-level skill | I29: 0 | J29: =IFERROR(IF(I29=0,0,IF(D9<=2,MIN(I29,1),IF(D9<=4,MIN(I29,2),I29))),0) -> 0 | L29: 0 | M29: =IFERROR(IF(L29=0,0,IF(D10<=2,MIN(L29,1),IF(D10<=4,MIN(L29,2),L29))),0) -> 0 | O29: 3 | P29: =IFERROR(IF(O29=0,0,IF(D11<=2,MIN(O29,1),IF(D11<=4,MIN(O29,2),O29))),0) -> 3 | Q29: Professional design skill
A31: AVERAGE MAPPING LEVEL PER CO | D31: =IFERROR(AVERAGE(D15:D29),0) -> 0.33333333 | G31: =IFERROR(AVERAGE(G15:G29),0) -> 1.2666667 | J31: =IFERROR(AVERAGE(J15:J29),0) -> 0.6 | M31: =IFERROR(AVERAGE(M15:M29),0) -> 0.93333333 | P31: =IFERROR(AVERAGE(P15:P29),0) -> 1.4

Sheet CO-PO Mapping
A1: CO–PO MAPPING MATRIX (Keywords Method) — Auto-linked from all course sheets
A2: Level: — No Mapping | 1 Low (LOTS+partial) | 2 Medium (HOTS+major) | 3 High (Exact PO verb+critical performance) | Bloom level gates maximum possible mapping level
A4: LEGEND → | G4: — No Mapping | H4: 1 Low (LOTS / partial) | I4: 2 Medium (HOTS / major) | J4: 3 High (Exact match)
A5: # | B5: Course | C5: Code | D5: CO | E5: Keyword | F5: Bloom | G5: PROGRAMME OUTCOMES (PO1–PO12) | S5: PSOs
G6: PO1 | H6: PO2 | I6: PO3 | J6: PO4 | K6: PO5 | L6: PO6 | M6: PO7 | N6: PO8 | O6: PO9 | P6: PO10 | Q6: PO11 | R6: PO12 | S6: PSO1 | T6: PSO2 | U6: PSO3
A7: 1 | B7: Data Structures & Algorithms | C7: CS301 | D7: CO1 | E7: Apply | F7: =CS301!D7 -> 3 | G7: =IF(CS301!D15=0,"—",TEXT(CS301!D15,"0")) -> 2 | H7: =IF(CS301!D16=0,"—",TEXT(CS301!D16,"0")) -> 2 | I7: =IF(CS301!D17=0,"—",TEXT(CS301!D17,"0")) -> — | J7: =IF(CS301!D18=0,"—",TEXT(CS301!D18,"0")) -> — | K7: =IF(CS301!D19=0,"—",TEXT(CS301!D19,"0")) -> 1 | L7: =IF(CS301!D20=0,"—",TEXT(CS301!D20,"0")) -> — | M7: =IF(CS301!D21=0,"—",TEXT(CS301!D21,"0")) -> — | N7: =IF(CS301!D22=0,"—",TEXT(CS301!D22,"0")) -> — | O7: =IF(CS301!D23=0,"—",TEXT(CS301!D23,"0")) -> — | P7: =IF(CS301!D24=0,"—",TEXT(CS301!D24,"0")) -> — | Q7: =IF(CS301!D25=0,"—",TEXT(CS301!D25,"0")) -> — | R7: =IF(CS301!D26=0,"—",TEXT(CS301!D26,"0")) -> 1 | S7: =IF(CS301!D27=0,"—",TEXT(CS301!D27,"0")) -> 2 | T7: =IF(CS301!D28=0,"—",TEXT(CS301!D28,"0")) -> 2 | U7: =IF(CS301!D29=0,"—",TEXT(CS301!D29,"0")) -> —
D8: CO2 | E8: Analyze | F8: =CS301!D8 -> 4 | G8: =IF(CS301!G15=0,"—",TEXT(CS301!G15,"0")) -> 2 | H8: =IF(CS301!G16=0,"—",TEXT(CS301!G16,"0")) -> 2 | I8: =IF(CS301!G17=0,"—",TEXT(CS301!G17,"0")) -> — | J8: =IF(CS301!G18=0,"—",TEXT(CS301!G18,"0")) -> 2 | K8: =IF(CS301!G19=0,"—",TEXT(CS301!G19,"0")) -> — | L8: =IF(CS301!G20=0,"—",TEXT(CS301!G20,"0")) -> — | M8: =IF(CS301!G21=0,"—",TEXT(CS301!G21,"0")) -> — | N8: =IF(CS301!G22=0,"—",TEXT(CS301!G22,"0")) -> — | O8: =IF(CS301!G23=0,"—",TEXT(CS301!G23,"0")) -> — | P8: =IF(CS301!G24=0,"—",TEXT(CS301!G24,"0")) -> — | Q8: =IF(CS301!G25=0,"—",TEXT(CS301!G25,"0")) -> — | R8: =IF(CS301!G26=0,"—",TEXT(CS301!G26,"0")) -> 1 | S8: =IF(CS301!G27=0,"—",TEXT(CS301!G27,"0")) -> 2 | T8: =IF(CS301!G28=0,"—",TEXT(CS301!G28,"0")) -> 1 | U8: =IF(CS301!G29=0,"—",TEXT(CS301!G29,"0")) -> —
D9: CO3 | E9: Design | F9: =CS301!D9 -> 6 | G9: =IF(CS301!J15=0,"—",TEXT(CS301!J15,"0")) -> 2 | H9: =IF(CS301!J16=0,"—",TEXT(CS301!J16,"0")) -> 2 | I9: =IF(CS301!J17=0,"—",TEXT(CS301!J17,"0")) -> 3 | J9: =IF(CS301!J18=0,"—",TEXT(CS301!J18,"0")) -> — | K9: =IF(CS301!J19=0,"—",TEXT(CS301!J19,"0")) -> 2 | L9: =IF(CS301!J20=0,"—",TEXT(CS301!J20,"0")) -> — | M9: =IF(CS301!J21=0,"—",TEXT(CS301!J21,"0")) -> — | N9: =IF(CS301!J22=0,"—",TEXT(CS301!J22,"0")) -> — | O9: =IF(CS301!J23=0,"—",TEXT(CS301!J23,"0")) -> — | P9: =IF(CS301!J24=0,"—",TEXT(CS301!J24,"0")) -> — | Q9: =IF(CS301!J25=0,"—",TEXT(CS301!J25,"0")) -> — | R9: =IF(CS301!J26=0,"—",TEXT(CS301!J26,"0")) -> 2 | S9: =IF(CS301!J27=0,"—",TEXT(CS301!J27,"0")) -> 3 | T9: =IF(CS301!J28=0,"—",TEXT(CS301!J28,"0")) -> 3 | U9: =IF(CS301!J29=0,"—",TEXT(CS301!J29,"0")) -> 2
D10: CO4 | E10: Evaluate | F10: =CS301!D10 -> 5 | G10: =IF(CS301!M15=0,"—",TEXT(CS301!M15,"0")) -> 2 | H10: =IF(CS301!M16=0,"—",TEXT(CS301!M16,"0")) -> 3 | I10: =IF(CS301!M17=0,"—",TEXT(CS301!M17,"0")) -> — | J10: =IF(CS301!M18=0,"—",TEXT(CS301!M18,"0")) -> 2 | K10: =IF(CS301!M19=0,"—",TEXT(CS301!M19,"0")) -> — | L10: =IF(CS301!M20=0,"—",TEXT(CS301!M20,"0")) -> — | M10: =IF(CS301!M21=0,"—",TEXT(CS301!M21,"0")) -> — | N10: =IF(CS301!M22=0,"—",TEXT(CS301!M22,"0")) -> — | O10: =IF(CS301!M23=0,"—",TEXT(CS301!M23,"0")) -> — | P10: =IF(CS301!M24=0,"—",TEXT(CS301!M24,"0")) -> — | Q10: =IF(CS301!M25=0,"—",TEXT(CS301!M25,"0")) -> — | R10: =IF(CS301!M26=0,"—",TEXT(CS301!M26,"0")) -> 2 | S10: =IF(CS301!M27=0,"—",TEXT(CS301!M27,"0")) -> 3 | T10: =IF(CS301!M28=0,"—",TEXT(CS301!M28,"0")) -> 2 | U10: =IF(CS301!M29=0,"—",TEXT(CS301!M29,"0")) -> —
D11: CO5 | E11: Implement | F11: =CS301!D11 -> 3 | G11: =IF(CS301!P15=0,"—",TEXT(CS301!P15,"0")) -> 2 | H11: =IF(CS301!P16=0,"—",TEXT(CS301!P16,"0")) -> 2 | I11: =IF(CS301!P17=0,"—",TEXT(CS301!P17,"0")) -> — | J11: =IF(CS301!P18=0,"—",TEXT(CS301!P18,"0")) -> — | K11: =IF(CS301!P19=0,"—",TEXT(CS301!P19,"0")) -> 2 | L11: =IF(CS301!P20=0,"—",TEXT(CS301!P20,"0")) -> — | M11: =IF(CS301!P21=0,"—",TEXT(CS301!P21,"0")) -> — | N11: =IF(CS301!P22=0,"—",TEXT(CS301!P22,"0")) -> — | O11: =IF(CS301!P23=0,"—",TEXT(CS301!P23,"0")) -> — | P11: =IF(CS301!P24=0,"—",TEXT(CS301!P24,"0")) -> — | Q11: =IF(CS301!P25=0,"—",TEXT(CS301!P25,"0")) -> — | R11: =IF(CS301!P26=0,"—",TEXT(CS301!P26,"0")) -> 1 | S11: =IF(CS301!P27=0,"—",TEXT(CS301!P27,"0")) -> 2 | T11: =IF(CS301!P28=0,"—",TEXT(CS301!P28,"0")) -> 2 | U11: =IF(CS301!P29=0,"—",TEXT(CS301!P29,"0")) -> 2
A12: 2 | B12: Database Management Systems | C12: CS302 | D12: CO1 | E12: Explain | F12: =CS302!D7 -> 2 | G12: =IF(CS302!D15=0,"—",TEXT(CS302!D15,"0")) -> 1 | H12: =IF(CS302!D16=0,"—",TEXT(CS302!D16,"0")) -> 1 | I12: =IF(CS302!D17=0,"—",TEXT(CS302!D17,"0")) -> — | J12: =IF(CS302!D18=0,"—",TEXT(CS302!D18,"0")) -> — | K12: =IF(CS302!D19=0,"—",TEXT(CS302!D19,"0")) -> — | L12: =IF(CS302!D20=0,"—",TEXT(CS302!D20,"0")) -> — | M12: =IF(CS302!D21=0,"—",TEXT(CS302!D21,"0")) -> — | N12: =IF(CS302!D22=0,"—",TEXT(CS302!D22,"0")) -> — | O12: =IF(CS302!D23=0,"—",TEXT(CS302!D23,"0")) -> — | P12: =IF(CS302!D24=0,"—",TEXT(CS302!D24,"0")) -> — | Q12: =IF(CS302!D25=0,"—",TEXT(CS302!D25,"0")) -> — | R12: =IF(CS302!D26=0,"—",TEXT(CS302!D26,"0")) -> 1 | S12: =IF(CS302!D27=0,"—",TEXT(CS302!D27,"0")) -> 1 | T12: =IF(CS302!D28=0,"—",TEXT(CS302!D28,"0")) -> 1 | U12: =IF(CS302!D29=0,"—",TEXT(CS302!D29,"0")) -> —
D13: CO2 | E13: Design | F13: =CS302!D8 -> 6 | G13: =IF(CS302!G15=0,"—",TEXT(CS302!G15,"0")) -> 2 | H13: =IF(CS302!G16=0,"—",TEXT(CS302!G16,"0")) -> — | I13: =IF(CS302!G17=0,"—",TEXT(CS302!G17,"0")) -> 3 | J13: =IF(CS302!G18=0,"—",TEXT(CS302!G18,"0")) -> — | K13: =IF(CS302!G19=0,"—",TEXT(CS302!G19,"0")) -> 3 | L13: =IF(CS302!G20=0,"—",TEXT(CS302!G20,"0")) -> — | M13: =IF(CS302!G21=0,"—",TEXT(CS302!G21,"0")) -> — | N13: =IF(CS302!G22=0,"—",TEXT(CS302!G22,"0")) -> — | O13: =IF(CS302!G23=0,"—",TEXT(CS302!G23,"0")) -> — | P13: =IF(CS302!G24=0,"—",TEXT(CS302!G24,"0")) -> — | Q13: =IF(CS302!G25=0,"—",TEXT(CS302!G25,"0")) -> — | R13: =IF(CS302!G26=0,"—",TEXT(CS302!G26,"0")) -> 2 | S13: =IF(CS302!G27=0,"—",TEXT(CS302!G27,"0")) -> 3 | T13: =IF(CS302!G28=0,"—",TEXT(CS302!G28,"0")) -> 3 | U13: =IF(CS302!G29=0,"—",TEXT(CS302!G29,"0")) -> 3
D14: CO3 | E14: Analyze | F14: =CS302!D9 -> 4 | G14: =IF(CS302!J15=0,"—",TEXT(CS302!J15,"0")) -> 2 | H14: =IF(CS302!J16=0,"—",TEXT(CS302!J16,"0")) -> 2 | I14: =IF(CS302!J17=0,"—",TEXT(CS302!J17,"0")) -> — | J14: =IF(CS302!J18=0,"—",TEXT(CS302!J18,"0")) -> 2 | K14: =IF(CS302!J19=0,"—",TEXT(CS302!J19,"0")) -> — | L14: =IF(CS302!J20=0,"—",TEXT(CS302!J20,"0")) -> — | M14: =IF(CS302!J21=0,"—",TEXT(CS302!J21,"0")) -> — | N14: =IF(CS302!J22=0,"—",TEXT(CS302!J22,"0")) -> — | O14: =IF(CS302!J23=0,"—",TEXT(CS302!J23,"0")) -> — | P14: =IF(CS302!J24=0,"—",TEXT(CS302!J24,"0")) -> — | Q14: =IF(CS302!J25=0,"—",TEXT(CS302!J25,"0")) -> — | R14: =IF(CS302!J26=0,"—",TEXT(CS302!J26,"0")) -> — | S14: =IF(CS302!J27=0,"—",TEXT(CS302!J27,"0")) -> 2 | T14: =IF(CS302!J28=0,"—",TEXT(CS302!J28,"0")) -> 1 | U14: =IF(CS302!J29=0,"—",TEXT(CS302!J29,"0")) -> —
D15: CO4 | E15: Evaluate | F15: =CS302!D10 -> 5 | G15: =IF(CS302!M15=0,"—",TEXT(CS302!M15,"0")) -> 2 | H15: =IF(CS302!M16=0,"—",TEXT(CS302!M16,"0")) -> 3 | I15: =IF(CS302!M17=0,"—",TEXT(CS302!M17,"0")) -> — | J15: =IF(CS302!M18=0,"—",TEXT(CS302!M18,"0")) -> 2 | K15: =IF(CS302!M19=0,"—",TEXT(CS302!M19,"0")) -> — | L15: =IF(CS302!M20=0,"—",TEXT(CS302!M20,"0")) -> — | M15: =IF(CS302!M21=0,"—",TEXT(CS302!M21,"0")) -> — | N15: =IF(CS302!M22=0,"—",TEXT(CS302!M22,"0")) -> — | O15: =IF(CS302!M23=0,"—",TEXT(CS302!M23,"0")) -> — | P15: =IF(CS302!M24=0,"—",TEXT(CS302!M24,"0")) -> — | Q15: =IF(CS302!M25=0,"—",TEXT(CS302!M25,"0")) -> — | R15: =IF(CS302!M26=0,"—",TEXT(CS302!M26,"0")) -> 2 | S15: =IF(CS302!M27=0,"—",TEXT(CS302!M27,"0")) -> 3 | T15: =IF(CS302!M28=0,"—",TEXT(CS302!M28,"0")) -> 2 | U15: =IF(CS302!M29=0,"—",TEXT(CS302!M29,"0")) -> —
D16: CO5 | E16: Design | F16: =CS302!D11 -> 6 | G16: =IF(CS302!P15=0,"—",TEXT(CS302!P15,"0")) -> 3 | H16: =IF(CS302!P16=0,"—",TEXT(CS302!P16,"0")) -> 2 | I16: =IF(CS302!P17=0,"—",TEXT(CS302!P17,"0")) -> 3 | J16: =IF(CS302!P18=0,"—",TEXT(CS302!P18,"0")) -> — | K16: =IF(CS302!P19=0,"—",TEXT(CS302!P19,"0")) -> 2 | L16: =IF(CS302!P20=0,"—",TEXT(CS302!P20,"0")) -> — | M16: =IF(CS302!P21=0,"—",TEXT(CS302!P21,"0")) -> — | N16: =IF(CS302!P22=0,"—",TEXT(CS302!P22,"0")) -> — | O16: =IF(CS302!P23=0,"—",TEXT(CS302!P23,"0")) -> — | P16: =IF(CS302!P24=0,"—",TEXT(CS302!P24,"0")) -> — | Q16: =IF(CS302!P25=0,"—",TEXT(CS302!P25,"0")) -> — | R16: =IF(CS302!P26=0,"—",TEXT(CS302!P26,"0")) -> 2 | S16: =IF(CS302!P27=0,"—",TEXT(CS302!P27,"0")) -> 3 | T16: =IF(CS302!P28=0,"—",TEXT(CS302!P28,"0")) -> 3 | U16: =IF(CS302!P29=0,"—",TEXT(CS302!P29,"0")) -> 3
A17: 3 | B17: Computer Networks | C17: CS303 | D17: CO1 | E17: Describe | F17: =CS303!D7 -> 2 | G17: =IF(CS303!D15=0,"—",TEXT(CS303!D15,"0")) -> 1 | H17: =IF(CS303!D16=0,"—",TEXT(CS303!D16,"0")) -> 1 | I17: =IF(CS303!D17=0,"—",TEXT(CS303!D17,"0")) -> — | J17: =IF(CS303!D18=0,"—",TEXT(CS303!D18,"0")) -> — | K17: =IF(CS303!D19=0,"—",TEXT(CS303!D19,"0")) -> — | L17: =IF(CS303!D20=0,"—",TEXT(CS303!D20,"0")) -> — | M17: =IF(CS303!D21=0,"—",TEXT(CS303!D21,"0")) -> — | N17: =IF(CS303!D22=0,"—",TEXT(CS303!D22,"0")) -> — | O17: =IF(CS303!D23=0,"—",TEXT(CS303!D23,"0")) -> — | P17: =IF(CS303!D24=0,"—",TEXT(CS303!D24,"0")) -> — | Q17: =IF(CS303!D25=0,"—",TEXT(CS303!D25,"0")) -> — | R17: =IF(CS303!D26=0,"—",TEXT(CS303!D26,"0")) -> 1 | S17: =IF(CS303!D27=0,"—",TEXT(CS303!D27,"0")) -> 1 | T17: =IF(CS303!D28=0,"—",TEXT(CS303!D28,"0")) -> 1 | U17: =IF(CS303!D29=0,"—",TEXT(CS303!D29,"0")) -> —
D18: CO2 | E18: Analyze | F18: =CS303!D8 -> 4 | G18: =IF(CS303!G15=0,"—",TEXT(CS303!G15,"0")) -> 2 | H18: =IF(CS303!G16=0,"—",TEXT(CS303!G16,"0")) -> 2 | I18: =IF(CS303!G17=0,"—",TEXT(CS303!G17,"0")) -> — | J18: =IF(CS303!G18=0,"—",TEXT(CS303!G18,"0")) -> — | K18: =IF(CS303!G19=0,"—",TEXT(CS303!G19,"0")) -> 2 | L18: =IF(CS303!G20=0,"—",TEXT(CS303!G20,"0")) -> — | M18: =IF(CS303!G21=0,"—",TEXT(CS303!G21,"0")) -> — | N18: =IF(CS303!G22=0,"—",TEXT(CS303!G22,"0")) -> — | O18: =IF(CS303!G23=0,"—",TEXT(CS303!G23,"0")) -> — | P18: =IF(CS303!G24=0,"—",TEXT(CS303!G24,"0")) -> — | Q18: =IF(CS303!G25=0,"—",TEXT(CS303!G25,"0")) -> — | R18: =IF(CS303!G26=0,"—",TEXT(CS303!G26,"0")) -> 2 | S18: =IF(CS303!G27=0,"—",TEXT(CS303!G27,"0")) -> 2 | T18: =IF(CS303!G28=0,"—",TEXT(CS303!G28,"0")) -> 2 | U18: =IF(CS303!G29=0,"—",TEXT(CS303!G29,"0")) -> —
D19: CO3 | E19: Design | F19: =CS303!D9 -> 6 | G19: =IF(CS303!J15=0,"—",TEXT(CS303!J15,"0")) -> 2 | H19: =IF(CS303!J16=0,"—",TEXT(CS303!J16,"0")) -> 2 | I19: =IF(CS303!J17=0,"—",TEXT(CS303!J17,"0")) -> 3 | J19: =IF(CS303!J18=0,"—",TEXT(CS303!J18,"0")) -> 2 | K19: =IF(CS303!J19=0,"—",TEXT(CS303!J19,"0")) -> 3 | L19: =IF(CS303!J20=0,"—",TEXT(CS303!J20,"0")) -> — | M19: =IF(CS303!J21=0,"—",TEXT(CS303!J21,"0")) -> — | N19: =IF(CS303!J22=0,"—",TEXT(CS303!J22,"0")) -> — | O19: =IF(CS303!J23=0,"—",TEXT(CS303!J23,"0")) -> — | P19: =IF(CS303!J24=0,"—",TEXT(CS303!J24,"0")) -> — | Q19: =IF(CS303!J25=0,"—",TEXT(CS303!J25,"0")) -> — | R19: =IF(CS303!J26=0,"—",TEXT(CS303!J26,"0")) -> — | S19: =IF(CS303!J27=0,"—",TEXT(CS303!J27,"0")) -> 3 | T19: =IF(CS303!J28=0,"—",TEXT(CS303!J28,"0")) -> 3 | U19: =IF(CS303!J29=0,"—",TEXT(CS303!J29,"0")) -> 2
D20: CO4 | E20: Evaluate | F20: =CS303!D10 -> 5 | G20: =IF(CS303!M15=0,"—",TEXT(CS303!M15,"0")) -> 2 | H20: =IF(CS303!M16=0,"—",TEXT(CS303!M16,"0")) -> 3 | I20: =IF(CS303!M17=0,"—",TEXT(CS303!M17,"0")) -> — | J20: =IF(CS303!M18=0,"—",TEXT(CS303!M18,"0")) -> 2 | K20: =IF(CS303!M19=0,"—",TEXT(CS303!M19,"0")) -> — | L20: =IF(CS303!M20=0,"—",TEXT(CS303!M20,"0")) -> — | M20: =IF(CS303!M21=0,"—",TEXT(CS303!M21,"0")) -> — | N20: =IF(CS303!M22=0,"—",TEXT(CS303!M22,"0")) -> — | O20: =IF(CS303!M23=0,"—",TEXT(CS303!M23,"0")) -> — | P20: =IF(CS303!M24=0,"—",TEXT(CS303!M24,"0")) -> — | Q20: =IF(CS303!M25=0,"—",TEXT(CS303!M25,"0")) -> — | R20: =IF(CS303!M26=0,"—",TEXT(CS303!M26,"0")) -> — | S20: =IF(CS303!M27=0,"—",TEXT(CS303!M27,"0")) -> 2 | T20: =IF(CS303!M28=0,"—",TEXT(CS303!M28,"0")) -> 2 | U20: =IF(CS303!M29=0,"—",TEXT(CS303!M29,"0")) -> —
D21: CO5 | E21: Use tools | F21: =CS303!D11 -> 3 | G21: =IF(CS303!P15=0,"—",TEXT(CS303!P15,"0")) -> 2 | H21: =IF(CS303!P16=0,"—",TEXT(CS303!P16,"0")) -> 2 | I21: =IF(CS303!P17=0,"—",TEXT(CS303!P17,"0")) -> — | J21: =IF(CS303!P18=0,"—",TEXT(CS303!P18,"0")) -> — | K21: =IF(CS303!P19=0,"—",TEXT(CS303!P19,"0")) -> 2 | L21: =IF(CS303!P20=0,"—",TEXT(CS303!P20,"0")) -> — | M21: =IF(CS303!P21=0,"—",TEXT(CS303!P21,"0")) -> — | N21: =IF(CS303!P22=0,"—",TEXT(CS303!P22,"0")) -> — | O21: =IF(CS303!P23=0,"—",TEXT(CS303!P23,"0")) -> — | P21: =IF(CS303!P24=0,"—",TEXT(CS303!P24,"0")) -> — | Q21: =IF(CS303!P25=0,"—",TEXT(CS303!P25,"0")) -> — | R21: =IF(CS303!P26=0,"—",TEXT(CS303!P26,"0")) -> 2 | S21: =IF(CS303!P27=0,"—",TEXT(CS303!P27,"0")) -> 2 | T21: =IF(CS303!P28=0,"—",TEXT(CS303!P28,"0")) -> 2 | U21: =IF(CS303!P29=0,"—",TEXT(CS303!P29,"0")) -> —
A22: 4 | B22: Operating Systems | C22: CS304 | D22: CO1 | E22: Analyze | F22: =CS304!D7 -> 4 | G22: =IF(CS304!D15=0,"—",TEXT(CS304!D15,"0")) -> 2 | H22: =IF(CS304!D16=0,"—",TEXT(CS304!D16,"0")) -> 2 | I22: =IF(CS304!D17=0,"—",TEXT(CS304!D17,"0")) -> — | J22: =IF(CS304!D18=0,"—",TEXT(CS304!D18,"0")) -> — | K22: =IF(CS304!D19=0,"—",TEXT(CS304!D19,"0")) -> — | L22: =IF(CS304!D20=0,"—",TEXT(CS304!D20,"0")) -> — | M22: =IF(CS304!D21=0,"—",TEXT(CS304!D21,"0")) -> — | N22: =IF(CS304!D22=0,"—",TEXT(CS304!D22,"0")) -> — | O22: =IF(CS304!D23=0,"—",TEXT(CS304!D23,"0")) -> — | P22: =IF(CS304!D24=0,"—",TEXT(CS304!D24,"0")) -> — | Q22: =IF(CS304!D25=0,"—",TEXT(CS304!D25,"0")) -> — | R22: =IF(CS304!D26=0,"—",TEXT(CS304!D26,"0")) -> 1 | S22: =IF(CS304!D27=0,"—",TEXT(CS304!D27,"0")) -> 2 | T22: =IF(CS304!D28=0,"—",TEXT(CS304!D28,"0")) -> 1 | U22: =IF(CS304!D29=0,"—",TEXT(CS304!D29,"0")) -> —
D23: CO2 | E23: Design | F23: =CS304!D8 -> 6 | G23: =IF(CS304!G15=0,"—",TEXT(CS304!G15,"0")) -> 2 | H23: =IF(CS304!G16=0,"—",TEXT(CS304!G16,"0")) -> 2 | I23: =IF(CS304!G17=0,"—",TEXT(CS304!G17,"0")) -> 3 | J23: =IF(CS304!G18=0,"—",TEXT(CS304!G18,"0")) -> 2 | K23: =IF(CS304!G19=0,"—",TEXT(CS304!G19,"0")) -> — | L23: =IF(CS304!G20=0,"—",TEXT(CS304!G20,"0")) -> — | M23: =IF(CS304!G21=0,"—",TEXT(CS304!G21,"0")) -> — | N23: =IF(CS304!G22=0,"—",TEXT(CS304!G22,"0")) -> — | O23: =IF(CS304!G23=0,"—",TEXT(CS304!G23,"0")) -> — | P23: =IF(CS304!G24=0,"—",TEXT(CS304!G24,"0")) -> — | Q23: =IF(CS304!G25=0,"—",TEXT(CS304!G25,"0")) -> — | R23: =IF(CS304!G26=0,"—",TEXT(CS304!G26,"0")) -> — | S23: =IF(CS304!G27=0,"—",TEXT(CS304!G27,"0")) -> 3 | T23: =IF(CS304!G28=0,"—",TEXT(CS304!G28,"0")) -> 2 | U23: =IF(CS304!G29=0,"—",TEXT(CS304!G29,"0")) -> —
D24: CO3 | E24: Analyze | F24: =CS304!D9 -> 4 | G24: =IF(CS304!J15=0,"—",TEXT(CS304!J15,"0")) -> 2 | H24: =IF(CS304!J16=0,"—",TEXT(CS304!J16,"0")) -> 2 | I24: =IF(CS304!J17=0,"—",TEXT(CS304!J17,"0")) -> — | J24: =IF(CS304!J18=0,"—",TEXT(CS304!J18,"0")) -> 2 | K24: =IF(CS304!J19=0,"—",TEXT(CS304!J19,"0")) -> — | L24: =IF(CS304!J20=0,"—",TEXT(CS304!J20,"0")) -> — | M24: =IF(CS304!J21=0,"—",TEXT(CS304!J21,"0")) -> — | N24: =IF(CS304!J22=0,"—",TEXT(CS304!J22,"0")) -> — | O24: =IF(CS304!J23=0,"—",TEXT(CS304!J23,"0")) -> — | P24: =IF(CS304!J24=0,"—",TEXT(CS304!J24,"0")) -> — | Q24: =IF(CS304!J25=0,"—",TEXT(CS304!J25,"0")) -> — | R24: =IF(CS304!J26=0,"—",TEXT(CS304!J26,"0")) -> 1 | S24: =IF(CS304!J27=0,"—",TEXT(CS304!J27,"0")) -> 2 | T24: =IF(CS304!J28=0,"—",TEXT(CS304!J28,"0")) -> 1 | U24: =IF(CS304!J29=0,"—",TEXT(CS304!J29,"0")) -> —
D25: CO4 | E25: Evaluate | F25: =CS304!D10 -> 5 | G25: =IF(CS304!M15=0,"—",TEXT(CS304!M15,"0")) -> 2 | H25: =IF(CS304!M16=0,"—",TEXT(CS304!M16,"0")) -> 3 | I25: =IF(CS304!M17=0,"—",TEXT(CS304!M17,"0")) -> — | J25: =IF(CS304!M18=0,"—",TEXT(CS304!M18,"0")) -> — | K25: =IF(CS304!M19=0,"—",TEXT(CS304!M19,"0")) -> 2 | L25: =IF(CS304!M20=0,"—",TEXT(CS304!M20,"0")) -> — | M25: =IF(CS304!M21=0,"—",TEXT(CS304!M21,"0")) -> — | N25: =IF(CS304!M22=0,"—",TEXT(CS304!M22,"0")) -> — | O25: =IF(CS304!M23=0,"—",TEXT(CS304!M23,"0")) -> — | P25: =IF(CS304!M24=0,"—",TEXT(CS304!M24,"0")) -> — | Q25: =IF(CS304!M25=0,"—",TEXT(CS304!M25,"0")) -> — | R25: =IF(CS304!M26=0,"—",TEXT(CS304!M26,"0")) -> — | S25: =IF(CS304!M27=0,"—",TEXT(CS304!M27,"0")) -> 2 | T25: =IF(CS304!M28=0,"—",TEXT(CS304!M28,"0")) -> 2 | U25: =IF(CS304!M29=0,"—",TEXT(CS304!M29,"0")) -> —
D26: CO5 | E26: Implement | F26: =CS304!D11 -> 3 | G26: =IF(CS304!P15=0,"—",TEXT(CS304!P15,"0")) -> 2 | H26: =IF(CS304!P16=0,"—",TEXT(CS304!P16,"0")) -> 2 | I26: =IF(CS304!P17=0,"—",TEXT(CS304!P17,"0")) -> — | J26: =IF(CS304!P18=0,"—",TEXT(CS304!P18,"0")) -> — | K26: =IF(CS304!P19=0,"—",TEXT(CS304!P19,"0")) -> 2 | L26: =IF(CS304!P20=0,"—",TEXT(CS304!P20,"0")) -> — | M26: =IF(CS304!P21=0,"—",TEXT(CS304!P21,"0")) -> — | N26: =IF(CS304!P22=0,"—",TEXT(CS304!P22,"0")) -> — | O26: =IF(CS304!P23=0,"—",TEXT(CS304!P23,"0")) -> — | P26: =IF(CS304!P24=0,"—",TEXT(CS304!P24,"0")) -> — | Q26: =IF(CS304!P25=0,"—",TEXT(CS304!P25,"0")) -> — | R26: =IF(CS304!P26=0,"—",TEXT(CS304!P26,"0")) -> 1 | S26: =IF(CS304!P27=0,"—",TEXT(CS304!P27,"0")) -> 2 | T26: =IF(CS304!P28=0,"—",TEXT(CS304!P28,"0")) -> 2 | U26: =IF(CS304!P29=0,"—",TEXT(CS304!P29,"0")) -> —
A27: 5 | B27: Machine Learning | C27: CS305 | D27: CO1 | E27: Apply | F27: =CS305!D7 -> 3 | G27: =IF(CS305!D16=0,"—",TEXT(CS305!D16,"0")) -> 2 | H27: =IF(CS305!D17=0,"—",TEXT(CS305!D17,"0")) -> 2 | I27: =IF(CS305!D18=0,"—",TEXT(CS305!D18,"0")) -> — | J27: =IF(CS305!D19=0,"—",TEXT(CS305!D19,"0")) -> — | K27: =IF(CS305!D20=0,"—",TEXT(CS305!D20,"0")) -> 2 | L27: =IF(CS305!D21=0,"—",TEXT(CS305!D21,"0")) -> — | M27: =IF(CS305!D22=0,"—",TEXT(CS305!D22,"0")) -> — | N27: =IF(CS305!D23=0,"—",TEXT(CS305!D23,"0")) -> — | O27: =IF(CS305!D24=0,"—",TEXT(CS305!D24,"0")) -> — | P27: =IF(CS305!D25=0,"—",TEXT(CS305!D25,"0")) -> — | Q27: =IF(CS305!D26=0,"—",TEXT(CS305!D26,"0")) -> — | R27: =IF(CS305!D27=0,"—",TEXT(CS305!D27,"0")) -> 2 | S27: =IF(CS305!D28=0,"—",TEXT(CS305!D28,"0")) -> 2 | T27: =IF(CS305!D29=0,"—",TEXT(CS305!D29,"0")) -> 2 | U27: =IF(CS305!D30=0,"—",TEXT(CS305!D30,"0")) -> 2
D28: CO2 | E28: Analyze | F28: =CS305!D8 -> 4 | G28: =IF(CS305!G16=0,"—",TEXT(CS305!G16,"0")) -> 2 | H28: =IF(CS305!G17=0,"—",TEXT(CS305!G17,"0")) -> 2 | I28: =IF(CS305!G18=0,"—",TEXT(CS305!G18,"0")) -> — | J28: =IF(CS305!G19=0,"—",TEXT(CS305!G19,"0")) -> 2 | K28: =IF(CS305!G20=0,"—",TEXT(CS305!G20,"0")) -> 2 | L28: =IF(CS305!G21=0,"—",TEXT(CS305!G21,"0")) -> — | M28: =IF(CS305!G22=0,"—",TEXT(CS305!G22,"0")) -> — | N28: =IF(CS305!G23=0,"—",TEXT(CS305!G23,"0")) -> — | O28: =IF(CS305!G24=0,"—",TEXT(CS305!G24,"0")) -> — | P28: =IF(CS305!G25=0,"—",TEXT(CS305!G25,"0")) -> — | Q28: =IF(CS305!G26=0,"—",TEXT(CS305!G26,"0")) -> — | R28: =IF(CS305!G27=0,"—",TEXT(CS305!G27,"0")) -> — | S28: =IF(CS305!G28=0,"—",TEXT(CS305!G28,"0")) -> 2 | T28: =IF(CS305!G29=0,"—",TEXT(CS305!G29,"0")) -> 2 | U28: =IF(CS305!G30=0,"—",TEXT(CS305!G30,"0")) -> —
D29: CO3 | E29: Design | F29: =CS305!D9 -> 6 | G29: =IF(CS305!J16=0,"—",TEXT(CS305!J16,"0")) -> 2 | H29: =IF(CS305!J17=0,"—",TEXT(CS305!J17,"0")) -> 2 | I29: =IF(CS305!J18=0,"—",TEXT(CS305!J18,"0")) -> 3 | J29: =IF(CS305!J19=0,"—",TEXT(CS305!J19,"0")) -> — | K29: =IF(CS305!J20=0,"—",TEXT(CS305!J20,"0")) -> 3 | L29: =IF(CS305!J21=0,"—",TEXT(CS305!J21,"0")) -> — | M29: =IF(CS305!J22=0,"—",TEXT(CS305!J22,"0")) -> — | N29: =IF(CS305!J23=0,"—",TEXT(CS305!J23,"0")) -> — | O29: =IF(CS305!J24=0,"—",TEXT(CS305!J24,"0")) -> — | P29: =IF(CS305!J25=0,"—",TEXT(CS305!J25,"0")) -> — | Q29: =IF(CS305!J26=0,"—",TEXT(CS305!J26,"0")) -> — | R29: =IF(CS305!J27=0,"—",TEXT(CS305!J27,"0")) -> 3 | S29: =IF(CS305!J28=0,"—",TEXT(CS305!J28,"0")) -> 3 | T29: =IF(CS305!J29=0,"—",TEXT(CS305!J29,"0")) -> 3 | U29: =IF(CS305!J30=0,"—",TEXT(CS305!J30,"0")) -> 3
D30: CO4 | E30: Evaluate | F30: =CS305!D10 -> 5 | G30: =IF(CS305!M16=0,"—",TEXT(CS305!M16,"0")) -> 2 | H30: =IF(CS305!M17=0,"—",TEXT(CS305!M17,"0")) -> 3 | I30: =IF(CS305!M18=0,"—",TEXT(CS305!M18,"0")) -> — | J30: =IF(CS305!M19=0,"—",TEXT(CS305!M19,"0")) -> 2 | K30: =IF(CS305!M20=0,"—",TEXT(CS305!M20,"0")) -> 2 | L30: =IF(CS305!M21=0,"—",TEXT(CS305!M21,"0")) -> — | M30: =IF(CS305!M22=0,"—",TEXT(CS305!M22,"0")) -> — | N30: =IF(CS305!M23=0,"—",TEXT(CS305!M23,"0")) -> — | O30: =IF(CS305!M24=0,"—",TEXT(CS305!M24,"0")) -> — | P30: =IF(CS305!M25=0,"—",TEXT(CS305!M25,"0")) -> — | Q30: =IF(CS305!M26=0,"—",TEXT(CS305!M26,"0")) -> — | R30: =IF(CS305!M27=0,"—",TEXT(CS305!M27,"0")) -> — | S30: =IF(CS305!M28=0,"—",TEXT(CS305!M28,"0")) -> 3 | T30: =IF(CS305!M29=0,"—",TEXT(CS305!M29,"0")) -> 3 | U30: =IF(CS305!M30=0,"—",TEXT(CS305!M30,"0")) -> —
D31: CO5 | E31: Investigate | F31: =CS305!D11 -> 4 | G31: =IF(CS305!P16=0,"—",TEXT(CS305!P16,"0")) -> 2 | H31: =IF(CS305!P17=0,"—",TEXT(CS305!P17,"0")) -> 2 | I31: =IF(CS305!P18=0,"—",TEXT(CS305!P18,"0")) -> — | J31: =IF(CS305!P19=0,"—",TEXT(CS305!P19,"0")) -> 2 | K31: =IF(CS305!P20=0,"—",TEXT(CS305!P20,"0")) -> 2 | L31: =IF(CS305!P21=0,"—",TEXT(CS305!P21,"0")) -> — | M31: =IF(CS305!P22=0,"—",TEXT(CS305!P22,"0")) -> — | N31: =IF(CS305!P23=0,"—",TEXT(CS305!P23,"0")) -> — | O31: =IF(CS305!P24=0,"—",TEXT(CS305!P24,"0")) -> — | P31: =IF(CS305!P25=0,"—",TEXT(CS305!P25,"0")) -> — | Q31: =IF(CS305!P26=0,"—",TEXT(CS305!P26,"0")) -> — | R31: =IF(CS305!P27=0,"—",TEXT(CS305!P27,"0")) -> 2 | S31: =IF(CS305!P28=0,"—",TEXT(CS305!P28,"0")) -> 2 | T31: =IF(CS305!P29=0,"—",TEXT(CS305!P29,"0")) -> 2 | U31: =IF(CS305!P30=0,"—",TEXT(CS305!P30,"0")) -> —
D32: CO6 | E32: Develop | F32: =CS305!D12 -> 6 | G32: =IF(CS305!S16=0,"—",TEXT(CS305!S16,"0")) -> 2 | H32: =IF(CS305!S17=0,"—",TEXT(CS305!S17,"0")) -> — | I32: =IF(CS305!S18=0,"—",TEXT(CS305!S18,"0")) -> 3 | J32: =IF(CS305!S19=0,"—",TEXT(CS305!S19,"0")) -> — | K32: =IF(CS305!S20=0,"—",TEXT(CS305!S20,"0")) -> 2 | L32: =IF(CS305!S21=0,"—",TEXT(CS305!S21,"0")) -> — | M32: =IF(CS305!S22=0,"—",TEXT(CS305!S22,"0")) -> — | N32: =IF(CS305!S23=0,"—",TEXT(CS305!S23,"0")) -> — | O32: =IF(CS305!S24=0,"—",TEXT(CS305!S24,"0")) -> 3 | P32: =IF(CS305!S25=0,"—",TEXT(CS305!S25,"0")) -> 3 | Q32: =IF(CS305!S26=0,"—",TEXT(CS305!S26,"0")) -> 2 | R32: =IF(CS305!S27=0,"—",TEXT(CS305!S27,"0")) -> 2 | S32: =IF(CS305!S28=0,"—",TEXT(CS305!S28,"0")) -> 3 | T32: =IF(CS305!S29=0,"—",TEXT(CS305!S29,"0")) -> 3 | U32: =IF(CS305!S30=0,"—",TEXT(CS305!S30,"0")) -> 3
A34: DEPT AVERAGE | F34: =IFERROR(AVERAGE(F7:F32),0) -> 4.3846154 | G34: =IFERROR(AVERAGEIF(G7:G32,"<>—"),"") | H34: =IFERROR(AVERAGEIF(H7:H32,"<>—"),"") | I34: =IFERROR(AVERAGEIF(I7:I32,"<>—"),"") | J34: =IFERROR(AVERAGEIF(J7:J32,"<>—"),"") | K34: =IFERROR(AVERAGEIF(K7:K32,"<>—"),"") | L34: =IFERROR(AVERAGEIF(L7:L32,"<>—"),"") | M34: =IFERROR(AVERAGEIF(M7:M32,"<>—"),"") | N34: =IFERROR(AVERAGEIF(N7:N32,"<>—"),"") | ... U34: =IFERROR(AVERAGEIF(U7:U32,"<>—"),"")

Sheet CS303
A1: KEYWORDS CO–PO MAPPING — Computer Networks (CS303)
A2: Method D: Enter Bloom Level (1–6) and Keyword Match Score (0–3) per PO in YELLOW cells | Level = IF(score=0, 0, IF(bloom≤2, min(score,1), IF(bloom≤4, min(score,2), score)))
A4: Score Guide → | C4: 0 = No Match | D4: 1 = Partial Match | E4: 2 = Major Match | F4: 3 = Exact Match | G4: Bloom: 1=Remember 2=Understand 3=Apply 4=Analyze 5=Evaluate 6=Create
A5: SECTION 1 — CO INFORMATION (Enter Bloom Level in yellow cell)
A6: CO | B6: CO Statement / Description | C6: Primary Keyword | D6: Bloom Level (1–6) | E6: Bloom Name | F6: Order (LOTS/HOTS) | G6: CO Statement Example justification
A7: CO1 | B7: Describe the OSI and TCP/IP reference models and identify the functions of each layer | C7: Describe | D7: 2 | E7: =CHOOSE(D7,"Remember","Understand","Apply","Analyze","Evaluate","Create") -> Understand | F7: =IF(D7<=2,"LOTS","HOTS") -> LOTS | G7: Describe (Understand) — Describe is LOTS — partial PO1
A8: CO2 | B8: Analyze data link layer protocols and apply error detection and correction techniques | C8: Analyze | D8: 4 | E8: =CHOOSE(D8,"Remember","Understand","Apply","Analyze","Evaluate","Create") -> Analyze | F8: =IF(D8<=2,"LOTS","HOTS") -> HOTS | G8: Analyze (Analyze) — Analyze needs engineering knowledge
A9: CO3 | B9: Design and implement routing algorithms and analyze IP addressing and network layer protocols | C9: Design | D9: 6 | E9: =CHOOSE(D9,"Remember","Understand","Apply","Analyze","Evaluate","Create") -> Create | F9: =IF(D9<=2,"LOTS","HOTS") -> HOTS | G9: Design (Create) — Design needs engineering knowledge
A10: CO4 | B10: Evaluate transport layer protocols including TCP and UDP and implement flow control mechanisms | C10: Evaluate | D10: 5 | E10: =CHOOSE(D10,"Remember","Understand","Apply","Analyze","Evaluate","Create") -> Evaluate | F10: =IF(D10<=2,"LOTS","HOTS") -> HOTS | G10: Evaluate (Evaluate) — Evaluation needs engineering knowledge
A11: CO5 | B11: Use modern network simulation tools to model and analyze application layer protocols and services | C11: Use tools | D11: 3 | E11: =CHOOSE(D11,"Remember","Understand","Apply","Analyze","Evaluate","Create") -> Apply | F11: =IF(D11<=2,"LOTS","HOTS") -> HOTS | G11: Use tools (Apply) — Apply engineering knowledge in tools
A13: SECTION 2 — CO–PO/PSO KEYWORD MAPPING (Enter Keyword Match Score 0–3 in YELLOW cells per PO per CO)
A14: PO / PSO | B14: PO Description | C14: CO1 KW Score | D14: CO1 Level | E14: CO1 Justification | F14: CO2 KW Score | G14: CO2 Level | H14: CO2 Justification | I14: CO3 KW Score | J14: CO3 Level | K14: CO3 Justification | L14: CO4 KW Score | M14: CO4 Level | N14: CO4 Justification | O14: CO5 KW Score | P14: CO5 Level | Q14: CO5 Justification
A15: PO1 | B15: Engineering Knowledge | C15: 1 | D15: =IFERROR(IF(C15=0,0,IF(D7<=2,MIN(C15,1),IF(D7<=4,MIN(C15,2),C15))),0) -> 1 | E15: Describe is LOTS — partial PO1 | F15: 2 | G15: =IFERROR(IF(F15=0,0,IF(D8<=2,MIN(F15,1),IF(D8<=4,MIN(F15,2),F15))),0) -> 2 | H15: Analyze needs engineering knowledge | I15: 2 | J15: =IFERROR(IF(I15=0,0,IF(D9<=2,MIN(I15,1),IF(D9<=4,MIN(I15,2),I15))),0) -> 2 | K15: Design needs engineering knowledge | L15: 2 | M15: =IFERROR(IF(L15=0,0,IF(D10<=2,MIN(L15,1),IF(D10<=4,MIN(L15,2),L15))),0) -> 2 | N15: Evaluation needs engineering knowledge | O15: 2 | P15: =IFERROR(IF(O15=0,0,IF(D11<=2,MIN(O15,1),IF(D11<=4,MIN(O15,2),O15))),0) -> 2 | Q15: Apply engineering knowledge in tools
A16: PO2 | B16: Problem Analysis | C16: 1 | D16: =IFERROR(IF(C16=0,0,IF(D7<=2,MIN(C16,1),IF(D7<=4,MIN(C16,2),C16))),0) -> 1 | E16: Low problem analysis from description | F16: 3 | G16: =IFERROR(IF(F16=0,0,IF(D8<=2,MIN(F16,1),IF(D8<=4,MIN(F16,2),F16))),0) -> 2 | H16: Analyze exactly matches PO2 | I16: 2 | J16: =IFERROR(IF(I16=0,0,IF(D9<=2,MIN(I16,1),IF(D9<=4,MIN(I16,2),I16))),0) -> 2 | K16: Problem analysis involved | L16: 3 | M16: =IFERROR(IF(L16=0,0,IF(D10<=2,MIN(L16,1),IF(D10<=4,MIN(L16,2),L16))),0) -> 3 | N16: Evaluate exactly matches PO2 | O16: 2 | P16: =IFERROR(IF(O16=0,0,IF(D11<=2,MIN(O16,1),IF(D11<=4,MIN(O16,2),O16))),0) -> 2 | Q16: Problem analysis through simulation
A17: PO3 | B17: Design/Development of Solutions | C17: 0 | D17: =IFERROR(IF(C17=0,0,IF(D7<=2,MIN(C17,1),IF(D7<=4,MIN(C17,2),C17))),0) -> 0 | F17: 0 | G17: =IFERROR(IF(F17=0,0,IF(D8<=2,MIN(F17,1),IF(D8<=4,MIN(F17,2),F17))),0) -> 0 | I17: 3 | J17: =IFERROR(IF(I17=0,0,IF(D9<=2,MIN(I17,1),IF(D9<=4,MIN(I17,2),I17))),0) -> 3 | K17: Design exactly matches PO3 | L17: 0 | M17: =IFERROR(IF(L17=0,0,IF(D10<=2,MIN(L17,1),IF(D10<=4,MIN(L17,2),L17))),0) -> 0 | O17: 0 | P17: =IFERROR(IF(O17=0,0,IF(D11<=2,MIN(O17,1),IF(D11<=4,MIN(O17,2),O17))),0) -> 0
A18: PO4 | B18: Conduct Investigations | C18: 0 | D18: =IFERROR(IF(C18=0,0,IF(D7<=2,MIN(C18,1),IF(D7<=4,MIN(C18,2),C18))),0) -> 0 | F18: 0 | G18: =IFERROR(IF(F18=0,0,IF(D8<=2,MIN(F18,1),IF(D8<=4,MIN(F18,2),F18))),0) -> 0 | I18: 2 | J18: =IFERROR(IF(I18=0,0,IF(D9<=2,MIN(I18,1),IF(D9<=4,MIN(I18,2),I18))),0) -> 2 | K18: Investigate routing behavior | L18: 2 | M18: =IFERROR(IF(L18=0,0,IF(D10<=2,MIN(L18,1),IF(D10<=4,MIN(L18,2),L18))),0) -> 2 | N18: Investigation of protocol behavior | O18: 0 | P18: =IFERROR(IF(O18=0,0,IF(D11<=2,MIN(O18,1),IF(D11<=4,MIN(O18,2),O18))),0) -> 0
A19: PO5 | B19: Modern Tool Usage | C19: 0 | D19: =IFERROR(IF(C19=0,0,IF(D7<=2,MIN(C19,1),IF(D7<=4,MIN(C19,2),C19))),0) -> 0 | F19: 2 | G19: =IFERROR(IF(F19=0,0,IF(D8<=2,MIN(F19,1),IF(D8<=4,MIN(F19,2),F19))),0) -> 2 | H19: Use modern protocol tools | I19: 3 | J19: =IFERROR(IF(I19=0,0,IF(D9<=2,MIN(I19,1),IF(D9<=4,MIN(I19,2),I19))),0) -> 3 | K19: Implement using modern network tools | L19: 0 | M19: =IFERROR(IF(L19=0,0,IF(D10<=2,MIN(L19,1),IF(D10<=4,MIN(L19,2),L19))),0) -> 0 | O19: 3 | P19: =IFERROR(IF(O19=0,0,IF(D11<=2,MIN(O19,1),IF(D11<=4,MIN(O19,2),O19))),0) -> 2 | Q19: Use tools exactly matches PO5 — high performance
A20: PO6 | B20: The Engineer and Society | C20: 0 | D20: =IFERROR(IF(C20=0,0,IF(D7<=2,MIN(C20,1),IF(D7<=4,MIN(C20,2),C20))),0) -> 0 | F20: 0 | G20: =IFERROR(IF(F20=0,0,IF(D8<=2,MIN(F20,1),IF(D8<=4,MIN(F20,2),F20))),0) -> 0 | I20: 0 | J20: =IFERROR(IF(I20=0,0,IF(D9<=2,MIN(I20,1),IF(D9<=4,MIN(I20,2),I20))),0) -> 0 | L20: 0 | M20: =IFERROR(IF(L20=0,0,IF(D10<=2,MIN(L20,1),IF(D10<=4,MIN(L20,2),L20))),0) -> 0 | O20: 0 | P20: =IFERROR(IF(O20=0,0,IF(D11<=2,MIN(O20,1),IF(D11<=4,MIN(O20,2),O20))),0) -> 0
A21: PO7 | B21: Environment and Sustainability | C21: 0 | D21: =IFERROR(IF(C21=0,0,IF(D7<=2,MIN(C21,1),IF(D7<=4,MIN(C21,2),C21))),0) -> 0 | F21: 0 | G21: =IFERROR(IF(F21=0,0,IF(D8<=2,MIN(F21,1),IF(D8<=4,MIN(F21,2),F21))),0) -> 0 | I21: 0 | J21: =IFERROR(IF(I21=0,0,IF(D9<=2,MIN(I21,1),IF(D9<=4,MIN(I21,2),I21))),0) -> 0 | L21: 0 | M21: =IFERROR(IF(L21=0,0,IF(D10<=2,MIN(L21,1),IF(D10<=4,MIN(L21,2),L21))),0) -> 0 | O21: 0 | P21: =IFERROR(IF(O21=0,0,IF(D11<=2,MIN(O21,1),IF(D11<=4,MIN(O21,2),O21))),0) -> 0
A22: PO8 | B22: Ethics | C22: 0 | D22: =IFERROR(IF(C22=0,0,IF(D7<=2,MIN(C22,1),IF(D7<=4,MIN(C22,2),C22))),0) -> 0 | F22: 0 | G22: =IFERROR(IF(F22=0,0,IF(D8<=2,MIN(F22,1),IF(D8<=4,MIN(F22,2),F22))),0) -> 0 | I22: 0 | J22: =IFERROR(IF(I22=0,0,IF(D9<=2,MIN(I22,1),IF(D9<=4,MIN(I22,2),I22))),0) -> 0 | L22: 0 | M22: =IFERROR(IF(L22=0,0,IF(D10<=2,MIN(L22,1),IF(D10<=4,MIN(L22,2),L22))),0) -> 0 | O22: 0 | P22: =IFERROR(IF(O22=0,0,IF(D11<=2,MIN(O22,1),IF(D11<=4,MIN(O22,2),O22))),0) -> 0
A23: PO9 | B23: Individual and Team Work | C23: 0 | D23: =IFERROR(IF(C23=0,0,IF(D7<=2,MIN(C23,1),IF(D7<=4,MIN(C23,2),C23))),0) -> 0 | F23: 0 | G23: =IFERROR(IF(F23=0,0,IF(D8<=2,MIN(F23,1),IF(D8<=4,MIN(F23,2),F23))),0) -> 0 | I23: 0 | J23: =IFERROR(IF(I23=0,0,IF(D9<=2,MIN(I23,1),IF(D9<=4,MIN(I23,2),I23))),0) -> 0 | L23: 0 | M23: =IFERROR(IF(L23=0,0,IF(D10<=2,MIN(L23,1),IF(D10<=4,MIN(L23,2),L23))),0) -> 0 | O23: 0 | P23: =IFERROR(IF(O23=0,0,IF(D11<=2,MIN(O23,1),IF(D11<=4,MIN(O23,2),O23))),0) -> 0
A24: PO10 | B24: Communication | C24: 0 | D24: =IFERROR(IF(C24=0,0,IF(D7<=2,MIN(C24,1),IF(D7<=4,MIN(C24,2),C24))),0) -> 0 | F24: 0 | G24: =IFERROR(IF(F24=0,0,IF(D8<=2,MIN(F24,1),IF(D8<=4,MIN(F24,2),F24))),0) -> 0 | I24: 0 | J24: =IFERROR(IF(I24=0,0,IF(D9<=2,MIN(I24,1),IF(D9<=4,MIN(I24,2),I24))),0) -> 0 | L24: 0 | M24: =IFERROR(IF(L24=0,0,IF(D10<=2,MIN(L24,1),IF(D10<=4,MIN(L24,2),L24))),0) -> 0 | O24: 0 | P24: =IFERROR(IF(O24=0,0,IF(D11<=2,MIN(O24,1),IF(D11<=4,MIN(O24,2),O24))),0) -> 0
