Workbook

Sheet Indirect PO Dashboard
A1: PO / PSO INDIRECT ATTAINMENT DASHBOARD — B.Tech CSE | Academic Year 2024-25
A2: Indirect Assessment Sources: Course Exit Survey · Programme Exit Survey · Alumni Survey · Employer Survey · Internship Feedback
A3: Formula: Indirect PO Attainment = Σ (Tool Weight × Tool Attainment%) / Σ Weights | Target = 60% | Level: 3=High ≥60% 2=Medium ≥40% 1=Low <40%
A5: Assessment Tools & Weights: | B5: T1: 20% | C5: T2: 25% | D5: T3: 20% | E5: T4: 20% | F5: T5: 15%
A7: # | B7: PO / PSO | C7: Programme Outcome / PSO Description | D7: Indirect Att% | E7: Target (60%) | F7: Level (3/2/1) | G7: Gap | H7: Status
A8: 1 | B8: PO1 | C8: Engineering Knowledge | D8: ='Indirect Attainment Summary'!I8 -> 0.7508 | E8: ='Indirect Attainment Summary'!K8 -> 0.6 | F8: =IF(D8>=0.6,3,IF(D8>=0.4,2,1)) -> 3 | G8: =D8-E8 -> 0.1508 | H8: =IF(D8>=E8,"✔ Met","✘ Not Met") -> ✔ Met
A9: 2 | B9: PO2 | C9: Problem Analysis | D9: ='Indirect Attainment Summary'!I9 -> 0.7809 | E9: ='Indirect Attainment Summary'!K9 -> 0.6 | F9: =IF(D9>=0.6,3,IF(D9>=0.4,2,1)) -> 3 | G9: =D9-E9 -> 0.1809 | H9: =IF(D9>=E9,"✔ Met","✘ Not Met") -> ✔ Met
A10: 3 | B10: PO3 | C10: Design/Development of Solutions | D10: ='Indirect Attainment Summary'!I10 -> 0.7671 | E10: ='Indirect Attainment Summary'!K10 -> 0.6 | F10: =IF(D10>=0.6,3,IF(D10>=0.4,2,1)) -> 3 | G10: =D10-E10 -> 0.1671 | H10: =IF(D10>=E10,"✔ Met","✘ Not Met") -> ✔ Met
A11: 4 | B11: PO4 | C11: Conduct Investigations of Complex Problems | D11: ='Indirect Attainment Summary'!I11 -> 0.8307 | E11: ='Indirect Attainment Summary'!K11 -> 0.6 | F11: =IF(D11>=0.6,3,IF(D11>=0.4,2,1)) -> 3 | G11: =D11-E11 -> 0.2307 | H11: =IF(D11>=E11,"✔ Met","✘ Not Met") -> ✔ Met
A12: 5 | B12: PO5 | C12: Modern Tool Usage | D12: ='Indirect Attainment Summary'!I12 -> 0.746 | E12: ='Indirect Attainment Summary'!K12 -> 0.6 | F12: =IF(D12>=0.6,3,IF(D12>=0.4,2,1)) -> 3 | G12: =D12-E12 -> 0.146 | H12: =IF(D12>=E12,"✔ Met","✘ Not Met") -> ✔ Met
A13: 6 | B13: PO6 | C13: The Engineer and Society | D13: ='Indirect Attainment Summary'!I13 -> 0.7936 | E13: ='Indirect Attainment Summary'!K13 -> 0.6 | F13: =IF(D13>=0.6,3,IF(D13>=0.4,2,1)) -> 3 | G13: =D13-E13 -> 0.1936 | H13: =IF(D13>=E13,"✔ Met","✘ Not Met") -> ✔ Met
A14: 7 | B14: PO7 | C14: Environment and Sustainability | D14: ='Indirect Attainment Summary'!I14 -> 0.8203 | E14: ='Indirect Attainment Summary'!K14 -> 0.6 | F14: =IF(D14>=0.6,3,IF(D14>=0.4,2,1)) -> 3 | G14: =D14-E14 -> 0.2203 | H14: =IF(D14>=E14,"✔ Met","✘ Not Met") -> ✔ Met
A15: 8 | B15: PO8 | C15: Ethics | D15: ='Indirect Attainment Summary'!I15 -> 0.7829 | E15: ='Indirect Attainment Summary'!K15 -> 0.6 | F15: =IF(D15>=0.6,3,IF(D15>=0.4,2,1)) -> 3 | G15: =D15-E15 -> 0.1829 | H15: =IF(D15>=E15,"✔ Met","✘ Not Met") -> ✔ Met
A16: 9 | B16: PO9 | C16: Individual and Team Work | D16: ='Indirect Attainment Summary'!I16 -> 0.6194 | E16: ='Indirect Attainment Summary'!K16 -> 0.6 | F16: =IF(D16>=0.6,3,IF(D16>=0.4,2,1)) -> 3 | G16: =D16-E16 -> 0.0194 | H16: =IF(D16>=E16,"✔ Met","✘ Not Met") -> ✔ Met
A17: 10 | B17: PO10 | C17: Communication | D17: ='Indirect Attainment Summary'!I17 -> 0.7576 | E17: ='Indirect Attainment Summary'!K17 -> 0.6 | F17: =IF(D17>=0.6,3,IF(D17>=0.4,2,1)) -> 3 | G17: =D17-E17 -> 0.1576 | H17: =IF(D17>=E17,"✔ Met","✘ Not Met") -> ✔ Met
A18: 11 | B18: PO11 | C18: Project Management and Finance | D18: ='Indirect Attainment Summary'!I18 -> 0.7518 | E18: ='Indirect Attainment Summary'!K18 -> 0.6 | F18: =IF(D18>=0.6,3,IF(D18>=0.4,2,1)) -> 3 | G18: =D18-E18 -> 0.1518 | H18: =IF(D18>=E18,"✔ Met","✘ Not Met") -> ✔ Met
A19: 12 | B19: PO12 | C19: Life-long Learning | D19: ='Indirect Attainment Summary'!I19 -> 0.7237 | E19: ='Indirect Attainment Summary'!K19 -> 0.6 | F19: =IF(D19>=0.6,3,IF(D19>=0.4,2,1)) -> 3 | G19: =D19-E19 -> 0.1237 | H19: =IF(D19>=E19,"✔ Met","✘ Not Met") -> ✔ Met
... A22: 15 | B22: PSO3 | C22: Demonstrate professional skills for industry/research | D22: ='Indirect Attainment Summary'!I22 -> 0.742 | E22: ='Indirect Attainment Summary'!K22 -> 0.6 | F22: =IF(D22>=0.6,3,IF(D22>=0.4,2,1)) -> 3 | G22: =D22-E22 -> 0.142 | H22: =IF(D22>=E22,"✔ Met","✘ Not Met") -> ✔ Met
A24: PROGRAMME OVERALL INDIRECT ATTAINMENT | D24: =AVERAGE(D8:D22) -> 0.75953333 | E24: 0.6 | F24: =IF(D24>=0.6,3,IF(D24>=0.4,2,1)) -> 3 | G24: =D24-E24 -> 0.15953333 | H24: =IF(D24>=E24,"✔ Met","✘ Not Met") -> ✔ Met
A26: 📌 HOW TO USE: (1) Go to 'Survey Data Input' sheet → enter Avg Score (1–5) in yellow cells for each tool & PO (2) Update No. of Respondents column (3) Adjust tool weights in the weight column if needed (4) All attainment %, levels, gaps and status update automatically across all sheets.

Sheet Indirect Attainment Summary
A1: PO / PSO INDIRECT ATTAINMENT SUMMARY — B.Tech Computer Science & Engineering
A2: Indirect Attainment = Weighted Average of all survey tool attainments | Target ≥ 60% | Academic Year 2024-25
A4: LEGEND → | C4: Level 3 : ≥60% HIGH | D4: Level 2 : 40–59% MEDIUM | E4: Level 1 : <40% LOW
A6: # | B6: PO/PSO | C6: Description | D6: ATTAINMENT % BY TOOL | I6: Weighted Att% | J6: Level (3/2/1) | K6: Target (60%) | L6: Gap | M6: Status
D7: T1 (20%) | E7: T2 (25%) | F7: T3 (20%) | G7: T4 (20%) | H7: T5 (15%)
A8: 1 | B8: PO1 | C8: Engineering Knowledge | D8: ='Tool-wise Attainment'!E6 -> 0.88 | E8: ='Tool-wise Attainment'!E7 -> 0.886 | F8: ='Tool-wise Attainment'!E8 -> 0.59 | G8: ='Tool-wise Attainment'!E9 -> 0.608 | H8: ='Tool-wise Attainment'!E10 -> 0.758 | I8: ='Tool-wise Attainment'!E12 -> 0.7508 | J8: =IF(I8>=0.6,3,IF(I8>=0.4,2,1)) -> 3 | K8: 0.6 | L8: =I8-K8 -> 0.1508 | M8: =IF(I8>=K8,"✔ Met","✘ Not Met") -> ✔ Met
A9: 2 | B9: PO2 | C9: Problem Analysis | D9: ='Tool-wise Attainment'!F6 -> 0.69 | E9: ='Tool-wise Attainment'!F7 -> 0.762 | F9: ='Tool-wise Attainment'!F8 -> 0.896 | G9: ='Tool-wise Attainment'!F9 -> 0.934 | H9: ='Tool-wise Attainment'!F10 -> 0.576 | I9: ='Tool-wise Attainment'!F12 -> 0.7809 | J9: =IF(I9>=0.6,3,IF(I9>=0.4,2,1)) -> 3 | K9: 0.6 | L9: =I9-K9 -> 0.1809 | M9: =IF(I9>=K9,"✔ Met","✘ Not Met") -> ✔ Met
A10: 3 | B10: PO3 | C10: Design/Development of Solutions | D10: ='Tool-wise Attainment'!G6 -> 0.656 | E10: ='Tool-wise Attainment'!G7 -> 0.894 | F10: ='Tool-wise Attainment'!G8 -> 0.952 | G10: ='Tool-wise Attainment'!G9 -> 0.582 | H10: ='Tool-wise Attainment'!G10 -> 0.704 | I10: ='Tool-wise Attainment'!G12 -> 0.7671 | J10: =IF(I10>=0.6,3,IF(I10>=0.4,2,1)) -> 3 | K10: 0.6 | L10: =I10-K10 -> 0.1671 | M10: =IF(I10>=K10,"✔ Met","✘ Not Met") -> ✔ Met
A11: 4 | B11: PO4 | C11: Conduct Investigations of Complex Problems | D11: ='Tool-wise Attainment'!H6 -> 0.89 | E11: ='Tool-wise Attainment'!H7 -> 0.634 | F11: ='Tool-wise Attainment'!H8 -> 0.856 | G11: ='Tool-wise Attainment'!H9 -> 0.898 | H11: ='Tool-wise Attainment'!H10 -> 0.956 | I11: ='Tool-wise Attainment'!H12 -> 0.8307 | J11: =IF(I11>=0.6,3,IF(I11>=0.4,2,1)) -> 3 | K11: 0.6 | L11: =I11-K11 -> 0.2307 | M11: =IF(I11>=K11,"✔ Met","✘ Not Met") -> ✔ Met
A12: 5 | B12: PO5 | C12: Modern Tool Usage | D12: ='Tool-wise Attainment'!I6 -> 0.606 | E12: ='Tool-wise Attainment'!I7 -> 0.688 | F12: ='Tool-wise Attainment'!I8 -> 0.858 | G12: ='Tool-wise Attainment'!I9 -> 0.95 | H12: ='Tool-wise Attainment'!I10 -> 0.608 | I12: ='Tool-wise Attainment'!I12 -> 0.746 | J12: =IF(I12>=0.6,3,IF(I12>=0.4,2,1)) -> 3 | K12: 0.6 | L12: =I12-K12 -> 0.146 | M12: =IF(I12>=K12,"✔ Met","✘ Not Met") -> ✔ Met
A13: 6 | B13: PO6 | C13: The Engineer and Society | D13: ='Tool-wise Attainment'!J6 -> 0.75 | E13: ='Tool-wise Attainment'!J7 -> 0.594 | F13: ='Tool-wise Attainment'!J8 -> 0.9 | G13: ='Tool-wise Attainment'!J9 -> 0.86 | H13: ='Tool-wise Attainment'!J10 -> 0.954 | I13: ='Tool-wise Attainment'!J12 -> 0.7936 | J13: =IF(I13>=0.6,3,IF(I13>=0.4,2,1)) -> 3 | K13: 0.6 | L13: =I13-K13 -> 0.1936 | M13: =IF(I13>=K13,"✔ Met","✘ Not Met") -> ✔ Met
A14: 7 | B14: PO7 | C14: Environment and Sustainability | D14: ='Tool-wise Attainment'!K6 -> 0.784 | E14: ='Tool-wise Attainment'!K7 -> 0.872 | F14: ='Tool-wise Attainment'!K8 -> 0.598 | G14: ='Tool-wise Attainment'!K9 -> 0.938 | H14: ='Tool-wise Attainment'!K10 -> 0.922 | I14: ='Tool-wise Attainment'!K12 -> 0.8203 | J14: =IF(I14>=0.6,3,IF(I14>=0.4,2,1)) -> 3 | K14: 0.6 | L14: =I14-K14 -> 0.2203 | M14: =IF(I14>=K14,"✔ Met","✘ Not Met") -> ✔ Met
A15: 8 | B15: PO8 | C15: Ethics | D15: ='Tool-wise Attainment'!L6 -> 0.804 | E15: ='Tool-wise Attainment'!L7 -> 0.774 | F15: ='Tool-wise Attainment'!L8 -> 0.744 | G15: ='Tool-wise Attainment'!L9 -> 0.772 | H15: ='Tool-wise Attainment'!L10 -> 0.836 | I15: ='Tool-wise Attainment'!L12 -> 0.7829 | J15: =IF(I15>=0.6,3,IF(I15>=0.4,2,1)) -> 3 | K15: 0.6 | L15: =I15-K15 -> 0.1829 | M15: =IF(I15>=K15,"✔ Met","✘ Not Met") -> ✔ Met
A16: 9 | B16: PO9 | C16: Individual and Team Work | D16: ='Tool-wise Attainment'!M6 -> 0.618 | E16: ='Tool-wise Attainment'!M7 -> 0.642 | F16: ='Tool-wise Attainment'!M8 -> 0.592 | G16: ='Tool-wise Attainment'!M9 -> 0.648 | H16: ='Tool-wise Attainment'!M10 -> 0.582 | I16: ='Tool-wise Attainment'!M12 -> 0.6194 | J16: =IF(I16>=0.6,3,IF(I16>=0.4,2,1)) -> 3 | K16: 0.6 | L16: =I16-K16 -> 0.0194 | M16: =IF(I16>=K16,"✔ Met","✘ Not Met") -> ✔ Met
A17: 10 | B17: PO10 | C17: Communication | D17: ='Tool-wise Attainment'!N6 -> 0.812 | E17: ='Tool-wise Attainment'!N7 -> 0.636 | F17: ='Tool-wise Attainment'!N8 -> 0.872 | G17: ='Tool-wise Attainment'!N9 -> 0.748 | H17: ='Tool-wise Attainment'!N10 -> 0.748 | I17: ='Tool-wise Attainment'!N12 -> 0.7576 | J17: =IF(I17>=0.6,3,IF(I17>=0.4,2,1)) -> 3 | K17: 0.6 | L17: =I17-K17 -> 0.1576 | M17: =IF(I17>=K17,"✔ Met","✘ Not Met") -> ✔ Met
A18: 11 | B18: PO11 | C18: Project Management and Finance | D18: ='Tool-wise Attainment'!O6 -> 0.76 | E18: ='Tool-wise Attainment'!O7 -> 0.592 | F18: ='Tool-wise Attainment'!O8 -> 0.776 | G18: ='Tool-wise Attainment'!O9 -> 0.856 | H18: ='Tool-wise Attainment'!O10 -> 0.836 | I18: ='Tool-wise Attainment'!O12 -> 0.7518 | J18: =IF(I18>=0.6,3,IF(I18>=0.4,2,1)) -> 3 | K18: 0.6 | L18: =I18-K18 -> 0.1518 | M18: =IF(I18>=K18,"✔ Met","✘ Not Met") -> ✔ Met
A19: 12 | B19: PO12 | C19: Life-long Learning | D19: ='Tool-wise Attainment'!P6 -> 0.9 | E19: ='Tool-wise Attainment'!P7 -> 0.64 | F19: ='Tool-wise Attainment'!P8 -> 0.602 | G19: ='Tool-wise Attainment'!P9 -> 0.868 | H19: ='Tool-wise Attainment'!P10 -> 0.598 | I19: ='Tool-wise Attainment'!P12 -> 0.7237 | J19: =IF(I19>=0.6,3,IF(I19>=0.4,2,1)) -> 3 | K19: 0.6 | L19: =I19-K19 -> 0.1237 | M19: =IF(I19>=K19,"✔ Met","✘ Not Met") -> ✔ Met
A20: 13 | B20: PSO1 | C20: Apply core CS concepts to design software systems | D20: ='Tool-wise Attainment'!Q6 -> 0.572 | E20: ='Tool-wise Attainment'!Q7 -> 0.784 | F20: ='Tool-wise Attainment'!Q8 -> 0.738 | G20: ='Tool-wise Attainment'!Q9 -> 0.714 | H20: ='Tool-wise Attainment'!Q10 -> 0.68 | I20: ='Tool-wise Attainment'!Q12 -> 0.7028 | J20: =IF(I20>=0.6,3,IF(I20>=0.4,2,1)) -> 3 | K20: 0.6 | L20: =I20-K20 -> 0.1028 | M20: =IF(I20>=K20,"✔ Met","✘ Not Met") -> ✔ Met
A21: 14 | B21: PSO2 | C21: Use modern tools to solve real-world engineering problems | D21: ='Tool-wise Attainment'!R6 -> 0.942 | E21: ='Tool-wise Attainment'!R7 -> 0.736 | F21: ='Tool-wise Attainment'!R8 -> 0.87 | G21: ='Tool-wise Attainment'!R9 -> 0.938 | H21: ='Tool-wise Attainment'!R10 -> 0.596 | I21: ='Tool-wise Attainment'!R12 -> 0.8234 | J21: =IF(I21>=0.6,3,IF(I21>=0.4,2,1)) -> 3 | K21: 0.6 | L21: =I21-K21 -> 0.2234 | M21: =IF(I21>=K21,"✔ Met","✘ Not Met") -> ✔ Met
A22: 15 | B22: PSO3 | C22: Demonstrate professional skills for industry/research | D22: ='Tool-wise Attainment'!S6 -> 0.63 | E22: ='Tool-wise Attainment'!S7 -> 0.842 | F22: ='Tool-wise Attainment'!S8 -> 0.78 | G22: ='Tool-wise Attainment'!S9 -> 0.574 | H22: ='Tool-wise Attainment'!S10 -> 0.898 | I22: ='Tool-wise Attainment'!S12 -> 0.742 | J22: =IF(I22>=0.6,3,IF(I22>=0.4,2,1)) -> 3 | K22: 0.6 | L22: =I22-K22 -> 0.142 | M22: =IF(I22>=K22,"✔ Met","✘ Not Met") -> ✔ Met

Sheet Tool-wise Attainment
A1: TOOL-WISE INDIRECT ATTAINMENT MATRIX — All Assessment Tools × All POs/PSOs
A2: Values are auto-pulled from Survey Data Input sheet. Each cell = Attainment% for that Tool–PO combination.
A4: # | B4: Tool ID | C4: Tool Name | D4: Weight | E4: PROGRAMME OUTCOMES (PO1–PO12) | Q4: PROGRAMME SPECIFIC OUTCOMES
E5: PO1 | F5: PO2 | G5: PO3 | H5: PO4 | I5: PO5 | J5: PO6 | K5: PO7 | L5: PO8 | M5: PO9 | N5: PO10 | O5: PO11 | P5: PO12 | Q5: PSO1 | R5: PSO2 | S5: PSO3
A6: 1 | B6: T1 | C6: Course Exit Survey | D6: ='Survey Data Input'!B5 -> 0.2 | E6: =IFERROR('Survey Data Input'!D14/'Survey Data Input'!C5,0) -> 0.88 | F6: =IFERROR('Survey Data Input'!D15/'Survey Data Input'!C5,0) -> 0.69 | G6: =IFERROR('Survey Data Input'!D16/'Survey Data Input'!C5,0) -> 0.656 | H6: =IFERROR('Survey Data Input'!D17/'Survey Data Input'!C5,0) -> 0.89 | I6: =IFERROR('Survey Data Input'!D18/'Survey Data Input'!C5,0) -> 0.606 | J6: =IFERROR('Survey Data Input'!D19/'Survey Data Input'!C5,0) -> 0.75 | K6: =IFERROR('Survey Data Input'!D20/'Survey Data Input'!C5,0) -> 0.784 | L6: =IFERROR('Survey Data Input'!D21/'Survey Data Input'!C5,0) -> 0.804 | M6: =IFERROR('Survey Data Input'!D22/'Survey Data Input'!C5,0) -> 0.618 | N6: =IFERROR('Survey Data Input'!D23/'Survey Data Input'!C5,0) -> 0.812 | O6: =IFERROR('Survey Data Input'!D24/'Survey Data Input'!C5,0) -> 0.76 | P6: =IFERROR('Survey Data Input'!D25/'Survey Data Input'!C5,0) -> 0.9 | Q6: =IFERROR('Survey Data Input'!D26/'Survey Data Input'!C5,0) -> 0.572 | R6: =IFERROR('Survey Data Input'!D27/'Survey Data Input'!C5,0) -> 0.942 | S6: =IFERROR('Survey Data Input'!D28/'Survey Data Input'!C5,0) -> 0.63
A7: 2 | B7: T2 | C7: Programme Exit Survey | D7: ='Survey Data Input'!B6 -> 0.25 | E7: =IFERROR('Survey Data Input'!D33/'Survey Data Input'!C6,0) -> 0.886 | F7: =IFERROR('Survey Data Input'!D34/'Survey Data Input'!C6,0) -> 0.762 | G7: =IFERROR('Survey Data Input'!D35/'Survey Data Input'!C6,0) -> 0.894 | H7: =IFERROR('Survey Data Input'!D36/'Survey Data Input'!C6,0) -> 0.634 | I7: =IFERROR('Survey Data Input'!D37/'Survey Data Input'!C6,0) -> 0.688 | J7: =IFERROR('Survey Data Input'!D38/'Survey Data Input'!C6,0) -> 0.594 | K7: =IFERROR('Survey Data Input'!D39/'Survey Data Input'!C6,0) -> 0.872 | L7: =IFERROR('Survey Data Input'!D40/'Survey Data Input'!C6,0) -> 0.774 | M7: =IFERROR('Survey Data Input'!D41/'Survey Data Input'!C6,0) -> 0.642 | N7: =IFERROR('Survey Data Input'!D42/'Survey Data Input'!C6,0) -> 0.636 | O7: =IFERROR('Survey Data Input'!D43/'Survey Data Input'!C6,0) -> 0.592 | P7: =IFERROR('Survey Data Input'!D44/'Survey Data Input'!C6,0) -> 0.64 | Q7: =IFERROR('Survey Data Input'!D45/'Survey Data Input'!C6,0) -> 0.784 | R7: =IFERROR('Survey Data Input'!D46/'Survey Data Input'!C6,0) -> 0.736 | S7: =IFERROR('Survey Data Input'!D47/'Survey Data Input'!C6,0) -> 0.842
A8: 3 | B8: T3 | C8: Alumni Survey | D8: ='Survey Data Input'!B7 -> 0.2 | E8: =IFERROR('Survey Data Input'!D52/'Survey Data Input'!C7,0) -> 0.59 | F8: =IFERROR('Survey Data Input'!D53/'Survey Data Input'!C7,0) -> 0.896 | G8: =IFERROR('Survey Data Input'!D54/'Survey Data Input'!C7,0) -> 0.952 | H8: =IFERROR('Survey Data Input'!D55/'Survey Data Input'!C7,0) -> 0.856 | I8: =IFERROR('Survey Data Input'!D56/'Survey Data Input'!C7,0) -> 0.858 | J8: =IFERROR('Survey Data Input'!D57/'Survey Data Input'!C7,0) -> 0.9 | K8: =IFERROR('Survey Data Input'!D58/'Survey Data Input'!C7,0) -> 0.598 | L8: =IFERROR('Survey Data Input'!D59/'Survey Data Input'!C7,0) -> 0.744 | M8: =IFERROR('Survey Data Input'!D60/'Survey Data Input'!C7,0) -> 0.592 | N8: =IFERROR('Survey Data Input'!D61/'Survey Data Input'!C7,0) -> 0.872 | O8: =IFERROR('Survey Data Input'!D62/'Survey Data Input'!C7,0) -> 0.776 | P8: =IFERROR('Survey Data Input'!D63/'Survey Data Input'!C7,0) -> 0.602 | Q8: =IFERROR('Survey Data Input'!D64/'Survey Data Input'!C7,0) -> 0.738 | R8: =IFERROR('Survey Data Input'!D65/'Survey Data Input'!C7,0) -> 0.87 | S8: =IFERROR('Survey Data Input'!D66/'Survey Data Input'!C7,0) -> 0.78
A9: 4 | B9: T4 | C9: Employer Survey | D9: ='Survey Data Input'!B8 -> 0.2 | E9: =IFERROR('Survey Data Input'!D71/'Survey Data Input'!C8,0) -> 0.608 | F9: =IFERROR('Survey Data Input'!D72/'Survey Data Input'!C8,0) -> 0.934 | G9: =IFERROR('Survey Data Input'!D73/'Survey Data Input'!C8,0) -> 0.582 | H9: =IFERROR('Survey Data Input'!D74/'Survey Data Input'!C8,0) -> 0.898 | I9: =IFERROR('Survey Data Input'!D75/'Survey Data Input'!C8,0) -> 0.95 | J9: =IFERROR('Survey Data Input'!D76/'Survey Data Input'!C8,0) -> 0.86 | K9: =IFERROR('Survey Data Input'!D77/'Survey Data Input'!C8,0) -> 0.938 | L9: =IFERROR('Survey Data Input'!D78/'Survey Data Input'!C8,0) -> 0.772 | M9: =IFERROR('Survey Data Input'!D79/'Survey Data Input'!C8,0) -> 0.648 | N9: =IFERROR('Survey Data Input'!D80/'Survey Data Input'!C8,0) -> 0.748 | O9: =IFERROR('Survey Data Input'!D81/'Survey Data Input'!C8,0) -> 0.856 | P9: =IFERROR('Survey Data Input'!D82/'Survey Data Input'!C8,0) -> 0.868 | Q9: =IFERROR('Survey Data Input'!D83/'Survey Data Input'!C8,0) -> 0.714 | R9: =IFERROR('Survey Data Input'!D84/'Survey Data Input'!C8,0) -> 0.938 | S9: =IFERROR('Survey Data Input'!D85/'Survey Data Input'!C8,0) -> 0.574
A10: 5 | B10: T5 | C10: Internship/Industry Feedback | D10: ='Survey Data Input'!B9 -> 0.15 | E10: =IFERROR('Survey Data Input'!D90/'Survey Data Input'!C9,0) -> 0.758 | F10: =IFERROR('Survey Data Input'!D91/'Survey Data Input'!C9,0) -> 0.576 | G10: =IFERROR('Survey Data Input'!D92/'Survey Data Input'!C9,0) -> 0.704 | H10: =IFERROR('Survey Data Input'!D93/'Survey Data Input'!C9,0) -> 0.956 | I10: =IFERROR('Survey Data Input'!D94/'Survey Data Input'!C9,0) -> 0.608 | J10: =IFERROR('Survey Data Input'!D95/'Survey Data Input'!C9,0) -> 0.954 | K10: =IFERROR('Survey Data Input'!D96/'Survey Data Input'!C9,0) -> 0.922 | L10: =IFERROR('Survey Data Input'!D97/'Survey Data Input'!C9,0) -> 0.836 | M10: =IFERROR('Survey Data Input'!D98/'Survey Data Input'!C9,0) -> 0.582 | N10: =IFERROR('Survey Data Input'!D99/'Survey Data Input'!C9,0) -> 0.748 | O10: =IFERROR('Survey Data Input'!D100/'Survey Data Input'!C9,0) -> 0.836 | P10: =IFERROR('Survey Data Input'!D101/'Survey Data Input'!C9,0) -> 0.598 | Q10: =IFERROR('Survey Data Input'!D102/'Survey Data Input'!C9,0) -> 0.68 | R10: =IFERROR('Survey Data Input'!D103/'Survey Data Input'!C9,0) -> 0.596 | S10: =IFERROR('Survey Data Input'!D104/'Survey Data Input'!C9,0) -> 0.898
A12: WEIGHTED INDIRECT ATTAINMENT (Programme Level) | D12: =SUM('Survey Data Input'!B5:B9) -> 1 | E12: =IFERROR((('Survey Data Input'!B5*'Tool-wise Attainment'!E6)+('Survey Data Input'!B6*'Tool-wise Attainment'!E7)+('Survey Data Input'!B7*'Tool-wise Attainment'!E8)+('Survey Data Input'!B8*'Tool-wise Attainment'!E9)+('Survey Data Input'!B9*'Tool-wise Attainment'!E10))/SUM('Survey Data Input'!B5:B9),0) -> 0.7508 | F12: =IFERROR((('Survey Data Input'!B5*'Tool-wise Attainment'!F6)+('Survey Data Input'!B6*'Tool-wise Attainment'!F7)+('Survey Data Input'!B7*'Tool-wise Attainment'!F8)+('Survey Data Input'!B8*'Tool-wise Attainment'!F9)+('Survey Data Input'!B9*'Tool-wise Attainment'!F10))/SUM('Survey Data Input'!B5:B9),0) -> 0.7809 | G12: =IFERROR((('Survey Data Input'!B5*'Tool-wise Attainment'!G6)+('Survey Data Input'!B6*'Tool-wise Attainment'!G7)+('Survey Data Input'!B7*'Tool-wise Attainment'!G8)+('Survey Data Input'!B8*'Tool-wise Attainment'!G9)+('Survey Data Input'!B9*'Tool-wise Attainment'!G10))/SUM('Survey Data Input'!B5:B9),0) -> 0.7671 | H12: =IFERROR((('Survey Data Input'!B5*'Tool-wise Attainment'!H6)+('Survey Data Input'!B6*'Tool-wise Attainment'!H7)+('Survey Data Input'!B7*'Tool-wise Attainment'!H8)+('Survey Data Input'!B8*'Tool-wise Attainment'!H9)+('Survey Data Input'!B9*'Tool-wise Attainment'!H10))/SUM('Survey Data Input'!B5:B9),0) -> 0.8307 | I12: =IFERROR((('Survey Data Input'!B5*'Tool-wise Attainment'!I6)+('Survey Data Input'!B6*'Tool-wise Attainment'!I7)+('Survey Data Input'!B7*'Tool-wise Attainment'!I8)+('Survey Data Input'!B8*'Tool-wise Attainment'!I9)+('Survey Data Input'!B9*'Tool-wise Attainment'!I10))/SUM('Survey Data Input'!B5:B9),0) -> 0.746 | J12: =IFERROR((('Survey Data Input'!B5*'Tool-wise Attainment'!J6)+('Survey Data Input'!B6*'Tool-wise Attainment'!J7)+('Survey Data Input'!B7*'Tool-wise Attainment'!J8)+('Survey Data Input'!B8*'Tool-wise Attainment'!J9)+('Survey Data Input'!B9*'Tool-wise Attainment'!J10))/SUM('Survey Data Input'!B5:B9),0) -> 0.7936 | K12: =IFERROR((('Survey Data Input'!B5*'Tool-wise Attainment'!K6)+('Survey Data Input'!B6*'Tool-wise Attainment'!K7)+('Survey Data Input'!B7*'Tool-wise Attainment'!K8)+('Survey Data Input'!B8*'Tool-wise Attainment'!K9)+('Survey Data Input'!B9*'Tool-wise Attainment'!K10))/SUM('Survey Data Input'!B5:B9),0) -> 0.8203 | L12: =IFERROR((('Survey Data Input'!B5*'Tool-wise Attainment'!L6)+('Survey Data Input'!B6*'Tool-wise Attainment'!L7)+('Survey Data Input'!B7*'Tool-wise Attainment'!L8)+('Survey Data Input'!B8*'Tool-wise Attainment'!L9)+('Survey Data Input'!B9*'Tool-wise Attainment'!L10))/SUM('Survey Data Input'!B5:B9),0) -> 0.7829 | M12: =IFERROR((('Survey Data Input'!B5*'Tool-wise Attainment'!M6)+('Survey Data Input'!B6*'Tool-wise Attainment'!M7)+('Survey Data Input'!B7*'Tool-wise Attainment'!M8)+('Survey Data Input'!B8*'Tool-wise Attainment'!M9)+('Survey Data Input'!B9*'Tool-wise Attainment'!M10))/SUM('Survey Data Input'!B5:B9),0) -> 0.6194 | N12: =IFERROR((('Survey Data Input'!B5*'Tool-wise Attainment'!N6)+('Survey Data Input'!B6*'Tool-wise Attainment'!N7)+('Survey Data Input'!B7*'Tool-wise Attainment'!N8)+('Survey Data Input'!B8*'Tool-wise Attainment'!N9)+('Survey Data Input'!B9*'Tool-wise Attainment'!N10))/SUM('Survey Data Input'!B5:B9),0) -> 0.7576 | O12: =IFERROR((('Survey Data Input'!B5*'Tool-wise Attainment'!O6)+('Survey Data Input'!B6*'Tool-wise Attainment'!O7)+('Survey Data Input'!B7*'Tool-wise Attainment'!O8)+('Survey Data Input'!B8*'Tool-wise Attainment'!O9)+('Survey Data Input'!B9*'Tool-wise Attainment'!O10))/SUM('Survey Data Input'!B5:B9),0) -> 0.7518 | P12: =IFERROR((('Survey Data Input'!B5*'Tool-wise Attainment'!P6)+('Survey Data Input'!B6*'Tool-wise Attainment'!P7)+('Survey Data Input'!B7*'Tool-wise Attainment'!P8)+('Survey Data Input'!B8*'Tool-wise Attainment'!P9)+('Survey Data Input'!B9*'Tool-wise Attainment'!P10))/SUM('Survey Data Input'!B5:B9),0) -> 0.7237 | Q12: =IFERROR((('Survey Data Input'!B5*'Tool-wise Attainment'!Q6)+('Survey Data Input'!B6*'Tool-wise Attainment'!Q7)+('Survey Data Input'!B7*'Tool-wise Attainment'!Q8)+('Survey Data Input'!B8*'Tool-wise Attainment'!Q9)+('Survey Data Input'!B9*'Tool-wise Attainment'!Q10))/SUM('Survey Data Input'!B5:B9),0) -> 0.7028 | R12: =IFERROR((('Survey Data Input'!B5*'Tool-wise Attainment'!R6)+('Survey Data Input'!B6*'Tool-wise Attainment'!R7)+('Survey Data Input'!B7*'Tool-wise Attainment'!R8)+('Survey Data Input'!B8*'Tool-wise Attainment'!R9)+('Survey Data Input'!B9*'Tool-wise Attainment'!R10))/SUM('Survey Data Input'!B5:B9),0) -> 0.8234 | S12: =IFERROR((('Survey Data Input'!B5*'Tool-wise Attainment'!S6)+('Survey Data Input'!B6*'Tool-wise Attainment'!S7)+('Survey Data Input'!B7*'Tool-wise Attainment'!S8)+('Survey Data Input'!B8*'Tool-wise Attainment'!S9)+('Survey Data Input'!B9*'Tool-wise Attainment'!S10))/SUM('Survey Data Input'!B5:B9),0) -> 0.742
A13: ATTAINMENT LEVEL (3=High≥60% 2=Med≥40% 1=Low<40%) | E13: =IF(E12>=0.6,3,IF(E12>=0.4,2,1)) -> 3 | F13: =IF(F12>=0.6,3,IF(F12>=0.4,2,1)) -> 3 | G13: =IF(G12>=0.6,3,IF(G12>=0.4,2,1)) -> 3 | H13: =IF(H12>=0.6,3,IF(H12>=0.4,2,1)) -> 3 | I13: =IF(I12>=0.6,3,IF(I12>=0.4,2,1)) -> 3 | J13: =IF(J12>=0.6,3,IF(J12>=0.4,2,1)) -> 3 | K13: =IF(K12>=0.6,3,IF(K12>=0.4,2,1)) -> 3 | L13: =IF(L12>=0.6,3,IF(L12>=0.4,2,1)) -> 3 | ... S13: =IF(S12>=0.6,3,IF(S12>=0.4,2,1)) -> 3
A14: TARGET (60%) | E14: 0.6 | F14: 0.6 | G14: 0.6 | H14: 0.6 | I14: 0.6 | J14: 0.6 | K14: 0.6 | L14: 0.6 | M14: 0.6 | N14: 0.6 | O14: 0.6 | P14: 0.6 | Q14: 0.6 | R14: 0.6 | S14: 0.6
A15: GAP (Att – Target) | E15: =E12-E14 -> 0.1508 | F15: =F12-F14 -> 0.1809 | G15: =G12-G14 -> 0.1671 | H15: =H12-H14 -> 0.2307 | I15: =I12-I14 -> 0.146 | J15: =J12-J14 -> 0.1936 | K15: =K12-K14 -> 0.2203 | L15: =L12-L14 -> 0.1829 | ... S15: =S12-S14 -> 0.142
A16: STATUS | E16: =IF(E12>=E14,"✔","✘") -> ✔ | F16: =IF(F12>=F14,"✔","✘") -> ✔ | G16: =IF(G12>=G14,"✔","✘") -> ✔ | H16: =IF(H12>=H14,"✔","✘") -> ✔ | I16: =IF(I12>=I14,"✔","✘") -> ✔ | J16: =IF(J12>=J14,"✔","✘") -> ✔ | K16: =IF(K12>=K14,"✔","✘") -> ✔ | L16: =IF(L12>=L14,"✔","✘") -> ✔ | ... S16: =IF(S12>=S14,"✔","✘") -> ✔

Sheet Survey Data Input
A1: INDIRECT ASSESSMENT — SURVEY DATA INPUT SHEET
A2: Enter average survey scores (per PO/PSO) in yellow cells for each assessment tool. Scores are on a 1–5 Likert scale. All attainment calculations update automatically.
A4: Tool | B4: Weight | C4: Scale | D4: Description
A5: T1 – Course Exit Survey | B5: 0.2 | C5: 5 | D5: End-of-semester student feedback on learning outcomes
A6: T2 – Programme Exit Survey | B6: 0.25 | C6: 5 | D6: Graduating student survey on overall PO achievement
A7: T3 – Alumni Survey | B7: 0.2 | C7: 5 | D7: Annual alumni feedback on programme relevance
A8: T4 – Employer Survey | B8: 0.2 | C8: 5 | D8: Employer feedback on graduate competency
A9: T5 – Internship/Industry Feedback | B9: 0.15 | C9: 5 | D9: Supervisor rating during internship/project
A10: TOTAL WEIGHT | B10: =SUM(B5:B9) -> 1
A12: T1 · COURSE EXIT SURVEY · Weight: 20% · Scale: 1–5 · End-of-semester student feedback on learning outcomes
A13: PO/PSO | B13: Description | C13: No. of Respondents | D13: Avg Score (1–5) | E13: Attainment % | F13: Level (3/2/1) | G13: Target Met? | H13: Remarks
A14: PO1 | B14: Engineering Knowledge | C14: 85 | D14: 4.4 | E14: =IFERROR(D14/C5,0) -> 0.88 | F14: =IF(E14>=0.6,3,IF(E14>=0.4,2,1)) -> 3 | G14: =IF(E14>=0.6,"✔ Yes","✘ No") -> ✔ Yes
A15: PO2 | B15: Problem Analysis | C15: 93 | D15: 3.45 | E15: =IFERROR(D15/C5,0) -> 0.69 | F15: =IF(E15>=0.6,3,IF(E15>=0.4,2,1)) -> 3 | G15: =IF(E15>=0.6,"✔ Yes","✘ No") -> ✔ Yes
A16: PO3 | B16: Design/Development of Solutions | C16: 113 | D16: 3.28 | E16: =IFERROR(D16/C5,0) -> 0.656 | F16: =IF(E16>=0.6,3,IF(E16>=0.4,2,1)) -> 3 | G16: =IF(E16>=0.6,"✔ Yes","✘ No") -> ✔ Yes
A17: PO4 | B17: Conduct Investigations of Complex Problems | C17: 40 | D17: 4.45 | E17: =IFERROR(D17/C5,0) -> 0.89 | F17: =IF(E17>=0.6,3,IF(E17>=0.4,2,1)) -> 3 | G17: =IF(E17>=0.6,"✔ Yes","✘ No") -> ✔ Yes
A18: PO5 | B18: Modern Tool Usage | C18: 47 | D18: 3.03 | E18: =IFERROR(D18/C5,0) -> 0.606 | F18: =IF(E18>=0.6,3,IF(E18>=0.4,2,1)) -> 3 | G18: =IF(E18>=0.6,"✔ Yes","✘ No") -> ✔ Yes
A19: PO6 | B19: The Engineer and Society | C19: 101 | D19: 3.75 | E19: =IFERROR(D19/C5,0) -> 0.75 | F19: =IF(E19>=0.6,3,IF(E19>=0.4,2,1)) -> 3 | G19: =IF(E19>=0.6,"✔ Yes","✘ No") -> ✔ Yes
A20: PO7 | B20: Environment and Sustainability | C20: 58 | D20: 3.92 | E20: =IFERROR(D20/C5,0) -> 0.784 | F20: =IF(E20>=0.6,3,IF(E20>=0.4,2,1)) -> 3 | G20: =IF(E20>=0.6,"✔ Yes","✘ No") -> ✔ Yes
A21: PO8 | B21: Ethics | C21: 43 | D21: 4.02 | E21: =IFERROR(D21/C5,0) -> 0.804 | F21: =IF(E21>=0.6,3,IF(E21>=0.4,2,1)) -> 3 | G21: =IF(E21>=0.6,"✔ Yes","✘ No") -> ✔ Yes
A22: PO9 | B22: Individual and Team Work | C22: 41 | D22: 3.09 | E22: =IFERROR(D22/C5,0) -> 0.618 | F22: =IF(E22>=0.6,3,IF(E22>=0.4,2,1)) -> 3 | G22: =IF(E22>=0.6,"✔ Yes","✘ No") -> ✔ Yes
A23: PO10 | B23: Communication | C23: 70 | D23: 4.06 | E23: =IFERROR(D23/C5,0) -> 0.812 | F23: =IF(E23>=0.6,3,IF(E23>=0.4,2,1)) -> 3 | G23: =IF(E23>=0.6,"✔ Yes","✘ No") -> ✔ Yes
A24: PO11 | B24: Project Management and Finance | C24: 51 | D24: 3.8 | E24: =IFERROR(D24/C5,0) -> 0.76 | F24: =IF(E24>=0.6,3,IF(E24>=0.4,2,1)) -> 3 | G24: =IF(E24>=0.6,"✔ Yes","✘ No") -> ✔ Yes
A25: PO12 | B25: Life-long Learning | C25: 99 | D25: 4.5 | E25: =IFERROR(D25/C5,0) -> 0.9 | F25: =IF(E25>=0.6,3,IF(E25>=0.4,2,1)) -> 3 | G25: =IF(E25>=0.6,"✔ Yes","✘ No") -> ✔ Yes
A26: PSO1 | B26: Apply core CS concepts to design software systems | C26: 54 | D26: 2.86 | E26: =IFERROR(D26/C5,0) -> 0.572 | F26: =IF(E26>=0.6,3,IF(E26>=0.4,2,1)) -> 2 | G26: =IF(E26>=0.6,"✔ Yes","✘ No") -> ✘ No
A27: PSO2 | B27: Use modern tools to solve real-world engineering problems | C27: 89 | D27: 4.71 | E27: =IFERROR(D27/C5,0) -> 0.942 | F27: =IF(E27>=0.6,3,IF(E27>=0.4,2,1)) -> 3 | G27: =IF(E27>=0.6,"✔ Yes","✘ No") -> ✔ Yes
A28: PSO3 | B28: Demonstrate professional skills for industry/research | C28: 100 | D28: 3.15 | E28: =IFERROR(D28/C5,0) -> 0.63 | F28: =IF(E28>=0.6,3,IF(E28>=0.4,2,1)) -> 3 | G28: =IF(E28>=0.6,"✔ Yes","✘ No") -> ✔ Yes
A31: T2 · PROGRAMME EXIT SURVEY · Weight: 25% · Scale: 1–5 · Graduating student survey on overall PO achievement
A32: PO/PSO | B32: Description | C32: No. of Respondents | D32: Avg Score (1–5) | E32: Attainment % | F32: Level (3/2/1) | G32: Target Met? | H32: Remarks
A33: PO1 | B33: Engineering Knowledge | C33: 53 | D33: 4.43 | E33: =IFERROR(D33/C6,0) -> 0.886 | F33: =IF(E33>=0.6,3,IF(E33>=0.4,2,1)) -> 3 | G33: =IF(E33>=0.6,"✔ Yes","✘ No") -> ✔ Yes
A34: PO2 | B34: Problem Analysis | C34: 57 | D34: 3.81 | E34: =IFERROR(D34/C6,0) -> 0.762 | F34: =IF(E34>=0.6,3,IF(E34>=0.4,2,1)) -> 3 | G34: =IF(E34>=0.6,"✔ Yes","✘ No") -> ✔ Yes
A35: PO3 | B35: Design/Development of Solutions | C35: 70 | D35: 4.47 | E35: =IFERROR(D35/C6,0) -> 0.894 | F35: =IF(E35>=0.6,3,IF(E35>=0.4,2,1)) -> 3 | G35: =IF(E35>=0.6,"✔ Yes","✘ No") -> ✔ Yes
A36: PO4 | B36: Conduct Investigations of Complex Problems | C36: 73 | D36: 3.17 | E36: =IFERROR(D36/C6,0) -> 0.634 | F36: =IF(E36>=0.6,3,IF(E36>=0.4,2,1)) -> 3 | G36: =IF(E36>=0.6,"✔ Yes","✘ No") -> ✔ Yes
A37: PO5 | B37: Modern Tool Usage | C37: 66 | D37: 3.44 | E37: =IFERROR(D37/C6,0) -> 0.688 | F37: =IF(E37>=0.6,3,IF(E37>=0.4,2,1)) -> 3 | G37: =IF(E37>=0.6,"✔ Yes","✘ No") -> ✔ Yes
A38: PO6 | B38: The Engineer and Society | C38: 51 | D38: 2.97 | E38: =IFERROR(D38/C6,0) -> 0.594 | F38: =IF(E38>=0.6,3,IF(E38>=0.4,2,1)) -> 2 | G38: =IF(E38>=0.6,"✔ Yes","✘ No") -> ✘ No
A39: PO7 | B39: Environment and Sustainability | C39: 60 | D39: 4.36 | E39: =IFERROR(D39/C6,0) -> 0.872 | F39: =IF(E39>=0.6,3,IF(E39>=0.4,2,1)) -> 3 | G39: =IF(E39>=0.6,"✔ Yes","✘ No") -> ✔ Yes
A40: PO8 | B40: Ethics | C40: 61 | D40: 3.87 | E40: =IFERROR(D40/C6,0) -> 0.774 | F40: =IF(E40>=0.6,3,IF(E40>=0.4,2,1)) -> 3 | G40: =IF(E40>=0.6,"✔ Yes","✘ No") -> ✔ Yes
A41: PO9 | B41: Individual and Team Work | C41: 59 | D41: 3.21 | E41: =IFERROR(D41/C6,0) -> 0.642 | F41: =IF(E41>=0.6,3,IF(E41>=0.4,2,1)) -> 3 | G41: =IF(E41>=0.6,"✔ Yes","✘ No") -> ✔ Yes
A42: PO10 | B42: Communication | C42: 43 | D42: 3.18 | E42: =IFERROR(D42/C6,0) -> 0.636 | F42: =IF(E42>=0.6,3,IF(E42>=0.4,2,1)) -> 3 | G42: =IF(E42>=0.6,"✔ Yes","✘ No") -> ✔ Yes
A43: PO11 | B43: Project Management and Finance | C43: 46 | D43: 2.96 | E43: =IFERROR(D43/C6,0) -> 0.592 | F43: =IF(E43>=0.6,3,IF(E43>=0.4,2,1)) -> 2 | G43: =IF(E43>=0.6,"✔ Yes","✘ No") -> ✘ No
A44: PO12 | B44: Life-long Learning | C44: 69 | D44: 3.2 | E44: =IFERROR(D44/C6,0) -> 0.64 | F44: =IF(E44>=0.6,3,IF(E44>=0.4,2,1)) -> 3 | G44: =IF(E44>=0.6,"✔ Yes","✘ No") -> ✔ Yes
...
