Workbook

Sheet Rubric Framework
A1: VIVA VOCE ASSESSMENT RUBRIC — COMPLETE EVALUATION FRAMEWORK
A2: Department of Computer Science & Engineering | Academic Year 2024-25 | Reference: Rubrics Guidelines Document — Section 8: Viva Voce Assessment Rubrics
A4: INTRODUCTION (From Document Section 8)
A5: ✦ Viva voce evaluates → Conceptual clarity, Technical understanding, Spontaneous response ability, Depth of knowledge
A6: ✦ Objectives → Standardize oral assessment, Reduce evaluator bias, Improve fairness and consistency
A7: ✦ Skills Assessed → Conceptual knowledge, Oral communication, Critical thinking, Technical reasoning
A8: ✦ Applications → Lab viva, Internal/External exam viva, Project defence, Research paper Q&A, Internship review
A10: SCORING SCALE | C10: 4 — Excellent | D10: 3 — Good | E10: 2 — Fair | F10: 1 — Poor | G10: Weighted Mark = Score / 4 × Criterion Max | Total = Σ Weighted | Max = 100M | Grade: O≥90 A+≥75 A≥60 B+≥50 B≥40 F<40 | Level: L3≥75% L2≥60% L1≥40% L0<40%
A12: # | B12: Criterion | C12: Wt% | D12: Max Mks | E12: Bloom's | F12: Excellent (4) | G12: Good (3) | H12: Fair (2) | I12: Poor (1) | J12: Skill | K12: CO | L12: PO Link
A13: 1 | B13: Conceptual Understanding | C13: 0.25 | D13: 25 | E13: L2 – Understand / L4 – Analyse | F13: Demonstrates complete, in-depth understanding of concepts; explains underlying principles accurately with no gaps | G13: Good understanding of core concepts; minor gaps in advanced or peripheral ideas | H13: Partial understanding; can explain basic concepts but struggles with deeper reasoning | I13: Weak or incorrect understanding; unable to explain fundamental concepts | J13: Cognitive / Technical Knowledge | K13: CO1 | L13: PO1 (Engineering Knowledge), PO2 (Problem Analysis)
A14: 2 | B14: Technical Explanation | C14: 0.25 | D14: 25 | E14: L3 – Apply / L4 – Analyse | F14: Logical, accurate and structured technical explanation; uses correct terminology; relates concepts to practical applications | G14: Mostly accurate explanation with minor errors in terminology or logic | H14: Some confusion in explanation; inaccurate use of technical terms; lacks structured reasoning | I14: Incorrect or irrelevant explanation; unable to explain technical aspects | J14: Technical Reasoning | K14: CO1 | L14: PO1 (Engineering Knowledge), PO4 (Conduct Investigations)
A15: 3 | B15: Confidence & Composure | C15: 0.15 | D15: 15 | E15: L3 – Apply | F15: Highly confident; maintains eye contact; composed and assertive under all questioning conditions | G15: Mostly confident; minor hesitation but recovers quickly and maintains composure | H15: Moderate confidence; visible nervousness; significant hesitation affecting responses | I15: Very hesitant; extreme nervousness; unable to sustain composure or deliver answers | J15: Professional Behavior | K15: CO3 | L15: PO9 (Individual & Team Work), PO12 (Lifelong Learning)
A16: 4 | B16: Problem-Solving Ability | C16: 0.2 | D16: 20 | E16: L3 – Apply / L5 – Evaluate | F16: Excellent ability to solve application-based questions; applies concepts creatively; derives logical solutions independently | G16: Good problem-solving; mostly correct approach with minor errors in application | H16: Limited problem-solving; requires prompting; partial solutions with errors | I16: Unable to solve application questions; incorrect approach; relies heavily on hints | J16: Analytical / Problem-Solving | K16: CO2 | L16: PO2 (Problem Analysis), PO3 (Design/Development)
A17: 5 | B17: Communication Skills | C17: 0.15 | D17: 15 | E17: L3 – Apply | F17: Clear, fluent and professional communication; precise language; excellent pace and articulation | G17: Mostly clear and fluent; minor grammatical or vocabulary lapses | H17: Limited clarity; noticeable hesitation; restricted vocabulary affecting comprehension | I17: Poor communication; unclear delivery; very limited vocabulary and fluency | J17: Verbal Communication | K17: CO3 | L17: PO10 (Communication)
A18: TOTAL | C18: 100% | D18: 100
A20: TYPES OF VIVA VOCE COVERED BY THIS RUBRIC
A21: # | B21: Viva Type | C21: Typical Marks | D21: Context / Setting | E21: Linked COs
A22: 1 | B22: Lab Viva | C22: 20M | D22: Post-experiment oral examination | E22: CO3, CO4
A23: 2 | B23: Internal Exam Viva | C23: 10M | D23: After internal examination to test deeper understanding | E23: CO1, CO2
A24: 3 | B24: Project Viva | C24: 20–30M | D24: Mini/Major/Capstone project defence | E24: All COs
A25: 4 | B25: End-Semester Practical Viva | C25: 20M | D25: Conducted by external examiner alongside practical | E25: CO1–CO4
A26: 5 | B26: Research Paper Viva | C26: Variable | D26: Presentation and Q&A on submitted research | E26: CO2, CO4
A27: 6 | B27: Internship Viva | C27: Variable | D27: Industry experience review by panel | E27: CO3, CO5
A30: COURSE OUTCOMES (COs) — VIVA VOCE
A31: CO | B31: Description | C31: Bloom's | D31: Mapped POs | E31: Assessed By | F31: Assessed By
A32: CO1 | B32: Demonstrate conceptual knowledge and explain technical principles accurately | C32: L2-L4 | D32: PO1, PO2 | E32: Conceptual Understanding, Technical Explanation
A33: CO2 | B33: Analyse problems, apply reasoning and arrive at logical technical solutions | C33: L3-L5 | D33: PO2, PO3 | E33: Problem-Solving Ability
A34: CO3 | B34: Communicate technical ideas clearly and confidently under oral examination conditions | C34: L3 | D34: PO10 | E34: Confidence & Composure, Communication Skills
A35: CO4 | B35: Respond adaptively to questioning; demonstrate analytical and problem-solving ability | C35: L3-L5 | D35: PO2, PO9, PO12 | E35: —

Sheet Score Entry
A1: VIVA VOCE ASSESSMENT RUBRIC — EXAMINER SCORE ENTRY SHEET
A2: Enter Score (4=Excellent / 3=Good / 2=Fair / 1=Poor) in YELLOW cells per criterion per student | Weighted Marks, Total, Grade, Level and Attainment % auto-calculate
A4: Viva Type: | C4: Course:
A5: Evaluator Name: | C5: Date:
A7: Score Guide → | D7: 4 = Excellent | E7: 3 = Good | F7: 2 = Fair | G7: 1 = Poor | H7: Weighted Mark = Score / 4 × Max Marks | Level: L3≥75% L2≥60% L1≥40% L0<40% | Grade: O≥90 A+≥75 A≥60 B+≥50 B≥40 F<40
A9: Student Information | D9: C1: Conceptual Understanding (25% Max:25M CO1) | F9: C2: Technical Explanation (25% Max:25M CO1) | H9: C3: Confidence & Composure (15% Max:15M CO3) | J9: C4: Problem-Solving Ability (20% Max:20M CO2) | L9: C5: Communication Skills (15% Max:15M CO3) | N9: Total (/100M) | O9: Grade | P9: Level (L0–L3) | Q9: CO Att% | R9: Result | S9: Auto Feedback
D10: Score (1–4) | E10: Wtd Mks | F10: Score (1–4) | G10: Wtd Mks | H10: Score (1–4) | I10: Wtd Mks | J10: Score (1–4) | K10: Wtd Mks | L10: Score (1–4) | M10: Wtd Mks
D11: /25M | E11: Max | F11: /25M | G11: Max | H11: /15M | I11: Max | J11: /20M | K11: Max | L11: /15M | M11: Max
A12: 1 | B12: S001 | C12: Aarav Sharma | D12: 1 | E12: =IFERROR(D12/4*25,0) -> 6.25 | F12: 4 | G12: =IFERROR(F12/4*25,0) -> 25 | H12: 2 | I12: =IFERROR(H12/4*15,0) -> 7.5 | J12: 1 | K12: =IFERROR(J12/4*20,0) -> 5 | L12: 3 | M12: =IFERROR(L12/4*15,0) -> 11.25 | N12: =SUM(E12,G12,I12,K12,M12) -> 55 | O12: =IF(N12>=90,"O",IF(N12>=75,"A+",IF(N12>=60,"A",IF(N12>=50,"B+",IF(N12>=40,"B","F"))))) -> B+ | P12: =IF(N12>=75,"L3-High",IF(N12>=60,"L2-Medium",IF(N12>=40,"L1-Low","L0-Below"))) -> L1-Low | Q12: =N12/100 -> 0.55 | R12: =IF(N12>=40,"Pass","Fail") -> Pass | S12: =IF(N12>=90,"Outstanding viva performance — exceptional conceptual clarity, technical accuracy, confidence and problem-solving",IF(N12>=75,"Excellent viva — strong technical knowledge and communication; minor areas for refinement",IF(N12>=60,"Good viva — solid understanding demonstrated; improve depth of technical explanation and problem-solving",IF(N12>=40,"Satisfactory — basic concepts understood; significant improvement needed in technical accuracy and confidence","Needs major improvement — revisit core concepts; viva preparation and communication skills require intensive development")))) -> Satisfactory — basic concepts understood; significant improvement needed in technical accuracy and confidence
A13: 2 | B13: S002 | C13: Priya Patel | D13: 4 | E13: =IFERROR(D13/4*25,0) -> 25 | F13: 2 | G13: =IFERROR(F13/4*25,0) -> 12.5 | H13: 1 | I13: =IFERROR(H13/4*15,0) -> 3.75 | J13: 4 | K13: =IFERROR(J13/4*20,0) -> 20 | L13: 4 | M13: =IFERROR(L13/4*15,0) -> 15 | N13: =SUM(E13,G13,I13,K13,M13) -> 76.25 | O13: =IF(N13>=90,"O",IF(N13>=75,"A+",IF(N13>=60,"A",IF(N13>=50,"B+",IF(N13>=40,"B","F"))))) -> A+ | P13: =IF(N13>=75,"L3-High",IF(N13>=60,"L2-Medium",IF(N13>=40,"L1-Low","L0-Below"))) -> L3-High | Q13: =N13/100 -> 0.7625 | R13: =IF(N13>=40,"Pass","Fail") -> Pass | S13: =IF(N13>=90,"Outstanding viva performance — exceptional conceptual clarity, technical accuracy, confidence and problem-solving",IF(N13>=75,"Excellent viva — strong technical knowledge and communication; minor areas for refinement",IF(N13>=60,"Good viva — solid understanding demonstrated; improve depth of technical explanation and problem-solving",IF(N13>=40,"Satisfactory — basic concepts understood; significant improvement needed in technical accuracy and confidence","Needs major improvement — revisit core concepts; viva preparation and communication skills require intensive development")))) -> Excellent viva — strong technical knowledge and communication; minor areas for refinement
A14: 3 | B14: S003 | C14: Rohan Mehta | D14: 1 | E14: =IFERROR(D14/4*25,0) -> 6.25 | F14: 1 | G14: =IFERROR(F14/4*25,0) -> 6.25 | H14: 1 | I14: =IFERROR(H14/4*15,0) -> 3.75 | J14: 2 | K14: =IFERROR(J14/4*20,0) -> 10 | L14: 4 | M14: =IFERROR(L14/4*15,0) -> 15 | N14: =SUM(E14,G14,I14,K14,M14) -> 41.25 | O14: =IF(N14>=90,"O",IF(N14>=75,"A+",IF(N14>=60,"A",IF(N14>=50,"B+",IF(N14>=40,"B","F"))))) -> B | P14: =IF(N14>=75,"L3-High",IF(N14>=60,"L2-Medium",IF(N14>=40,"L1-Low","L0-Below"))) -> L1-Low | Q14: =N14/100 -> 0.4125 | R14: =IF(N14>=40,"Pass","Fail") -> Pass | S14: =IF(N14>=90,"Outstanding viva performance — exceptional conceptual clarity, technical accuracy, confidence and problem-solving",IF(N14>=75,"Excellent viva — strong technical knowledge and communication; minor areas for refinement",IF(N14>=60,"Good viva — solid understanding demonstrated; improve depth of technical explanation and problem-solving",IF(N14>=40,"Satisfactory — basic concepts understood; significant improvement needed in technical accuracy and confidence","Needs major improvement — revisit core concepts; viva preparation and communication skills require intensive development")))) -> Satisfactory — basic concepts understood; significant improvement needed in technical accuracy and confidence
A15: 4 | B15: S004 | C15: Sneha Reddy | D15: 1 | E15: =IFERROR(D15/4*25,0) -> 6.25 | F15: 4 | G15: =IFERROR(F15/4*25,0) -> 25 | H15: 1 | I15: =IFERROR(H15/4*15,0) -> 3.75 | J15: 1 | K15: =IFERROR(J15/4*20,0) -> 5 | L15: 1 | M15: =IFERROR(L15/4*15,0) -> 3.75 | N15: =SUM(E15,G15,I15,K15,M15) -> 43.75 | O15: =IF(N15>=90,"O",IF(N15>=75,"A+",IF(N15>=60,"A",IF(N15>=50,"B+",IF(N15>=40,"B","F"))))) -> B | P15: =IF(N15>=75,"L3-High",IF(N15>=60,"L2-Medium",IF(N15>=40,"L1-Low","L0-Below"))) -> L1-Low | Q15: =N15/100 -> 0.4375 | R15: =IF(N15>=40,"Pass","Fail") -> Pass | S15: =IF(N15>=90,"Outstanding viva performance — exceptional conceptual clarity, technical accuracy, confidence and problem-solving",IF(N15>=75,"Excellent viva — strong technical knowledge and communication; minor areas for refinement",IF(N15>=60,"Good viva — solid understanding demonstrated; improve depth of technical explanation and problem-solving",IF(N15>=40,"Satisfactory — basic concepts understood; significant improvement needed in technical accuracy and confidence","Needs major improvement — revisit core concepts; viva preparation and communication skills require intensive development")))) -> Satisfactory — basic concepts understood; significant improvement needed in technical accuracy and confidence
A16: 5 | B16: S005 | C16: Vikram Singh | D16: 2 | E16: =IFERROR(D16/4*25,0) -> 12.5 | F16: 2 | G16: =IFERROR(F16/4*25,0) -> 12.5 | H16: 1 | I16: =IFERROR(H16/4*15,0) -> 3.75 | J16: 2 | K16: =IFERROR(J16/4*20,0) -> 10 | L16: 4 | M16: =IFERROR(L16/4*15,0) -> 15 | N16: =SUM(E16,G16,I16,K16,M16) -> 53.75 | O16: =IF(N16>=90,"O",IF(N16>=75,"A+",IF(N16>=60,"A",IF(N16>=50,"B+",IF(N16>=40,"B","F"))))) -> B+ | P16: =IF(N16>=75,"L3-High",IF(N16>=60,"L2-Medium",IF(N16>=40,"L1-Low","L0-Below"))) -> L1-Low | Q16: =N16/100 -> 0.5375 | R16: =IF(N16>=40,"Pass","Fail") -> Pass | S16: =IF(N16>=90,"Outstanding viva performance — exceptional conceptual clarity, technical accuracy, confidence and problem-solving",IF(N16>=75,"Excellent viva — strong technical knowledge and communication; minor areas for refinement",IF(N16>=60,"Good viva — solid understanding demonstrated; improve depth of technical explanation and problem-solving",IF(N16>=40,"Satisfactory — basic concepts understood; significant improvement needed in technical accuracy and confidence","Needs major improvement — revisit core concepts; viva preparation and communication skills require intensive development")))) -> Satisfactory — basic concepts understood; significant improvement needed in technical accuracy and confidence
A17: 6 | B17: S006 | C17: Anjali Nair | D17: 4 | E17: =IFERROR(D17/4*25,0) -> 25 | F17: 3 | G17: =IFERROR(F17/4*25,0) -> 18.75 | H17: 1 | I17: =IFERROR(H17/4*15,0) -> 3.75 | J17: 1 | K17: =IFERROR(J17/4*20,0) -> 5 | L17: 2 | M17: =IFERROR(L17/4*15,0) -> 7.5 | N17: =SUM(E17,G17,I17,K17,M17) -> 60 | O17: =IF(N17>=90,"O",IF(N17>=75,"A+",IF(N17>=60,"A",IF(N17>=50,"B+",IF(N17>=40,"B","F"))))) -> A | P17: =IF(N17>=75,"L3-High",IF(N17>=60,"L2-Medium",IF(N17>=40,"L1-Low","L0-Below"))) -> L2-Medium | Q17: =N17/100 -> 0.6 | R17: =IF(N17>=40,"Pass","Fail") -> Pass | S17: =IF(N17>=90,"Outstanding viva performance — exceptional conceptual clarity, technical accuracy, confidence and problem-solving",IF(N17>=75,"Excellent viva — strong technical knowledge and communication; minor areas for refinement",IF(N17>=60,"Good viva — solid understanding demonstrated; improve depth of technical explanation and problem-solving",IF(N17>=40,"Satisfactory — basic concepts understood; significant improvement needed in technical accuracy and confidence","Needs major improvement — revisit core concepts; viva preparation and communication skills require intensive development")))) -> Good viva — solid understanding demonstrated; improve depth of technical explanation and problem-solving
A18: 7 | B18: S007 | C18: Kiran Kumar | D18: 2 | E18: =IFERROR(D18/4*25,0) -> 12.5 | F18: 1 | G18: =IFERROR(F18/4*25,0) -> 6.25 | H18: 2 | I18: =IFERROR(H18/4*15,0) -> 7.5 | J18: 1 | K18: =IFERROR(J18/4*20,0) -> 5 | L18: 1 | M18: =IFERROR(L18/4*15,0) -> 3.75 | N18: =SUM(E18,G18,I18,K18,M18) -> 35 | O18: =IF(N18>=90,"O",IF(N18>=75,"A+",IF(N18>=60,"A",IF(N18>=50,"B+",IF(N18>=40,"B","F"))))) -> F | P18: =IF(N18>=75,"L3-High",IF(N18>=60,"L2-Medium",IF(N18>=40,"L1-Low","L0-Below"))) -> L0-Below | Q18: =N18/100 -> 0.35 | R18: =IF(N18>=40,"Pass","Fail") -> Fail | S18: =IF(N18>=90,"Outstanding viva performance — exceptional conceptual clarity, technical accuracy, confidence and problem-solving",IF(N18>=75,"Excellent viva — strong technical knowledge and communication; minor areas for refinement",IF(N18>=60,"Good viva — solid understanding demonstrated; improve depth of technical explanation and problem-solving",IF(N18>=40,"Satisfactory — basic concepts understood; significant improvement needed in technical accuracy and confidence","Needs major improvement — revisit core concepts; viva preparation and communication skills require intensive development")))) -> Needs major improvement — revisit core concepts; viva preparation and communication skills require intensive development
A19: 8 | B19: S008 | C19: Divya Rao | D19: 2 | E19: =IFERROR(D19/4*25,0) -> 12.5 | F19: 3 | G19: =IFERROR(F19/4*25,0) -> 18.75 | H19: 1 | I19: =IFERROR(H19/4*15,0) -> 3.75 | J19: 4 | K19: =IFERROR(J19/4*20,0) -> 20 | L19: 3 | M19: =IFERROR(L19/4*15,0) -> 11.25 | N19: =SUM(E19,G19,I19,K19,M19) -> 66.25 | O19: =IF(N19>=90,"O",IF(N19>=75,"A+",IF(N19>=60,"A",IF(N19>=50,"B+",IF(N19>=40,"B","F"))))) -> A | P19: =IF(N19>=75,"L3-High",IF(N19>=60,"L2-Medium",IF(N19>=40,"L1-Low","L0-Below"))) -> L2-Medium | Q19: =N19/100 -> 0.6625 | R19: =IF(N19>=40,"Pass","Fail") -> Pass | S19: =IF(N19>=90,"Outstanding viva performance — exceptional conceptual clarity, technical accuracy, confidence and problem-solving",IF(N19>=75,"Excellent viva — strong technical knowledge and communication; minor areas for refinement",IF(N19>=60,"Good viva — solid understanding demonstrated; improve depth of technical explanation and problem-solving",IF(N19>=40,"Satisfactory — basic concepts understood; significant improvement needed in technical accuracy and confidence","Needs major improvement — revisit core concepts; viva preparation and communication skills require intensive development")))) -> Good viva — solid understanding demonstrated; improve depth of technical explanation and problem-solving
A20: 9 | B20: S009 | C20: Arjun Gupta | D20: 4 | E20: =IFERROR(D20/4*25,0) -> 25 | F20: 2 | G20: =IFERROR(F20/4*25,0) -> 12.5 | H20: 3 | I20: =IFERROR(H20/4*15,0) -> 11.25 | J20: 4 | K20: =IFERROR(J20/4*20,0) -> 20 | L20: 4 | M20: =IFERROR(L20/4*15,0) -> 15 | N20: =SUM(E20,G20,I20,K20,M20) -> 83.75 | O20: =IF(N20>=90,"O",IF(N20>=75,"A+",IF(N20>=60,"A",IF(N20>=50,"B+",IF(N20>=40,"B","F"))))) -> A+ | P20: =IF(N20>=75,"L3-High",IF(N20>=60,"L2-Medium",IF(N20>=40,"L1-Low","L0-Below"))) -> L3-High | Q20: =N20/100 -> 0.8375 | R20: =IF(N20>=40,"Pass","Fail") -> Pass | S20: =IF(N20>=90,"Outstanding viva performance — exceptional conceptual clarity, technical accuracy, confidence and problem-solving",IF(N20>=75,"Excellent viva — strong technical knowledge and communication; minor areas for refinement",IF(N20>=60,"Good viva — solid understanding demonstrated; improve depth of technical explanation and problem-solving",IF(N20>=40,"Satisfactory — basic concepts understood; significant improvement needed in technical accuracy and confidence","Needs major improvement — revisit core concepts; viva preparation and communication skills require intensive development")))) -> Excellent viva — strong technical knowledge and communication; minor areas for refinement
A21: 10 | B21: S010 | C21: Pooja Iyer | D21: 4 | E21: =IFERROR(D21/4*25,0) -> 25 | F21: 1 | G21: =IFERROR(F21/4*25,0) -> 6.25 | H21: 4 | I21: =IFERROR(H21/4*15,0) -> 15 | J21: 1 | K21: =IFERROR(J21/4*20,0) -> 5 | L21: 3 | M21: =IFERROR(L21/4*15,0) -> 11.25 | N21: =SUM(E21,G21,I21,K21,M21) -> 62.5 | O21: =IF(N21>=90,"O",IF(N21>=75,"A+",IF(N21>=60,"A",IF(N21>=50,"B+",IF(N21>=40,"B","F"))))) -> A | P21: =IF(N21>=75,"L3-High",IF(N21>=60,"L2-Medium",IF(N21>=40,"L1-Low","L0-Below"))) -> L2-Medium | Q21: =N21/100 -> 0.625 | R21: =IF(N21>=40,"Pass","Fail") -> Pass | S21: =IF(N21>=90,"Outstanding viva performance — exceptional conceptual clarity, technical accuracy, confidence and problem-solving",IF(N21>=75,"Excellent viva — strong technical knowledge and communication; minor areas for refinement",IF(N21>=60,"Good viva — solid understanding demonstrated; improve depth of technical explanation and problem-solving",IF(N21>=40,"Satisfactory — basic concepts understood; significant improvement needed in technical accuracy and confidence","Needs major improvement — revisit core concepts; viva preparation and communication skills require intensive development")))) -> Good viva — solid understanding demonstrated; improve depth of technical explanation and problem-solving
A22: 11 | B22: S011 | C22: Rahul Verma | D22: 2 | E22: =IFERROR(D22/4*25,0) -> 12.5 | F22: 3 | G22: =IFERROR(F22/4*25,0) -> 18.75 | H22: 2 | I22: =IFERROR(H22/4*15,0) -> 7.5 | J22: 3 | K22: =IFERROR(J22/4*20,0) -> 15 | L22: 2 | M22: =IFERROR(L22/4*15,0) -> 7.5 | N22: =SUM(E22,G22,I22,K22,M22) -> 61.25 | O22: =IF(N22>=90,"O",IF(N22>=75,"A+",IF(N22>=60,"A",IF(N22>=50,"B+",IF(N22>=40,"B","F"))))) -> A | P22: =IF(N22>=75,"L3-High",IF(N22>=60,"L2-Medium",IF(N22>=40,"L1-Low","L0-Below"))) -> L2-Medium | Q22: =N22/100 -> 0.6125 | R22: =IF(N22>=40,"Pass","Fail") -> Pass | S22: =IF(N22>=90,"Outstanding viva performance — exceptional conceptual clarity, technical accuracy, confidence and problem-solving",IF(N22>=75,"Excellent viva — strong technical knowledge and communication; minor areas for refinement",IF(N22>=60,"Good viva — solid understanding demonstrated; improve depth of technical explanation and problem-solving",IF(N22>=40,"Satisfactory — basic concepts understood; significant improvement needed in technical accuracy and confidence","Needs major improvement — revisit core concepts; viva preparation and communication skills require intensive development")))) -> Good viva — solid understanding demonstrated; improve depth of technical explanation and problem-solving
A23: 12 | B23: S012 | C23: Meera Joshi | D23: 3 | E23: =IFERROR(D23/4*25,0) -> 18.75 | F23: 3 | G23: =IFERROR(F23/4*25,0) -> 18.75 | H23: 3 | I23: =IFERROR(H23/4*15,0) -> 11.25 | J23: 3 | K23: =IFERROR(J23/4*20,0) -> 15 | L23: 1 | M23: =IFERROR(L23/4*15,0) -> 3.75 | N23: =SUM(E23,G23,I23,K23,M23) -> 67.5 | O23: =IF(N23>=90,"O",IF(N23>=75,"A+",IF(N23>=60,"A",IF(N23>=50,"B+",IF(N23>=40,"B","F"))))) -> A | P23: =IF(N23>=75,"L3-High",IF(N23>=60,"L2-Medium",IF(N23>=40,"L1-Low","L0-Below"))) -> L2-Medium | Q23: =N23/100 -> 0.675 | R23: =IF(N23>=40,"Pass","Fail") -> Pass | S23: =IF(N23>=90,"Outstanding viva performance — exceptional conceptual clarity, technical accuracy, confidence and problem-solving",IF(N23>=75,"Excellent viva — strong technical knowledge and communication; minor areas for refinement",IF(N23>=60,"Good viva — solid understanding demonstrated; improve depth of technical explanation and problem-solving",IF(N23>=40,"Satisfactory — basic concepts understood; significant improvement needed in technical accuracy and confidence","Needs major improvement — revisit core concepts; viva preparation and communication skills require intensive development")))) -> Good viva — solid understanding demonstrated; improve depth of technical explanation and problem-solving
... A41: 30 | B41: S030 | C41: Hema Pillai | D41: 4 | E41: =IFERROR(D41/4*25,0) -> 25 | F41: 4 | G41: =IFERROR(F41/4*25,0) -> 25 | H41: 3 | I41: =IFERROR(H41/4*15,0) -> 11.25 | J41: 3 | K41: =IFERROR(J41/4*20,0) -> 15 | L41: 3 | M41: =IFERROR(L41/4*15,0) -> 11.25 | N41: =SUM(E41,G41,I41,K41,M41) -> 87.5 | O41: =IF(N41>=90,"O",IF(N41>=75,"A+",IF(N41>=60,"A",IF(N41>=50,"B+",IF(N41>=40,"B","F"))))) -> A+ | P41: =IF(N41>=75,"L3-High",IF(N41>=60,"L2-Medium",IF(N41>=40,"L1-Low","L0-Below"))) -> L3-High | Q41: =N41/100 -> 0.875 | R41: =IF(N41>=40,"Pass","Fail") -> Pass | S41: =IF(N41>=90,"Outstanding viva performance — exceptional conceptual clarity, technical accuracy, confidence and problem-solving",IF(N41>=75,"Excellent viva — strong technical knowledge and communication; minor areas for refinement",IF(N41>=60,"Good viva — solid understanding demonstrated; improve depth of technical explanation and problem-solving",IF(N41>=40,"Satisfactory — basic concepts understood; significant improvement needed in technical accuracy and confidence","Needs major improvement — revisit core concepts; viva preparation and communication skills require intensive development")))) -> Excellent viva — strong technical knowledge and communication; minor areas for refinement
A43: CLASS AVERAGE | D43: =AVERAGE(D12:D41) -> 2.4333333 | E43: =AVERAGE(E12:E41) -> 15.208333 | F43: =AVERAGE(F12:F41) -> 2.3666667 | G43: =AVERAGE(G12:G41) -> 14.791667 | H43: =AVERAGE(H12:H41) -> 2.3333333 | I43: =AVERAGE(I12:I41) -> 8.75 | J43: =AVERAGE(J12:J41) -> 2.4 | K43: =AVERAGE(K12:K41) -> 12 | ... N43: =AVERAGE(N12:N41) -> 60.25
A44: HIGHEST SCORE | N44: =MAX(N12:N41) -> 91.25
A45: LOWEST SCORE | N45: =MIN(N12:N41) -> 35
A46: PASS COUNT (≥40) | N46: =COUNTIF(N12:N41,">=40") -> 29
A47: FAIL COUNT (<40) | N47: =COUNTIF(N12:N41,"<40") -> 1
A48: L3 COUNT (≥75) | N48: =COUNTIF(N12:N41,">=75") -> 4
A49: CO ATTAINMENT AVG | N49: =AVERAGE(Q12:Q41) -> 0.6025
A51: GRADE DISTRIBUTION | D51: O(≥90) | E51: =COUNTIF(N12:N41,">=90") -> 1 | F51: A+(≥75) | G51: =COUNTIF(N12:N41,">=75") -> 4 | H51: A(≥60) | I51: =COUNTIF(N12:N41,">=60") -> 16 | J51: B+(≥50) | K51: =COUNTIF(N12:N41,">=50") -> 24 | L51: B(≥40) | M51: =COUNTIF(N12:N41,">=40") -> 29 | N51: F(<40) | O51: =COUNTIF(N12:N41,"<40") -> 1

Sheet Panel Viva (3 Evaluators)
A1: VIVA VOCE — PANEL EVALUATION SHEET (3 Evaluators → Average Score)
A2: Each evaluator enters scores independently | Panel Average = (E1 Total + E2 Total + E3 Total) / 3 | Final Grade based on Panel Average
A4: Student Info | D4: Internal Examiner 1 (5 criteria × Max 100M) | N4: Internal Examiner 2 (5 criteria × Max 100M) | X4: External Examiner (5 criteria × Max 100M) | AH4: E3 Total | AI4: Panel Avg /100 | AJ4: Grade | AK4: Level | AL4: Result
A5: S.No | Reg No | Name | D5: C1 Sc | E5: C1 Wt | F5: C2 Sc | G5: C2 Wt | H5: C3 Sc | I5: C3 Wt | J5: C4 Sc | K5: C4 Wt | L5: C5 Sc | M5: C5 Wt | N5: C1 Sc | O5: C1 Wt | P5: C2 Sc | Q5: C2 Wt | R5: C3 Sc | S5: C3 Wt | T5: C4 Sc | U5: C4 Wt | V5: C5 Sc | W5: C5 Wt | X5: C1 Sc | Y5: C1 Wt | Z5: C2 Sc | AA5: C2 Wt | AB5: C3 Sc | AC5: C3 Wt | AD5: C4 Sc | AE5: C4 Wt | AF5: C5 Sc | AG5: C5 Wt | AH5: /100
A6: 1 | B6: S001 | C6: Aarav Sharma | D6: 2 | E6: =IFERROR(D6/4*25,0) -> 12.5 | F6: 3 | G6: =IFERROR(F6/4*25,0) -> 18.75 | H6: 4 | I6: =IFERROR(H6/4*15,0) -> 15 | J6: 1 | K6: =IFERROR(J6/4*20,0) -> 5 | L6: 3 | M6: =IFERROR(L6/4*15,0) -> 11.25 | N6: 1 | O6: =IFERROR(N6/4*25,0) -> 6.25 | P6: 4 | Q6: =IFERROR(P6/4*25,0) -> 25 | R6: 2 | S6: =IFERROR(R6/4*15,0) -> 7.5 | T6: 1 | U6: =IFERROR(T6/4*20,0) -> 5 | V6: 4 | W6: =IFERROR(V6/4*15,0) -> 15 | X6: 4 | Y6: =IFERROR(X6/4*25,0) -> 25 | Z6: 3 | AA6: =IFERROR(Z6/4*25,0) -> 18.75 | AB6: 4 | AC6: =IFERROR(AB6/4*15,0) -> 15 | AD6: 1 | AE6: =IFERROR(AD6/4*20,0) -> 5 | AF6: 1 | AG6: =IFERROR(AF6/4*15,0) -> 3.75 | AH6: =SUM(Y6,AA6,AC6,AE6,AG6) -> 67.5 | AI6: =IFERROR(AVERAGE(N6,X6,AH6),0) -> 24.166667 | AJ6: =IF(AI6>=90,"O",IF(AI6>=75,"A+",IF(AI6>=60,"A",IF(AI6>=50,"B+",IF(AI6>=40,"B","F"))))) -> F | AK6: =IF(AI6>=75,"L3-High",IF(AI6>=60,"L2-Medium",IF(AI6>=40,"L1-Low","L0-Below"))) -> L0-Below | AL6: =IF(AI6>=40,"Pass","Fail") -> Fail
A7: 2 | B7: S002 | C7: Priya Patel | D7: 3 | E7: =IFERROR(D7/4*25,0) -> 18.75 | F7: 1 | G7: =IFERROR(F7/4*25,0) -> 6.25 | H7: 1 | I7: =IFERROR(H7/4*15,0) -> 3.75 | J7: 4 | K7: =IFERROR(J7/4*20,0) -> 20 | L7: 4 | M7: =IFERROR(L7/4*15,0) -> 15 | N7: 3 | O7: =IFERROR(N7/4*25,0) -> 18.75 | P7: 1 | Q7: =IFERROR(P7/4*25,0) -> 6.25 | R7: 3 | S7: =IFERROR(R7/4*15,0) -> 11.25 | T7: 1 | U7: =IFERROR(T7/4*20,0) -> 5 | V7: 3 | W7: =IFERROR(V7/4*15,0) -> 11.25 | X7: 3 | Y7: =IFERROR(X7/4*25,0) -> 18.75 | Z7: 1 | AA7: =IFERROR(Z7/4*25,0) -> 6.25 | AB7: 2 | AC7: =IFERROR(AB7/4*15,0) -> 7.5 | AD7: 4 | AE7: =IFERROR(AD7/4*20,0) -> 20 | AF7: 3 | AG7: =IFERROR(AF7/4*15,0) -> 11.25 | AH7: =SUM(Y7,AA7,AC7,AE7,AG7) -> 63.75 | AI7: =IFERROR(AVERAGE(N7,X7,AH7),0) -> 23.25 | AJ7: =IF(AI7>=90,"O",IF(AI7>=75,"A+",IF(AI7>=60,"A",IF(AI7>=50,"B+",IF(AI7>=40,"B","F"))))) -> F | AK7: =IF(AI7>=75,"L3-High",IF(AI7>=60,"L2-Medium",IF(AI7>=40,"L1-Low","L0-Below"))) -> L0-Below | AL7: =IF(AI7>=40,"Pass","Fail") -> Fail
A8: 3 | B8: S003 | C8: Rohan Mehta | D8: 1 | E8: =IFERROR(D8/4*25,0) -> 6.25 | F8: 3 | G8: =IFERROR(F8/4*25,0) -> 18.75 | H8: 3 | I8: =IFERROR(H8/4*15,0) -> 11.25 | J8: 3 | K8: =IFERROR(J8/4*20,0) -> 15 | L8: 1 | M8: =IFERROR(L8/4*15,0) -> 3.75 | N8: 4 | O8: =IFERROR(N8/4*25,0) -> 25 | P8: 1 | Q8: =IFERROR(P8/4*25,0) -> 6.25 | R8: 3 | S8: =IFERROR(R8/4*15,0) -> 11.25 | T8: 3 | U8: =IFERROR(T8/4*20,0) -> 15 | V8: 3 | W8: =IFERROR(V8/4*15,0) -> 11.25 | X8: 1 | Y8: =IFERROR(X8/4*25,0) -> 6.25 | Z8: 1 | AA8: =IFERROR(Z8/4*25,0) -> 6.25 | AB8: 1 | AC8: =IFERROR(AB8/4*15,0) -> 3.75 | AD8: 3 | AE8: =IFERROR(AD8/4*20,0) -> 15 | AF8: 3 | AG8: =IFERROR(AF8/4*15,0) -> 11.25 | AH8: =SUM(Y8,AA8,AC8,AE8,AG8) -> 42.5 | AI8: =IFERROR(AVERAGE(N8,X8,AH8),0) -> 15.833333 | AJ8: =IF(AI8>=90,"O",IF(AI8>=75,"A+",IF(AI8>=60,"A",IF(AI8>=50,"B+",IF(AI8>=40,"B","F"))))) -> F | AK8: =IF(AI8>=75,"L3-High",IF(AI8>=60,"L2-Medium",IF(AI8>=40,"L1-Low","L0-Below"))) -> L0-Below | AL8: =IF(AI8>=40,"Pass","Fail") -> Fail
A9: 4 | B9: S004 | C9: Sneha Reddy | D9: 4 | E9: =IFERROR(D9/4*25,0) -> 25 | F9: 1 | G9: =IFERROR(F9/4*25,0) -> 6.25 | H9: 2 | I9: =IFERROR(H9/4*15,0) -> 7.5 | J9: 3 | K9: =IFERROR(J9/4*20,0) -> 15 | L9: 3 | M9: =IFERROR(L9/4*15,0) -> 11.25 | N9: 3 | O9: =IFERROR(N9/4*25,0) -> 18.75 | P9: 2 | Q9: =IFERROR(P9/4*25,0) -> 12.5 | R9: 2 | S9: =IFERROR(R9/4*15,0) -> 7.5 | T9: 2 | U9: =IFERROR(T9/4*20,0) -> 10 | V9: 2 | W9: =IFERROR(V9/4*15,0) -> 7.5 | X9: 3 | Y9: =IFERROR(X9/4*25,0) -> 18.75 | Z9: 1 | AA9: =IFERROR(Z9/4*25,0) -> 6.25 | AB9: 4 | AC9: =IFERROR(AB9/4*15,0) -> 15 | AD9: 4 | AE9: =IFERROR(AD9/4*20,0) -> 20 | AF9: 4 | AG9: =IFERROR(AF9/4*15,0) -> 15 | AH9: =SUM(Y9,AA9,AC9,AE9,AG9) -> 75 | AI9: =IFERROR(AVERAGE(N9,X9,AH9),0) -> 27 | AJ9: =IF(AI9>=90,"O",IF(AI9>=75,"A+",IF(AI9>=60,"A",IF(AI9>=50,"B+",IF(AI9>=40,"B","F"))))) -> F | AK9: =IF(AI9>=75,"L3-High",IF(AI9>=60,"L2-Medium",IF(AI9>=40,"L1-Low","L0-Below"))) -> L0-Below | AL9: =IF(AI9>=40,"Pass","Fail") -> Fail
A10: 5 | B10: S005 | C10: Vikram Singh | D10: 2 | E10: =IFERROR(D10/4*25,0) -> 12.5 | F10: 2 | G10: =IFERROR(F10/4*25,0) -> 12.5 | H10: 2 | I10: =IFERROR(H10/4*15,0) -> 7.5 | J10: 1 | K10: =IFERROR(J10/4*20,0) -> 5 | L10: 4 | M10: =IFERROR(L10/4*15,0) -> 15 | N10: 3 | O10: =IFERROR(N10/4*25,0) -> 18.75 | P10: 2 | Q10: =IFERROR(P10/4*25,0) -> 12.5 | R10: 1 | S10: =IFERROR(R10/4*15,0) -> 3.75 | T10: 3 | U10: =IFERROR(T10/4*20,0) -> 15 | V10: 3 | W10: =IFERROR(V10/4*15,0) -> 11.25 | X10: 2 | Y10: =IFERROR(X10/4*25,0) -> 12.5 | Z10: 1 | AA10: =IFERROR(Z10/4*25,0) -> 6.25 | AB10: 4 | AC10: =IFERROR(AB10/4*15,0) -> 15 | AD10: 2 | AE10: =IFERROR(AD10/4*20,0) -> 10 | AF10: 4 | AG10: =IFERROR(AF10/4*15,0) -> 15 | AH10: =SUM(Y10,AA10,AC10,AE10,AG10) -> 58.75 | AI10: =IFERROR(AVERAGE(N10,X10,AH10),0) -> 21.25 | AJ10: =IF(AI10>=90,"O",IF(AI10>=75,"A+",IF(AI10>=60,"A",IF(AI10>=50,"B+",IF(AI10>=40,"B","F"))))) -> F | AK10: =IF(AI10>=75,"L3-High",IF(AI10>=60,"L2-Medium",IF(AI10>=40,"L1-Low","L0-Below"))) -> L0-Below | AL10: =IF(AI10>=40,"Pass","Fail") -> Fail
A11: 6 | B11: S006 | C11: Anjali Nair | D11: 2 | E11: =IFERROR(D11/4*25,0) -> 12.5 | F11: 2 | G11: =IFERROR(F11/4*25,0) -> 12.5 | H11: 1 | I11: =IFERROR(H11/4*15,0) -> 3.75 | J11: 1 | K11: =IFERROR(J11/4*20,0) -> 5 | L11: 3 | M11: =IFERROR(L11/4*15,0) -> 11.25 | N11: 4 | O11: =IFERROR(N11/4*25,0) -> 25 | P11: 3 | Q11: =IFERROR(P11/4*25,0) -> 18.75 | R11: 4 | S11: =IFERROR(R11/4*15,0) -> 15 | T11: 1 | U11: =IFERROR(T11/4*20,0) -> 5 | V11: 1 | W11: =IFERROR(V11/4*15,0) -> 3.75 | X11: 3 | Y11: =IFERROR(X11/4*25,0) -> 18.75 | Z11: 2 | AA11: =IFERROR(Z11/4*25,0) -> 12.5 | AB11: 1 | AC11: =IFERROR(AB11/4*15,0) -> 3.75 | AD11: 2 | AE11: =IFERROR(AD11/4*20,0) -> 10 | AF11: 3 | AG11: =IFERROR(AF11/4*15,0) -> 11.25 | AH11: =SUM(Y11,AA11,AC11,AE11,AG11) -> 56.25 | AI11: =IFERROR(AVERAGE(N11,X11,AH11),0) -> 21.083333 | AJ11: =IF(AI11>=90,"O",IF(AI11>=75,"A+",IF(AI11>=60,"A",IF(AI11>=50,"B+",IF(AI11>=40,"B","F"))))) -> F | AK11: =IF(AI11>=75,"L3-High",IF(AI11>=60,"L2-Medium",IF(AI11>=40,"L1-Low","L0-Below"))) -> L0-Below | AL11: =IF(AI11>=40,"Pass","Fail") -> Fail
A12: 7 | B12: S007 | C12: Kiran Kumar | D12: 2 | E12: =IFERROR(D12/4*25,0) -> 12.5 | F12: 3 | G12: =IFERROR(F12/4*25,0) -> 18.75 | H12: 3 | I12: =IFERROR(H12/4*15,0) -> 11.25 | J12: 1 | K12: =IFERROR(J12/4*20,0) -> 5 | L12: 2 | M12: =IFERROR(L12/4*15,0) -> 7.5 | N12: 1 | O12: =IFERROR(N12/4*25,0) -> 6.25 | P12: 2 | Q12: =IFERROR(P12/4*25,0) -> 12.5 | R12: 1 | S12: =IFERROR(R12/4*15,0) -> 3.75 | T12: 2 | U12: =IFERROR(T12/4*20,0) -> 10 | V12: 2 | W12: =IFERROR(V12/4*15,0) -> 7.5 | X12: 2 | Y12: =IFERROR(X12/4*25,0) -> 12.5 | Z12: 4 | AA12: =IFERROR(Z12/4*25,0) -> 25 | AB12: 2 | AC12: =IFERROR(AB12/4*15,0) -> 7.5 | AD12: 1 | AE12: =IFERROR(AD12/4*20,0) -> 5 | AF12: 1 | AG12: =IFERROR(AF12/4*15,0) -> 3.75 | AH12: =SUM(Y12,AA12,AC12,AE12,AG12) -> 53.75 | AI12: =IFERROR(AVERAGE(N12,X12,AH12),0) -> 18.916667 | AJ12: =IF(AI12>=90,"O",IF(AI12>=75,"A+",IF(AI12>=60,"A",IF(AI12>=50,"B+",IF(AI12>=40,"B","F"))))) -> F | AK12: =IF(AI12>=75,"L3-High",IF(AI12>=60,"L2-Medium",IF(AI12>=40,"L1-Low","L0-Below"))) -> L0-Below | AL12: =IF(AI12>=40,"Pass","Fail") -> Fail
A13: 8 | B13: S008 | C13: Divya Rao | D13: 2 | E13: =IFERROR(D13/4*25,0) -> 12.5 | F13: 2 | G13: =IFERROR(F13/4*25,0) -> 12.5 | H13: 1 | I13: =IFERROR(H13/4*15,0) -> 3.75 | J13: 1 | K13: =IFERROR(J13/4*20,0) -> 5 | L13: 3 | M13: =IFERROR(L13/4*15,0) -> 11.25 | N13: 2 | O13: =IFERROR(N13/4*25,0) -> 12.5 | P13: 3 | Q13: =IFERROR(P13/4*25,0) -> 18.75 | R13: 2 | S13: =IFERROR(R13/4*15,0) -> 7.5 | T13: 3 | U13: =IFERROR(T13/4*20,0) -> 15 | V13: 4 | W13: =IFERROR(V13/4*15,0) -> 15 | X13: 4 | Y13: =IFERROR(X13/4*25,0) -> 25 | Z13: 2 | AA13: =IFERROR(Z13/4*25,0) -> 12.5 | AB13: 2 | AC13: =IFERROR(AB13/4*15,0) -> 7.5 | AD13: 3 | AE13: =IFERROR(AD13/4*20,0) -> 15 | AF13: 2 | AG13: =IFERROR(AF13/4*15,0) -> 7.5 | AH13: =SUM(Y13,AA13,AC13,AE13,AG13) -> 67.5 | AI13: =IFERROR(AVERAGE(N13,X13,AH13),0) -> 24.5 | AJ13: =IF(AI13>=90,"O",IF(AI13>=75,"A+",IF(AI13>=60,"A",IF(AI13>=50,"B+",IF(AI13>=40,"B","F"))))) -> F | AK13: =IF(AI13>=75,"L3-High",IF(AI13>=60,"L2-Medium",IF(AI13>=40,"L1-Low","L0-Below"))) -> L0-Below | AL13: =IF(AI13>=40,"Pass","Fail") -> Fail
A14: 9 | B14: S009 | C14: Arjun Gupta | D14: 2 | E14: =IFERROR(D14/4*25,0) -> 12.5 | F14: 3 | G14: =IFERROR(F14/4*25,0) -> 18.75 | H14: 2 | I14: =IFERROR(H14/4*15,0) -> 7.5 | J14: 3 | K14: =IFERROR(J14/4*20,0) -> 15 | L14: 3 | M14: =IFERROR(L14/4*15,0) -> 11.25 | N14: 2 | O14: =IFERROR(N14/4*25,0) -> 12.5 | P14: 4 | Q14: =IFERROR(P14/4*25,0) -> 25 | R14: 3 | S14: =IFERROR(R14/4*15,0) -> 11.25 | T14: 4 | U14: =IFERROR(T14/4*20,0) -> 20 | V14: 1 | W14: =IFERROR(V14/4*15,0) -> 3.75 | X14: 2 | Y14: =IFERROR(X14/4*25,0) -> 12.5 | Z14: 2 | AA14: =IFERROR(Z14/4*25,0) -> 12.5 | AB14: 1 | AC14: =IFERROR(AB14/4*15,0) -> 3.75 | AD14: 2 | AE14: =IFERROR(AD14/4*20,0) -> 10 | AF14: 1 | AG14: =IFERROR(AF14/4*15,0) -> 3.75 | AH14: =SUM(Y14,AA14,AC14,AE14,AG14) -> 42.5 | AI14: =IFERROR(AVERAGE(N14,X14,AH14),0) -> 15.5 | AJ14: =IF(AI14>=90,"O",IF(AI14>=75,"A+",IF(AI14>=60,"A",IF(AI14>=50,"B+",IF(AI14>=40,"B","F"))))) -> F | AK14: =IF(AI14>=75,"L3-High",IF(AI14>=60,"L2-Medium",IF(AI14>=40,"L1-Low","L0-Below"))) -> L0-Below | AL14: =IF(AI14>=40,"Pass","Fail") -> Fail
A15: 10 | B15: S010 | C15: Pooja Iyer | D15: 3 | E15: =IFERROR(D15/4*25,0) -> 18.75 | F15: 3 | G15: =IFERROR(F15/4*25,0) -> 18.75 | H15: 2 | I15: =IFERROR(H15/4*15,0) -> 7.5 | J15: 2 | K15: =IFERROR(J15/4*20,0) -> 10 | L15: 4 | M15: =IFERROR(L15/4*15,0) -> 15 | N15: 4 | O15: =IFERROR(N15/4*25,0) -> 25 | P15: 4 | Q15: =IFERROR(P15/4*25,0) -> 25 | R15: 1 | S15: =IFERROR(R15/4*15,0) -> 3.75 | T15: 4 | U15: =IFERROR(T15/4*20,0) -> 20 | V15: 3 | W15: =IFERROR(V15/4*15,0) -> 11.25 | X15: 4 | Y15: =IFERROR(X15/4*25,0) -> 25 | Z15: 2 | AA15: =IFERROR(Z15/4*25,0) -> 12.5 | AB15: 1 | AC15: =IFERROR(AB15/4*15,0) -> 3.75 | AD15: 3 | AE15: =IFERROR(AD15/4*20,0) -> 15 | AF15: 2 | AG15: =IFERROR(AF15/4*15,0) -> 7.5 | AH15: =SUM(Y15,AA15,AC15,AE15,AG15) -> 63.75 | AI15: =IFERROR(AVERAGE(N15,X15,AH15),0) -> 23.916667 | AJ15: =IF(AI15>=90,"O",IF(AI15>=75,"A+",IF(AI15>=60,"A",IF(AI15>=50,"B+",IF(AI15>=40,"B","F"))))) -> F | AK15: =IF(AI15>=75,"L3-High",IF(AI15>=60,"L2-Medium",IF(AI15>=40,"L1-Low","L0-Below"))) -> L0-Below | AL15: =IF(AI15>=40,"Pass","Fail") -> Fail
A16: 11 | B16: S011 | C16: Rahul Verma | D16: 1 | E16: =IFERROR(D16/4*25,0) -> 6.25 | F16: 3 | G16: =IFERROR(F16/4*25,0) -> 18.75 | H16: 1 | I16: =IFERROR(H16/4*15,0) -> 3.75 | J16: 1 | K16: =IFERROR(J16/4*20,0) -> 5 | L16: 1 | M16: =IFERROR(L16/4*15,0) -> 3.75 | N16: 3 | O16: =IFERROR(N16/4*25,0) -> 18.75 | P16: 1 | Q16: =IFERROR(P16/4*25,0) -> 6.25 | R16: 3 | S16: =IFERROR(R16/4*15,0) -> 11.25 | T16: 3 | U16: =IFERROR(T16/4*20,0) -> 15 | V16: 3 | W16: =IFERROR(V16/4*15,0) -> 11.25 | X16: 2 | Y16: =IFERROR(X16/4*25,0) -> 12.5 | Z16: 1 | AA16: =IFERROR(Z16/4*25,0) -> 6.25 | AB16: 4 | AC16: =IFERROR(AB16/4*15,0) -> 15 | AD16: 1 | AE16: =IFERROR(AD16/4*20,0) -> 5 | AF16: 2 | AG16: =IFERROR(AF16/4*15,0) -> 7.5 | AH16: =SUM(Y16,AA16,AC16,AE16,AG16) -> 46.25 | AI16: =IFERROR(AVERAGE(N16,X16,AH16),0) -> 17.083333 | AJ16: =IF(AI16>=90,"O",IF(AI16>=75,"A+",IF(AI16>=60,"A",IF(AI16>=50,"B+",IF(AI16>=40,"B","F"))))) -> F | AK16: =IF(AI16>=75,"L3-High",IF(AI16>=60,"L2-Medium",IF(AI16>=40,"L1-Low","L0-Below"))) -> L0-Below | AL16: =IF(AI16>=40,"Pass","Fail") -> Fail
A17: 12 | B17: S012 | C17: Meera Joshi | D17: 1 | E17: =IFERROR(D17/4*25,0) -> 6.25 | F17: 3 | G17: =IFERROR(F17/4*25,0) -> 18.75 | H17: 2 | I17: =IFERROR(H17/4*15,0) -> 7.5 | J17: 3 | K17: =IFERROR(J17/4*20,0) -> 15 | L17: 3 | M17: =IFERROR(L17/4*15,0) -> 11.25 | N17: 3 | O17: =IFERROR(N17/4*25,0) -> 18.75 | P17: 2 | Q17: =IFERROR(P17/4*25,0) -> 12.5 | R17: 1 | S17: =IFERROR(R17/4*15,0) -> 3.75 | T17: 1 | U17: =IFERROR(T17/4*20,0) -> 5 | V17: 4 | W17: =IFERROR(V17/4*15,0) -> 15 | X17: 2 | Y17: =IFERROR(X17/4*25,0) -> 12.5 | Z17: 1 | AA17: =IFERROR(Z17/4*25,0) -> 6.25 | AB17: 3 | AC17: =IFERROR(AB17/4*15,0) -> 11.25 | AD17: 1 | AE17: =IFERROR(AD17/4*20,0) -> 5 | AF17: 2 | AG17: =IFERROR(AF17/4*15,0) -> 7.5 | AH17: =SUM(Y17,AA17,AC17,AE17,AG17) -> 42.5 | AI17: =IFERROR(AVERAGE(N17,X17,AH17),0) -> 15.833333 | AJ17: =IF(AI17>=90,"O",IF(AI17>=75,"A+",IF(AI17>=60,"A",IF(AI17>=50,"B+",IF(AI17>=40,"B","F"))))) -> F | AK17: =IF(AI17>=75,"L3-High",IF(AI17>=60,"L2-Medium",IF(AI17>=40,"L1-Low","L0-Below"))) -> L0-Below | AL17: =IF(AI17>=40,"Pass","Fail") -> Fail
... A35: 30 | B35: S030 | C35: Hema Pillai | D35: 2 | E35: =IFERROR(D35/4*25,0) -> 12.5 | F35: 2 | G35: =IFERROR(F35/4*25,0) -> 12.5 | H35: 3 | I35: =IFERROR(H35/4*15,0) -> 11.25 | J35: 4 | K35: =IFERROR(J35/4*20,0) -> 20 | L35: 1 | M35: =IFERROR(L35/4*15,0) -> 3.75 | N35: 4 | O35: =IFERROR(N35/4*25,0) -> 25 | P35: 4 | Q35: =IFERROR(P35/4*25,0) -> 25 | R35: 4 | S35: =IFERROR(R35/4*15,0) -> 15 | T35: 1 | U35: =IFERROR(T35/4*20,0) -> 5 | V35: 1 | W35: =IFERROR(V35/4*15,0) -> 3.75 | X35: 2 | Y35: =IFERROR(X35/4*25,0) -> 12.5 | Z35: 1 | AA35: =IFERROR(Z35/4*25,0) -> 6.25 | AB35: 4 | AC35: =IFERROR(AB35/4*15,0) -> 15 | AD35: 1 | AE35: =IFERROR(AD35/4*20,0) -> 5 | AF35: 2 | AG35: =IFERROR(AF35/4*15,0) -> 7.5 | AH35: =SUM(Y35,AA35,AC35,AE35,AG35) -> 46.25 | AI35: =IFERROR(AVERAGE(N35,X35,AH35),0) -> 17.416667 | AJ35: =IF(AI35>=90,"O",IF(AI35>=75,"A+",IF(AI35>=60,"A",IF(AI35>=50,"B+",IF(AI35>=40,"B","F"))))) -> F | AK35: =IF(AI35>=75,"L3-High",IF(AI35>=60,"L2-Medium",IF(AI35>=40,"L1-Low","L0-Below"))) -> L0-Below | AL35: =IF(AI35>=40,"Pass","Fail") -> Fail

Sheet Student Dashboard
A1: VIVA VOCE RUBRIC — STUDENT PERFORMANCE DASHBOARD
A2: All values auto-linked from Score Entry sheet. Per-criterion scores, totals, grades, CO attainment and level at a glance.
A4: GRADE / LEVEL → | D4: O ≥90 | E4: A+ ≥75 | F4: A ≥60 | G4: B+ ≥50 | H4: B ≥40 | I4: F <40 | J4: L3 ≥75% | K4: L2 ≥60% | L4: L1 ≥40%
A6: # | B6: Reg No | C6: Student Name | D6: C1 | E6: C2 | F6: C3 | G6: C4 | H6: C5 | I6: Total /100 | J6: Grade | K6: Level | L6: CO Att% | M6: Result
A7: 1 | B7: ='Score Entry'!B12 -> S001 | C7: ='Score Entry'!C12 -> Aarav Sharma | D7: ='Score Entry'!D12 -> 1 | E7: ='Score Entry'!F12 -> 4 | F7: ='Score Entry'!H12 -> 2 | G7: ='Score Entry'!J12 -> 1 | H7: ='Score Entry'!L12 -> 3 | I7: ='Score Entry'!N12 -> 55 | J7: ='Score Entry'!O12 -> B+ | K7: ='Score Entry'!P12 -> L1-Low | L7: ='Score Entry'!Q12 -> 0.55 | M7: ='Score Entry'!R12 -> Pass
A8: 2 | B8: ='Score Entry'!B13 -> S002 | C8: ='Score Entry'!C13 -> Priya Patel | D8: ='Score Entry'!D13 -> 4 | E8: ='Score Entry'!F13 -> 2 | F8: ='Score Entry'!H13 -> 1 | G8: ='Score Entry'!J13 -> 4 | H8: ='Score Entry'!L13 -> 4 | I8: ='Score Entry'!N13 -> 76.25 | J8: ='Score Entry'!O13 -> A+ | K8: ='Score Entry'!P13 -> L3-High | L8: ='Score Entry'!Q13 -> 0.7625 | M8: ='Score Entry'!R13 -> Pass
A9: 3 | B9: ='Score Entry'!B14 -> S003 | C9: ='Score Entry'!C14 -> Rohan Mehta | D9: ='Score Entry'!D14 -> 1 | E9: ='Score Entry'!F14 -> 1 | F9: ='Score Entry'!H14 -> 1 | G9: ='Score Entry'!J14 -> 2 | H9: ='Score Entry'!L14 -> 4 | I9: ='Score Entry'!N14 -> 41.25 | J9: ='Score Entry'!O14 -> B | K9: ='Score Entry'!P14 -> L1-Low | L9: ='Score Entry'!Q14 -> 0.4125 | M9: ='Score Entry'!R14 -> Pass
A10: 4 | B10: ='Score Entry'!B15 -> S004 | C10: ='Score Entry'!C15 -> Sneha Reddy | D10: ='Score Entry'!D15 -> 1 | E10: ='Score Entry'!F15 -> 4 | F10: ='Score Entry'!H15 -> 1 | G10: ='Score Entry'!J15 -> 1 | H10: ='Score Entry'!L15 -> 1 | I10: ='Score Entry'!N15 -> 43.75 | J10: ='Score Entry'!O15 -> B | K10: ='Score Entry'!P15 -> L1-Low | L10: ='Score Entry'!Q15 -> 0.4375 | M10: ='Score Entry'!R15 -> Pass
A11: 5 | B11: ='Score Entry'!B16 -> S005 | C11: ='Score Entry'!C16 -> Vikram Singh | D11: ='Score Entry'!D16 -> 2 | E11: ='Score Entry'!F16 -> 2 | F11: ='Score Entry'!H16 -> 1 | G11: ='Score Entry'!J16 -> 2 | H11: ='Score Entry'!L16 -> 4 | I11: ='Score Entry'!N16 -> 53.75 | J11: ='Score Entry'!O16 -> B+ | K11: ='Score Entry'!P16 -> L1-Low | L11: ='Score Entry'!Q16 -> 0.5375 | M11: ='Score Entry'!R16 -> Pass
A12: 6 | B12: ='Score Entry'!B17 -> S006 | C12: ='Score Entry'!C17 -> Anjali Nair | D12: ='Score Entry'!D17 -> 4 | E12: ='Score Entry'!F17 -> 3 | F12: ='Score Entry'!H17 -> 1 | G12: ='Score Entry'!J17 -> 1 | H12: ='Score Entry'!L17 -> 2 | I12: ='Score Entry'!N17 -> 60 | J12: ='Score Entry'!O17 -> A | K12: ='Score Entry'!P17 -> L2-Medium | L12: ='Score Entry'!Q17 -> 0.6 | M12: ='Score Entry'!R17 -> Pass
A13: 7 | B13: ='Score Entry'!B18 -> S007 | C13: ='Score Entry'!C18 -> Kiran Kumar | D13: ='Score Entry'!D18 -> 2 | E13: ='Score Entry'!F18 -> 1 | F13: ='Score Entry'!H18 -> 2 | G13: ='Score Entry'!J18 -> 1 | H13: ='Score Entry'!L18 -> 1 | I13: ='Score Entry'!N18 -> 35 | J13: ='Score Entry'!O18 -> F | K13: ='Score Entry'!P18 -> L0-Below | L13: ='Score Entry'!Q18 -> 0.35 | M13: ='Score Entry'!R18 -> Fail
A14: 8 | B14: ='Score Entry'!B19 -> S008 | C14: ='Score Entry'!C19 -> Divya Rao | D14: ='Score Entry'!D19 -> 2 | E14: ='Score Entry'!F19 -> 3 | F14: ='Score Entry'!H19 -> 1 | G14: ='Score Entry'!J19 -> 4 | H14: ='Score Entry'!L19 -> 3 | I14: ='Score Entry'!N19 -> 66.25 | J14: ='Score Entry'!O19 -> A | K14: ='Score Entry'!P19 -> L2-Medium | L14: ='Score Entry'!Q19 -> 0.6625 | M14: ='Score Entry'!R19 -> Pass
A15: 9 | B15: ='Score Entry'!B20 -> S009 | C15: ='Score Entry'!C20 -> Arjun Gupta | D15: ='Score Entry'!D20 -> 4 | E15: ='Score Entry'!F20 -> 2 | F15: ='Score Entry'!H20 -> 3 | G15: ='Score Entry'!J20 -> 4 | H15: ='Score Entry'!L20 -> 4 | I15: ='Score Entry'!N20 -> 83.75 | J15: ='Score Entry'!O20 -> A+ | K15: ='Score Entry'!P20 -> L3-High | L15: ='Score Entry'!Q20 -> 0.8375 | M15: ='Score Entry'!R20 -> Pass
A16: 10 | B16: ='Score Entry'!B21 -> S010 | C16: ='Score Entry'!C21 -> Pooja Iyer | D16: ='Score Entry'!D21 -> 4 | E16: ='Score Entry'!F21 -> 1 | F16: ='Score Entry'!H21 -> 4 | G16: ='Score Entry'!J21 -> 1 | H16: ='Score Entry'!L21 -> 3 | I16: ='Score Entry'!N21 -> 62.5 | J16: ='Score Entry'!O21 -> A | K16: ='Score Entry'!P21 -> L2-Medium | L16: ='Score Entry'!Q21 -> 0.625 | M16: ='Score Entry'!R21 -> Pass
A17: 11 | B17: ='Score Entry'!B22 -> S011 | C17: ='Score Entry'!C22 -> Rahul Verma | D17: ='Score Entry'!D22 -> 2 | E17: ='Score Entry'!F22 -> 3 | F17: ='Score Entry'!H22 -> 2 | G17: ='Score Entry'!J22 -> 3 | H17: ='Score Entry'!L22 -> 2 | I17: ='Score Entry'!N22 -> 61.25 | J17: ='Score Entry'!O22 -> A | K17: ='Score Entry'!P22 -> L2-Medium | L17: ='Score Entry'!Q22 -> 0.6125 | M17: ='Score Entry'!R22 -> Pass
A18: 12 | B18: ='Score Entry'!B23 -> S012 | C18: ='Score Entry'!C23 -> Meera Joshi | D18: ='Score Entry'!D23 -> 3 | E18: ='Score Entry'!F23 -> 3 | F18: ='Score Entry'!H23 -> 3 | G18: ='Score Entry'!J23 -> 3 | H18: ='Score Entry'!L23 -> 1 | I18: ='Score Entry'!N23 -> 67.5 | J18: ='Score Entry'!O23 -> A | K18: ='Score Entry'!P23 -> L2-Medium | L18: ='Score Entry'!Q23 -> 0.675 | M18: ='Score Entry'!R23 -> Pass
... A36: 30 | B36: ='Score Entry'!B41 -> S030 | C36: ='Score Entry'!C41 -> Hema Pillai | D36: ='Score Entry'!D41 -> 4 | E36: ='Score Entry'!F41 -> 4 | F36: ='Score Entry'!H41 -> 3 | G36: ='Score Entry'!J41 -> 3 | H36: ='Score Entry'!L41 -> 3 | I36: ='Score Entry'!N41 -> 87.5 | J36: ='Score Entry'!O41 -> A+ | K36: ='Score Entry'!P41 -> L3-High | L36: ='Score Entry'!Q41 -> 0.875 | M36: ='Score Entry'!R41 -> Pass
A38: CLASS AVERAGE | D38: =AVERAGE(D7:D36) -> 2.4333333 | E38: =AVERAGE(E7:E36) -> 2.3666667 | F38: =AVERAGE(F7:F36) -> 2.3333333 | G38: =AVERAGE(G7:G36) -> 2.4 | H38: =AVERAGE(H7:H36) -> 2.5333333 | I38: =AVERAGE(I7:I36) -> 60.25

Sheet Criterion Analysis
A1: VIVA VOCE RUBRIC — CRITERION-WISE CLASS ANALYSIS
A2: Statistical breakdown per criterion — all values auto-linked from Score Entry sheet.
A4: Metric | B4: C1: Conceptual Understanding (Max:25M Wt:25%) | C4: C2: Technical Explanation (Max:25M Wt:25%) | D4: C3: Confidence & Composure (Max:15M Wt:15%) | E4: C4: Problem-Solving Ability (Max:20M Wt:20%) | F4: C5: Communication Skills (Max:15M Wt:15%) | G4: Overall Avg | H4: Crit Att%
A6: Average Score (1–4) | B6: =IFERROR(AVERAGE('Score Entry'!D12:D41),0) -> 2.4333333 | C6: =IFERROR(AVERAGE('Score Entry'!F12:F41),0) -> 2.3666667 | D6: =IFERROR(AVERAGE('Score Entry'!H12:H41),0) -> 2.3333333 | E6: =IFERROR(AVERAGE('Score Entry'!J12:J41),0) -> 2.4 | F6: =IFERROR(AVERAGE('Score Entry'!L12:L41),0) -> 2.5333333 | G6: =IFERROR(AVERAGE(B6,C6,D6,E6,F6),0) -> 2.4133333
A7: Average Weighted Marks | B7: =IFERROR(AVERAGE('Score Entry'!E12:E41),0) -> 15.208333 | C7: =IFERROR(AVERAGE('Score Entry'!G12:G41),0) -> 14.791667 | D7: =IFERROR(AVERAGE('Score Entry'!I12:I41),0) -> 8.75 | E7: =IFERROR(AVERAGE('Score Entry'!K12:K41),0) -> 12 | F7: =IFERROR(AVERAGE('Score Entry'!M12:M41),0) -> 9.5 | G7: =IFERROR(AVERAGE(B7,C7,D7,E7,F7),0) -> 12.05
A8: Max Score | B8: =MAX('Score Entry'!D12:D41) -> 4 | C8: =MAX('Score Entry'!F12:F41) -> 4 | D8: =MAX('Score Entry'!H12:H41) -> 4 | E8: =MAX('Score Entry'!J12:J41) -> 4 | F8: =MAX('Score Entry'!L12:L41) -> 4 | G8: =IFERROR(AVERAGE(B8,C8,D8,E8,F8),0) -> 4
A9: Min Score | B9: =MIN('Score Entry'!D12:D41) -> 1 | C9: =MIN('Score Entry'!F12:F41) -> 1 | D9: =MIN('Score Entry'!H12:H41) -> 1 | E9: =MIN('Score Entry'!J12:J41) -> 1 | F9: =MIN('Score Entry'!L12:L41) -> 1 | G9: =IFERROR(AVERAGE(B9,C9,D9,E9,F9),0) -> 1
A10: Excellent (4) Count | B10: =COUNTIF('Score Entry'!D12:D41,4) -> 7 | C10: =COUNTIF('Score Entry'!F12:F41,4) -> 4 | D10: =COUNTIF('Score Entry'!H12:H41,4) -> 6 | E10: =COUNTIF('Score Entry'!J12:J41,4) -> 4 | F10: =COUNTIF('Score Entry'!L12:L41,4) -> 7 | G10: =IFERROR(AVERAGE(B10,C10,D10,E10,F10),0) -> 5.6
A11: Good (3) Count | B11: =COUNTIF('Score Entry'!D12:D41,3) -> 6 | C11: =COUNTIF('Score Entry'!F12:F41,3) -> 9 | D11: =COUNTIF('Score Entry'!H12:H41,3) -> 7 | E11: =COUNTIF('Score Entry'!J12:J41,3) -> 11 | F11: =COUNTIF('Score Entry'!L12:L41,3) -> 9 | G11: =IFERROR(AVERAGE(B11,C11,D11,E11,F11),0) -> 8.4
A12: Fair (2) Count | B12: =COUNTIF('Score Entry'!D12:D41,2) -> 10 | C12: =COUNTIF('Score Entry'!F12:F41,2) -> 11 | D12: =COUNTIF('Score Entry'!H12:H41,2) -> 8 | E12: =COUNTIF('Score Entry'!J12:J41,2) -> 8 | F12: =COUNTIF('Score Entry'!L12:L41,2) -> 7 | G12: =IFERROR(AVERAGE(B12,C12,D12,E12,F12),0) -> 8.8
A13: Poor (1) Count | B13: =COUNTIF('Score Entry'!D12:D41,1) -> 7 | C13: =COUNTIF('Score Entry'!F12:F41,1) -> 6 | D13: =COUNTIF('Score Entry'!H12:H41,1) -> 9 | E13: =COUNTIF('Score Entry'!J12:J41,1) -> 7 | F13: =COUNTIF('Score Entry'!L12:L41,1) -> 7 | G13: =IFERROR(AVERAGE(B13,C13,D13,E13,F13),0) -> 7.2
A14: Criterion Attainment % | B14: =IFERROR(AVERAGE('Score Entry'!D12:D41)/4*100,0) -> 60.833333 | C14: =IFERROR(AVERAGE('Score Entry'!F12:F41)/4*100,0) -> 59.166667 | D14: =IFERROR(AVERAGE('Score Entry'!H12:H41)/4*100,0) -> 58.333333 | E14: =IFERROR(AVERAGE('Score Entry'!J12:J41)/4*100,0) -> 60 | F14: =IFERROR(AVERAGE('Score Entry'!L12:L41)/4*100,0) -> 63.333333 | G14: =IFERROR(AVERAGE(B14,C14,D14,E14,F14),0) -> 60.333333 | H14: =IFERROR(AVERAGE(B14,C14,D14,E14,F14),0) -> 60.333333
A16: Attainment Level | B16: =IF(B14>=75,"L3-High",IF(B14>=60,"L2-Med",IF(B14>=40,"L1-Low","L0-Below"))) -> L2-Med | C16: =IF(C14>=75,"L3-High",IF(C14>=60,"L2-Med",IF(C14>=40,"L1-Low","L0-Below"))) -> L1-Low | D16: =IF(D14>=75,"L3-High",IF(D14>=60,"L2-Med",IF(D14>=40,"L1-Low","L0-Below"))) -> L1-Low | E16: =IF(E14>=75,"L3-High",IF(E14>=60,"L2-Med",IF(E14>=40,"L1-Low","L0-Below"))) -> L2-Med | F16: =IF(F14>=75,"L3-High",IF(F14>=60,"L2-Med",IF(F14>=40,"L1-Low","L0-Below"))) -> L2-Med | G16: =IF(G14>=75,"L3-High",IF(G14>=60,"L2-Med",IF(G14>=40,"L1-Low","L0-Below"))) -> L2-Med | H16: =H14 -> 60.333333

Sheet CO & PO Attainment
A1: VIVA VOCE RUBRIC — CO & PO ATTAINMENT SUMMARY
A2: CO Att% = Avg of criterion attainments | PO Att% = SUMPRODUCT(CO_Att × Strength) / SUM(Strength) | Target ≥ 60%
A4: SECTION A — COURSE OUTCOME ATTAINMENT
A5: # | B5: CO | C5: Description | D5: Bloom's | E5: Mapped Criteria | F5: CO Att% | G5: Target | H5: Gap | I5: Level | J5: Status
A6: 1 | B6: CO1 | C6: Demonstrate conceptual knowledge and explain technical principles accurately | D6: L2-L4 | E6: Conceptual Understanding, Technical Explanation | F6: =IFERROR(AVERAGE('Criterion Analysis'!B14,'Criterion Analysis'!C14),0) -> 60 | G6: 60 | H6: =F6-G6 -> 0 | I6: =IF(F6>=75,"L3-High",IF(F6>=60,"L2-Medium",IF(F6>=40,"L1-Low","L0-Below"))) -> L2-Medium | J6: =IF(F6>=60,"✔ Met","✘ Not Met") -> ✔ Met
A7: 2 | B7: CO2 | C7: Analyse problems, apply reasoning and arrive at logical technical solutions | D7: L3-L5 | E7: Problem-Solving Ability | F7: =IFERROR(AVERAGE('Criterion Analysis'!E14),0) -> 60 | G7: 60 | H7: =F7-G7 -> 0 | I7: =IF(F7>=75,"L3-High",IF(F7>=60,"L2-Medium",IF(F7>=40,"L1-Low","L0-Below"))) -> L2-Medium | J7: =IF(F7>=60,"✔ Met","✘ Not Met") -> ✔ Met
A8: 3 | B8: CO3 | C8: Communicate technical ideas clearly and confidently under oral examination conditions | D8: L3 | E8: Confidence & Composure, Communication Skills | F8: =IFERROR(AVERAGE('Criterion Analysis'!D14,'Criterion Analysis'!F14),0) -> 60.833333 | G8: 60 | H8: =F8-G8 -> 0.83333333 | I8: =IF(F8>=75,"L3-High",IF(F8>=60,"L2-Medium",IF(F8>=40,"L1-Low","L0-Below"))) -> L2-Medium | J8: =IF(F8>=60,"✔ Met","✘ Not Met") -> ✔ Met
A9: 4 | B9: CO4 | C9: Respond adaptively to questioning; demonstrate analytical and problem-solving ability | D9: L3-L5 | F9: — | G9: 60 | H9: =IFERROR(F9-G9,"—") -> — | I9: =IF(F9>=75,"L3-High",IF(F9>=60,"L2-Medium",IF(F9>=40,"L1-Low","L0-Below"))) -> L3-High | J9: =IF(F9>=60,"✔ Met","✘ Not Met") -> ✔ Met
A12: SECTION B — PROGRAMME OUTCOME ATTAINMENT
A13: # | B13: PO | C13: Description | D13: Linked COs (Strength) | E13: PO Att% | F13: Target | G13: Gap | H13: Level | I13: Status
A14: 1 | B14: PO1 | C14: Engineering Knowledge | D14: CO1(S3) | E14: =IFERROR((('CO & PO Attainment'!F6*3))/3,0) -> 60 | F14: 60 | G14: =E14-F14 -> 0 | H14: =IF(E14>=75,"L3-High",IF(E14>=60,"L2-Medium",IF(E14>=40,"L1-Low","L0-Below"))) -> L2-Medium | I14: =IF(E14>=60,"✔ Met","✘ Not Met") -> ✔ Met
A15: 2 | B15: PO2 | C15: Problem Analysis | D15: CO1(S2), CO2(S3), CO4(S2) | E15: =IFERROR((('CO & PO Attainment'!F6*2)+('CO & PO Attainment'!F7*3)+('CO & PO Attainment'!F9*2))/7,0) -> 0 | F15: 60 | G15: =E15-F15 -> -60 | H15: =IF(E15>=75,"L3-High",IF(E15>=60,"L2-Medium",IF(E15>=40,"L1-Low","L0-Below"))) -> L0-Below | I15: =IF(E15>=60,"✔ Met","✘ Not Met") -> ✘ Not Met
A16: 3 | B16: PO3 | C16: Design/Development of Solutions | D16: CO2(S2) | E16: =IFERROR((('CO & PO Attainment'!F7*2))/2,0) -> 60 | F16: 60 | G16: =E16-F16 -> 0 | H16: =IF(E16>=75,"L3-High",IF(E16>=60,"L2-Medium",IF(E16>=40,"L1-Low","L0-Below"))) -> L2-Medium | I16: =IF(E16>=60,"✔ Met","✘ Not Met") -> ✔ Met
A17: 4 | B17: PO4 | C17: Conduct Investigations | D17: — | E17: — | F17: — | G17: — | H17: — | I17: —
A18: 5 | B18: PO5 | C18: Modern Tool Usage | D18: — | E18: — | F18: — | G18: — | H18: — | I18: —
A19: 6 | B19: PO6 | C19: The Engineer and Society | D19: — | E19: — | F19: — | G19: — | H19: — | I19: —
A20: 7 | B20: PO7 | C20: Environment and Sustainability | D20: — | E20: — | F20: — | G20: — | H20: — | I20: —
A21: 8 | B21: PO8 | C21: Ethics | D21: — | E21: — | F21: — | G21: — | H21: — | I21: —
A22: 9 | B22: PO9 | C22: Individual and Team Work | D22: CO4(S2) | E22: =IFERROR((('CO & PO Attainment'!F9*2))/2,0) -> 0 | F22: 60 | G22: =E22-F22 -> -60 | H22: =IF(E22>=75,"L3-High",IF(E22>=60,"L2-Medium",IF(E22>=40,"L1-Low","L0-Below"))) -> L0-Below | I22: =IF(E22>=60,"✔ Met","✘ Not Met") -> ✘ Not Met
A23: 10 | B23: PO10 | C23: Communication | D23: CO3(S3) | E23: =IFERROR((('CO & PO Attainment'!F8*3))/3,0) -> 60.833333 | F23: 60 | G23: =E23-F23 -> 0.83333333 | H23: =IF(E23>=75,"L3-High",IF(E23>=60,"L2-Medium",IF(E23>=40,"L1-Low","L0-Below"))) -> L2-Medium | I23: =IF(E23>=60,"✔ Met","✘ Not Met") -> ✔ Met
A24: 11 | B24: PO11 | C24: Project Management and Finance | D24: — | E24: — | F24: — | G24: — | H24: — | I24: —
A25: 12 | B25: PO12 | C25: Life-long Learning | D25: CO4(S2) | E25: =IFERROR((('CO & PO Attainment'!F9*2))/2,0) -> 0 | F25: 60 | G25: =E25-F25 -> -60 | H25: =IF(E25>=75,"L3-High",IF(E25>=60,"L2-Medium",IF(E25>=40,"L1-Low","L0-Below"))) -> L0-Below | I25: =IF(E25>=60,"✔ Met","✘ Not Met") -> ✘ Not Met

Sheet Feedback Report
A1: VIVA VOCE RUBRIC — INDIVIDUAL STUDENT FEEDBACK REPORT
A2: Auto-generated score labels per criterion + overall feedback text for each student.
A4: # | B4: Reg No | C4: Student Name | D4: C1 | E4: C2 | F4: C3 | G4: C4 | H4: C5 | I4: Total | J4: Grade | K4: CO Att% | L4: Overall Viva Feedback
A5: 1 | B5: ='Score Entry'!B12 -> S001 | C5: ='Score Entry'!C12 -> Aarav Sharma | D5: =IF('Score Entry'!D12=4,"Excellent",IF('Score Entry'!D12=3,"Good",IF('Score Entry'!D12=2,"Fair","Poor"))) -> Poor | E5: =IF('Score Entry'!F12=4,"Excellent",IF('Score Entry'!F12=3,"Good",IF('Score Entry'!F12=2,"Fair","Poor"))) -> Excellent | F5: =IF('Score Entry'!H12=4,"Excellent",IF('Score Entry'!H12=3,"Good",IF('Score Entry'!H12=2,"Fair","Poor"))) -> Fair | G5: =IF('Score Entry'!J12=4,"Excellent",IF('Score Entry'!J12=3,"Good",IF('Score Entry'!J12=2,"Fair","Poor"))) -> Poor | H5: =IF('Score Entry'!L12=4,"Excellent",IF('Score Entry'!L12=3,"Good",IF('Score Entry'!L12=2,"Fair","Poor"))) -> Good | I5: ='Score Entry'!N12 -> 55 | J5: ='Score Entry'!O12 -> B+ | K5: ='Score Entry'!Q12 -> 0.55 | L5: =IF('Score Entry'!N12>=90,"Outstanding viva — exemplary conceptual understanding, technical accuracy and confidence",IF('Score Entry'!N12>=75,"Excellent viva — strong knowledge and communication; minor technical refinements needed",IF('Score Entry'!N12>=60,"Good viva — solid understanding demonstrated; deepen technical explanation and problem-solving",IF('Score Entry'!N12>=40,"Satisfactory — basic concepts grasped; improve confidence, technical accuracy and spontaneous response","Needs improvement — revisit fundamentals; focus on conceptual clarity, technical reasoning and communication")))) -> Satisfactory — basic concepts grasped; improve confidence, technical accuracy and spontaneous response
A6: 2 | B6: ='Score Entry'!B13 -> S002 | C6: ='Score Entry'!C13 -> Priya Patel | D6: =IF('Score Entry'!D13=4,"Excellent",IF('Score Entry'!D13=3,"Good",IF('Score Entry'!D13=2,"Fair","Poor"))) -> Excellent | E6: =IF('Score Entry'!F13=4,"Excellent",IF('Score Entry'!F13=3,"Good",IF('Score Entry'!F13=2,"Fair","Poor"))) -> Fair | F6: =IF('Score Entry'!H13=4,"Excellent",IF('Score Entry'!H13=3,"Good",IF('Score Entry'!H13=2,"Fair","Poor"))) -> Poor | G6: =IF('Score Entry'!J13=4,"Excellent",IF('Score Entry'!J13=3,"Good",IF('Score Entry'!J13=2,"Fair","Poor"))) -> Excellent | H6: =IF('Score Entry'!L13=4,"Excellent",IF('Score Entry'!L13=3,"Good",IF('Score Entry'!L13=2,"Fair","Poor"))) -> Excellent | I6: ='Score Entry'!N13 -> 76.25 | J6: ='Score Entry'!O13 -> A+ | K6: ='Score Entry'!Q13 -> 0.7625 | L6: =IF('Score Entry'!N13>=90,"Outstanding viva — exemplary conceptual understanding, technical accuracy and confidence",IF('Score Entry'!N13>=75,"Excellent viva — strong knowledge and communication; minor technical refinements needed",IF('Score Entry'!N13>=60,"Good viva — solid understanding demonstrated; deepen technical explanation and problem-solving",IF('Score Entry'!N13>=40,"Satisfactory — basic concepts grasped; improve confidence, technical accuracy and spontaneous response","Needs improvement — revisit fundamentals; focus on conceptual clarity, technical reasoning and communication")))) -> Excellent viva — strong knowledge and communication; minor technical refinements needed
A7: 3 | B7: ='Score Entry'!B14 -> S003 | C7: ='Score Entry'!C14 -> Rohan Mehta | D7: =IF('Score Entry'!D14=4,"Excellent",IF('Score Entry'!D14=3,"Good",IF('Score Entry'!D14=2,"Fair","Poor"))) -> Poor | E7: =IF('Score Entry'!F14=4,"Excellent",IF('Score Entry'!F14=3,"Good",IF('Score Entry'!F14=2,"Fair","Poor"))) -> Poor | F7: =IF('Score Entry'!H14=4,"Excellent",IF('Score Entry'!H14=3,"Good",IF('Score Entry'!H14=2,"Fair","Poor"))) -> Poor | G7: =IF('Score Entry'!J14=4,"Excellent",IF('Score Entry'!J14=3,"Good",IF('Score Entry'!J14=2,"Fair","Poor"))) -> Fair | H7: =IF('Score Entry'!L14=4,"Excellent",IF('Score Entry'!L14=3,"Good",IF('Score Entry'!L14=2,"Fair","Poor"))) -> Excellent | I7: ='Score Entry'!N14 -> 41.25 | J7: ='Score Entry'!O14 -> B | K7: ='Score Entry'!Q14 -> 0.4125 | L7: =IF('Score Entry'!N14>=90,"Outstanding viva — exemplary conceptual understanding, technical accuracy and confidence",IF('Score Entry'!N14>=75,"Excellent viva — strong knowledge and communication; minor technical refinements needed",IF('Score Entry'!N14>=60,"Good viva — solid understanding demonstrated; deepen technical explanation and problem-solving",IF('Score Entry'!N14>=40,"Satisfactory — basic concepts grasped; improve confidence, technical accuracy and spontaneous response","Needs improvement — revisit fundamentals; focus on conceptual clarity, technical reasoning and communication")))) -> Satisfactory — basic concepts grasped; improve confidence, technical accuracy and spontaneous response
A8: 4 | B8: ='Score Entry'!B15 -> S004 | C8: ='Score Entry'!C15 -> Sneha Reddy | D8: =IF('Score Entry'!D15=4,"Excellent",IF('Score Entry'!D15=3,"Good",IF('Score Entry'!D15=2,"Fair","Poor"))) -> Poor | E8: =IF('Score Entry'!F15=4,"Excellent",IF('Score Entry'!F15=3,"Good",IF('Score Entry'!F15=2,"Fair","Poor"))) -> Excellent | F8: =IF('Score Entry'!H15=4,"Excellent",IF('Score Entry'!H15=3,"Good",IF('Score Entry'!H15=2,"Fair","Poor"))) -> Poor | G8: =IF('Score Entry'!J15=4,"Excellent",IF('Score Entry'!J15=3,"Good",IF('Score Entry'!J15=2,"Fair","Poor"))) -> Poor | H8: =IF('Score Entry'!L15=4,"Excellent",IF('Score Entry'!L15=3,"Good",IF('Score Entry'!L15=2,"Fair","Poor"))) -> Poor | I8: ='Score Entry'!N15 -> 43.75 | J8: ='Score Entry'!O15 -> B | K8: ='Score Entry'!Q15 -> 0.4375 | L8: =IF('Score Entry'!N15>=90,"Outstanding viva — exemplary conceptual understanding, technical accuracy and confidence",IF('Score Entry'!N15>=75,"Excellent viva — strong knowledge and communication; minor technical refinements needed",IF('Score Entry'!N15>=60,"Good viva — solid understanding demonstrated; deepen technical explanation and problem-solving",IF('Score Entry'!N15>=40,"Satisfactory — basic concepts grasped; improve confidence, technical accuracy and spontaneous response","Needs improvement — revisit fundamentals; focus on conceptual clarity, technical reasoning and communication")))) -> Satisfactory — basic concepts grasped; improve confidence, technical accuracy and spontaneous response
